Workbook

Sheet Main
A1: Apple | D1: Price | E1: 309
D2: Share | E2: 14598.18 | F2: Q326
D3: MC | E3: =+E2*E1 -> 4510837.6
D4: Cash | E4: 62399 | F4: Q326
D5: Debt | E5: =+11007+71340 -> 82347 | F5: Q326
D6: EV | E6: =+E3-E4+E5 -> 4530785.6
A9: P/FCF | B9: =+E3/SUM(Model!I126:L126) -> 26.657434 | D9: BETA | E9: 1.09 | G9: WACC | H9: =+(E3/(E3+E5))*E10+(E5/(E3+E5))*F11*(1-Model!Z52) -> 0.10300751 | J9: mu | K9: 0.0007926
A10: EV/EBITDA | B10: =+E6/SUM(Model!I70:L70) -> 26.975545 | D10: CAPM | E10: =+'[1]Zero-rate curve US'!J3+E9*(0.1-'[1]Zero-rate curve US'!J3) -> 0.10434567 | J10: sigma
A11: EV/FCF | B11: =+E6/SUM(Model!I126:L126) -> 26.775319 | D11: Cost of Debt | E11: =+'[1]Zero-rate curve US'!I3+(E12/100) -> 0.053294304 | F11: 0.0352
A12: Inc. Margin | D12: Cr. Spread | E12: =+'[1]Credit Spread US'!J6 -> 0.79478261
A13: P/E | B13: =+E1/SUM(Model!I42:L42) -> 35.422428 | D13: Rating | E13: AAA | F13: Aaa
A14: Leverage | B14: =+(E5-E4)/SUM(Model!I70:L70) -> 0.11876708 | E14: S&P | F14: Moody’s
A17: Products
A18: iPhone | B18: Smartphone and iOS perating system
B19: Types
B20: Pro
B21: Air
B22: Normal
B23: e
A25: Mac | B25: PC based on MacOS
B26: Macbook Air
B27: Macbook Pro
B28: Macbook Neo
B29: iMac
B30: Mac Mini
B31: Mac Studio
B32: Mac Pro | C32: ?
A34: iPad | B34: tabet based on iPadOS
B35: iPad Pro
B36: iPad Aid
B37: iPad
B38: iPad mini
A40: Wearables | B40: smartwatches, headphones, “Spatial computers”
B41: Apple Watch
B42: AirPods and Beats
B43: Apple Vision Pro (spatial computer based on VisionOS)
A44: Home
B45: Apple TV (based on tvOS)
B46: HomePod
A48: Services
...

Sheet Model
A1: Main
A2: in Million | B2: Q124 | C2: Q224 | D2: Q324 | E2: Q424 | F2: Q125 | G2: Q225 | H2: Q325 | I2: Q425 | J2: Q126 | K2: Q226 | L2: Q326 | M2: Q426 | Q2: 2016 | R2: =+Q2+1 -> 2017 | S2: =+R2+1 -> 2018 | T2: =+S2+1 -> 2019 | U2: =+T2+1 -> 2020 | V2: =+U2+1 -> 2021 | W2: =+V2+1 -> 2022 | X2: =+W2+1 -> 2023 | Y2: =+X2+1 -> 2024 | ... AE2: =+AD2+1 -> 2030
A4: iPhone | B4: 69702 | C4: 45963 | D4: 39296 | E4: 46222 | F4: 69138 | G4: 46841 | H4: 44582 | I4: 49025 | J4: 85269 | K4: 56994 | L4: 54252 | Q4: 86613 | R4: 96600 | S4: 166699 | T4: 142381 | U4: 137781 | V4: 191973 | W4: 205489 | X4: 200583 | Y4: 201183 | Z4: 209586
A5: Y/Y | F5: =+F4/B4-1 -> -0.0080915899 | G5: =+G4/C4-1 -> 0.019102321 | H5: =+H4/D4-1 -> 0.13451751 | I5: =+I4/E4-1 -> 0.060642118 | J5: =+J4/F4-1 -> 0.23331598 | K5: =+K4/G4-1 -> 0.21675455 | L5: =+L4/H4-1 -> 0.21690368 | R5: =+R4/Q4-1 -> 0.11530602 | S5: =+S4/R4-1 -> 0.72566253 | T5: =+T4/S4-1 -> -0.1458797 | U5: =+U4/T4-1 -> -0.032307682 | V5: =+V4/U4-1 -> 0.39331983 | W5: =+W4/V4-1 -> 0.070405734 | X5: =+X4/W4-1 -> -0.023874757 | Y5: =+Y4/X4-1 -> 0.0029912804 | Z5: =+Z4/Y4-1 -> 0.041767943
A6: Mac | B6: 7780 | C6: 7451 | D6: 7009 | E6: 7744 | F6: 8987 | G6: 7949 | H6: 8046 | I6: 8726 | J6: 8386 | K6: 8399 | L6: 10352 | Q6: 49952 | R6: 54938 | S6: 18805 | T6: 25740 | U6: 28622 | V6: 35190 | W6: 40177 | X6: 29357 | Y6: 29984 | Z6: 33708
A7: Y/Y | F7: =+F6/B6-1 -> 0.15514139 | G7: =+G6/C6-1 -> 0.066836666 | H7: =+H6/D6-1 -> 0.14795263 | I7: =+I6/E6-1 -> 0.12680785 | J7: =+J6/F6-1 -> -0.066874374 | K7: =+K6/G6-1 -> 0.056610894 | L7: =+L6/H6-1 -> 0.28660204 | R7: =+R6/Q6-1 -> 0.099815823 | S7: =+S6/R6-1 -> -0.65770505 | T7: =+T6/S6-1 -> 0.3687849 | U7: =+U6/T6-1 -> 0.11196581 | V7: =+V6/U6-1 -> 0.22947383 | W7: =+W6/V6-1 -> 0.1417164 | X7: =+X6/W6-1 -> -0.26930831 | Y7: =+Y6/X6-1 -> 0.021357768 | Z7: =+Z6/Y6-1 -> 0.12419957
A8: iPad | B8: 7023 | C8: 5559 | D8: 7162 | E8: 6950 | F8: 8088 | G8: 6402 | H8: 6581 | I8: 6952 | J8: 8595 | K8: 6914 | L8: 6191 | Q8: 48492 | R8: 44764 | S8: 25484 | T8: 21280 | U8: 23724 | V8: 31862 | W8: 29292 | X8: 28300 | Y8: 26694 | Z8: 28023
A9: Y/Y | F9: =+F8/B8-1 -> 0.1516446 | G9: =+G8/C8-1 -> 0.15164598 | H9: =+H8/D8-1 -> -0.081122591 | I9: =+I8/E8-1 -> 0.00028776978 | J9: =+J8/F8-1 -> 0.06268546 | K9: =+K8/G8-1 -> 0.079975008 | L9: =+L8/H8-1 -> -0.05926151 | R9: =+R8/Q8-1 -> -0.07687866 | S9: =+S8/R8-1 -> -0.43070324 | T9: =+T8/S8-1 -> -0.16496625 | U9: =+U8/T8-1 -> 0.11484962 | V9: =+V8/U8-1 -> 0.34302816 | W9: =+W8/V8-1 -> -0.080660348 | X9: =+X8/W8-1 -> -0.033865902 | Y9: =+Y8/X8-1 -> -0.056749117 | Z9: =+Z8/Y8-1 -> 0.049786469
A10: Wearable | B10: 11953 | C10: 7913 | D10: 8097 | E10: 9042 | F10: 11747 | G10: 7522 | H10: 7404 | I10: 9013 | J10: 11493 | K10: 7901 | L10: 7883 | Q10: 16928 | R10: 17733 | S10: 37190 | T10: 24482 | U10: 30620 | V10: 38367 | W10: 41241 | X10: 39845 | Y10: 37005 | Z10: 35686
A11: Y/Y | F11: =+F10/B10-1 -> -0.017234167 | G11: =+G10/C10-1 -> -0.049412359 | H11: =+H10/D10-1 -> -0.085587255 | I11: =+I10/E10-1 -> -0.003207255 | J11: =+J10/F10-1 -> -0.021622542 | K11: =+K10/G10-1 -> 0.050385536 | L11: =+L10/H10-1 -> 0.06469476 | R11: =+R10/Q10-1 -> 0.047554348 | S11: =+S10/R10-1 -> 1.0972199 | T11: =+T10/S10-1 -> -0.34170476 | U11: =+U10/T10-1 -> 0.25071481 | V11: =+V10/U10-1 -> 0.25300457 | W11: =+W10/V10-1 -> 0.074908124 | X11: =+X10/W10-1 -> -0.03384981 | Y11: =+Y10/X10-1 -> -0.071276195 | Z11: =+Z10/Y10-1 -> -0.035643832
A12: Products | B12: =+B10+B8+B6+B4 -> 96458 | C12: =+C10+C8+C6+C4 -> 66886 | D12: =+D10+D8+D6+D4 -> 61564 | E12: =+E10+E8+E6+E4 -> 69958 | F12: =+F10+F8+F6+F4 -> 97960 | G12: =+G10+G8+G6+G4 -> 68714 | H12: =+H10+H8+H6+H4 -> 66613 | I12: =+I10+I8+I6+I4 -> 73716 | ... L12: =+L10+L8+L6+L4 -> 78678 | Q12: =+Q10+Q8+Q6+Q4 -> 201985 | R12: =+R10+R8+R6+R4 -> 214035 | S12: =+S10+S8+S6+S4 -> 248178 | T12: =+T10+T8+T6+T4 -> 213883 | U12: =+U10+U8+U6+U4 -> 220747 | V12: =+V10+V8+V6+V4 -> 297392 | W12: =+W10+W8+W6+W4 -> 316199 | X12: =+X10+X8+X6+X4 -> 298085 | ... Z12: =+Z10+Z8+Z6+Z4 -> 307003
A13: Y/Y | F13: =+F12/B12-1 -> 0.015571544 | G13: =+G12/C12-1 -> 0.027330084 | H13: =+H12/D12-1 -> 0.082012215 | I13: =+I12/E12-1 -> 0.053717945 | J13: =+J12/F12-1 -> 0.16111678 | K13: =+K12/G12-1 -> 0.16727304 | L13: =+L12/H12-1 -> 0.1811208 | R13: =+R12/Q12-1 -> 0.059657895 | S13: =+S12/R12-1 -> 0.15952064 | T13: =+T12/S12-1 -> -0.13818711 | U13: =+U12/T12-1 -> 0.032092312 | V13: =+V12/U12-1 -> 0.34720744 | W13: =+W12/V12-1 -> 0.063239764 | X13: =+X12/W12-1 -> -0.057286709 | Y13: =+Y12/X12-1 -> -0.010798933 | Z13: =+Z12/Y12-1 -> 0.04116107
A14: Services | B14: 23117 | C14: 23867 | D14: 24213 | E14: 24972 | F14: 26340 | G14: 26645 | H14: 27423 | I14: 28750 | J14: 30013 | K14: 30976 | L14: 30739 | Q14: 11132 | R14: 12863 | S14: 17417 | T14: 46291 | U14: 53768 | V14: 68425 | W14: 78129 | X14: 85200 | Y14: 96169 | Z14: 109158
A15: Y/Y | F15: =+F14/B14-1 -> 0.13942121 | G15: =+G14/C14-1 -> 0.11639502 | H15: =+H14/D14-1 -> 0.13257341 | I15: =+I14/E14-1 -> 0.15128944 | J15: =+J14/F14-1 -> 0.13944571 | K15: =+K14/G14-1 -> 0.16254457 | L15: =+L14/H14-1 -> 0.1209204 | R15: =+R14/Q14-1 -> 0.15549766 | S15: =+S14/R14-1 -> 0.35403872 | T15: =+T14/S14-1 -> 1.6578056 | U15: =+U14/T14-1 -> 0.16152168 | V15: =+V14/U14-1 -> 0.27259708 | W15: =+W14/V14-1 -> 0.14181951 | X15: =+X14/W14-1 -> 0.090504166 | Y15: =+Y14/X14-1 -> 0.12874413 | Z15: =+Z14/Y14-1 -> 0.13506431
A16: Revenue | B16: =+B14+B12 -> 119575 | C16: =+C14+C12 -> 90753 | D16: =+D14+D12 -> 85777 | E16: =+E14+E12 -> 94930 | F16: =+F14+F12 -> 124300 | G16: =+G14+G12 -> 95359 | H16: =+H14+H12 -> 94036 | I16: =+I14+I12 -> 102466 | ... L16: =+L14+L12 -> 109417 | Q16: =+Q14+Q12 -> 213117 | R16: =+R14+R12 -> 226898 | S16: =+S14+S12 -> 265595 | T16: =+T14+T12 -> 260174 | U16: =+U14+U12 -> 274515 | V16: =+V14+V12 -> 365817 | W16: =+W14+W12 -> 394328 | X16: =+X14+X12 -> 383285 | ... Z16: =+Z14+Z12 -> 416161 | AA16: =+Z16*1.08 -> 449453.88 | AB16: =+AA16*1.06 -> 476421.11 | AC16: =+AB16*1.06 -> 505006.38 | AD16: =+AC16*1.06 -> 535306.76 | AE16: =+AD16*1.06 -> 567425.17
A17: Y/Y | F17: =+F16/B16-1 -> 0.039514949 | G17: =+G16/C16-1 -> 0.050753143 | H17: =+H16/D16-1 -> 0.096284552 | I17: =+I16/E16-1 -> 0.07938481 | J17: =+J16/F16-1 -> 0.15652454 | K17: =+K16/G16-1 -> 0.16595182 | L17: =+L16/H16-1 -> 0.16356502 | R17: =+R16/Q16-1 -> 0.064664011 | S17: =+S16/R16-1 -> 0.170548 | T17: =+T16/S16-1 -> -0.020410776 | U17: =+U16/T16-1 -> 0.055120804 | V17: =+V16/U16-1 -> 0.33259385 | W17: =+W16/V16-1 -> 0.077937876 | X17: =+X16/W16-1 -> -0.028004605 | Y17: =+Y16/X16-1 -> 0.020219941 | ... AE17: =+AE16/AD16-1 -> 0.06
A18: Products COGS | B18: 58440 | C18: 42424 | D18: 39803 | E18: 44566 | F18: 59447 | G18: 44030 | H18: 43620 | I18: 47019 | J18: 67478 | K18: 49179 | L18: 47153 | T18: 144996 | U18: 151286 | V18: 192266 | W18: 201471 | X18: 189282 | Y18: 185233 | Z18: 194116
A19: % COGS | B19: =+B18/B22 -> 0.90296663 | C19: =+C18/C22 -> 0.87504641 | D19: =+D18/D22 -> 0.86342437 | E19: =+E18/E22 -> 0.87297017 | F19: =+F18/F22 -> 0.90037107 | G19: =+G18/G22 -> 0.87201933 | H19: =+H18/H22 -> 0.8668866 | I19: =+I18/I22 -> 0.86871132 | ... L19: =+L18/L22 -> 0.8628653 | Q19: =+Q18/Q22 -> 0 | R19: =+R18/R22 -> 0 | S19: =+S18/S22 -> 0 | T19: =+T18/T22 -> 0.89624309 | U19: =+U18/U22 -> 0.8922322 | V19: =+V18/V22 -> 0.9027378 | W19: =+W18/W22 -> 0.90125075 | X19: =+X18/X22 -> 0.88392945 | ... Z19: =+Z18/Z22 -> 0.87851195
A20: Services COGS | B20: 6280 | C20: 6058 | D20: 6296 | E20: 6485 | F20: 6578 | G20: 6462 | H20: 6698 | I20: 7106 | J20: 7047 | K20: 7224 | L20: 7494 | T20: 16786 | U20: 18273 | V20: 20715 | W20: 22075 | X20: 24855 | Y20: 25119 | Z20: 26844
A21: % COGS | B21: =+B20/B22 -> 0.097033375 | C21: =+C20/C22 -> 0.12495359 | D21: =+D20/D22 -> 0.13657563 | E21: =+E20/E22 -> 0.12702983 | F21: =+F20/F22 -> 0.099628928 | G21: =+G20/G22 -> 0.12798067 | H21: =+H20/H22 -> 0.1331134 | I21: =+I20/I22 -> 0.13128868 | ... L21: =+L20/L22 -> 0.1371347 | Q21: =+Q20/Q24 -> 0 | R21: =+R20/R24 -> 0 | S21: =+S20/S24 -> 0 | T21: =+T20/T24 -> 0.1706033 | U21: =+U20/U24 -> 0.17410153 | V21: =+V20/V24 -> 0.13553744 | W21: =+W20/W24 -> 0.12925835 | X21: =+X20/X24 -> 0.14694232 | ... Z21: =+Z20/Z24 -> 0.13751979
A22: COGS | B22: =+B20+B18 -> 64720 | C22: =+C20+C18 -> 48482 | D22: =+D20+D18 -> 46099 | E22: =+E20+E18 -> 51051 | F22: =+F20+F18 -> 66025 | G22: =+G20+G18 -> 50492 | H22: =+H20+H18 -> 50318 | I22: =+I20+I18 -> 54125 | ... L22: =+L20+L18 -> 54647 | Q22: 131376 | R22: 141048 | S22: 163756 | T22: =+T20+T18 -> 161782 | U22: =+U20+U18 -> 169559 | V22: =+V20+V18 -> 212981 | W22: =+W20+W18 -> 223546 | X22: =+X20+X18 -> 214137 | Y22: =+Y20+Y18 -> 210352 | Z22: =+Z20+Z18 -> 220960 | AA22: =+AA16-AA24 -> 238210.56 | AB22: =+AB16-AB24 -> 250121.08 | AC22: =+AC16-AC24 -> 262603.32 | AD22: =+AD16-AD24 -> 275682.98 | AE22: =+AE16-AE24 -> 289386.84
A23: % Rev | B23: =+B22/B$16 -> 0.54125026 | C23: =+C22/C$16 -> 0.53421925 | D23: =+D22/D$16 -> 0.53742845 | E23: =+E22/E$16 -> 0.5377752 | F23: =+F22/F$16 -> 0.53117458 | G23: =+G22/G$16 -> 0.52949381 | H23: =+H22/H$16 -> 0.53509294 | I23: =+I22/I$16 -> 0.528224 | ... L23: =+L22/L$16 -> 0.49943793 | Q23: =+Q22/Q$16 -> 0.61645012 | R23: =+R22/R$16 -> 0.62163615 | S23: =+S22/S$16 -> 0.61656281 | T23: =+T22/T$16 -> 0.62182232 | U23: =+U22/U$16 -> 0.61766752 | V23: =+V22/V$16 -> 0.5822064 | W23: =+W22/W$16 -> 0.56690369 | X23: =+X22/X$16 -> 0.5586887 | ... AE23: =+AE22/AE$16 -> 0.51
A24: Gross Profit | B24: =+B16-B22 -> 54855 | C24: =+C16-C22 -> 42271 | D24: =+D16-D22 -> 39678 | E24: =+E16-E22 -> 43879 | F24: =+F16-F22 -> 58275 | G24: =+G16-G22 -> 44867 | H24: =+H16-H22 -> 43718 | I24: =+I16-I22 -> 48341 | ... L24: =+L16-L22 -> 54770 | Q24: =+Q16-Q22 -> 81741 | R24: =+R16-R22 -> 85850 | S24: =+S16-S22 -> 101839 | T24: =+T16-T22 -> 98392 | U24: =+U16-U22 -> 104956 | V24: =+V16-V22 -> 152836 | W24: =+W16-W22 -> 170782 | X24: =+X16-X22 -> 169148 | ... Z24: =+Z16-Z22 -> 195201 | AA24: =+AA16*0.47 -> 211243.32 | AB24: =+AB16*0.475 -> 226300.03 | AC24: =+AC16*0.48 -> 242403.06 | AD24: =+AD16*0.485 -> 259623.78 | AE24: =+AE16*0.49 -> 278038.33
A25: % Rev | B25: =+B24/B$16 -> 0.45874974 | C25: =+C24/C$16 -> 0.46578075 | D25: =+D24/D$16 -> 0.46257155 | E25: =+E24/E$16 -> 0.4622248 | F25: =+F24/F$16 -> 0.46882542 | G25: =+G24/G$16 -> 0.47050619 | H25: =+H24/H$16 -> 0.46490706 | I25: =+I24/I$16 -> 0.471776 | ... L25: =+L24/L$16 -> 0.50056207 | Q25: =+Q24/Q$16 -> 0.38354988 | R25: =+R24/R$16 -> 0.37836385 | S25: =+S24/S$16 -> 0.38343719 | T25: =+T24/T$16 -> 0.37817768 | U25: =+U24/U$16 -> 0.38233248 | V25: =+V24/V$16 -> 0.4177936 | W25: =+W24/W$16 -> 0.43309631 | X25: =+X24/X$16 -> 0.4413113 | ... AE25: =+AE24/AE$16 -> 0.49
A26: R&D | B26: 7696 | C26: 7903 | D26: 8006 | E26: 7765 | F26: 8268 | G26: 8550 | H26: 8866 | I26: 8866 | J26: 10887 | K26: 11419 | L26: 11729 | Q26: 10045 | R26: 11581 | S26: 14236 | T26: 16217 | U26: 18752 | V26: 21914 | W26: 26251 | X26: 29915 | Y26: 31370 | Z26: 34550 | AA26: =+AA16*0.08 -> 35956.31 | AB26: =+AB16*0.08 -> 38113.689 | AC26: =+AC16*0.076 -> 38380.485 | AD26: =+AD16*0.076 -> 40683.314 | AE26: =+AE16*0.076 -> 43124.313
A27: % Rev | B27: =+B26/B$16 -> 0.06436128 | C27: =+C26/C$16 -> 0.087082521 | D27: =+D26/D$16 -> 0.093335043 | E27: =+E26/E$16 -> 0.081797114 | F27: =+F26/F$16 -> 0.066516492 | G27: =+G26/G$16 -> 0.089661175 | H27: =+H26/H$16 -> 0.094283041 | I27: =+I26/I$16 -> 0.086526262 | ... L27: =+L26/L$16 -> 0.10719541 | Q27: =+Q26/Q$16 -> 0.047133734 | R27: =+R26/R$16 -> 0.051040556 | S27: =+S26/S$16 -> 0.053600407 | T27: =+T26/T$16 -> 0.062331363 | U27: =+U26/U$16 -> 0.068309564 | V27: =+V26/V$16 -> 0.059904269 | W27: =+W26/W$16 -> 0.066571484 | X27: =+X26/X$16 -> 0.078048971 | ... AE27: =+AE26/AE$16 -> 0.076
A28: SG&A | B28: 6786 | C28: 6468 | D28: 6320 | E28: 6523 | F28: 7175 | G28: 6728 | H28: 6650 | I28: 7048 | J28: 7492 | K28: 7477 | L28: 7346 | Q28: 14194 | R28: 15261 | S28: 16705 | T28: 18245 | U28: 19916 | V28: 21973 | W28: 25094 | X28: 24932 | Y28: 26097 | Z28: 27601 | AA28: =+AA16*0.065 -> 29214.502 | AB28: =+AB16*0.065 -> 30967.372 | AC28: =+AC16*0.063 -> 31815.402 | AD28: =+AD16*0.063 -> 33724.326 | AE28: =+AE16*0.063 -> 35747.786
A29: % Rev | B29: =+B28/B$16 -> 0.056750993 | C29: =+C28/C$16 -> 0.071270371 | D29: =+D28/D$16 -> 0.073679425 | E29: =+E28/E$16 -> 0.068713789 | F29: =+F28/F$16 -> 0.05772325 | G29: =+G28/G$16 -> 0.070554431 | H29: =+H28/H$16 -> 0.070717598 | I29: =+I28/I$16 -> 0.068783792 | ... L29: =+L28/L$16 -> 0.067137648 | Q29: =+Q28/Q$16 -> 0.066601914 | R29: =+R28/R$16 -> 0.067259297 | S29: =+S28/S$16 -> 0.062896515 | T29: =+T28/T$16 -> 0.070126146 | U29: =+U28/U$16 -> 0.07254977 | V29: =+V28/V$16 -> 0.060065552 | W29: =+W28/W$16 -> 0.063637378 | X29: =+X28/X$16 -> 0.065048202 | ... AE29: =+AE28/AE$16 -> 0.063
A30: OP Exp. | B30: =+B28+B26 -> 14482 | C30: =+C28+C26 -> 14371 | D30: =+D28+D26 -> 14326 | E30: =+E28+E26 -> 14288 | F30: =+F28+F26 -> 15443 | G30: =+G28+G26 -> 15278 | H30: =+H28+H26 -> 15516 | I30: =+I28+I26 -> 15914 | ... L30: =+L28+L26 -> 19075 | Q30: =+Q28+Q26 -> 24239 | R30: =+R28+R26 -> 26842 | S30: =+S28+S26 -> 30941 | T30: =+T28+T26 -> 34462 | U30: =+U28+U26 -> 38668 | V30: =+V28+V26 -> 43887 | W30: =+W28+W26 -> 51345 | X30: =+X28+X26 -> 54847 | ... Z30: =+Z28+Z26 -> 62151 | AA30: =+AA16*0.14 -> 62923.543 | AB30: =+AB16*0.14 -> 66698.956 | AC30: =+AC16*0.135 -> 68175.861 | AD30: =+AD16*0.135 -> 72266.413 | AE30: =+AE16*0.135 -> 76602.398
A31: % Rev | B31: =+B30/B$16 -> 0.12111227 | C31: =+C30/C$16 -> 0.15835289 | D31: =+D30/D$16 -> 0.16701447 | E31: =+E30/E$16 -> 0.1505109 | F31: =+F30/F$16 -> 0.12423974 | G31: =+G30/G$16 -> 0.16021561 | H31: =+H30/H$16 -> 0.16500064 | I31: =+I30/I$16 -> 0.15531005 | ... L31: =+L30/L$16 -> 0.17433306 | Q31: =+Q30/Q$16 -> 0.11373565 | R31: =+R30/R$16 -> 0.11829985 | S31: =+S30/S$16 -> 0.11649692 | T31: =+T30/T$16 -> 0.13245751 | U31: =+U30/U$16 -> 0.14085933 | V31: =+V30/V$16 -> 0.11996982 | W31: =+W30/W$16 -> 0.13020886 | X31: =+X30/X$16 -> 0.14309717 | ... AE31: =+AE30/AE$16 -> 0.135
A32: EBIT | B32: =+B24-B30 -> 40373 | C32: =+C24-C30 -> 27900 | D32: =+D24-D30 -> 25352 | E32: =+E24-E30 -> 29591 | F32: =+F24-F30 -> 42832 | G32: =+G24-G30 -> 29589 | H32: =+H24-H30 -> 28202 | I32: =+I24-I30 -> 32427 | ... L32: =+L24-L30 -> 35695 | Q32: =+Q24-Q30 -> 57502 | R32: =+R24-R30 -> 59008 | S32: =+S24-S30 -> 70898 | T32: =+T24-T30 -> 63930 | U32: =+U24-U30 -> 66288 | V32: =+V24-V30 -> 108949 | W32: =+W24-W30 -> 119437 | X32: =+X24-X30 -> 114301 | ... AE32: =+AE24-AE30 -> 201435.93
A33: % Rev | B33: =+B32/B$16 -> 0.33763747 | C33: =+C32/C$16 -> 0.30742785 | D33: =+D32/D$16 -> 0.29555708 | E33: =+E32/E$16 -> 0.31171389 | F33: =+F32/F$16 -> 0.34458568 | G33: =+G32/G$16 -> 0.31029059 | H33: =+H32/H$16 -> 0.29990642 | I33: =+I32/I$16 -> 0.31646595 | ... L33: =+L32/L$16 -> 0.32622901 | Q33: =+Q32/Q$16 -> 0.26981423 | R33: =+R32/R$16 -> 0.26006399 | S33: =+S32/S$16 -> 0.26694027 | T33: =+T32/T$16 -> 0.24572017 | U33: =+U32/U$16 -> 0.24147314 | V33: =+V32/V$16 -> 0.29782378 | W33: =+W32/W$16 -> 0.30288744 | X33: =+X32/X$16 -> 0.29821412 | ... AE33: =+AE32/AE$16 -> 0.355
A34: Other Income | B34: -50 | C34: 158 | D34: 142 | E34: 19 | F34: -248 | G34: -279 | H34: -171 | I34: 377 | J34: 150 | K34: -52 | L34: 572 | Q34: 1348 | R34: 2745 | S34: 2005 | T34: 1807 | U34: 803 | V34: 258 | W34: -334 | X34: -565 | Y34: 269 | Z34: -321 | AA34: 200 | AB34: 200 | AC34: 200 | AD34: 200 | AE34: 200
A35: % Rev | B35: =+B34/B$16 -> -0.00041814761 | C35: =+C34/C$16 -> 0.0017409893 | D35: =+D34/D$16 -> 0.0016554554 | E35: =+E34/E$16 -> 0.00020014748 | F35: =+F34/F$16 -> -0.001995173 | G35: =+G34/G$16 -> -0.0029257857 | H35: =+H34/H$16 -> -0.0018184525 | I35: =+I34/I$16 -> 0.0036792692 | ... L35: =+L34/L$16 -> 0.0052277068 | Q35: =+Q34/Q$16 -> 0.0063251641 | R35: =+R34/R$16 -> 0.012097947 | S35: =+S34/S$16 -> 0.0075490879 | T35: =+T34/T$16 -> 0.006945352 | U35: =+U34/U$16 -> 0.0029251589 | V35: =+V34/V$16 -> 0.00070527067 | W35: =+W34/W$16 -> -0.00084701061 | X35: =+X34/X$16 -> -0.0014740989 | ... AE35: =+AE34/AE$16 -> 0.00035246938
A36: EBT | B36: =+B32+B34 -> 40323 | C36: =+C32+C34 -> 28058 | D36: =+D32+D34 -> 25494 | E36: =+E32+E34 -> 29610 | F36: =+F32+F34 -> 42584 | G36: =+G32+G34 -> 29310 | H36: =+H32+H34 -> 28031 | I36: =+I32+I34 -> 32804 | ... L36: =+L32+L34 -> 36267 | Q36: =+Q32+Q34 -> 58850 | R36: =+R32+R34 -> 61753 | S36: =+S32+S34 -> 72903 | T36: =+T32+T34 -> 65737 | U36: =+U32+U34 -> 67091 | V36: =+V32+V34 -> 109207 | W36: =+W32+W34 -> 119103 | X36: =+X32+X34 -> 113736 | ... AE36: =+AE32+AE34 -> 201635.93
A37: % Rev | B37: =+B36/B$16 -> 0.33721932 | C37: =+C36/C$16 -> 0.30916884 | D37: =+D36/D$16 -> 0.29721254 | E37: =+E36/E$16 -> 0.31191404 | F37: =+F36/F$16 -> 0.34259051 | G37: =+G36/G$16 -> 0.3073648 | H37: =+H36/H$16 -> 0.29808797 | I37: =+I36/I$16 -> 0.32014522 | ... L37: =+L36/L$16 -> 0.33145672 | Q37: =+Q36/Q$16 -> 0.2761394 | R37: =+R36/R$16 -> 0.27216194 | S37: =+S36/S$16 -> 0.27448935 | T37: =+T36/T$16 -> 0.25266552 | U37: =+U36/U$16 -> 0.2443983 | V37: =+V36/V$16 -> 0.29852905 | W37: =+W36/W$16 -> 0.30204043 | X37: =+X36/X$16 -> 0.29674002 | ... AE37: =+AE36/AE$16 -> 0.35535247
A38: Taxes | B38: 6407 | C38: 4422 | D38: 4046 | E38: 14874 | F38: 6254 | G38: 4530 | H38: 4597 | I38: 5338 | J38: 8905 | K38: 6255 | L38: 6478 | Q38: 15685 | R38: 15738 | S38: 13372 | T38: 10481 | U38: 9680 | V38: 14527 | W38: 19300 | X38: 16741 | Y38: 29749 | Z38: 20719 | AA38: =+AA36*0.15 -> 22277.967 | AB38: =+AB36*0.15 -> 23970.161 | AC38: =+AC36*0.15 -> 26164.08 | AD38: =+AD36*0.15 -> 28133.605 | AE38: =+AE36*0.15 -> 30245.39
A39: % Rev | B39: =+B38/B$16 -> 0.053581434 | C39: =+C38/C$16 -> 0.048725662 | D39: =+D38/D$16 -> 0.047168821 | E39: =+E38/E$16 -> 0.15668387 | F39: =+F38/F$16 -> 0.050313757 | G39: =+G38/G$16 -> 0.047504693 | H39: =+H38/H$16 -> 0.048885533 | I39: =+I38/I$16 -> 0.052095329 | ... L39: =+L38/L$16 -> 0.059204694 | Q39: =+Q38/Q$16 -> 0.073598071 | R39: =+R38/R$16 -> 0.069361563 | S39: =+S38/S$16 -> 0.050347333 | T39: =+T38/T$16 -> 0.040284579 | U39: =+U38/U$16 -> 0.03526219 | V39: =+V38/V$16 -> 0.039711112 | W39: =+W38/W$16 -> 0.048944026 | X39: =+X38/X$16 -> 0.043677681 | ... AE39: =+AE38/AE$16 -> 0.05330287
A40: Net Income | B40: =+B36-B38 -> 33916 | C40: =+C36-C38 -> 23636 | D40: =+D36-D38 -> 21448 | E40: =+E36-E38 -> 14736 | F40: =+F36-F38 -> 36330 | G40: =+G36-G38 -> 24780 | H40: =+H36-H38 -> 23434 | I40: =+I36-I38 -> 27466 | ... L40: =+L36-L38 -> 29789 | Q40: =+Q36-Q38 -> 43165 | R40: =+R36-R38 -> 46015 | S40: =+S36-S38 -> 59531 | T40: =+T36-T38 -> 55256 | U40: =+U36-U38 -> 57411 | V40: =+V36-V38 -> 94680 | W40: =+W36-W38 -> 99803 | X40: =+X36-X38 -> 96995 | ... AE40: =+AE36-AE38 -> 171390.54
A41: % Rev | B41: =+B40/B$16 -> 0.28363788 | C41: =+C40/C$16 -> 0.26044318 | D41: =+D40/D$16 -> 0.25004372 | E41: =+E40/E$16 -> 0.15523017 | F41: =+F40/F$16 -> 0.29227675 | G41: =+G40/G$16 -> 0.25986011 | H41: =+H40/H$16 -> 0.24920243 | I41: =+I40/I$16 -> 0.26804989 | ... L41: =+L40/L$16 -> 0.27225203 | Q41: =+Q40/Q$16 -> 0.20254133 | R41: =+R40/R$16 -> 0.20280038 | S41: =+S40/S$16 -> 0.22414202 | T41: =+T40/T$16 -> 0.21238095 | U41: =+U40/U$16 -> 0.20913611 | V41: =+V40/V$16 -> 0.25881793 | W41: =+W40/W$16 -> 0.25309641 | X41: =+X40/X$16 -> 0.25306234 | ... AE41: =+AE40/AE$16 -> 0.3020496
...

Sheet Bond
A1: Main
B3: ISIN | C3: Bond Type | D3: Immediate Issuer | E3: Coupon (%) | F3: Maturity Date | G3: Callable | H3: Currency | I3: Seniority Level | J3: Yield To Worst
B4: US037833DN70 | C4: - | D4: Apple Inc. | E4: 2050 | F4: Sep 11, 2026 | G4: Yes | H4: USD | I4: Senior | J4: 3.68
B5: XS1135337498 | C5: - | D5: Apple Inc. | E5: 1625 | F5: Nov 10, 2026 | G5: Yes | H5: EUR | I5: Senior | J5: -
B6: US037833CJ77 | C6: - | D6: Apple Inc. | E6: 3350 | F6: Feb 09, 2027 | G6: Yes | H6: USD | I6: Senior | J6: 4.142
B7: US037833CR93 | C7: - | D7: Apple Inc. | E7: 3200 | F7: May 11, 2027 | G7: Yes | H7: USD | I7: Senior | J7: 4.1
B8: US037833CX61 | C8: Green | D8: Apple Inc. | E8: 3000 | F8: Jun 20, 2027 | G8: Yes | H8: USD | I8: Senior | J8: 4.145
B9: US037833DB33 | C9: - | D9: Apple Inc. | E9: 2900 | F9: Sep 12, 2027 | G9: Yes | H9: USD | I9: Senior | J9: 4.202
B10: XS1292389415 | C10: - | D10: Apple Inc. | E10: 2000 | F10: Sep 17, 2027 | G10: Yes | H10: EUR | I10: Senior | J10: -
B11: US037833DK32 | C11: - | D11: Apple Inc. | E11: 3000 | F11: Nov 13, 2027 | G11: Yes | H11: USD | I11: Senior | J11: 4.268
B12: US037833EC07 | C12: - | D12: Apple Inc. | E12: 1200 | F12: Feb 08, 2028 | G12: Yes | H12: USD | I12: Senior | J12: 4.387
B13: US037833ET32 | C13: - | D13: Apple Inc. | E13: 4000 | F13: May 10, 2028 | G13: Yes | H13: USD | I13: Senior | J13: 4.367
B14: US037833EY27 | C14: - | D14: Apple Inc. | E14: 4000 | F14: May 12, 2028 | G14: Yes | H14: USD | I14: Senior | J14: 4.416
B15: US037833EH93 | C15: - | D15: Apple Inc. | E15: 1400 | F15: Aug 05, 2028 | G15: Yes | H15: USD | I15: Senior | J15: 4.393
B16: XS1619312686 | C16: - | D16: Apple Inc. | E16: 1375 | F16: May 24, 2029 | G16: Yes | H16: EUR | I16: Senior | J16: -
B17: XS1269175466 | C17: - | D17: Apple Inc. | E17: 3050 | F17: Jul 31, 2029 | G17: Yes | H17: GBP | I17: Senior | J17: -
B18: US037833EN61 | C18: - | D18: Apple Inc. | E18: 3250 | F18: Aug 08, 2029 | G18: Yes | H18: USD | I18: Senior | J18: 4.472
B19: US037833DP29 | C19: - | D19: Apple Inc. | E19: 2200 | F19: Sep 11, 2029 | G19: Yes | H19: USD | I19: Senior | J19: 4.491
B20: CH0271171693 | C20: - | D20: Apple Inc. | E20: 750 | F20: Feb 25, 2030 | G20: -- | H20: CHF | I20: Senior | J20: -
B21: US037833EU05 | C21: - | D21: Apple Inc. | E21: 4150 | F21: May 10, 2030 | G21: Yes | H21: USD | I21: Senior | J21: 4.632
B22: US037833DU14 | C22: - | D22: Apple Inc. | E22: 1650 | F22: May 11, 2030 | G22: Yes | H22: USD | I22: Senior | J22: 4.703
B23: US037833EZ91 | C23: - | D23: Apple Inc. | E23: 4200 | F23: May 12, 2030 | G23: Yes | H23: USD | I23: Senior | J23: 4.588
B24: US037833DY36 | C24: - | D24: Apple Inc. | E24: 1250 | F24: Aug 20, 2030 | G24: Yes | H24: USD | I24: Senior | J24: 4.692
B25: US037833ED89 | C25: - | D25: Apple Inc. | E25: 1650 | F25: Feb 08, 2031 | G25: Yes | H25: USD | I25: Senior | J25: 4.675
B26: US037833EJ59 | C26: - | D26: Apple Inc. | E26: 1700 | F26: Aug 05, 2031 | G26: Yes | H26: USD | I26: Senior | J26: 4.747
B27: XS2079716937 | C27: Green | D27: Apple Inc. | E27: 500 | F27: Nov 15, 2031 | G27: Yes | H27: EUR | I27: Senior | J27: -
B28: US037833FA32 | C28: - | D28: Apple Inc. | E28: 4500 | F28: May 12, 2032 | G28: Yes | H28: USD | I28: Senior | J28: 4.704
B29: US037833EP10 | C29: - | D29: Apple Inc. | E29: 3350 | F29: Aug 08, 2032 | G29: Yes | H29: USD | I29: Senior | J29: 4.746
B30: US037833EV87 | C30: - | D30: Apple Inc. | E30: 4300 | F30: May 10, 2033 | G30: Yes | H30: USD | I30: Senior | J30: 4.747
B31: US037833FB15 | C31: - | D31: Apple Inc. | E31: 4750 | F31: May 12, 2035 | G31: Yes | H31: USD | I31: Senior | J31: 4.96
B32: US037833BW97 | C32: - | D32: Apple Inc. | E32: 4500 | F32: Feb 23, 2036 | G32: Yes | H32: USD | I32: Senior | J32: 4.965
B33: US037833EE62 | C33: - | D33: Apple Inc. | E33: 2375 | F33: Feb 08, 2041 | G33: Yes | H33: USD | I33: Senior | J33: 5.589
B34: XS1269176191 | C34: - | D34: Apple Inc. | E34: 3600 | F34: Jul 31, 2042 | G34: Yes | H34: GBP | I34: Senior | J34: -
B35: US037833AL42 | C35: - | D35: Apple Inc. | E35: 3850 | F35: May 04, 2043 | G35: Yes | H35: USD | I35: Senior | J35: 5.772
B36: US037833AT77 | C36: - | D36: Apple Inc. | E36: 4450 | F36: May 06, 2044 | G36: Yes | H36: USD | I36: Senior | J36: 5.797
B37: US037833BA77 | C37: - | D37: Apple Inc. | E37: 3450 | F37: Feb 09, 2045 | G37: Yes | H37: USD | I37: Senior | J37: 5.882
B38: US037833BH21 | C38: - | D38: Apple Inc. | E38: 4375 | F38: May 13, 2045 | G38: Yes | H38: USD | I38: Senior | J38: 5.88
B39: US037833BX70 | C39: - | D39: Apple Inc. | E39: 4650 | F39: Feb 23, 2046 | G39: Yes | H39: USD | I39: Senior | J39: 5.848
B40: US037833CD08 | C40: - | D40: Apple Inc. | E40: 3850 | F40: Aug 04, 2046 | G40: Yes | H40: USD | I40: Senior | J40: 5.924
B41: US037833CH12 | C41: - | D41: Apple Inc. | E41: 4250 | F41: Feb 09, 2047 | G41: Yes | H41: USD | I41: Senior | J41: 5.925
...
