Workbook

Sheet Main
A1: Adobe Inc. | E1: Price | F1: 277
E2: Share | F2: 397.5 | G2: Q226
E3: MC | F3: =+F2*F1 -> 110107.5
E4: Cash | F4: 5626 | G4: Q226
E5: Debt | F5: 6645 | G5: Q226
E6: EV | F6: =+F3-F4+F5 -> 111126.5
A10: P/FCF | B10: =+F3/SUM(Model!P139:S139) -> 10.71132 | D10: BETA | E10: 1.42 | G10: WACC | H10: =+(F3/(F3+F5))*E11+(F5/(F3+F5))*E12*(1-Model!AF68) -> 0.12633021
A11: EV/EBITDA | B11: =+F6/SUM(Model!P85:S85) -> 11.229436 | D11: CAPM | E11: =+0.0495+E10*(0.1-0.045) -> 0.1276
A12: EV/FCF | B12: =+F6/SUM(Model!P139:S139) -> 10.810448 | D12: Cost of Debt | E12: =+0.0495 + (E13/10) -> 0.12897826
A13: Inc. Margin | B13: =+(SUM(Model!P45:S45)-SUM(Model!L45:O45))/(SUM(Model!P23:S23)-SUM(Model!L23:O23)) -> 0.33461687 | D13: Cr. Spread | E13: =+'[1]Credit Spread US'!J6 -> 0.79478261
A14: P/E | B14: =+F1/SUM(Model!P59:S59) -> 15.842243 | D14: Rating | E14: A+ | F14: A1
A15: Leverage | B15: =+(F5-F4)/SUM(Model!P85:S85) -> 0.1029709 | E15: S&P | F15: Moody’s
A22: -> | B22: Subscription, fees charged for subscriptions, services and subscription-based consulting services
A23: -> | B23: Product, fees related to licences for on-premise software
A24: -> | B24: Services and Other, fees for project-based consulting and training and mantainance for ceertain licences
A26: Segments
A27: -> | B27: Digital Media, products to create (Creative Cloud)
A28: -> | B28: Digital experience, platform and set of products to optimize customer experience and data management (A Experience, Journey Optimiser, GenStudio, …)
A29: -> | B29: Publishing and Advertising, eLearning solutions, technial documentation, web conferences, PDF standard, …
A31: Total Adobe ARR | B31: annual value of subscriptions contracts in the creative & marketing and Business Professional & Consumers customer groups
A35: Geography division
B36: 2020 | C36: =+B36+1 -> 2021 | D36: =+C36+1 -> 2022 | E36: =+D36+1 -> 2023 | F36: =+E36+1 -> 2024 | G36: =+F36+1 -> 2025
A37: America | B37: 7454 | C37: 8996 | D37: 10251 | E37: 11654 | F37: 12891 | G37: 14120
C38: =+C37/B37-1 -> 0.2068688 | D38: =+D37/C37-1 -> 0.13950645 | E38: =+E37/D37-1 -> 0.1368647 | F38: =+F37/E37-1 -> 0.10614381 | G38: =+G37/F37-1 -> 0.095337833
A39: EMEA | B39: 3400 | C39: 4252 | D39: 4593 | E39: 4881 | F39: 5554 | G39: 6289
C40: =+C39/B39-1 -> 0.25058824 | D40: =+D39/C39-1 -> 0.080197554 | E40: =+E39/D39-1 -> 0.062704115 | F40: =+F39/E39-1 -> 0.13788158 | G40: =+G39/F39-1 -> 0.13233705
A41: APAC | B41: 2014 | C41: 2537 | D41: 2762 | E41: 2874 | F41: 3060 | G41: 3360
C42: =+C41/B41-1 -> 0.25968222 | D42: =+D41/C41-1 -> 0.088687426 | E42: =+E41/D41-1 -> 0.040550326 | F42: =+F41/E41-1 -> 0.064718163 | G42: =+G41/F41-1 -> 0.098039216
B46: -> | C46: Business Professionals and Customers
C47: Acrobat Suite (PDF reader enhanced with AI features)
D48: Acrobad Studio, AI vertical tool to use PDFs
D49: Adobe Acrobat, PDF reader tool
D50: Adobe Acrobat Reader, free PDF tool
D51: Adobe Express, all-in-one AI app for videmaking, marketing and social content
B53: -> | C53: Creative and Marketing Professionals
D54: Adobe Creative Cloud Pro, subscription based ecosystem. It includes Adobe Firefly models
E55: Photography
E56: Adobe Photoshop – Lightroom, PS – imaging and design app. LR – edit, organise, store photoes app.
E57: Adobe PS Express, non specialist PS
E58: Lightroom Classic and Web, both alternatives for non specialist
...

Sheet Model
A1: Main | B1: 02/22 | C1: 05/22 | D1: 08/22 | E1: 11/22 | F1: 02/23 | G1: 05/23 | H1: 08/23 | I1: 11/23 | J1: 02/24 | K1: 05/24 | L1: 08/24 | M1: 11/24 | N1: 02/25 | O1: 05/25 | P1: 08/25 | Q1: 11/25 | R1: 02/26 | S1: 05/26 | T1: 08/26 | U1: 11/26 | AA1: 11/20 | AB1: 11/21 | AC1: 11/22 | AD1: 11/23 | AE1: 11/24 | AF1: 11/25 | AG1: 11/26 | AH1: 11/27 | AI1: 11/28 | AJ1: 11/29 | AK1: 11/30 | AL1: 11/31 | AM1: 11/32 | AN1: 11/33 | AO1: 11/34 | AP1: 11/35 | AQ1: 11/36
A2: in Millions | B2: Q122 | C2: Q222 | D2: Q322 | E2: Q422 | F2: Q123 | G2: Q223 | H2: Q323 | I2: Q423 | J2: Q124 | K2: Q224 | L2: Q324 | M2: Q424 | N2: Q125 | O2: Q225 | P2: Q325 | Q2: Q425 | R2: Q126 | S2: Q226 | T2: Q326 | U2: Q426 | AA2: 2020 | AB2: =+AA2+1 -> 2021 | AC2: =+AB2+1 -> 2022 | AD2: =+AC2+1 -> 2023 | AE2: =+AD2+1 -> 2024 | AF2: =+AE2+1 -> 2025 | AG2: =+AF2+1 -> 2026 | AH2: =+AG2+1 -> 2027 | AI2: =+AH2+1 -> 2028 | ... AQ2: =+AP2+1 -> 2036
A3: Total Adobe ARR | AE3: 22610 | AF3: 25200
A5: Creative & Marketing Pro | AD5: 13425 | AE5: 14749 | AF5: 16303
AE6: =+AE5/AD5-1 -> 0.098621974 | AF6: =+AF5/AE5-1 -> 0.10536308
A7: Business Pro & Consumers | AD7: 4744 | AE7: 5662 | AF7: 6495
AE8: =+AE7/AD7-1 -> 0.19350759 | AF8: =+AF7/AE7-1 -> 0.14712116
A11: Digital Media | B11: 2995 | C11: 3079 | D11: 3116 | E11: =+AC11-D11-C11-B11 -> 3195 | F11: 3301 | G11: 3418 | H11: 3506 | I11: =+AD11-H11-G11-F11 -> 3613 | J11: 3725 | K11: 3828 | L11: 3921 | M11: =+AE11-L11-K11-J11 -> 4073 | N11: 4159 | O11: 4280 | P11: 4397 | Q11: =+AF11-P11-O11-N11 -> 4553 | AA11: 8813 | AB11: 11048 | AC11: 12385 | AD11: 13838 | AE11: 15547 | AF11: 17389
A12: % | F12: =+F11/B11-1 -> 0.10217028 | G12: =+G11/C11-1 -> 0.11010068 | H12: =+H11/D11-1 -> 0.12516046 | I12: =+I11/E11-1 -> 0.13082942 | J12: =+J11/F11-1 -> 0.12844593 | K12: =+K11/G11-1 -> 0.11995319 | L12: =+L11/H11-1 -> 0.11836851 | M12: =+M11/I11-1 -> 0.12731802 | ... Q12: =+Q11/M11-1 -> 0.11784925 | AB12: =+AB11/AA11-1 -> 0.25360263 | AC12: =+AC11/AB11-1 -> 0.12101738 | AD12: =+AD11/AC11-1 -> 0.11731934 | AE12: =+AE11/AD11-1 -> 0.12350051 | AF12: =+AF11/AE11-1 -> 0.11847945
A13: Digital Experience | B13: 932 | C13: 961 | D13: 981 | E13: =+AC13-D13-C13-B13 -> 1006 | F13: 1042 | G13: 1070 | H13: 1096 | I13: =+AD13-H13-G13-F13 -> 1123 | J13: 1164 | K13: 1204 | L13: 1231 | M13: =+AE13-L13-K13-J13 -> 1265 | N13: 1297 | O13: 1334 | P13: 1368 | Q13: =+AF13-P13-O13-N13 -> 1410 | AA13: 2660 | AB13: 3379 | AC13: 3880 | AD13: 4331 | AE13: 4864 | AF13: 5409
A14: % | F14: =+F13/B13-1 -> 0.11802575 | G14: =+G13/C13-1 -> 0.11342352 | H14: =+H13/D13-1 -> 0.11722732 | I14: =+I13/E13-1 -> 0.11630219 | J14: =+J13/F13-1 -> 0.11708253 | K14: =+K13/G13-1 -> 0.12523364 | L14: =+L13/H13-1 -> 0.12317518 | M14: =+M13/I13-1 -> 0.12644702 | ... Q14: =+Q13/M13-1 -> 0.11462451 | AB14: =+AB13/AA13-1 -> 0.27030075 | AC14: =+AC13/AB13-1 -> 0.14826872 | AD14: =+AD13/AC13-1 -> 0.11623711 | AE14: =+AE13/AD13-1 -> 0.12306627 | AF14: =+AF13/AE13-1 -> 0.1120477
A15: Publishing and ADV | B15: 31 | C15: 30 | D15: 31 | E15: =+AC15-D15-C15-B15 -> 31 | F15: 30 | G15: 29 | H15: 29 | I15: =+AD15-H15-G15-F15 -> 27 | J15: 27 | K15: 28 | L15: 28 | M15: =+AE15-L15-K15-J15 -> 27 | N15: 27 | O15: 27 | P15: 26 | Q15: =+AF15-P15-O15-N15 -> 26 | AA15: 153 | AB15: 146 | AC15: 123 | AD15: 115 | AE15: 110 | AF15: 106
A16: % | F16: =+F15/B15-1 -> -0.032258065 | G16: =+G15/C15-1 -> -0.033333333 | H16: =+H15/D15-1 -> -0.064516129 | I16: =+I15/E15-1 -> -0.12903226 | J16: =+J15/F15-1 -> -0.1 | K16: =+K15/G15-1 -> -0.034482759 | L16: =+L15/H15-1 -> -0.034482759 | M16: =+M15/I15-1 -> 0 | ... Q16: =+Q15/M15-1 -> -0.037037037 | AB16: =+AB15/AA15-1 -> -0.045751634 | AC16: =+AC15/AB15-1 -> -0.15753425 | AD16: =+AD15/AC15-1 -> -0.06504065 | AE16: =+AE15/AD15-1 -> -0.043478261 | AF16: =+AF15/AE15-1 -> -0.036363636
A17: Subscription | B17: =+B15+B13+B11 -> 3958 | C17: =+C15+C13+C11 -> 4070 | D17: =+D15+D13+D11 -> 4128 | E17: =+E15+E13+E11 -> 4232 | F17: =+F15+F13+F11 -> 4373 | G17: =+G15+G13+G11 -> 4517 | H17: =+H15+H13+H11 -> 4631 | I17: =+I15+I13+I11 -> 4763 | ... Q17: =+Q15+Q13+Q11 -> 5989 | R17: 6198 | S17: 6416 | AA17: =+AA15+AA13+AA11 -> 11626 | AB17: =+AB15+AB13+AB11 -> 14573 | AC17: =+AC15+AC13+AC11 -> 16388 | AD17: =+AD15+AD13+AD11 -> 18284 | AE17: =+AE15+AE13+AE11 -> 20521 | AF17: =+AF15+AF13+AF11 -> 22904
A18: % | F18: =+F17/B17-1 -> 0.10485093 | G18: =+G17/C17-1 -> 0.10982801 | H18: =+H17/D17-1 -> 0.12185078 | I18: =+I17/E17-1 -> 0.12547259 | J18: =+J17/F17-1 -> 0.12417105 | K18: =+K17/G17-1 -> 0.12021253 | L18: =+L17/H17-1 -> 0.11854891 | M18: =+M17/I17-1 -> 0.12639093 | ... S18: =+S17/O17-1 -> 0.13738699 | AA18: =+AA17/AA$23 -> 0.9034815 | AB18: =+AB17/AB$23 -> 0.92321825 | AC18: =+AC17/AC$23 -> 0.93081904 | AD18: =+AD17/AD$23 -> 0.9420372 | AE18: =+AE17/AE$23 -> 0.9542432 | AF18: =+AF17/AF$23 -> 0.96360806
A19: Product | B19: 145 | C19: 146 | D19: 126 | E19: 115 | F19: 120 | G19: 130 | H19: 96 | I19: 114 | J19: 119 | K19: 104 | L19: 82 | M19: 81 | N19: 95 | O19: 88 | P19: 68 | Q19: 74 | R19: 90 | S19: 89 | AA19: 507 | AB19: 555 | AC19: 532 | AD19: 460 | AE19: 386 | AF19: 325
A20: % | F20: =+F19/B19-1 -> -0.17241379 | G20: =+G19/C19-1 -> -0.10958904 | H20: =+H19/D19-1 -> -0.23809524 | I20: =+I19/E19-1 -> -0.0086956522 | J20: =+J19/F19-1 -> -0.0083333333 | K20: =+K19/G19-1 -> -0.2 | L20: =+L19/H19-1 -> -0.14583333 | M20: =+M19/I19-1 -> -0.28947368 | ... S20: =+S19/O19-1 -> 0.011363636 | AA20: =+AA19/AA$23 -> 0.039400062 | AB20: =+AB19/AB$23 -> 0.035159962 | AC20: =+AC19/AC$23 -> 0.030216971 | AD20: =+AD19/AD$23 -> 0.023700345 | AE20: =+AE19/AE$23 -> 0.017949314 | AF20: =+AF19/AF$23 -> 0.013673272
A21: Services | B21: 159 | C21: 170 | D21: 179 | E21: 178 | F21: 162 | G21: 169 | H21: 163 | I21: 171 | J21: 147 | K21: 145 | L21: 146 | M21: 160 | N21: 136 | O21: 144 | P21: 129 | Q21: 131 | R21: 110 | S21: 113 | AA21: 735 | AB21: 657 | AC21: 686 | AD21: 665 | AE21: 598 | AF21: 540
A22: % | F22: =+F21/B21-1 -> 0.018867925 | G22: =+G21/C21-1 -> -0.0058823529 | H22: =+H21/D21-1 -> -0.089385475 | I22: =+I21/E21-1 -> -0.039325843 | J22: =+J21/F21-1 -> -0.092592593 | K22: =+K21/G21-1 -> -0.14201183 | L22: =+L21/H21-1 -> -0.10429448 | M22: =+M21/I21-1 -> -0.064327485 | ... S22: =+S21/O21-1 -> -0.21527778 | AA22: =+AA21/AA$23 -> 0.057118433 | AB22: =+AB21/AB$23 -> 0.041621793 | AC22: =+AC21/AC$23 -> 0.03896399 | AD22: =+AD21/AD$23 -> 0.034262456 | AE22: =+AE21/AE$23 -> 0.027807487 | AF22: =+AF21/AF$23 -> 0.022718667
A23: Revenues | B23: =+B21+B19+B17 -> 4262 | C23: =+C21+C19+C17 -> 4386 | D23: =+D21+D19+D17 -> 4433 | E23: =+E21+E19+E17 -> 4525 | F23: =+F21+F19+F17 -> 4655 | G23: =+G21+G19+G17 -> 4816 | H23: =+H21+H19+H17 -> 4890 | I23: =+I21+I19+I17 -> 5048 | ... S23: =+S21+S19+S17 -> 6618 | T23: =+P23*1.11 -> 6646.68 | U23: =+Q23*1.11 -> 6875.34 | AA23: =+AA21+AA19+AA17 -> 12868 | AB23: =+AB21+AB19+AB17 -> 15785 | AC23: =+AC21+AC19+AC17 -> 17606 | AD23: =+AD21+AD19+AD17 -> 19409 | AE23: =+AE21+AE19+AE17 -> 21505 | AF23: =+AF21+AF19+AF17 -> 23769 | AG23: =+AF23*1.115 -> 26502.435 | AH23: =+AG23*1.105 -> 29285.191 | AI23: =+AH23*1.095 -> 32067.284 | AJ23: =+AI23*1.09 -> 34953.339 | AK23: =+AJ23*1.08 -> 37749.606 | AL23: =+AK23*1.07 -> 40392.079 | AM23: =+AL23*1.06 -> 42815.604 | AN23: =+AM23*1.05 -> 44956.384 | AO23: =+AN23*1.04 -> 46754.639 | AP23: =+AO23*1.03 -> 48157.278 | AQ23: =+AP23*1.02 -> 49120.424
A24: % | F24: =+F23/B23-1 -> 0.09221023 | G24: =+G23/C23-1 -> 0.098039216 | H24: =+H23/D23-1 -> 0.10309046 | I24: =+I23/E23-1 -> 0.11558011 | J24: =+J23/F23-1 -> 0.1132116 | K24: =+K23/G23-1 -> 0.10236711 | L24: =+L23/H23-1 -> 0.10593047 | M24: =+M23/I23-1 -> 0.11053883 | ... U24: =+U23/Q23-1 -> 0.11 | AB24: =+AB23/AA23-1 -> 0.22668635 | AC24: =+AC23/AB23-1 -> 0.11536269 | AD24: =+AD23/AC23-1 -> 0.10240827 | AE24: =+AE23/AD23-1 -> 0.10799114 | AF24: =+AF23/AE23-1 -> 0.10527784 | AG24: =+AG23/AF23-1 -> 0.115 | AH24: =+AH23/AG23-1 -> 0.105 | AI24: =+AI23/AH23-1 -> 0.095 | ... AQ24: =+AQ23/AP23-1 -> 0.02
A25: Subscription | B25: 393 | C25: 410 | D25: 413 | E25: 430 | F25: 434 | G25: 436 | H25: 447 | I25: 505 | J25: 455 | K25: 456 | L25: 413 | M25: 475 | N25: 490 | O25: 505 | P25: 510 | Q25: 522 | R25: 540 | S25: 586 | AA25: 1108 | AB25: 1374 | AC25: 1646 | AD25: 1822 | AE25: 1799 | AF25: 2027
A26: % | F26: =+F25/B25-1 -> 0.1043257 | G26: =+G25/C25-1 -> 0.063414634 | H26: =+H25/D25-1 -> 0.082324455 | I26: =+I25/E25-1 -> 0.1744186 | J26: =+J25/F25-1 -> 0.048387097 | K26: =+K25/G25-1 -> 0.04587156 | L26: =+L25/H25-1 -> -0.07606264 | M26: =+M25/I25-1 -> -0.059405941 | ... U26: =+U25/Q25-1 -> -1 | AB26: =+AB25/AA25-1 -> 0.2400722 | AC26: =+AC25/AB25-1 -> 0.19796215 | AD26: =+AD25/AC25-1 -> 0.10692588 | AE26: =+AE25/AD25-1 -> -0.012623491 | AF26: =+AF25/AE25-1 -> 0.12673708
A27: Product | B27: 10 | C27: 9 | D27: 8 | E27: 8 | F27: 8 | G27: 8 | H27: 7 | I27: 6 | J27: 5 | K27: 8 | L27: 6 | M27: 6 | N27: 6 | O27: 6 | P27: 5 | Q27: 6 | R27: 6 | S27: 5 | AA27: 36 | AB27: 41 | AC27: 35 | AD27: 29 | AE27: 25 | AF27: 23
A28: % | F28: =+F27/B27-1 -> -0.2 | G28: =+G27/C27-1 -> -0.11111111 | H28: =+H27/D27-1 -> -0.125 | I28: =+I27/E27-1 -> -0.25 | J28: =+J27/F27-1 -> -0.375 | K28: =+K27/G27-1 -> 0 | L28: =+L27/H27-1 -> -0.14285714 | M28: =+M27/I27-1 -> 0 | ... U28: =+U27/Q27-1 -> -1 | AB28: =+AB27/AA27-1 -> 0.13888889 | AC28: =+AC27/AB27-1 -> -0.14634146 | AD28: =+AD27/AC27-1 -> -0.17142857 | AE28: =+AE27/AD27-1 -> -0.13793103 | AF28: =+AF27/AE27-1 -> -0.08
A29: Services | B29: 109 | C29: 120 | D29: 125 | E29: 130 | F29: 126 | G29: 128 | H29: 126 | I29: 123 | J29: 130 | K29: 134 | L29: 135 | M29: 135 | N29: 126 | O29: 127 | P29: 127 | Q29: 121 | R29: 118 | S29: 124 | AA29: 578 | AB29: 450 | AC29: 484 | AD29: 503 | AE29: 534 | AF29: 501
A30: % | F30: =+F29/B29-1 -> 0.1559633 | G30: =+G29/C29-1 -> 0.066666667 | H30: =+H29/D29-1 -> 0.008 | I30: =+I29/E29-1 -> -0.053846154 | J30: =+J29/F29-1 -> 0.031746032 | K30: =+K29/G29-1 -> 0.046875 | L30: =+L29/H29-1 -> 0.071428571 | M30: =+M29/I29-1 -> 0.097560976 | ... U30: =+U29/Q29-1 -> -1 | AB30: =+AB29/AA29-1 -> -0.22145329 | AC30: =+AC29/AB29-1 -> 0.075555556 | AD30: =+AD29/AC29-1 -> 0.039256198 | AE30: =+AE29/AD29-1 -> 0.061630219 | AF30: =+AF29/AE29-1 -> -0.061797753
A31: COGS | B31: =+B29+B27+B25+42 -> 554 | C31: =+C29+C27+C25+42 -> 581 | D31: =+D29+D27+D25+43 -> 589 | E31: =+E29+E27+E25+42 -> 610 | F31: =+F29+F27+F25+42 -> 610 | G31: =+G29+G27+G25+42 -> 614 | H31: =+H29+H27+H25+42 -> 622 | I31: =+I29+I27+I25+42 -> 676 | J31: =+J29+J27+J25+42 -> 632 | K31: =+K29+K27+K25+42 -> 640 | L31: =+L29+L27+L25+43 -> 597 | M31: =+M29+M27+M25+42 -> 658 | N31: =+N29+N27+N25+41 -> 663 | O31: =+O29+O27+O25+41 -> 679 | P31: =+P29+P27+P25+38 -> 680 | Q31: =+Q29+Q27+Q25+37 -> 686 | R31: =+R29+R27+R25+35 -> 699 | S31: =+S29+S27+S25+37 -> 752 | T31: =+T23-T33 -> 731.1348 | U31: =+U23-U33 -> 756.2874 | AA31: =SUM(AA25:AA29)+162 -> 1884 | AB31: =SUM(AB25:AB29)+172 -> 2037.379 | AC31: =SUM(AC25:AC29)+169 -> 2334.0516 | AD31: =SUM(AD25:AD29)+168 -> 2521.9355 | AE31: =SUM(AE25:AE29)+169 -> 2526.8494 | AF31: =SUM(AF25:AF29)+157 -> 2708.0467 | AG31: =+AG23-AG33 -> 2955.0215 | AH31: =+AH23-AH33 -> 3221.371 | AI31: =+AI23-AI33 -> 3367.0648 | AJ31: =+AJ23-AJ33 -> 3495.3339 | AK31: =+AK23-AK33 -> 3586.2126 | AL31: =+AL23-AL33 -> 3635.2871 | AM31: =+AM23-AM33 -> 3639.3263 | AN31: =+AN23-AN33 -> 3596.5107 | ... AQ31: =+AQ23-AQ33 -> 3192.8276
A32: % | B32: =+B31/B$23 -> 0.12998592 | C32: =+C31/C$23 -> 0.13246694 | D32: =+D31/D$23 -> 0.13286713 | E32: =+E31/E$23 -> 0.13480663 | F32: =+F31/F$23 -> 0.13104189 | G32: =+G31/G$23 -> 0.12749169 | H32: =+H31/H$23 -> 0.12719836 | I32: =+I31/I$23 -> 0.13391442 | ... U32: =+U31/U$23 -> 0.11 | AA32: =+AA31/AA$23 -> 0.1464097 | AB32: =+AB31/AB$23 -> 0.12907057 | AC32: =+AC31/AC$23 -> 0.13257137 | AD32: =+AD31/AD$23 -> 0.1299364 | AE32: =+AE31/AE$23 -> 0.11750056 | AF32: =+AF31/AF$23 -> 0.11393188 | AG32: =+AG31/AG$23 -> 0.1115 | AH32: =+AH31/AH$23 -> 0.11 | ... AQ32: =+AQ31/AQ$23 -> 0.065
A33: Gross Margin | B33: =+B23-B31 -> 3708 | C33: =+C23-C31 -> 3805 | D33: =+D23-D31 -> 3844 | E33: =+E23-E31 -> 3915 | F33: =+F23-F31 -> 4045 | G33: =+G23-G31 -> 4202 | H33: =+H23-H31 -> 4268 | I33: =+I23-I31 -> 4372 | ... S33: =+S23-S31 -> 5866 | T33: =+T23*0.89 -> 5915.5452 | U33: =+U23*0.89 -> 6119.0526 | AA33: =+AA23-AA31 -> 10984 | AB33: =+AB23-AB31 -> 13747.621 | AC33: =+AC23-AC31 -> 15271.948 | AD33: =+AD23-AD31 -> 16887.065 | AE33: =+AE23-AE31 -> 18978.151 | AF33: =+AF23-AF31 -> 21060.953 | AG33: =+AG23*0.8885 -> 23547.413 | AH33: =+AH23*0.89 -> 26063.82 | AI33: =+AI23*0.895 -> 28700.219 | AJ33: =+AJ23*0.9 -> 31458.005 | AK33: =+AK23*0.905 -> 34163.394 | AL33: =+AL23*0.91 -> 36756.792 | AM33: =+AM23*0.915 -> 39176.277 | AN33: =+AN23*0.92 -> 41359.873 | AO33: =+AO23*0.925 -> 43248.041 | AP33: =+AP23*0.93 -> 44786.269 | AQ33: =+AQ23*0.935 -> 45927.596
A34: % | B34: =+B33/B$23 -> 0.87001408 | C34: =+C33/C$23 -> 0.86753306 | D34: =+D33/D$23 -> 0.86713287 | E34: =+E33/E$23 -> 0.86519337 | F34: =+F33/F$23 -> 0.86895811 | G34: =+G33/G$23 -> 0.87250831 | H34: =+H33/H$23 -> 0.87280164 | I34: =+I33/I$23 -> 0.86608558 | ... U34: =+U33/U$23 -> 0.89 | AA34: =+AA33/AA$23 -> 0.8535903 | AB34: =+AB33/AB$23 -> 0.87092943 | AC34: =+AC33/AC$23 -> 0.86742863 | AD34: =+AD33/AD$23 -> 0.8700636 | AE34: =+AE33/AE$23 -> 0.88249944 | AF34: =+AF33/AF$23 -> 0.88606812 | AG34: =+AG33/AG$23 -> 0.8885 | AH34: =+AH33/AH$23 -> 0.89 | ... AQ34: =+AQ33/AQ$23 -> 0.935
A35: R&D | B35: 701 | C35: 738 | D35: 775 | E35: 773 | F35: 827 | G35: 876 | H35: 881 | I35: 889 | J35: 939 | K35: 984 | L35: 1022 | M35: 999 | N35: 1026 | O35: 1082 | P35: 1088 | Q35: 1098 | R35: 1110 | S35: 1198 | T35: =+P35*1.1 -> 1196.8 | U35: =+Q35*1.1 -> 1207.8 | AA35: 2188 | AB35: 2540 | AC35: 2987 | AD35: 3473 | AE35: 3944 | AF35: 4294 | AG35: =+AG23*0.17 -> 4505.414 | AH35: =+AH23*0.17 -> 4978.4824 | AI35: =+AI23*0.17 -> 5451.4382 | AJ35: =+AJ23*0.15 -> 5243.0009 | AK35: =+AK23*0.15 -> 5662.441 | AL35: =+AL23*0.15 -> 6058.8118 | AM35: =+AM23*0.15 -> 6422.3405 | AN35: =+AN23*0.15 -> 6743.4576 | AO35: =+AO23*0.15 -> 7013.1959 | AP35: =+AP23*0.15 -> 7223.5918 | AQ35: =+AQ23*0.15 -> 7368.0636
A36: % | B36: =+B35/B$23 -> 0.16447677 | C36: =+C35/C$23 -> 0.16826265 | D36: =+D35/D$23 -> 0.17482517 | E36: =+E35/E$23 -> 0.17082873 | F36: =+F35/F$23 -> 0.17765843 | G36: =+G35/G$23 -> 0.18189369 | H36: =+H35/H$23 -> 0.1801636 | I36: =+I35/I$23 -> 0.17610935 | ... U36: =+U35/U$23 -> 0.17567131 | AA36: =+AA35/AA$23 -> 0.17003419 | AB36: =+AB35/AB$23 -> 0.16091226 | AC36: =+AC35/AC$23 -> 0.16965807 | AD36: =+AD35/AD$23 -> 0.17893761 | AE36: =+AE35/AE$23 -> 0.18339921 | AF36: =+AF35/AF$23 -> 0.18065548 | AG36: =+AG35/AG$23 -> 0.17 | AH36: =+AH35/AH$23 -> 0.17 | ... AQ36: =+AQ35/AQ$23 -> 0.15
A37: S&M | B37: 1158 | C37: 1247 | D37: 1266 | E37: 1297 | F37: 1301 | G37: 1345 | H37: 1337 | I37: 1368 | J37: 1352 | K37: 1445 | L37: 1431 | M37: 1536 | N37: 1495 | O37: 1626 | P37: 1639 | Q37: 1728 | R37: 1708 | S37: 1884 | T37: =+P37*1.1 -> 1802.9 | U37: =+Q37*1.1 -> 1900.8 | AA37: 3591 | AB37: 4321 | AC37: 4968 | AD37: 5351 | AE37: 5764 | AF37: 6488 | AG37: =+AG23*0.27 -> 7155.6574 | AH37: =+AH23*0.27 -> 7907.0015 | AI37: =+AI23*0.25 -> 8016.8209 | AJ37: =+AJ23*0.25 -> 8738.3348 | AK37: =+AK23*0.25 -> 9437.4016 | AL37: =+AL23*0.25 -> 10098.02 | AM37: =+AM23*0.2 -> 8563.1207 | AN37: =+AN23*0.2 -> 8991.2768 | AO37: =+AO23*0.2 -> 9350.9278 | AP37: =+AP23*0.2 -> 9631.4557 | AQ37: =+AQ23*0.2 -> 9824.0848
A38: % | B38: =+B37/B$23 -> 0.27170343 | C38: =+C37/C$23 -> 0.28431373 | D38: =+D37/D$23 -> 0.28558538 | E38: =+E37/E$23 -> 0.28662983 | F38: =+F37/F$23 -> 0.27948443 | G38: =+G37/G$23 -> 0.27927741 | H38: =+H37/H$23 -> 0.27341513 | I38: =+I37/I$23 -> 0.27099842 | ... U38: =+U37/U$23 -> 0.27646633 | AA38: =+AA37/AA$23 -> 0.27906435 | AB38: =+AB37/AB$23 -> 0.27374089 | AC38: =+AC37/AC$23 -> 0.28217653 | AD38: =+AD37/AD$23 -> 0.27569684 | AE38: =+AE37/AE$23 -> 0.26803069 | AF38: =+AF37/AF$23 -> 0.27296058 | AG38: =+AG37/AG$23 -> 0.27 | AH38: =+AH37/AH$23 -> 0.27 | ... AQ38: =+AQ37/AQ$23 -> 0.2
A39: G&A | B39: 269 | C39: 291 | D39: 319 | E39: 340 | F39: 331 | G39: 357 | H39: 353 | I39: 372 | J39: 352 | K39: 355 | L39: 366 | M39: 456 | N39: 367 | O39: 377 | P39: 408 | Q39: 421 | R39: 463 | S39: 546 | T39: =+P39*1.1 -> 448.8 | U39: =+Q39*1.1 -> 463.1 | AA39: 968 | AB39: 1085 | AC39: 1219 | AD39: 1413 | AE39: 1529 | AF39: 1573 | AG39: =+AF39*1.06 -> 1667.38 | AH39: =+AG39*1.06 -> 1767.4228 | AI39: =+AH39*1.06 -> 1873.4682 | AJ39: =+AI39*1.06 -> 1985.8763 | AK39: =+AJ39*1.055 -> 2095.0995 | AL39: =+AK39*1.054 -> 2208.2348 | AM39: =+AL39*1.05 -> 2318.6466 | AN39: =+AM39*1.05 -> 2434.5789 | AO39: =+AN39*1.05 -> 2556.3078 | AP39: =+AO39*1.05 -> 2684.1232 | AQ39: =+AP39*1.05 -> 2818.3294
A40: % | B40: =+B39/B$23 -> 0.063115908 | C40: =+C39/C$23 -> 0.066347469 | D40: =+D39/D$23 -> 0.071960298 | E40: =+E39/E$23 -> 0.075138122 | F40: =+F39/F$23 -> 0.071106337 | G40: =+G39/G$23 -> 0.074127907 | H40: =+H39/H$23 -> 0.072188139 | I40: =+I39/I$23 -> 0.073692552 | ... U40: =+U39/U$23 -> 0.067356669 | AA40: =+AA39/AA$23 -> 0.075225365 | AB40: =+AB39/AB$23 -> 0.068736142 | AC40: =+AC39/AC$23 -> 0.06923776 | AD40: =+AD39/AD$23 -> 0.072801278 | AE40: =+AE39/AE$23 -> 0.071099744 | AF40: =+AF39/AF$23 -> 0.066178636 | AG40: =+AG39/AG$23 -> 0.062914219 | AH40: =+AH39/AH$23 -> 0.060352101 | ... AQ40: =+AQ39/AQ$23 -> 0.057375917
A41: Acquisition fee | B41: 0 | C41: 0 | D41: 0 | E41: 0 | F41: 0 | G41: 0 | H41: 0 | I41: 0 | J41: 1000 | K41: 0 | L41: 0 | M41: 0 | N41: 0 | O41: 0 | P41: 0 | Q41: 0 | R41: 0 | S41: 0 | T41: 0 | U41: 0 | AA41: 0 | AB41: 0 | AC41: 0 | AD41: 0 | AE41: 1000 | AF41: 0 | AG41: =+AF41*1.1 -> 0 | AH41: =+AG41*1.1 -> 0 | AI41: =+AH41*1.1 -> 0 | AJ41: =+AI41*1.1 -> 0 | AK41: =+AJ41*1.1 -> 0 | AL41: =+AK41*1.1 -> 0 | AM41: =+AL41*1.1 -> 0 | AN41: =+AM41*1.1 -> 0 | ... AQ41: =+AP41*1.1 -> 0
A42: % | F42: N.M. | G42: N.M. | H42: N.M. | I42: N.M. | J42: N.M. | K42: N.M. | L42: N.M. | M42: N.M. | N42: N.M. | O42: N.M. | P42: N.M. | Q42: N.M. | R42: N.M. | S42: N.M. | T42: N.M. | U42: N.M. | AB42: N.M. | AC42: N.M. | AD42: N.M. | AE42: N.M. | AF42: N.M. | AG42: N.M. | AH42: N.M. | AI42: N.M. | AJ42: N.M. | AK42: N.M. | AL42: N.M. | AM42: N.M. | AN42: N.M. | AO42: N.M. | AP42: N.M. | AQ42: N.M.
A43: Op Exp | B43: =+B35+B37+B39+B41 -> 2128 | C43: =+C35+C37+C39+C41 -> 2276 | D43: =+D35+D37+D39+D41 -> 2360 | E43: =+E35+E37+E39+E41 -> 2410 | F43: =+F35+F37+F39+F41 -> 2459 | G43: =+G35+G37+G39+G41 -> 2578 | H43: =+H35+H37+H39+H41 -> 2571 | I43: =+I35+I37+I39+I41 -> 2629 | ... U43: =+U35+U37+U39+U41 -> 3571.7 | AA43: =SUM(AA35:AA41) -> 6747.5243 | AB43: =SUM(AB35:AB41) -> 7946.5034 | AC43: =SUM(AC35:AC41) -> 9174.5211 | AD43: =SUM(AD35:AD41) -> 10237.527 | AE43: =SUM(AE35:AE41) -> 12237.523 | AF43: =SUM(AF35:AF41) -> 12355.52 | AG43: =SUM(AG35:AG41) -> 13328.954 | AH43: =SUM(AH35:AH41) -> 14653.407 | ... AQ43: =SUM(AQ35:AQ41) -> 20010.885
...

Sheet Bond
A1: Main
B3: ISIN | C3: Coupon (%) | D3: Maturity Date
B4: US00724PAC32 | C4: 2.15 | D4: Feb 01, 2027
B5: US00724PAE97 | C5: 4.85 | D5: Apr 04, 2027
B6: US00724PAH29 | C6: 4.75 | D6: Jan 17, 2028
B7: US00724PAF62 | C7: 4.8 | D7: Apr 04, 2029
B8: US00724PAJ84 | C8: 4.95 | D8: Jan 17, 2030
B9: US00724PAD15 | C9: 2.3 | D9: Feb 01, 2030
B10: US00724PAG46 | C10: 4.95 | D10: Apr 04, 2034
B11: US00724PAK57 | C11: 5.3 | D11: Jan 17, 2035
C12: =+AVERAGE(C4:C11) -> 4.25625

Sheet Board
A1: Main | E1: Auditor | F1: KPMG
