Workbook

Sheet Main
A1: Autodesk Inc. | E1: Price | F1: 230
E2: Share | F2: 209 | G2: Q227
E3: MC | F3: =+F2*F1 -> 48070
E4: Cash | F4: 4357 | G4: Q227
E5: Debt | F5: =+994+499+1985 -> 3478 | G5: Q227
E6: EV | F6: =+F3-F4+F5 -> 47191
A10: BETA | B10: 1.31 | D10: WACC | E10: =+(F3/(F3+F5))*B11+(F5/(F3+F5))*B12*(1-0.17) -> 0.11095369 | G10: EV/EBITDA | H10: =+F6/SUM(Model!L77:O77) -> 16.23916
A11: CAPM | B11: =+0.05+B10*(0.1-0.05) -> 0.1155 | G11: EV/FCF | H11: =+F6/SUM(Model!L151:O151) -> 16.622402
A12: Cost of Debt | B12: =+0.05+(B13/100) -> 0.057973913 | D12: P/E | E12: =+F1/SUM(Model!L63:O63) -> 29.793612 | G12: P/EBITDA | H12: =+F3/SUM(Model!L77:O77) -> 16.541638
A13: Cr. Spread | B13: =+'[1]Credit Spread US'!J6 -> 0.7973913 | D13: FP/E | G13: P/FCF | H13: =+F3/SUM(Model!L151:O151) -> 16.932018
A14: Rating | B14: AA- | C14: A3 | G14: Inc. Margin | H14: =+(SUM(Model!L53:O53)-SUM(Model!H53:K53))/(SUM(Model!L29:O29)-SUM(Model!H29:K29)) -> 0.55021097
B15: S&P | C15: Moody’s
A21: AECO, Architecture, Engineering, Contruction and Operations
A22: AutoCAD and AutoCAD LT
A23: MFG, Manufacturing
A24: M&E, Media and Entertainment
A25: Other

Sheet Model
A1: Main | B1: 04/23 | C1: 07/23 | D1: 09/23 | E1: 12/23 | F1: 04/24 | G1: 07/24 | H1: 09/24 | I1: 12/24 | J1: 04/25 | K1: 07/25 | L1: 09/25 | M1: 12/25 | N1: 04/26 | O1: 07/26 | P1: 09/26 | Q1: 12/26 | U1: 01/16 | V1: 01/17 | W1: 01/18 | X1: 01/19 | Y1: 01/20 | Z1: 01/21 | AA1: 01/22 | AB1: 01/23 | AC1: 01/24 | AD1: 01/25 | AE1: 01/26
A2: in Millions | B2: Q124 | C2: Q224 | D2: Q324 | E2: Q424 | F2: Q125 | G2: Q225 | H2: Q325 | I2: Q425 | J2: Q126 | K2: Q226 | L2: Q326 | M2: Q426 | N2: Q127 | O2: Q227 | P2: Q327 | Q2: Q427 | U2: 2016 | V2: =+U2+1 -> 2017 | W2: =+V2+1 -> 2018 | X2: =+W2+1 -> 2019 | Y2: =+X2+1 -> 2020 | Z2: =+Y2+1 -> 2021 | AA2: =+Z2+1 -> 2022 | AB2: =+AA2+1 -> 2023 | AC2: =+AB2+1 -> 2024 | ... AJ2: =+AI2+1 -> 2031
A4: Total Subs (‘000) | U4: 2578.2 | V4: 3107 | W4: 3715.7 | X4: 4330
A6: ARR | U6: 1376.4 | V6: 1599.9 | W6: 2.0541 | X6: 2.7494
A8: ARPS | U8: 534 | V8: 515 | W8: =+W4/W6 -> 1808.9187 | X8: =+X4/X6 -> 1574.8891
A12: AECO | B12: 582 | C12: 627 | D12: 675 | E12: 696 | F12: 674 | G12: 713 | H12: 751 | I12: 799 | J12: 809 | K12: 878 | L12: 921 | M12: 975 | N12: 970 | O12: 1029 | U12: 949.1 | V12: 880.9 | W12: 949.1 | Y12: 1377.1 | Z12: 1648.6 | AA12: 1969 | AB12: 2278 | AC12: 2580 | AD12: 2937 | AE12: 3583
B13: =+B12/B$29 -> 0.45862884 | C13: =+C12/C$29 -> 0.466171 | D13: =+D12/D$29 -> 0.47736917 | E13: =+E12/E$29 -> 0.4737917 | F13: =+F12/F$29 -> 0.47565279 | G13: =+G12/G$29 -> 0.47375415 | H13: =+H12/H$29 -> 0.47834395 | I13: =+I12/I$29 -> 0.48749237 | ... O13: =+O12/O$29 -> 0.50293255 | Y13: =+Y12/Y$29 -> 0.42057844 | Z13: =+Z12/Z$29 -> 0.43498681 | AA13: =+AA12/AA$29 -> 0.44892841 | AB13: =+AB12/AB$29 -> 0.45514486 | AC13: =+AC12/AC$29 -> 0.46934692 | AD13: =+AD12/AD$29 -> 0.47904094 | AE13: =+AE12/AE$29 -> 0.49722454
A14: AutoCAD and AutoCAD LT | B14: 349 | C14: 364 | D14: 372 | E14: 377 | F14: 376 | G14: 389 | H14: 398 | I14: 409 | J14: 411 | K14: 440 | L14: 458 | M14: 478 | N14: 474 | O14: 500 | U14: 594.8 | V14: 326.7 | W14: 594.8 | Y14: 948.2 | Z14: 1099.4 | AA14: 1244 | AB14: 1387 | AC14: 1462 | AD14: 1572 | AE14: 1787
B15: =+B14/B$29 -> 0.2750197 | C15: =+C14/C$29 -> 0.27063197 | D15: =+D14/D$29 -> 0.26308345 | E15: =+E14/E$29 -> 0.25663717 | F15: =+F14/F$29 -> 0.26534933 | G15: =+G14/G$29 -> 0.25847176 | H15: =+H14/H$29 -> 0.25350318 | I15: =+I14/I$29 -> 0.2495424 | ... O15: =+O14/O$29 -> 0.24437928 | Y15: =+Y14/Y$29 -> 0.28958861 | Z15: =+Z14/Z$29 -> 0.29007916 | AA15: =+AA14/AA$29 -> 0.28362973 | AB15: =+AB14/AB$29 -> 0.27712288 | AC15: =+AC14/AC$29 -> 0.26596325 | AD15: =+AD14/AD$29 -> 0.25640189 | AE15: =+AE14/AE$29 -> 0.24798779
A16: MFG | B16: 246 | C16: 256 | D16: 269 | E16: 292 | F16: 268 | G16: 296 | H16: 307 | I16: 318 | J16: 309 | K16: 334 | L16: 355 | M16: 381 | N16: 367 | O16: 385 | U16: 724.6 | V16: 625.8 | W16: 724.6 | Y16: 726.1 | Z16: 798.6 | AA16: 876 | AB16: 978 | AC16: 1063 | AD16: 1189 | AE16: 1379
B17: =+B16/B$29 -> 0.19385343 | C17: =+C16/C$29 -> 0.19033457 | D17: =+D16/D$29 -> 0.19024045 | E17: =+E16/E$29 -> 0.19877468 | F17: =+F16/F$29 -> 0.18913197 | G17: =+G16/G$29 -> 0.19667774 | H17: =+H16/H$29 -> 0.1955414 | I17: =+I16/I$29 -> 0.19402074 | ... O17: =+O16/O$29 -> 0.18817204 | Y17: =+Y16/Y$29 -> 0.22175732 | Z17: =+Z16/Z$29 -> 0.2107124 | AA17: =+AA16/AA$29 -> 0.1997264 | AB17: =+AB16/AB$29 -> 0.1954046 | AC17: =+AC16/AC$29 -> 0.19337821 | AD17: =+AD16/AD$29 -> 0.19393247 | AE17: =+AE16/AE$29 -> 0.1913683
A18: M&E | B18: 71 | C18: 74 | D18: 73 | E18: 77 | F18: 71 | G18: 77 | H18: 83 | I18: 84 | J18: 76 | K18: 80 | L18: 86 | M18: 90 | N18: 86 | O18: 92 | U18: 160 | V18: 138.9 | W18: 160 | Y18: 199.2 | Z18: 219.4 | AA18: 259 | AB18: 291 | AC18: 295 | AD18: 315 | AE18: 332
B19: =+B18/B$29 -> 0.055949567 | C19: =+C18/C$29 -> 0.055018587 | D19: =+D18/D$29 -> 0.051626591 | E19: =+E18/E$29 -> 0.05241661 | F19: =+F18/F$29 -> 0.050105857 | G19: =+G18/G$29 -> 0.051162791 | H19: =+H18/H$29 -> 0.052866242 | I19: =+I18/I$29 -> 0.051250763 | ... O19: =+O18/O$29 -> 0.044965787 | Y19: =+Y18/Y$29 -> 0.060837431 | Z19: =+Z18/Z$29 -> 0.057889182 | AA19: =+AA18/AA$29 -> 0.059051528 | AB19: =+AB18/AB$29 -> 0.058141858 | AC19: =+AC18/AC$29 -> 0.053665636 | AD19: =+AD18/AD$29 -> 0.051378242 | AE19: =+AE18/AE$29 -> 0.046072717
A20: Other | B20: 21 | C20: 24 | D20: 25 | E20: 27 | F20: 28 | G20: 30 | H20: 31 | I20: 29 | J20: 28 | K20: 31 | L20: 33 | M20: 33 | N20: 37 | O20: 40 | U20: 75.6 | V20: 58.7 | W20: 75.6 | Y20: 23.7 | Z20: 24.4 | AA20: 38 | AB20: 71 | AC20: 97 | AD20: 118 | AE20: 125
B21: =+B20/B$29 -> 0.016548463 | C21: =+C20/C$29 -> 0.017843866 | D21: =+D20/D$29 -> 0.017680339 | E21: =+E20/E$29 -> 0.01837985 | F21: =+F20/F$29 -> 0.019760056 | G21: =+G20/G$29 -> 0.019933555 | H21: =+H20/H$29 -> 0.019745223 | I21: =+I20/I$29 -> 0.017693716 | ... O21: =+O20/O$29 -> 0.019550342 | Y21: =+Y20/Y$29 -> 0.0072381883 | Z21: =+Z20/Z$29 -> 0.0064379947 | AA21: =+AA20/AA$29 -> 0.0086639307 | AB21: =+AB20/AB$29 -> 0.014185814 | AC21: =+AC20/AC$29 -> 0.017645989 | AD21: =+AD20/AD$29 -> 0.019246452 | AE21: =+AE20/AE$29 -> 0.017346656
A25: Subscriptions | B25: 1193 | C25: 1270 | D25: 1314 | E25: 1339 | F25: 1330 | G25: 1408 | H25: 1457 | I25: 1522 | J25: 1540 | K25: 1667 | L25: 1734 | M25: 1819 | N25: 1836 | O25: 1952 | U25: 228.1 | V25: 443.1 | W25: 894.3 | X25: 1802.3 | Y25: 2751.9 | Z25: 3381 | AA25: 4060 | AB25: 4651 | AC25: 5116 | AD25: 5717 | AE25: 6743
B26: =+B25/B$29 -> 0.94011032 | C26: =+C25/C$29 -> 0.94423792 | D26: =+D25/D$29 -> 0.92927864 | E26: =+E25/E$29 -> 0.91150442 | F26: =+F25/F$29 -> 0.93860268 | G26: =+G25/G$29 -> 0.93554817 | H26: =+H25/H$29 -> 0.92802548 | I26: =+I25/I$29 -> 0.92861501 | ... O26: =+O25/O$29 -> 0.9540567 | U26: =+U25/U$29 -> 0.091090611 | V26: =+V25/V$29 -> 0.21816839 | W26: =+W25/W$29 -> 0.43484392 | X26: =+X25/X$29 -> 0.70133863 | Y26: =+Y25/Y$29 -> 0.84045445 | Z26: =+Z25/Z$29 -> 0.89208443 | AA26: =+AA25/AA$29 -> 0.92567259 | AB26: =+AB25/AB$29 -> 0.92927073 | ... AE26: =+AE25/AE$29 -> 0.93574799
A27: Other | B27: =+14+62 -> 76 | C27: =+14+61 -> 75 | D27: =+12+88 -> 100 | E27: =+14+116 -> 130 | F27: =+11+76 -> 87 | G27: =+11+86 -> 97 | H27: =+9+104 -> 113 | I27: =+10+107 -> 117 | J27: 93 | K27: 96 | L27: =+8+111 -> 119 | M27: =+8+130 -> 138 | N27: 98 | O27: 94 | U27: =+1123.5+1152.5 -> 2276 | V27: =+1103.1+484.8 -> 1587.9 | W27: =+989.6+172.7 -> 1162.3 | X27: =+635.1+132.4 -> 767.5 | Y27: =+386.6+135.8 -> 522.4 | Z27: =+183+226 -> 409 | AA27: =+76+250 -> 326 | AB27: =+65+289 -> 354 | AC27: =+54+327 -> 381 | AD27: =+41+373 -> 414 | AE27: =+430+33 -> 463
B28: =+B27/B$29 -> 0.059889677 | C28: =+C27/C$29 -> 0.055762082 | D28: =+D27/D$29 -> 0.070721358 | E28: =+E27/E$29 -> 0.088495575 | F28: =+F27/F$29 -> 0.061397318 | G28: =+G27/G$29 -> 0.064451827 | H28: =+H27/H$29 -> 0.071974522 | I28: =+I27/I$29 -> 0.071384991 | ... O28: =+O27/O$29 -> 0.045943304 | U28: =+U27/U$29 -> 0.90890939 | V28: =+V27/V$29 -> 0.78183161 | W28: =+W27/W$29 -> 0.56515608 | X28: =+X27/X$29 -> 0.29866137 | Y28: =+Y27/Y$29 -> 0.15954555 | Z28: =+Z27/Z$29 -> 0.10791557 | AA28: =+AA27/AA$29 -> 0.074327405 | AB28: =+AB27/AB$29 -> 0.070729271 | ... AE28: =+AE27/AE$29 -> 0.064252012
A29: Revenue | B29: =+B27+B25 -> 1269 | C29: =+C27+C25 -> 1345 | D29: =+D27+D25 -> 1414 | E29: =+E27+E25 -> 1469 | F29: =+F27+F25 -> 1417 | G29: =+G27+G25 -> 1505 | H29: =+H27+H25 -> 1570 | I29: =+I27+I25 -> 1639 | ... Q29: =+Q27+Q25 -> 0 | U29: =+U27+U25 -> 2504.1 | V29: =+V27+V25 -> 2031 | W29: =+W27+W25 -> 2056.6 | X29: =+X27+X25 -> 2569.8 | Y29: =+Y27+Y25 -> 3274.3 | Z29: =+Z27+Z25 -> 3790 | AA29: =+AA27+AA25 -> 4386 | AB29: =+AB27+AB25 -> 5005 | ... AE29: =+AE27+AE25 -> 7206 | AF29: =+AE29*1.15 -> 8286.9 | AG29: =+AF29*1.14 -> 9447.066 | AH29: =+AG29*1.13 -> 10675.185 | AI29: =+AH29*1.12 -> 11956.207 | AJ29: =+AI29*1.11 -> 13271.389
F30: =+F29/B29-1 -> 0.11662727 | G30: =+G29/C29-1 -> 0.11895911 | H30: =+H29/D29-1 -> 0.11032532 | I30: =+I29/E29-1 -> 0.11572498 | J30: =+J29/F29-1 -> 0.15243472 | K30: =+K29/G29-1 -> 0.17142857 | L30: =+L29/H29-1 -> 0.18025478 | M30: =+M29/I29-1 -> 0.19402074 | ... O30: =+O29/K29-1 -> 0.16052184 | V30: =+V29/U29-1 -> -0.18893015 | W30: =+W29/V29-1 -> 0.012604628 | X30: =+X29/W29-1 -> 0.24953807 | Y30: =+Y29/X29-1 -> 0.27414585 | Z30: =+Z29/Y29-1 -> 0.15749931 | AA30: =+AA29/Z29-1 -> 0.15725594 | AB30: =+AB29/AA29-1 -> 0.14113087 | AC30: =+AC29/AB29-1 -> 0.098301698 | ... AJ30: =+AJ29/AI29-1 -> 0.11
A31: Cost of Subs | B31: 96 | C31: 95 | D31: 94 | E31: 96 | F31: 100 | G31: 100 | H31: 105 | I31: 108 | J31: 111 | K31: 114 | L31: 118 | M31: 120 | N31: 129 | O31: 130 | U31: 162.3 | V31: 191.7 | W31: 214.4 | X31: 216 | Y31: 223.9 | Z31: 242 | AA31: 299 | AB31: 343 | AC31: 381 | AD31: 413 | AE31: 463
B32: =+B31/B$29 -> 0.075650118 | C32: =+C31/C$29 -> 0.07063197 | D32: =+D31/D$29 -> 0.066478076 | E32: =+E31/E$29 -> 0.065350579 | F32: =+F31/F$29 -> 0.07057163 | G32: =+G31/G$29 -> 0.066445183 | H32: =+H31/H$29 -> 0.066878981 | I32: =+I31/I$29 -> 0.065893838 | ... O32: =+O31/O$29 -> 0.063538612 | U32: =+U31/U$29 -> 0.064813706 | V32: =+V31/V$29 -> 0.094387001 | W32: =+W31/W$29 -> 0.10424973 | X32: =+X31/X$29 -> 0.084053234 | Y32: =+Y31/Y$29 -> 0.068381028 | Z32: =+Z31/Z$29 -> 0.063852243 | AA32: =+AA31/AA$29 -> 0.068171455 | AB32: =+AB31/AB$29 -> 0.068531469 | ... AE32: =+AE31/AE$29 -> 0.064252012
A33: Cost of Other | B33: 20 | C33: 21 | D33: 21 | E33: 20 | F33: 20 | G33: 18 | H33: 19 | I33: 23 | J33: 24 | K33: 22 | L33: 22 | M33: 22 | N33: 21 | O33: 22 | U33: 159.4 | V33: 110.2 | W33: 72.6 | X33: 54.4 | Y33: 66.5 | Z33: 64 | AA33: 67 | AB33: 79 | AC33: 82 | AD33: 80 | AE33: 90
B34: =+B33/B$29 -> 0.015760441 | C34: =+C33/C$29 -> 0.015613383 | D34: =+D33/D$29 -> 0.014851485 | E34: =+E33/E$29 -> 0.013614704 | F34: =+F33/F$29 -> 0.014114326 | G34: =+G33/G$29 -> 0.011960133 | H34: =+H33/H$29 -> 0.012101911 | I34: =+I33/I$29 -> 0.014032947 | ... O34: =+O33/O$29 -> 0.010752688 | U34: =+U33/U$29 -> 0.063655605 | V34: =+V33/V$29 -> 0.054258986 | W34: =+W33/W$29 -> 0.035300982 | X34: =+X33/X$29 -> 0.021168963 | Y34: =+Y33/Y$29 -> 0.020309685 | Z34: =+Z33/Z$29 -> 0.016886544 | AA34: =+AA33/AA$29 -> 0.015275878 | AB34: =+AB33/AB$29 -> 0.015784216 | ... AE34: =+AE33/AE$29 -> 0.012489592
A35: D&A | B35: 11 | C35: 11 | D35: 12 | E35: 14 | F35: 17 | G35: 22 | H35: 23 | I35: 23 | J35: 25 | K35: 23 | L35: 25 | M35: 24 | N35: 25 | O35: 24 | U35: 49 | V35: 40 | W35: 16.4 | X35: 15.5 | Y35: 34.5 | Z35: 31 | AA35: 52 | AB35: 58 | AC35: 48 | AD35: 85 | AE35: 97
B36: =+B35/B$29 -> 0.0086682427 | C36: =+C35/C$29 -> 0.0081784387 | D36: =+D35/D$29 -> 0.0084865629 | E36: =+E35/E$29 -> 0.0095302927 | F36: =+F35/F$29 -> 0.011997177 | G36: =+G35/G$29 -> 0.01461794 | H36: =+H35/H$29 -> 0.014649682 | I36: =+I35/I$29 -> 0.014032947 | ... O36: =+O35/O$29 -> 0.011730205 | U36: =+U35/U$29 -> 0.019567909 | V36: =+V35/V$29 -> 0.019694732 | W36: =+W35/W$29 -> 0.0079743266 | X36: =+X35/X$29 -> 0.0060315978 | Y36: =+Y35/Y$29 -> 0.010536603 | Z36: =+Z35/Z$29 -> 0.0081794195 | AA36: =+AA35/AA$29 -> 0.011855905 | AB36: =+AB35/AB$29 -> 0.011588412 | ... AE36: =+AE35/AE$29 -> 0.013461005
A37: COGS | B37: =+B35+B33+B31 -> 127 | C37: =+C35+C33+C31 -> 127 | D37: =+D35+D33+D31 -> 127 | E37: =+E35+E33+E31 -> 130 | F37: =+F35+F33+F31 -> 137 | G37: =+G35+G33+G31 -> 140 | H37: =+H35+H33+H31 -> 147 | I37: =+I35+I33+I31 -> 154 | ... Q37: =+Q35+Q33+Q31 -> 0 | U37: =+U35+U33+U31 -> 370.7 | V37: =+V35+V33+V31 -> 341.9 | W37: =+W35+W33+W31 -> 303.4 | X37: =+X35+X33+X31 -> 285.9 | Y37: =+Y35+Y33+Y31 -> 324.9 | Z37: =+Z35+Z33+Z31 -> 337 | AA37: =+AA35+AA33+AA31 -> 418 | AB37: =+AB35+AB33+AB31 -> 480 | ... AE37: =+AE35+AE33+AE31 -> 650 | AF37: =+AF29-AF39 -> 745.821 | AG37: =+AG29-AG39 -> 850.23594 | AH37: =+AH29-AH39 -> 960.76661 | AI37: =+AI29-AI39 -> 1076.0586 | AJ37: =+AJ29-AJ39 -> 1194.4251
B38: =+B37/B$29 -> 0.1000788 | C38: =+C37/C$29 -> 0.094423792 | D38: =+D37/D$29 -> 0.089816124 | E38: =+E37/E$29 -> 0.088495575 | F38: =+F37/F$29 -> 0.096683133 | G38: =+G37/G$29 -> 0.093023256 | H38: =+H37/H$29 -> 0.093630573 | I38: =+I37/I$29 -> 0.093959732 | ... O38: =+O37/O$29 -> 0.086021505 | U38: =+U37/U$29 -> 0.14803722 | V38: =+V37/V$29 -> 0.16834072 | W38: =+W37/W$29 -> 0.14752504 | X38: =+X37/X$29 -> 0.11125379 | Y38: =+Y37/Y$29 -> 0.099227316 | Z38: =+Z37/Z$29 -> 0.088918206 | AA38: =+AA37/AA$29 -> 0.095303238 | AB38: =+AB37/AB$29 -> 0.095904096 | ... AJ38: =+AJ37/AJ$29 -> 0.09
A39: Gross Profit | B39: =+B29-B37 -> 1142 | C39: =+C29-C37 -> 1218 | D39: =+D29-D37 -> 1287 | E39: =+E29-E37 -> 1339 | F39: =+F29-F37 -> 1280 | G39: =+G29-G37 -> 1365 | H39: =+H29-H37 -> 1423 | I39: =+I29-I37 -> 1485 | ... Q39: =+Q29-Q37 -> 0 | U39: =+U29-U37 -> 2133.4 | V39: =+V29-V37 -> 1689.1 | W39: =+W29-W37 -> 1753.2 | X39: =+X29-X37 -> 2283.9 | Y39: =+Y29-Y37 -> 2949.4 | Z39: =+Z29-Z37 -> 3453 | AA39: =+AA29-AA37 -> 3968 | AB39: =+AB29-AB37 -> 4525 | ... AE39: =+AE29-AE37 -> 6556 | AF39: =+AF29*0.91 -> 7541.079 | AG39: =+AG29*0.91 -> 8596.8301 | AH39: =+AH29*0.91 -> 9714.418 | AI39: =+AI29*0.91 -> 10880.148 | AJ39: =+AJ29*0.91 -> 12076.964
B40: =+B39/B$29 -> 0.8999212 | C40: =+C39/C$29 -> 0.90557621 | D40: =+D39/D$29 -> 0.91018388 | E40: =+E39/E$29 -> 0.91150442 | F40: =+F39/F$29 -> 0.90331687 | G40: =+G39/G$29 -> 0.90697674 | H40: =+H39/H$29 -> 0.90636943 | I40: =+I39/I$29 -> 0.90604027 | ... O40: =+O39/O$29 -> 0.91397849 | U40: =+U39/U$29 -> 0.85196278 | V40: =+V39/V$29 -> 0.83165928 | W40: =+W39/W$29 -> 0.85247496 | X40: =+X39/X$29 -> 0.88874621 | Y40: =+Y39/Y$29 -> 0.90077268 | Z40: =+Z39/Z$29 -> 0.91108179 | AA40: =+AA39/AA$29 -> 0.90469676 | AB40: =+AB39/AB$29 -> 0.9040959 | ... AJ40: =+AJ39/AJ$29 -> 0.91
A41: M&S | B41: 456 | C41: 449 | D41: 439 | E41: 479 | F41: 469 | G41: 480 | H41: 525 | I41: 526 | J41: 566 | K41: 559 | L41: 612 | M41: 636 | N41: 593 | O41: 616 | U41: 1015.5 | V41: 1022.5 | W41: 1087.3 | X41: 1183.9 | Y41: 1310.3 | Z41: 1440 | AA41: 1623 | AB41: 1745 | AC41: 1823 | AD41: 2000 | AE41: 2373 | AF41: =+AF29*0.32 -> 2651.808 | AG41: =+AG29*0.32 -> 3023.0611 | AH41: =+AH29*0.3 -> 3202.5554 | AI41: =+AI29*0.3 -> 3586.862 | AJ41: =+AJ29*0.3 -> 3981.4168
B42: =+B41/B$29 -> 0.35933806 | C42: =+C41/C$29 -> 0.333829 | D42: =+D41/D$29 -> 0.31046676 | E42: =+E41/E$29 -> 0.32607216 | F42: =+F41/F$29 -> 0.33098095 | G42: =+G41/G$29 -> 0.31893688 | H42: =+H41/H$29 -> 0.3343949 | I42: =+I41/I$29 -> 0.32092739 | ... O42: =+O41/O$29 -> 0.30107527 | U42: =+U41/U$29 -> 0.40553492 | V42: =+V41/V$29 -> 0.50344658 | W42: =+W41/W$29 -> 0.52868813 | X42: =+X41/X$29 -> 0.46069733 | Y42: =+Y41/Y$29 -> 0.40017714 | Z42: =+Z41/Z$29 -> 0.37994723 | AA42: =+AA41/AA$29 -> 0.37004104 | AB42: =+AB41/AB$29 -> 0.34865135 | ... AJ42: =+AJ41/AJ$29 -> 0.3
A43: R&D | B43: 327 | C43: 355 | D43: 339 | E43: 352 | F43: 346 | G43: 368 | H43: 378 | I43: 393 | J43: 394 | K43: 413 | L43: 416 | M43: 420 | N43: 421 | O43: 464 | U43: 790 | V43: 766.1 | W43: 755.5 | X43: 725 | Y43: 851.1 | Z43: 932 | AA43: 1115 | AB43: 1219 | AC43: 1373 | AD43: 1485 | AE43: 1643 | AF43: =+AF29*0.24 -> 1988.856 | AG43: =+AG29*0.22 -> 2078.3545 | AH43: =+AH29*0.22 -> 2348.5406 | AI43: =+AI29*0.2 -> 2391.2413 | AJ43: =+AJ29*0.2 -> 2654.2779
B44: =+B43/B$29 -> 0.25768322 | C44: =+C43/C$29 -> 0.26394052 | D44: =+D43/D$29 -> 0.2397454 | E44: =+E43/E$29 -> 0.23961879 | F44: =+F43/F$29 -> 0.24417784 | G44: =+G43/G$29 -> 0.24451827 | H44: =+H43/H$29 -> 0.24076433 | I44: =+I43/I$29 -> 0.23978035 | ... O44: =+O43/O$29 -> 0.22678397 | U44: =+U43/U$29 -> 0.31548261 | V44: =+V43/V$29 -> 0.37720335 | W44: =+W43/W$29 -> 0.36735389 | X44: =+X43/X$29 -> 0.28212312 | Y44: =+Y43/Y$29 -> 0.25993342 | Z44: =+Z43/Z$29 -> 0.24591029 | AA44: =+AA43/AA$29 -> 0.25421797 | AB44: =+AB43/AB$29 -> 0.24355644 | ... AJ44: =+AJ43/AJ$29 -> 0.2
A45: G&A | B45: 132 | C45: 141 | D45: 165 | E45: 182 | F45: 155 | G45: 161 | H45: 161 | I45: 173 | J45: 162 | K45: 168 | L45: 172 | M45: 191 | N45: 162 | O45: 179 | U45: 293.4 | V45: 287.8 | W45: 305.2 | X45: 340.1 | Y45: 405.6 | Z45: 414 | AA45: 572 | AB45: 532 | AC45: 620 | AD45: 650 | AE45: 693 | AF45: =+AF29*0.1 -> 828.69 | AG45: =+AG29*0.095 -> 897.47127 | AH45: =+AH29*0.095 -> 1014.1425 | AI45: =+AI29*0.09 -> 1076.0586 | AJ45: =+AJ29*0.09 -> 1194.4251
B46: =+B45/B$29 -> 0.10401891 | C46: =+C45/C$29 -> 0.10483271 | D46: =+D45/D$29 -> 0.11669024 | E46: =+E45/E$29 -> 0.12389381 | F46: =+F45/F$29 -> 0.10938603 | G46: =+G45/G$29 -> 0.10697674 | H46: =+H45/H$29 -> 0.10254777 | I46: =+I45/I$29 -> 0.10555217 | ... O46: =+O45/O$29 -> 0.087487781 | U46: =+U45/U$29 -> 0.11716784 | V46: =+V45/V$29 -> 0.14170359 | W46: =+W45/W$29 -> 0.14840027 | X46: =+X45/X$29 -> 0.13234493 | Y46: =+Y45/Y$29 -> 0.12387381 | Z46: =+Z45/Z$29 -> 0.10923483 | AA46: =+AA45/AA$29 -> 0.13041496 | AB46: =+AB45/AB$29 -> 0.10629371 | ... AJ46: =+AJ45/AJ$29 -> 0.09
A47: Amortisation purchase | B47: 10 | C47: 11 | D47: 10 | E47: 11 | F47: 11 | G47: 13 | H47: 13 | I47: 12 | J47: 13 | K47: 14 | L47: 13 | M47: 13 | N47: 12 | O47: 13 | U47: 33.2 | V47: 31.8 | W47: 20.2 | X47: 18 | Y47: 38.9 | Z47: 38 | AA47: 40 | AB47: 40 | AC47: 42 | AD47: 49 | AE47: 53 | AF47: =+AF29*0.008 -> 66.2952 | AG47: =+AG29*0.008 -> 75.576528 | AH47: =+AH29*0.008 -> 85.401477 | AI47: =+AI29*0.008 -> 95.649654 | AJ47: =+AJ29*0.008 -> 106.17112
B48: =+B47/B$29 -> 0.0078802206 | C48: =+C47/C$29 -> 0.0081784387 | D48: =+D47/D$29 -> 0.0070721358 | E48: =+E47/E$29 -> 0.0074880871 | F48: =+F47/F$29 -> 0.0077628793 | G48: =+G47/G$29 -> 0.0086378738 | H48: =+H47/H$29 -> 0.0082802548 | I48: =+I47/I$29 -> 0.0073215375 | ... O48: =+O47/O$29 -> 0.0063538612 | U48: =+U47/U$29 -> 0.013258256 | V48: =+V47/V$29 -> 0.015657312 | W48: =+W47/W$29 -> 0.0098220364 | X48: =+X47/X$29 -> 0.0070044361 | Y48: =+Y47/Y$29 -> 0.011880402 | Z48: =+Z47/Z$29 -> 0.010026385 | AA48: =+AA47/AA$29 -> 0.009119927 | AB48: =+AB47/AB$29 -> 0.007992008 | ... AJ48: =+AJ47/AJ$29 -> 0.008
A49: Restructuring | B49: 0 | C49: 0 | D49: 0 | E49: 0 | F49: 0 | G49: 0 | H49: 0 | I49: 15 | J49: 105 | K49: 6 | L49: 5 | M49: 100 | N49: 30 | O49: -1 | U49: 0 | V49: 80.5 | W49: 94.1 | X49: 41.9 | Y49: 0.5 | Z49: 0 | AA49: 0 | AB49: 0 | AC49: 0 | AD49: 15 | AE49: 216 | AF49: 0 | AG49: 0 | AH49: 0 | AI49: 0 | AJ49: 0
...
