Workbook

Sheet Main
A1: Amazon.com | D1: Price | E1: 259 | J1: -> | K1: Q126 began testing robotaxis in Miami and Austin, expanded service in SF and Las Vegas.
D2: Share | E2: 10786.314 | F2: Q226 | K2: Driven 2 million miles and carried 350,000+ rides
D3: MC | E3: =+E2*E1 -> 2793655.2
D4: Cash | E4: 122988 | F4: Q226
D5: Debt | E5: 128894 | F5: Q226
D6: EV | E6: =+E3-E4+E5 -> 2799561.2
A8: CAPM | B8: =+0.05+B10*(0.1-0.05) -> 0.123 | D8: WACC | E8: =+(E3/(E3+E5))*B8+(E5/(E5+E3))*B9*(1-0.2) -> 0.11961632
A9: Cost of Debt | B9: =+0.05+(B19/100) -> 0.057847826
A10: BETA | B10: 1.46 | D10: FPE | E10: =+E1/SUM(Model!Q49:T49) -> 20.684523
A11: P/FCF | B11: =+E3/SUM(Model!P125:S125) -> -239.58051
A12: P/E | B12: =+E1/SUM(Model!P49:S49) -> 20.832267
A13: EV/EBITDA | B13: =+E6/SUM(Model!P74:S74) -> 16.574081 | D13: NTM | E13: =+E6/Model!AL74 -> 13.2917
A14: EV/FCF | B14: =+E6/SUM(Model!P125:S125) -> -240.087
A15: Inc Margin | B15: =+((Model!S33+Model!R33+Model!Q33+Model!P33)-(Model!O33+Model!N33+Model!M33+Model!L33))/((Model!S15+Model!R15+Model!Q15+Model!P15)-(Model!O15+Model!N15+Model!M15+Model!L15)) -> 0.16586206
A19: Cr. Spread | B19: =+'[1]Credit Spread US'!J6 -> 0.78478261
A20: Rating | B20: AA | C20: Aa2
B21: S&P | C21: Moody’s
A25: Manufacture products
B26: Kindle
B27: Fire Tablet
B28: Fire TV
B29: Echo
B30: Ring
B31: Blink
B32: Eero
B33: Amazon Leo (Satellite)
B34: -> | C34: AMZN to acquire GSAT to aff direct to devide (D2D) services.
B35: -> | C35: Partnership with AAPL to use satellites to iPhone and Apple Watches SOS call
A37: Services
B38: AWS (Amazon Web Service)
B39: -> | C39: Lambda (data centers)
B40: -> | C40: Annapurna Labs (acquired in 2015), it is AWS’ in house silicon-design organization
C41: responsible for the design of Trainium, Inferentia, Nitro (EC2 virtualisation/security infrastructure), Graviton (general CPU)
C42: This allows AWS to vertically integrate Chip Design / Networking Design / Build Data Centers / Offer EC2 / Offer SageMaker/Bedrock / Sell AI compute
C43: -> | D43: Annapurna projects the AI accelletarors together with Marvell
C44: -> | D44: TSMC is later in charge of materially manifactures the chips
C45: -> | D45: Marvell is in charge of the packaging, silicon engineering, connectivity, interfaces, …
B46: -> | C46: EC2 (Elastic Compute Cloud – Virtual servers)
C47: This service allows firms to rent compute, choosing RAM, CPU, storage, …
C48: EBS, is the persistent memory that survives the virtual machine.
...

Sheet Model
A1: Main | B1: 03/22 | C1: 06/22 | D1: 09/22 | E1: 12/22 | F1: 03/23 | G1: 06/23 | H1: 09/23 | I1: 12/23 | J1: 03/24 | K1: 06/24 | L1: 09/24 | M1: 12/24 | N1: 03/25 | O1: 06/25 | P1: 09/25 | Q1: 12/25 | R1: 03/26 | S1: 06/26 | T1: 09/26 | U1: 12/26 | AE1: 12/19 | AF1: 12/20 | AG1: 12/21 | AH1: 12/22 | AI1: 12/23 | AJ1: 12/24 | AK1: 12/25 | AL1: 12/26 | AM1: 12/27 | AN1: 12/28 | AO1: 12/29 | AP1: 12/30
A2: in Millions | B2: Q122 | C2: Q222 | D2: Q322 | E2: Q422 | F2: Q123 | G2: Q223 | H2: Q323 | I2: Q423 | J2: Q124 | K2: Q224 | L2: Q324 | M2: Q424 | N2: Q125 | O2: Q225 | P2: Q325 | Q2: Q425 | R2: Q126 | S2: Q226 | T2: Q326 | U2: Q426 | AA2: =+AB2-1 -> 2015 | AB2: =+AC2-1 -> 2016 | AC2: =+AD2-1 -> 2017 | AD2: =+AE2-1 -> 2018 | AE2: 2019 | AF2: 2020 | AG2: =AF2+1 -> 2021 | AH2: =AG2+1 -> 2022 | AI2: =AH2+1 -> 2023 | AJ2: =AI2+1 -> 2024 | AK2: =AJ2+1 -> 2025 | AL2: =AK2+1 -> 2026 | AM2: =AL2+1 -> 2027 | AN2: =AM2+1 -> 2028 | ... AP2: =AO2+1 -> 2030
A3: Microsoft Azure
A5: Google Cloud | B5: 5821 | C5: 6276 | D5: 6868 | E5: 7315 | F5: 7454 | G5: 8031 | H5: 8411 | I5: 9192 | J5: 9574 | K5: 10347 | L5: 11353 | M5: 11955 | N5: 12260 | O5: 13624 | P5: 15157 | Q5: 17664 | R5: 20028 | S5: =+O5*1.35 -> 18392.4 | T5: =+P5*1.35 -> 20461.95 | U5: =+Q5*1.35 -> 23846.4 | AF5: 13059 | AG5: 19206 | AH5: =+SUM(B5:E5) -> 26280 | AI5: =+SUM(F5:I5) -> 33088 | AJ5: =+SUM(J5:M5) -> 43229 | AK5: =+SUM(N5:Q5) -> 58705
F6: =+F5/B5-1 -> 0.28053599 | G6: =+G5/C5-1 -> 0.27963671 | H6: =+H5/D5-1 -> 0.22466511 | I6: =+I5/E5-1 -> 0.25659604 | J6: =+J5/F5-1 -> 0.28441105 | K6: =+K5/G5-1 -> 0.28838252 | L6: =+L5/H5-1 -> 0.34978005 | M6: =+M5/I5-1 -> 0.30058747 | ... S6: =+S5/O5-1 -> 0.35 | AG6: =+AG5/AF5-1 -> 0.47070986 | AH6: =+AH5/AG5-1 -> 0.3683224 | AI6: =+AI5/AH5-1 -> 0.25905632 | AJ6: =+AJ5/AI5-1 -> 0.30648574 | AK6: =+AK5/AJ5-1 -> 0.35800042
A7: AWS | B7: 18441 | C7: 19739 | D7: 20538 | E7: 21378 | F7: 21354 | G7: 22140 | H7: 23059 | I7: 24204 | J7: 25037 | K7: 26281 | L7: 27452 | M7: 28786 | N7: 29267 | O7: 30873 | P7: 33006 | Q7: 35579 | R7: 37587 | S7: 42232 | AA7: 7880 | AB7: 12219 | AC7: 17459 | AD7: 25655 | AE7: 35026 | AF7: 45370 | AG7: 62202 | AH7: 80096 | AI7: 90757 | AJ7: 107556 | AK7: 128725
B8: =+B7/B15 -> 0.15836797 | C8: =+C7/C15 -> 0.16281736 | D8: =+D7/D15 -> 0.16158803 | E8: =+E7/E15 -> 0.14328034 | F8: =+F7/F15 -> 0.16766909 | G8: =+G7/G15 -> 0.16475298 | H8: =+H7/H15 -> 0.16115821 | I8: =+I7/I15 -> 0.14240914 | ... S8: =+S7/S15 -> 0.21052212 | AA8: =+AA7/AA15 -> 0.07364073 | AB8: =+AB7/AB15 -> 0.089854177 | AC8: =+AC7/AC15 -> 0.098158164 | AD8: =+AD7/AD15 -> 0.11016072 | AE8: =+AE7/AE15 -> 0.12486008 | AF8: =+AF7/AF15 -> 0.11751938 | AG8: =+AG7/AG15 -> 0.13239482 | AH8: =+AH7/AH15 -> 0.15583395 | ... AK8: =+AK7/AK15 -> 0.17955181
A9: Y/Y | F9: =+F7/B7-1 -> 0.15796323 | G9: =+G7/C7-1 -> 0.12163737 | H9: =+H7/D7-1 -> 0.12274808 | I9: =+I7/E7-1 -> 0.13219197 | J9: =+J7/F7-1 -> 0.17247354 | K9: =+K7/G7-1 -> 0.18703704 | L9: =+L7/H7-1 -> 0.1905113 | M9: =+M7/I7-1 -> 0.18930755 | ... S9: =+S7/O7-1 -> 0.36792667 | AB9: =+AB7/AA7-1 -> 0.55063452 | AC9: =+AC7/AB7-1 -> 0.42884033 | AD9: =+AD7/AC7-1 -> 0.46944269 | AE9: =+AE7/AD7-1 -> 0.36526993 | AF9: =+AF7/AE7-1 -> 0.29532347 | AG9: =+AG7/AF7-1 -> 0.37099405 | AH9: =+AH7/AG7-1 -> 0.28767564 | AI9: =+AI7/AH7-1 -> 0.13310278 | ... AK9: =+AK7/AJ7-1 -> 0.1968184
A11: Product Sales | B11: 56455 | C11: 56575 | D11: 59340 | E11: 70531 | F11: 56981 | G11: 59032 | H11: 63171 | I11: 76703 | J11: 60915 | K11: 61569 | L11: 67601 | M11: 82226 | N11: 63970 | O11: 68246 | P11: 74058 | Q11: 89992 | R11: 71304 | S11: 77602 | AA11: 79268 | AB11: 94665 | AC11: 118573 | AD11: 141915 | AE11: 160408 | AF11: 215915 | AG11: 241787 | AH11: 242901 | AI11: 255887 | AJ11: 272311 | AK11: 296266
F12: =+F11/B11-1 -> 0.0093171553 | G12: =+G11/C11-1 -> 0.043429076 | H12: =+H11/D11-1 -> 0.064560162 | I12: =+I11/E11-1 -> 0.087507621 | J12: =+J11/F11-1 -> 0.069040557 | K12: =+K11/G11-1 -> 0.042976691 | L12: =+L11/H11-1 -> 0.070127115 | M12: =+M11/I11-1 -> 0.072005006 | ... S12: =+S11/O11-1 -> 0.13709228 | AF12: =+AF11/AE11-1 -> 0.34603636 | AG12: =+AG11/AF11-1 -> 0.11982493 | AH12: =+AH11/AG11-1 -> 0.004607361 | AI12: =+AI11/AH11-1 -> 0.05346211 | AJ12: =+AJ11/AI11-1 -> 0.064184581 | AK12: =+AK11/AJ11-1 -> 0.08796927
A13: Service Sales | B13: 59989 | C13: 64659 | D13: 67761 | E13: 78673 | F13: 70377 | G13: 75351 | H13: 79912 | I13: 93258 | J13: 82398 | K13: 86408 | L13: 91276 | M13: 105566 | N13: 91697 | O13: 99456 | P13: 106111 | Q13: 123394 | R13: 110215 | S13: 123004 | AA13: 27738 | AB13: 41322 | AC13: 59293 | AD13: 90972 | AE13: 120114 | AF13: 170149 | AG13: 228035 | AH13: 271082 | AI13: 318898 | AJ13: 365648 | AK13: 420658
F14: =+F13/B13-1 -> 0.17316508 | G14: =+G13/C13-1 -> 0.16535981 | H14: =+H13/D13-1 -> 0.17932144 | I14: =+I13/E13-1 -> 0.18538762 | J14: =+J13/F13-1 -> 0.17080864 | K14: =+K13/G13-1 -> 0.14673992 | L14: =+L13/H13-1 -> 0.14220643 | M14: =+M13/I13-1 -> 0.13197795 | ... S14: =+S13/O13-1 -> 0.23676802 | AF14: =+AF13/AE13-1 -> 0.4165626 | AG14: =+AG13/AF13-1 -> 0.3402077 | AH14: =+AH13/AG13-1 -> 0.18877365 | AI14: =+AI13/AH13-1 -> 0.17638943 | AJ14: =+AJ13/AI13-1 -> 0.1465986 | AK14: =+AK13/AJ13-1 -> 0.15044524
A15: Revenue | B15: =+B13+B11 -> 116444 | C15: =+C13+C11 -> 121234 | D15: =+D13+D11 -> 127101 | E15: =+E13+E11 -> 149204 | F15: =+F13+F11 -> 127358 | G15: =+G13+G11 -> 134383 | H15: =+H13+H11 -> 143083 | I15: =+I13+I11 -> 169961 | ... S15: =+S13+S11 -> 200606 | T15: =+P15*1.12 -> 201789.28 | U15: =+Q15*1.165 -> 248594.69 | AA15: =+AA13+AA11 -> 107006 | AB15: =+AB13+AB11 -> 135987 | AC15: =+AC13+AC11 -> 177866 | AD15: =+AD13+AD11 -> 232887 | AE15: =+AE13+AE11 -> 280522 | AF15: =+AF13+AF11 -> 386064 | AG15: =+AG13+AG11 -> 469822 | AH15: =+AH13+AH11 -> 513983 | ... AK15: =+AK13+AK11 -> 716924 | AL15: =+SUM(R15:U15) -> 832508.97 | AM15: =+AL15*1.15 -> 957385.32 | AN15: =+AM15*1.14 -> 1091419.3 | AO15: =+AN15*1.13 -> 1233303.8 | AP15: =+AO15*1.12 -> 1381300.2
F16: =+F15/B15-1 -> 0.093727457 | G16: =+G15/C15-1 -> 0.10845967 | H16: =+H15/D15-1 -> 0.12574252 | I16: =+I15/E15-1 -> 0.13911825 | J16: =+J15/F15-1 -> 0.12527678 | K16: =+K15/G15-1 -> 0.10115863 | L16: =+L15/H15-1 -> 0.11038348 | M16: =+M15/I15-1 -> 0.1049123 | ... U16: =+U15/Q15-1 -> 0.165 | AF16: =+AF15/AE15-1 -> 0.37623431 | AG16: =+AG15/AF15-1 -> 0.21695367 | AH16: =+AH15/AG15-1 -> 0.093995173 | AI16: =+AI15/AH15-1 -> 0.11829574 | AJ16: =+AJ15/AI15-1 -> 0.10990892 | AK16: =+AK15/AJ15-1 -> 0.12377755 | AL16: =+AL15/AK15-1 -> 0.16122346 | AM16: =+AM15/AL15-1 -> 0.15 | ... AP16: =+AP15/AO15-1 -> 0.12
A17: COGS | B17: 66499 | C17: 66424 | D17: 70268 | E17: 85640 | F17: 67791 | G17: 69373 | H17: 75022 | I17: 92553 | J17: 72633 | K17: 73785 | L17: 80977 | M17: 98893 | N17: 76976 | O17: 80809 | P17: 88670 | Q17: 109959 | R17: 87463 | S17: 95778 | T17: =+T15-T19 -> 98876.747 | U17: =+U15-U19 -> 121811.4 | AA17: 71651 | AB17: 88265 | AC17: 111934 | AD17: 139156 | AE17: 165536 | AF17: 233307 | AG17: 272344 | AH17: 288831 | AI17: 304739 | AJ17: 326288 | AK17: 356414 | AL17: =+AL15-AL19 -> 407929.4 | AM17: =+AM15-AM19 -> 459544.95 | AN17: =+AN15-AN19 -> 512967.05 | AO17: =+AO15-AO19 -> 567319.73 | AP17: =+AP15-AP19 -> 635398.1
B18: =+B17/B$15 -> 0.57108138 | C18: =+C17/C$15 -> 0.5478991 | D18: =+D17/D$15 -> 0.55285167 | E18: =+E17/E$15 -> 0.57397925 | F18: =+F17/F$15 -> 0.53228694 | G18: =+G17/G$15 -> 0.51623345 | H18: =+H17/H$15 -> 0.52432504 | I18: =+I17/I$15 -> 0.54455434 | ... U18: =+U17/U$15 -> 0.49 | AE18: =+AE17/AE$15 -> 0.59009989 | AF18: =+AF17/AF$15 -> 0.60432208 | AG18: =+AG17/AG$15 -> 0.57967486 | AH18: =+AH17/AH$15 -> 0.5619466 | AI18: =+AI17/AI$15 -> 0.53017911 | AJ18: =+AJ17/AJ$15 -> 0.51145607 | AK18: =+AK17/AK$15 -> 0.49714335 | AL18: =+AL17/AL$15 -> 0.49 | ... AP18: =+AP17/AP$15 -> 0.46
A19: Gross Margin | B19: =+B15-B17 -> 49945 | C19: =+C15-C17 -> 54810 | D19: =+D15-D17 -> 56833 | E19: =+E15-E17 -> 63564 | F19: =+F15-F17 -> 59567 | G19: =+G15-G17 -> 65010 | H19: =+H15-H17 -> 68061 | I19: =+I15-I17 -> 77408 | ... S19: =+S15-S17 -> 104828 | T19: =+T15*0.51 -> 102912.53 | U19: =+U15*0.51 -> 126783.29 | AA19: =+AA15-AA17 -> 35355 | AB19: =+AB15-AB17 -> 47722 | AC19: =+AC15-AC17 -> 65932 | AD19: =+AD15-AD17 -> 93731 | AE19: =+AE15-AE17 -> 114986 | AF19: =+AF15-AF17 -> 152757 | AG19: =+AG15-AG17 -> 197478 | AH19: =+AH15-AH17 -> 225152 | ... AK19: =+AK15-AK17 -> 360510 | AL19: =+AL15*0.51 -> 424579.57 | AM19: =+AM15*0.52 -> 497840.36 | AN19: =+AN15*0.53 -> 578452.21 | AO19: =+AO15*0.54 -> 665984.03 | AP19: =+AP15*0.54 -> 745902.12
B20: =+B19/B$15 -> 0.42891862 | C20: =+C19/C$15 -> 0.4521009 | D20: =+D19/D$15 -> 0.44714833 | E20: =+E19/E$15 -> 0.42602075 | F20: =+F19/F$15 -> 0.46771306 | G20: =+G19/G$15 -> 0.48376655 | H20: =+H19/H$15 -> 0.47567496 | I20: =+I19/I$15 -> 0.45544566 | ... U20: =+U19/U$15 -> 0.51 | AE20: =+AE19/AE$15 -> 0.40990011 | AF20: =+AF19/AF$15 -> 0.39567792 | AG20: =+AG19/AG$15 -> 0.42032514 | AH20: =+AH19/AH$15 -> 0.4380534 | AI20: =+AI19/AI$15 -> 0.46982089 | AJ20: =+AJ19/AJ$15 -> 0.48854393 | AK20: =+AK19/AK$15 -> 0.50285665 | AL20: =+AL19/AL$15 -> 0.51 | ... AP20: =+AP19/AP$15 -> 0.54
A21: Fulfillment | B21: 20271 | C21: 20342 | D21: 20583 | E21: 23103 | F21: 20905 | G21: 21305 | H21: 22314 | I21: 26095 | J21: 22317 | K21: 23566 | L21: 24660 | M21: 27962 | N21: 24593 | O21: 25976 | P21: 27679 | Q21: 30826 | R21: 27289 | S21: 29633 | T21: =+P21*1.1 -> 30446.9 | U21: =+Q21*1.1 -> 33908.6 | AA21: 13410 | AB21: 17619 | AC21: 25249 | AD21: 34027 | AE21: 40232 | AF21: 58517 | AG21: 75111 | AH21: 84299 | AI21: 90619 | AJ21: 98505 | AK21: 109074 | AL21: =+AL15*0.14 -> 116551.26 | AM21: =+AM15*0.14 -> 134033.94 | AN21: =+AN15*0.13 -> 141884.5 | AO21: =+AO15*0.13 -> 160329.49 | AP21: =+AP15*0.13 -> 179569.03
B22: =+B21/B$15 -> 0.17408368 | C22: =+C21/C$15 -> 0.16779121 | D22: =+D21/D$15 -> 0.16194208 | E22: =+E21/E$15 -> 0.15484169 | F22: =+F21/F$15 -> 0.1641436 | G22: =+G21/G$15 -> 0.1585394 | H22: =+H21/H$15 -> 0.15595144 | I22: =+I21/I$15 -> 0.15353522 | ... U22: =+U21/U$15 -> 0.13640114 | AE22: =+AE21/AE$15 -> 0.14341834 | AF22: =+AF21/AF$15 -> 0.15157331 | AG22: =+AG21/AG$15 -> 0.15987119 | AH22: =+AH21/AH$15 -> 0.16401126 | AI22: =+AI21/AI$15 -> 0.15765721 | AJ22: =+AJ21/AJ$15 -> 0.15440647 | AK22: =+AK21/AK$15 -> 0.15214165 | AL22: =+AL21/AL$15 -> 0.14 | ... AP22: =+AP21/AP$15 -> 0.13
A23: R&D | B23: 14842 | C23: 18072 | D23: 19485 | E23: 20814 | F23: 20450 | G23: 21931 | H23: 21203 | I23: 22038 | J23: 20424 | K23: 22304 | L23: 22245 | M23: 23571 | N23: 22994 | O23: 27166 | P23: 28962 | Q23: 29399 | R23: 29567 | S23: 33158 | T23: =+T15*0.165 -> 33295.231 | U23: =+U15*0.165 -> 41018.124 | AA23: 5254 | AB23: 7233 | AC23: 10069 | AD23: 13814 | AE23: 35931 | AF23: 42740 | AG23: 56052 | AH23: 73213 | AI23: 85622 | AJ23: 88544 | AK23: 108521 | AL23: =+AL15*0.14 -> 116551.26 | AM23: =+AM15*0.14 -> 134033.94 | AN23: =+AN15*0.14 -> 152798.7 | AO23: =+AO15*0.13 -> 160329.49 | AP23: =+AP15*0.13 -> 179569.03
B24: =+B23/B$15 -> 0.12746041 | C24: =+C23/C$15 -> 0.14906709 | D24: =+D23/D$15 -> 0.15330328 | E24: =+E23/E$15 -> 0.13950028 | F24: =+F23/F$15 -> 0.16057099 | G24: =+G23/G$15 -> 0.16319773 | H24: =+H23/H$15 -> 0.14818672 | I24: =+I23/I$15 -> 0.12966504 | ... U24: =+U23/U$15 -> 0.165 | AE24: =+AE23/AE$15 -> 0.12808621 | AF24: =+AF23/AF$15 -> 0.11070703 | AG24: =+AG23/AG$15 -> 0.11930476 | AH24: =+AH23/AH$15 -> 0.14244245 | AI24: =+AI23/AI$15 -> 0.14896353 | AJ24: =+AJ23/AJ$15 -> 0.13879262 | AK24: =+AK23/AK$15 -> 0.1513703 | AL24: =+AL23/AL$15 -> 0.14 | ... AP24: =+AP23/AP$15 -> 0.13
A25: S&M | B25: 8320 | C25: 10086 | D25: 11014 | E25: 12818 | F25: 10172 | G25: 10745 | H25: 10551 | I25: 12902 | J25: 9662 | K25: 10512 | L25: 10609 | M25: 13124 | N25: 9763 | O25: 11416 | P25: 11686 | Q25: 14264 | R25: 10314 | S25: 11698 | T25: =+T15*0.058 -> 11703.778 | U25: =+U15*0.058 -> 14418.492 | AA25: 12540 | AB25: 16085 | AC25: 22620 | AD25: 28837 | AE25: 18878 | AF25: 22008 | AG25: 32551 | AH25: 42238 | AI25: 44370 | AJ25: 43907 | AK25: 47129 | AL25: =+AL15*0.05 -> 41625.448 | AM25: =+AM15*0.05 -> 47869.266 | AN25: =+AN15*0.05 -> 54570.963 | AO25: =+AO15*0.05 -> 61665.188 | AP25: =+AP15*0.04 -> 55252.009
B26: =+B25/B$15 -> 0.071450654 | C26: =+C25/C$15 -> 0.083194483 | D26: =+D25/D$15 -> 0.086655494 | E26: =+E25/E$15 -> 0.085909225 | F26: =+F25/F$15 -> 0.079869345 | G26: =+G25/G$15 -> 0.07995803 | H26: =+H25/H$15 -> 0.073740416 | I26: =+I25/I$15 -> 0.075911533 | ... U26: =+U25/U$15 -> 0.058 | AE26: =+AE25/AE$15 -> 0.06729597 | AF26: =+AF25/AF$15 -> 0.057006092 | AG26: =+AG25/AG$15 -> 0.069283686 | AH26: =+AH25/AH$15 -> 0.082177815 | AI26: =+AI25/AI$15 -> 0.077194081 | AJ26: =+AJ25/AJ$15 -> 0.068824172 | AK26: =+AK25/AK$15 -> 0.065737791 | AL26: =+AL25/AL$15 -> 0.05 | ... AP26: =+AP25/AP$15 -> 0.04
A27: G&A | B27: 2594 | C27: 2903 | D27: 3061 | E27: 3333 | F27: 3043 | G27: 3202 | H27: 2561 | I27: 3010 | J27: 2742 | K27: 3041 | L27: 2713 | M27: 2863 | N27: 2628 | O27: 2965 | P27: 2875 | Q27: 2704 | R27: 2587 | S27: 2788 | T27: =+P27*1 -> 2875 | U27: =+Q27*1 -> 2704 | AA27: 1747 | AB27: 2432 | AC27: 3674 | AD27: 4336 | AE27: 5203 | AF27: 6668 | AG27: 8823 | AH27: 11891 | AI27: 11816 | AJ27: 11359 | AK27: 11172 | AL27: =+AL15*0.015 -> 12487.635 | AM27: =+AM15*0.015 -> 14360.78 | AN27: =+AN15*0.01 -> 10914.193 | AO27: =+AO15*0.01 -> 12333.038 | AP27: =+AP15*0.01 -> 13813.002
B28: =+B27/B$15 -> 0.022276803 | C28: =+C27/C$15 -> 0.023945428 | D28: =+D27/D$15 -> 0.024083209 | E28: =+E27/E$15 -> 0.022338543 | F28: =+F27/F$15 -> 0.023893277 | G28: =+G27/G$15 -> 0.023827419 | H28: =+H27/H$15 -> 0.017898702 | I28: =+I27/I$15 -> 0.017709945 | ... U28: =+U27/U$15 -> 0.010877143 | AE28: =+AE27/AE$15 -> 0.018547565 | AF28: =+AF27/AF$15 -> 0.017271748 | AG28: =+AG27/AG$15 -> 0.018779453 | AH28: =+AH27/AH$15 -> 0.023135006 | AI28: =+AI27/AI$15 -> 0.020557252 | AJ28: =+AJ27/AJ$15 -> 0.017805219 | AK28: =+AK27/AK$15 -> 0.015583242 | AL28: =+AL27/AL$15 -> 0.015 | ... AP28: =+AP27/AP$15 -> 0.01
A29: Other expense | B29: 249 | C29: 90 | D29: 165 | E29: 759 | F29: 223 | G29: 146 | H29: 244 | I29: 154 | J29: 228 | K29: 97 | L29: 262 | M29: 176 | N29: 308 | O29: 199 | P29: 2875 | Q29: 1257 | R29: 447 | S29: 90 | T29: 100 | U29: 100 | AA29: 171 | AB29: 167 | AC29: 214 | AD29: 296 | AE29: 201 | AF29: -75 | AG29: 62 | AH29: 1263 | AI29: 767 | AJ29: 763 | AK29: 4639 | AL29: =+AL15*0.006 -> 4995.0538 | AM29: =+AM15*0.006 -> 5744.3119 | AN29: =+AN15*0.006 -> 6548.5156 | AO29: =+AO15*0.006 -> 7399.8226 | AP29: =+AP15*0.006 -> 8287.8013
B30: =+B29/B$15 -> 0.0021383669 | C30: =+C29/C$15 -> 0.000742366 | D30: =+D29/D$15 -> 0.0012981802 | E30: =+E29/E$15 -> 0.005086995 | F30: =+F29/F$15 -> 0.0017509697 | G30: =+G29/G$15 -> 0.0010864469 | H30: =+H29/H$15 -> 0.0017053039 | I30: =+I29/I$15 -> 0.00090609022 | ... U30: =+U29/U$15 -> 0.00040226121 | AE30: =+AE29/AE$15 -> 0.00071652134 | AF30: =+AF29/AF$15 -> -0.00019426831 | AG30: =+AG29/AG$15 -> 0.00013196487 | AH30: =+AH29/AH$15 -> 0.0024572797 | AI30: =+AI29/AI$15 -> 0.001334412 | AJ30: =+AJ29/AJ$15 -> 0.0011960016 | AK30: =+AK29/AK$15 -> 0.0064706998 | AL30: =+AL29/AL$15 -> 0.006 | ... AP30: =+AP29/AP$15 -> 0.006
A31: Op Ex. | B31: =+B21+B23+B25+B27+B29 -> 46276 | C31: =+C21+C23+C25+C27+C29 -> 51493 | D31: =+D21+D23+D25+D27+D29 -> 54308 | E31: =+E21+E23+E25+E27+E29 -> 60827 | F31: =+F21+F23+F25+F27+F29 -> 54793 | G31: =+G21+G23+G25+G27+G29 -> 57329 | H31: =+H21+H23+H25+H27+H29 -> 56873 | I31: =+I21+I23+I25+I27+I29 -> 64199 | ... U31: =+U21+U23+U25+U27+U29 -> 92149.216 | AA31: =+AA21+AA23+AA25+AA27+AA29 -> 33122 | AB31: =+AB21+AB23+AB25+AB27+AB29 -> 43536 | AC31: =+AC21+AC23+AC25+AC27+AC29 -> 61826 | AD31: =+AD21+AD23+AD25+AD27+AD29 -> 81310 | AE31: =+AE21+AE23+AE25+AE27+AE29 -> 100445 | AF31: =+AF21+AF23+AF25+AF27+AF29 -> 129858 | AG31: =+AG21+AG23+AG25+AG27+AG29 -> 172599 | AH31: =+AH21+AH23+AH25+AH27+AH29 -> 212904 | ... AP31: =+AP21+AP23+AP25+AP27+AP29 -> 436490.87
B32: =+B31/B$15 -> 0.39740991 | C32: =+C31/C$15 -> 0.42474058 | D32: =+D31/D$15 -> 0.42728224 | E32: =+E31/E$15 -> 0.40767674 | F32: =+F31/F$15 -> 0.43022818 | G32: =+G31/G$15 -> 0.42660902 | H32: =+H31/H$15 -> 0.39748258 | I32: =+I31/I$15 -> 0.37772783 | ... U32: =+U31/U$15 -> 0.37068055 | AE32: =+AE31/AE$15 -> 0.35806461 | AF32: =+AF31/AF$15 -> 0.33636392 | AG32: =+AG31/AG$15 -> 0.36737105 | AH32: =+AH31/AH$15 -> 0.41422382 | AI32: =+AI31/AI$15 -> 0.40570648 | AJ32: =+AJ31/AJ$15 -> 0.38102449 | AK32: =+AK31/AK$15 -> 0.39130368 | AL32: =+AL31/AL$15 -> 0.351 | ... AP32: =+AP31/AP$15 -> 0.316
A33: EBIT | B33: =+B19-B31 -> 3669 | C33: =+C19-C31 -> 3317 | D33: =+D19-D31 -> 2525 | E33: =+E19-E31 -> 2737 | F33: =+F19-F31 -> 4774 | G33: =+G19-G31 -> 7681 | H33: =+H19-H31 -> 11188 | I33: =+I19-I31 -> 13209 | ... U33: =+U19-U31 -> 34634.076 | AA33: =+AA19-AA31 -> 2233 | AB33: =+AB19-AB31 -> 4186 | AC33: =+AC19-AC31 -> 4106 | AD33: =+AD19-AD31 -> 12421 | AE33: =+AE19-AE31 -> 14541 | AF33: =+AF19-AF31 -> 22899 | AG33: =+AG19-AG31 -> 24879 | AH33: =+AH19-AH31 -> 12248 | ... AP33: =+AP19-AP31 -> 309411.25
B34: =+B33/B$15 -> 0.031508708 | C34: =+C33/C$15 -> 0.027360311 | D34: =+D33/D$15 -> 0.019866091 | E34: =+E33/E$15 -> 0.018344012 | F34: =+F33/F$15 -> 0.037484885 | G34: =+G33/G$15 -> 0.057157527 | H34: =+H33/H$15 -> 0.078192378 | I34: =+I33/I$15 -> 0.077717829 | ... U34: =+U33/U$15 -> 0.13931945 | AE34: =+AE33/AE$15 -> 0.051835507 | AF34: =+AF33/AF$15 -> 0.059314 | AG34: =+AG33/AG$15 -> 0.052954098 | AH34: =+AH33/AH$15 -> 0.023829582 | AI34: =+AI33/AI$15 -> 0.064114408 | AJ34: =+AJ33/AJ$15 -> 0.10751945 | AK34: =+AK33/AK$15 -> 0.11155297 | AL34: =+AL33/AL$15 -> 0.159 | ... AP34: =+AP33/AP$15 -> 0.224
A35: Interest Income | B35: 108 | C35: 159 | D35: 277 | E35: 445 | F35: 611 | G35: 661 | H35: 776 | I35: 901 | J35: 993 | K35: 1180 | L35: 1256 | M35: 1248 | N35: 1066 | O35: 1085 | P35: 1100 | Q35: 1130 | R35: 1135 | S35: 1295 | T35: =+$AK$77*(0.05/4) -> 1085.125 | U35: =+$AK$77*(0.05/4) -> 1085.125 | AA35: 50 | AB35: 100 | AC35: 202 | AD35: 440 | AE35: 832 | AF35: 555 | AG35: 448 | AH35: 989 | AI35: 2949 | AJ35: 4677 | AK35: 4381 | AL35: =+$AK$77*0.05 -> 4340.5 | AM35: =+$AK$77*0.05 -> 4340.5 | AN35: =+$AK$77*0.05 -> 4340.5 | AO35: =+$AK$77*0.05 -> 4340.5 | AP35: =+$AK$77*0.05 -> 4340.5
B36: =+B35/B$15 -> 0.00092748446 | C36: =+C35/C$15 -> 0.0013115133 | D36: =+D35/D$15 -> 0.0021793692 | E36: =+E35/E$15 -> 0.0029824938 | F36: =+F35/F$15 -> 0.0047975 | G36: =+G35/G$15 -> 0.0049187769 | H36: =+H35/H$15 -> 0.0054234256 | I36: =+I35/I$15 -> 0.0053012162 | ... U36: =+U35/U$15 -> 0.0043650369 | AE36: =+AE35/AE$15 -> 0.0029658993 | AF36: =+AF35/AF$15 -> 0.0014375855 | AG36: =+AG35/AG$15 -> 0.00095355262 | AH36: =+AH35/AH$15 -> 0.0019241882 | AI36: =+AI35/AI$15 -> 0.0051306141 | AJ36: =+AJ35/AJ$15 -> 0.0073311921 | AK36: =+AK35/AK$15 -> 0.006110829 | AL36: =+AL35/AL$15 -> 0.0052137576 | ... AP36: =+AP35/AP$15 -> 0.0031423292
A37: Interest Expense | B37: -472 | C37: -584 | D37: -617 | E37: -694 | F37: -823 | G37: -840 | H37: -806 | I37: -713 | J37: -644 | K37: -589 | L37: -603 | M37: -570 | N37: -541 | O37: -516 | P37: -538 | Q37: -679 | R37: -800 | S37: -1314 | T37: =-($AK$95*(0.05/4)) -> -820.6 | U37: =-($AK$95*(0.05/4)) -> -820.6 | AA37: -459 | AB37: -484 | AC37: -848 | AD37: -1417 | AE37: -1600 | AF37: -1647 | AG37: -1809 | AH37: -2367 | AI37: -3182 | AJ37: -2406 | AK37: -2274 | AL37: =-($AK$95*0.05) -> -3282.4 | AM37: =-($AK$95*0.05) -> -3282.4 | AN37: =-($AK$95*0.05) -> -3282.4 | AO37: =-($AK$95*0.05) -> -3282.4 | AP37: =-($AK$95*0.05) -> -3282.4
B38: =+B37/B$15 -> -0.0040534506 | C38: =+C37/C$15 -> -0.0048171305 | D38: =+D37/D$15 -> -0.0048544071 | E38: =+E37/E$15 -> -0.0046513498 | F38: =+F37/F$15 -> -0.006462099 | G38: =+G37/G$15 -> -0.0062507907 | H38: =+H37/H$15 -> -0.0056330941 | I38: =+I37/I$15 -> -0.00419508 | ... U38: =+U37/U$15 -> -0.0033009555 | AE38: =+AE37/AE$15 -> -0.0057036525 | AF38: =+AF37/AF$15 -> -0.004266132 | AG38: =+AG37/AG$15 -> -0.0038503944 | AH38: =+AH37/AH$15 -> -0.0046052107 | AI38: =+AI37/AI$15 -> -0.005535983 | AJ38: =+AJ37/AJ$15 -> -0.0037714022 | AK38: =+AK37/AK$15 -> -0.0031718843 | AL38: =+AL37/AL$15 -> -0.0039427803 | ... AP38: =+AP37/AP$15 -> -0.0023763118
A39: Other Income | B39: -8570 | C39: -5545 | D39: 759 | E39: -3450 | F39: -443 | G39: 61 | H39: 1031 | I39: 289 | J39: -2673 | K39: -18 | L39: -27 | M39: 468 | N39: 2749 | O39: 1117 | P39: 10186 | Q39: 1177 | R39: 15647 | S39: 53415 | T39: 7000 | U39: 7000 | AA39: -256 | AB39: 90 | AC39: 346 | AD39: -183 | AE39: 203 | AF39: 2371 | AG39: 14633 | AH39: -16806 | AI39: 938 | AJ39: -2250 | AK39: 15229 | AL39: =+SUM(R39:U39) -> 83062 | AM39: =+AL75*$AS$56 -> 6772.2732 | AN39: =+AM75*$AS$56 -> 10726.58 | AO39: =+AN75*$AS$56 -> 15941.948 | AP39: =+AO75*$AS$56 -> 22500.641
B40: =+B39/B$15 -> -0.073597609 | C40: =+C39/C$15 -> -0.045737994 | D40: =+D39/D$15 -> 0.0059716289 | E40: =+E39/E$15 -> -0.023122704 | F40: =+F39/F$15 -> -0.0034783838 | G40: =+G39/G$15 -> 0.00045392646 | H40: =+H39/H$15 -> 0.0072056079 | I40: =+I39/I$15 -> 0.0017003901 | ... U40: =+U39/U$15 -> 0.028158284 | AE40: =+AE39/AE$15 -> 0.00072365091 | AF40: =+AF39/AF$15 -> 0.0061414688 | AG40: =+AG39/AG$15 -> 0.031145838 | AH40: =+AH39/AH$15 -> -0.032697579 | AI40: =+AI39/AI$15 -> 0.0016319145 | AJ40: =+AJ39/AJ$15 -> -0.0035268724 | AK40: =+AK39/AK$15 -> 0.02124214 | AL40: =+AL39/AL$15 -> 0.099773099 | ... AP40: =+AP39/AP$15 -> 0.016289465
A41: EBT | B41: =+B39+B37+B35+B33 -> -5265 | C41: =+C39+C37+C35+C33 -> -2653 | D41: =+D39+D37+D35+D33 -> 2944 | E41: =+E39+E37+E35+E33 -> -962 | F41: =+F39+F37+F35+F33 -> 4119 | G41: =+G39+G37+G35+G33 -> 7563 | H41: =+H39+H37+H35+H33 -> 12189 | I41: =+I39+I37+I35+I33 -> 13686 | ... U41: =+U39+U37+U35+U33 -> 41898.601 | AA41: =+AA39+AA37+AA35+AA33 -> 1568 | AB41: =+AB39+AB37+AB35+AB33 -> 3892 | AC41: =+AC39+AC37+AC35+AC33 -> 3806 | AD41: =+AD39+AD37+AD35+AD33 -> 11261 | AE41: =+AE39+AE37+AE35+AE33 -> 13976 | AF41: =+AF39+AF37+AF35+AF33 -> 24178 | AG41: =+AG39+AG37+AG35+AG33 -> 38151 | AH41: =+AH39+AH37+AH35+AH33 -> -5936 | ... AP41: =+AP39+AP37+AP35+AP33 -> 332969.99
B42: =+B41/B$15 -> -0.045214867 | C42: =+C41/C$15 -> -0.0218833 | D42: =+D41/D$15 -> 0.023162682 | E42: =+E41/E$15 -> -0.0064475483 | F42: =+F41/F$15 -> 0.032341902 | G42: =+G41/G$15 -> 0.05627944 | H42: =+H41/H$15 -> 0.085188317 | I42: =+I41/I$15 -> 0.080524356 | ... U42: =+U41/U$15 -> 0.16854182 | AE42: =+AE41/AE$15 -> 0.049821404 | AF42: =+AF41/AF$15 -> 0.062626922 | AG42: =+AG41/AG$15 -> 0.081203094 | AH42: =+AH41/AH$15 -> -0.01154902 | AI42: =+AI41/AI$15 -> 0.065340954 | AJ42: =+AJ41/AJ$15 -> 0.10755237 | AK42: =+AK41/AK$15 -> 0.13573405 | AL42: =+AL41/AL$15 -> 0.26004408 | ... AP42: =+AP41/AP$15 -> 0.24105548
...

Sheet Bond
A1: Main
B3: isin | C3: bondType | D3: immediateIssuer | E3: coupon | F3: couponType | G3: maturityDate | H3: callable | I3: currency | J3: seniorityLevel | K3: liquidityScore
B4: US023135BX34 | C4: — | D4: Amazon.com, Inc. | E4: 1000 | F4: Fixed Listing | G4: 12/05/2026 | H4: Y | I4: USD | J4: Senior | K4: — | O4: Axio is a firm that Amazon acquired in 2024
B5: INE491W08251 | C5: — | D5: Axio | E5: 13000 | F5: Fixed Listing | G5: 12/06/2026 | H5: N | I5: INR | J5: Senior | K5: —
B6: INE1FMW07013 | C6: — | D6: Axio Digital Private Limited | E6: 12500 | F6: Fixed Listing | G6: 24/07/2026 | H6: N | I6: INR | J6: Senior | K6: —
B7: INE491W08426 | C7: — | D7: Axio | E7: 13000 | F7: Fixed Listing | G7: 31/08/2026 | H7: N | I7: INR | J7: Senior | K7: —
B8: INE1FMW07070 | C8: — | D8: Axio Digital Private Limited | E8: 12500 | F8: Fixed Listing | G8: 07/09/2026 | H8: N | I8: INR | J8: Senior | K8: —
B9: INE491W07535 | C9: — | D9: Axio | E9: 13500 | F9: Fixed Listing | G9: 28/09/2026 | H9: N | I9: INR | J9: Senior | K9: —
B10: INE1FMW07088 | C10: — | D10: Axio Digital Private Limited | E10: 12500 | F10: Fixed Listing | G10: 09/11/2026 | H10: N | I10: INR | J10: Senior | K10: —
B11: INE1FMW07104 | C11: — | D11: Axio Digital Private Limited | E11: 12500 | F11: Fixed Listing | G11: 13/12/2026 | H11: N | I11: INR | J11: Senior | K11: —
B12: US023135CF19 | C12: — | D12: Amazon.com, Inc. | E12: 3300 | F12: Fixed Listing | G12: 13/04/2027 | H12: Y | I12: USD | J12: Senior | K12: —
B13: US023135BR65 | C13: — | D13: Amazon.com, Inc. | E13: 1200 | F13: Fixed Listing | G13: 03/06/2027 | H13: Y | I13: USD | J13: Senior | K13: —
B14: US023135BC96 | C14: — | D14: Amazon.com, Inc. | E14: 3150 | F14: Fixed Listing | G14: 22/08/2027 | H14: Y | I14: USD | J14: Senior | K14: —
B15: US023135CP90 | C15: — | D15: Amazon.com, Inc. | E15: 4550 | F15: Fixed Listing | G15: 01/12/2027 | H15: Y | I15: USD | J15: Senior | K15: —
B16: INE491W08277 | C16: — | D16: Axio | E16: 13000 | F16: Fixed Listing | G16: 04/01/2028 | H16: N | I16: INR | J16: Senior | K16: —
... B63: US023135DK94 | C63: — | D63: Amazon.com, Inc. | E63: 6050 | F63: Fixed Listing | G63: 13/03/2076 | H63: Y | I63: USD | J63: Senior | K63: —
E64: =+AVERAGE(E4:E63) -> 5314.1167

Sheet Board
A1: Main | E1: auditor | F1: E&Y
