Workbook

Sheet Main
A1: Figma | E1: Price | F1: 23.9
E2: Share A | F2: 445.68259
E3: Share B | F3: 82.693978
E4: MC | F4: =+F1*(F2+F3) -> 12628.2
E5: Cash | F5: 1663
E6: Debt | F6: 0
E7: EV | F7: =+F4-F5+F6 -> 10965.2
A10: HQ | B10: 760 Market Street Floor 10, San Francisco, CA 94102, United States
A11: CEO | B11: Dylan Field
A13: BETA | B13: 1.5 | D13: WACC | E13: =+(F5/(F5+F6))*B14+(F6/(F5+F6))*B15*(1-0.05) -> 0.12525
A14: CAPM | B14: =+0.0495+B13*(0.1-0.0495) -> 0.12525
A15: Cost of Debt | B15: =+0.0495+(B24/10) -> 0.32241667
A22: Rating | B22: BB | C22: Ba2
B23: S&P | C23: Moody’s
A24: Cr. Spread | B24: =+'[1]Credit Spread US'!L6 -> 2.7291667

Sheet Model
A1: Main
A2: in thousands | B2: Q224 | C2: Q324 | D2: Q424 | E2: Q125 | F2: Q225 | G2: Q325 | H2: Q425 | I2: Q126 | J2: Q226 | K2: Q326 | L2: Q426 | R2: 2023 | S2: =+R2+1 -> 2024 | T2: =+S2+1 -> 2025 | U2: =+T2+1 -> 2026 | V2: =+U2+1 -> 2027 | W2: =+V2+1 -> 2028 | X2: =+W2+1 -> 2029 | Y2: =+X2+1 -> 2030 | Z2: =+Y2+1 -> 2031 | ... AE2: =+AD2+1 -> 2036
A3: Revenue | B3: 177198 | C3: 198639 | D3: 216945 | E3: 228199 | F3: 249640 | G3: 274173 | H3: 303776 | I3: 333439 | R3: 504874 | S3: 749011 | T3: 1055788 | U3: =+T3*1.4 -> 1478103.2 | V3: =+U3*1.4 -> 2069344.5 | W3: =+V3*1.35 -> 2793615 | X3: =+W3*1.35 -> 3771380.3 | Y3: =+X3*1.2 -> 4525656.4 | Z3: =+Y3*1.2 -> 5430787.7 | AA3: =+Z3*1.2 -> 6516945.2 | AB3: =+AA3*1.19 -> 7755164.8 | AC3: =+AB3*1.18 -> 9151094.4 | AD3: =+AC3*1.17 -> 10706780 | AE3: =+AD3*1.16 -> 12419865
F4: =+F3/B3-1 -> 0.40881951 | G4: =+G3/C3-1 -> 0.38025765 | H4: =+H3/D3-1 -> 0.4002443 | I4: =+I3/E3-1 -> 0.46117643 | S4: =+S3/R3-1 -> 0.48356025 | T4: =+T3/S3-1 -> 0.40957609 | U4: =+U3/T3-1 -> 0.4 | V4: =+V3/U3-1 -> 0.4 | W4: =+W3/V3-1 -> 0.35 | X4: =+X3/W3-1 -> 0.35 | Y4: =+Y3/X3-1 -> 0.2 | Z4: =+Z3/Y3-1 -> 0.2 | ... AE4: =+AE3/AD3-1 -> 0.16
A5: COGS | B5: 39558 | C5: 18703 | D5: 16463 | E5: 19452 | F5: 27889 | G5: 83884 | H5: 54302 | I5: 68666 | R5: 44500 | S5: 87514 | T5: 185527 | U5: =+U3-U7 -> 251277.54 | V5: =+V3-V7 -> 341441.84 | W5: =+W3-W7 -> 446978.41 | X5: =+X3-X7 -> 584563.95 | Y5: =+Y3-Y7 -> 678848.46 | Z5: =+Z3-Z7 -> 787464.21 | AA5: =+AA3-AA7 -> 912372.33 | AB5: =+AB3-AB7 -> 1046947.2 | ... AE5: =+AE3-AE7 -> 1490383.8
F6: =+F5/B5-1 -> -0.29498458 | G6: =+G5/C5-1 -> 3.4850559 | H6: =+H5/D5-1 -> 2.2984268 | I6: =+I5/E5-1 -> 2.5300226 | S6: =+S5/R5-1 -> 0.96660674 | T6: =+T5/S5-1 -> 1.1199694 | U6: =+U5/T5-1 -> 0.35439879 | V6: =+V5/U5-1 -> 0.35882353 | W6: =+W5/V5-1 -> 0.30909091 | X6: =+X5/W5-1 -> 0.3078125 | Y6: =+Y5/X5-1 -> 0.16129032 | Z6: =+Z5/Y5-1 -> 0.16 | ... AE6: =+AE5/AD5-1 -> 0.1136
A7: Gross Profit | B7: =+B3-B5 -> 137640 | C7: =+C3-C5 -> 179936 | D7: =+D3-D5 -> 200482 | E7: =+E3-E5 -> 208747 | F7: =+F3-F5 -> 221751 | G7: =+G3-G5 -> 190289 | H7: =+H3-H5 -> 249474 | I7: =+I3-I5 -> 264773 | ... L7: =+L3-L5 -> 0 | R7: =+R3-R5 -> 460374 | S7: =+S3-S5 -> 661497 | T7: =+T3-T5 -> 870261 | U7: =+U3*0.83 -> 1226825.7 | V7: =+V3*0.835 -> 1727902.6 | W7: =+W3*0.84 -> 2346636.6 | X7: =+X3*0.845 -> 3186816.4 | Y7: =+Y3*0.85 -> 3846807.9 | Z7: =+Z3*0.855 -> 4643323.4 | AA7: =+AA3*0.86 -> 5604572.9 | AB7: =+AB3*0.865 -> 6708217.5 | AC7: =+AC3*0.87 -> 7961452.2 | AD7: =+AD3*0.875 -> 9368432.9 | AE7: =+AE3*0.88 -> 10929482
F8: =+F7/B7-1 -> 0.61109416 | G8: =+G7/C7-1 -> 0.057537124 | H8: =+H7/D7-1 -> 0.24437107 | I8: =+I7/E7-1 -> 0.26839188 | S8: =+S7/R7-1 -> 0.43686872 | T8: =+T7/S7-1 -> 0.31559327 | U8: =+U7/T7-1 -> 0.40972152 | V8: =+V7/U7-1 -> 0.40843373 | W8: =+W7/V7-1 -> 0.35808383 | X8: =+X7/W7-1 -> 0.35803571 | Y8: =+Y7/X7-1 -> 0.20710059 | Z8: =+Z7/Y7-1 -> 0.20705882 | ... AE8: =+AE7/AD7-1 -> 0.16662857
A9: R&D | B9: 535676 | C9: 104182 | D9: 58551 | E9: 69925 | F9: 83052 | G9: 680885 | H9: 195838 | I9: 172974 | R9: 164774 | S9: 751120 | T9: 1029700 | U9: =+T9*1.25 -> 1287125 | V9: =+U9*1.25 -> 1608906.2 | W9: =+V9*1.2 -> 1930687.5 | X9: =+W9*1.2 -> 2316825 | Y9: =+X9*1.1 -> 2548507.5 | Z9: =+Y9*1.1 -> 2803358.2 | AA9: =+Z9*1.1 -> 3083694.1 | AB9: =+AA9*1.05 -> 3237878.8 | AC9: =+AB9*1.05 -> 3399772.7 | AD9: =+AC9*1.05 -> 3569761.4 | AE9: =+AD9*1.05 -> 3748249.4
F10: =+F9/B9-1 -> -0.84495852 | G10: =+G9/C9-1 -> 5.535534 | H10: =+H9/D9-1 -> 2.3447422 | I10: =+I9/E9-1 -> 1.4737075 | S10: =+S9/R9-1 -> 3.5584862 | T10: =+T9/S9-1 -> 0.37088614 | U10: =+U9/T9-1 -> 0.25 | V10: =+V9/U9-1 -> 0.25 | W10: =+W9/V9-1 -> 0.2 | X10: =+X9/W9-1 -> 0.2 | Y10: =+Y9/X9-1 -> 0.1 | Z10: =+Z9/Y9-1 -> 0.1 | ... AE10: =+AE9/AD9-1 -> 0.05
A11: S&M | B11: 276246 | C11: 79290 | D11: 61206 | E11: 68840 | F11: 97701 | G11: 274759 | H11: 134208 | I11: 125568 | R11: 201377 | S11: 472076 | T11: 575508 | U11: =+T11*1.2 -> 690609.6 | V11: =+U11*1.2 -> 828731.52 | W11: =+V11*1.2 -> 994477.82 | X11: =+W11*1.15 -> 1143649.5 | Y11: =+X11*1.15 -> 1315196.9 | Z11: =+Y11*1.15 -> 1512476.5 | AA11: =+Z11*1.1 -> 1663724.1 | AB11: =+AA11*1.05 -> 1746910.3 | AC11: =+AB11*1.05 -> 1834255.8 | AD11: =+AC11*1.05 -> 1925968.6 | AE11: =+AD11*1.05 -> 2022267
F12: =+F11/B11-1 -> -0.6463261 | G12: =+G11/C11-1 -> 2.4652415 | H12: =+H11/D11-1 -> 1.1927262 | I12: =+I11/E11-1 -> 0.82405578 | S12: =+S11/R11-1 -> 1.3442399 | T12: =+T11/S11-1 -> 0.21910031 | U12: =+U11/T11-1 -> 0.2 | V12: =+V11/U11-1 -> 0.2 | W12: =+W11/V11-1 -> 0.2 | X12: =+X11/W11-1 -> 0.15 | Y12: =+Y11/X11-1 -> 0.15 | Z12: =+Z11/Y11-1 -> 0.15 | ... AE12: =+AE11/AD11-1 -> 0.05
A13: G&A | B13: 220005 | C13: 43800 | D13: 29056 | E13: 30233 | F13: 38922 | G13: 371425 | H13: 114930 | I13: 103629 | R13: 167679 | S13: 315734 | T13: 555510 | U13: =+T13*1.2 -> 666612 | V13: =+U13*1.2 -> 799934.4 | W13: =+V13*1.2 -> 959921.28 | X13: =+W13*1.15 -> 1103909.5 | Y13: =+X13*1.15 -> 1269495.9 | Z13: =+Y13*1.15 -> 1459920.3 | AA13: =+Z13*1.1 -> 1605912.3 | AB13: =+AA13*1.05 -> 1686207.9 | AC13: =+AB13*1.05 -> 1770518.3 | AD13: =+AC13*1.05 -> 1859044.2 | AE13: =+AD13*1.05 -> 1951996.4
F14: =+F13/B13-1 -> -0.82308584 | G14: =+G13/C13-1 -> 7.4800228 | H14: =+H13/D13-1 -> 2.9554653 | I14: =+I13/E13-1 -> 2.4276784 | S14: =+S13/R13-1 -> 0.88296686 | T14: =+T13/S13-1 -> 0.75942407 | U14: =+U13/T13-1 -> 0.2 | V14: =+V13/U13-1 -> 0.2 | W14: =+W13/V13-1 -> 0.2 | X14: =+X13/W13-1 -> 0.15 | Y14: =+Y13/X13-1 -> 0.15 | Z14: =+Z13/Y13-1 -> 0.15 | ... AE14: =+AE13/AD13-1 -> 0.05
A15: Op Ex | B15: =+B13+B11+B9 -> 1031927 | C15: =+C13+C11+C9 -> 227272 | D15: =+D13+D11+D9 -> 148813 | E15: =+E13+E11+E9 -> 168998 | F15: =+F13+F11+F9 -> 219675 | G15: =+G13+G11+G9 -> 1327069 | H15: =+H13+H11+H9 -> 444976 | I15: =+I13+I11+I9 -> 402171 | ... L15: =+L13+L11+L9 -> 0 | R15: =+R13+R11+R9 -> 533830 | S15: =+S13+S11+S9 -> 1538930 | T15: =+T13+T11+T9 -> 2160718 | U15: =+U13+U11+U9 -> 2644346.6 | V15: =+V13+V11+V9 -> 3237572.2 | W15: =+W13+W11+W9 -> 3885086.6 | X15: =+X13+X11+X9 -> 4564384 | Y15: =+Y13+Y11+Y9 -> 5133200.3 | ... AE15: =+AE13+AE11+AE9 -> 7722512.9
F16: =+F15/B15-1 -> -0.78712157 | G16: =+G15/C15-1 -> 4.8391223 | H16: =+H15/D15-1 -> 1.9901689 | I16: =+I15/E15-1 -> 1.3797382 | S16: =+S15/R15-1 -> 1.8828091 | T16: =+T15/S15-1 -> 0.40403917 | U16: =+U15/T15-1 -> 0.22382773 | V16: =+V15/U15-1 -> 0.2243373 | W16: =+W15/V15-1 -> 0.2 | X16: =+X15/W15-1 -> 0.17484742 | Y16: =+Y15/X15-1 -> 0.12462062 | Z16: =+Z15/Y15-1 -> 0.12517623 | ... AE16: =+AE15/AD15-1 -> 0.05
A17: EBIT | B17: =+B7-B15 -> -894287 | C17: =+C7-C15 -> -47336 | D17: =+D7-D15 -> 51669 | E17: =+E7-E15 -> 39749 | F17: =+F7-F15 -> 2076 | G17: =+G7-G15 -> -1136780 | H17: =+H7-H15 -> -195502 | I17: =+I7-I15 -> -137398 | ... L17: =+L7-L15 -> 0 | R17: =+R7-R15 -> -73456 | S17: =+S7-S15 -> -877433 | T17: =+T7-T15 -> -1290457 | U17: =+U7-U15 -> -1417520.9 | V17: =+V7-V15 -> -1509669.5 | W17: =+W7-W15 -> -1538450 | X17: =+X7-X15 -> -1377567.6 | Y17: =+Y7-Y15 -> -1286392.4 | ... AE17: =+AE7-AE15 -> 3206968.6
F18: =+F17/B17-1 -> -1.0023214 | G18: =+G17/C17-1 -> 23.015126 | H18: =+H17/D17-1 -> -4.7837388 | I18: =+I17/E17-1 -> -4.4566404 | S18: =+S17/R17-1 -> 10.945015 | T18: =+T17/S17-1 -> 0.47071856 | U18: =+U17/T17-1 -> 0.098464299 | V18: =+V17/U17-1 -> 0.06500686 | W18: =+W17/V17-1 -> 0.019064063 | X18: =+X17/W17-1 -> -0.10457432 | Y18: =+Y17/X17-1 -> -0.066185652 | Z18: =+Z17/Y17-1 -> -0.1196842 | ... AE18: =+AE17/AD17-1 -> 0.59260781
A19: Other Income | B19: 10139 | C19: 17910 | D19: 39128 | E19: 7274 | F19: 36978 | G19: 29305 | H19: -8742 | I19: -4325 | R19: 1019375 | S19: 84362 | T19: 64815 | U19: 70000 | V19: 70000 | W19: 70000 | X19: 70000 | Y19: 70000 | Z19: 70000 | AA19: 70000 | AB19: 70000 | AC19: 70000 | AD19: 70000 | AE19: 70000
F20: =+F19/B19-1 -> 2.6471052 | G20: =+G19/C19-1 -> 0.63623674 | H20: =+H19/D19-1 -> -1.2234206 | I20: =+I19/E19-1 -> -1.5945834 | S20: =+S19/R19-1 -> -0.91724145 | T20: =+T19/S19-1 -> -0.23170385 | U20: =+U19/T19-1 -> 0.079996914 | V20: =+V19/U19-1 -> 0 | W20: =+W19/V19-1 -> 0 | X20: =+X19/W19-1 -> 0 | Y20: =+Y19/X19-1 -> 0 | Z20: =+Z19/Y19-1 -> 0 | ... AE20: =+AE19/AD19-1 -> 0
A21: EBT | B21: =+B17+B19 -> -884148 | C21: =+C17+C19 -> -29426 | D21: =+D17+D19 -> 90797 | E21: =+E17+E19 -> 47023 | F21: =+F17+F19 -> 39054 | G21: =+G17+G19 -> -1107475 | H21: =+H17+H19 -> -204244 | I21: =+I17+I19 -> -141723 | ... L21: =+L17+L19 -> 0 | R21: =+R17+R19 -> 945919 | S21: =+S17+S19 -> -793071 | T21: =+T17+T19 -> -1225642 | U21: =+U17+U19 -> -1347520.9 | V21: =+V17+V19 -> -1439669.5 | W21: =+W17+W19 -> -1468450 | X21: =+X17+X19 -> -1307567.6 | Y21: =+Y17+Y19 -> -1216392.4 | ... AE21: =+AE17+AE19 -> 3276968.6
F22: =+F21/B21-1 -> -1.0441713 | G22: =+G21/C21-1 -> 36.635934 | H22: =+H21/D21-1 -> -3.2494576 | I22: =+I21/E21-1 -> -4.0139081 | S22: =+S21/R21-1 -> -1.8384132 | T22: =+T21/S21-1 -> 0.54543792 | U22: =+U21/T21-1 -> 0.0994409 | V22: =+V21/U21-1 -> 0.068383787 | W22: =+W21/V21-1 -> 0.019991001 | X22: =+X21/W21-1 -> -0.10955931 | Y22: =+Y21/X21-1 -> -0.069728869 | Z22: =+Z21/Y21-1 -> -0.1265717 | ... AE22: =+AE21/AD21-1 -> 0.5726993
A23: Taxes | B23: -56294 | C23: -13828 | D23: -7010 | E23: 2141 | F23: 10827 | G23: -10460 | H23: 22313 | I23: 678 | R23: 208078 | S23: -60951 | T23: 24821 | U23: =+U21*(-0.1) -> 134752.09 | V23: =+V21*(-0.1) -> 143966.95 | W23: =+W21*(-0.1) -> 146845 | AC23: =+AC21*(0.22) -> 225919.16 | AD23: =+AD21*(0.22) -> 458404.92 | AE23: =+AE21*(0.22) -> 720933.09
F24: =+F23/B23-1 -> -1.1923296 | G24: =+G23/C23-1 -> -0.24356378 | H24: =+H23/D23-1 -> -4.1830243 | I24: =+I23/E23-1 -> -0.68332555 | S24: =+S23/R23-1 -> -1.2929238 | T24: N.M. | U24: =+U23/T23-1 -> 4.4289551 | V24: =+V23/U23-1 -> 0.068383787 | W24: =+W23/V23-1 -> 0.019991001 | X24: =+X23/W23-1 -> -1 | Y24: =+Y23/X23-1 -> #DIV/0! | Z24: =+Z23/Y23-1 -> #DIV/0! | AA24: =+AA23/Z23-1 -> #DIV/0! | AB24: =+AB23/AA23-1 -> #DIV/0! | ... AE24: =+AE23/AD23-1 -> 0.5726993
A25: Net Income | B25: =+B21-B23 -> -827854 | C25: =+C21-C23 -> -15598 | D25: =+D21-D23 -> 97807 | E25: =+E21-E23 -> 44882 | F25: =+F21-F23 -> 28227 | G25: =+G21-G23 -> -1097015 | H25: =+H21-H23 -> -226557 | I25: =+I21-I23 -> -142401 | ... L25: =+L21-L23 -> 0 | R25: =+R21-R23 -> 737841 | S25: =+S21-S23 -> -732120 | T25: =+T21-T23 -> -1250463 | U25: =+U21-U23 -> -1482273 | V25: =+V21-V23 -> -1583636.5 | W25: =+W21-W23 -> -1615295 | X25: =+X21-X23 -> -1307567.6 | Y25: =+Y21-Y23 -> -1216392.4 | ... AE25: =+AE21-AE23 -> 2556035.5
F26: =+F25/B25-1 -> -1.0340966 | G26: =+G25/C25-1 -> 69.330491 | H26: =+H25/D25-1 -> -3.3163679 | I26: =+I25/E25-1 -> -4.1727864 | S26: =+S25/R25-1 -> -1.9922463 | T26: =+T25/S25-1 -> 0.70800279 | U26: =+U25/T25-1 -> 0.18537937 | V26: =+V25/U25-1 -> 0.068383787 | W26: =+W25/V25-1 -> 0.019991001 | X26: =+X25/W25-1 -> -0.19050846 | Y26: =+Y25/X25-1 -> -0.069728869 | Z26: =+Z25/Y25-1 -> -0.1265717 | ... AE26: =+AE25/AD25-1 -> 0.5726993
A27: NCI | B27: 0 | C27: 0 | D27: -64737 | E27: -36271 | F27: -27381 | G27: 0 | H27: 0 | I27: 0 | R27: -451982 | S27: 0 | T27: 0 | U27: 0 | V27: 0 | W27: 0 | X27: 0 | Y27: 0 | Z27: 0 | AA27: 0 | AB27: 0 | AC27: 0 | AD27: 0 | AE27: 0
F28: =+F27/B27-1 -> #DIV/0! | G28: =+G27/C27-1 -> #DIV/0! | H28: =+H27/D27-1 -> -1 | I28: =+I27/E27-1 -> -1 | S28: N.M. | T28: N.M.
A29: Net Income FIG | B29: =+B25+B27 -> -827854 | C29: =+C25+C27 -> -15598 | D29: =+D25+D27 -> 33070 | E29: =+E25+E27 -> 8611 | F29: =+F25+F27 -> 846 | G29: =+G25+G27 -> -1097015 | H29: =+H25+H27 -> -226557 | I29: =+I25+I27 -> -142401 | ... L29: =+L25+L27 -> 0 | R29: =+R25+R27 -> 285859 | S29: =+S25+S27 -> -732120 | T29: =+T25+T27 -> -1250463 | U29: =+U25+U27 -> -1482273 | V29: =+V25+V27 -> -1583636.5 | W29: =+W25+W27 -> -1615295 | X29: =+X25+X27 -> -1307567.6 | Y29: =+Y25+Y27 -> -1216392.4 | ... AE29: =+AE25+AE27 -> 2556035.5 | AF29: =+AE29*(1+$AJ$36) -> 2581595.9 | AG29: =+AF29*(1+$AJ$36) -> 2607411.8 | AH29: =+AG29*(1+$AJ$36) -> 2633485.9 | AI29: =+AH29*(1+$AJ$36) -> 2659820.8 | AJ29: =+AI29*(1+$AJ$36) -> 2686419 | AK29: =+AJ29*(1+$AJ$36) -> 2713283.2 | AL29: =+AK29*(1+$AJ$36) -> 2740416 | AM29: =+AL29*(1+$AJ$36) -> 2767820.2 | ... CW29: =+CV29*(1+$AJ$36) -> 5129358.4
F30: =+F29/B29-1 -> -1.0010219 | G30: =+G29/C29-1 -> 69.330491 | H30: =+H29/D29-1 -> -7.8508316 | I30: =+I29/E29-1 -> -17.537104 | S30: =+S29/R29-1 -> -3.5611228 | T30: =+T29/S29-1 -> 0.70800279 | U30: =+U29/T29-1 -> 0.18537937 | V30: =+V29/U29-1 -> 0.068383787 | W30: =+W29/V29-1 -> 0.019991001 | X30: =+X29/W29-1 -> -0.19050846 | Y30: =+Y29/X29-1 -> -0.069728869 | Z30: =+Z29/Y29-1 -> -0.1265717 | ... AE30: =+AE29/AD29-1 -> 0.5726993
A31: EPS | B31: =+B29/B33 -> -4.385238 | C31: =+C29/C33 -> -0.074005542 | D31: =+D29/D33 -> 0.14572455 | E31: =+E29/E33 -> 0.037264796 | F31: =+F29/F33 -> 0.0036512417 | G31: =+G29/G33 -> -2.7206904 | H31: =+H29/H33 -> -0.44332885 | I31: =+I29/I33 -> -0.27202499 | R31: =+R29/R33 -> 1.5269675 | S31: =+S29/S33 -> -3.7427152 | T31: =+T29/T33 -> -3.7100883 | U31: =+U29/U33 -> -3.9980565 | V31: =+V29/V33 -> -3.8831443 | W31: =+W29/W33 -> -3.600702 | X31: =+X29/X33 -> -2.6497617 | Y31: =+Y29/Y33 -> -2.4898957 | ... AE31: =+AE29/AE33 -> 5.5572915
F32: =+F31/B31-1 -> -1.0008326 | G32: =+G31/C31-1 -> 35.763333 | H32: =+H31/D31-1 -> -4.0422386 | I32: =+I31/E31-1 -> -8.2997847 | S32: =+S31/R31-1 -> -3.4510772 | T32: =+T31/S31-1 -> -0.0087174343 | U32: =+U31/T31-1 -> 0.077617606 | V32: =+V31/U31-1 -> -0.028742012 | W32: =+W31/V31-1 -> -0.072735454 | X32: =+X31/W31-1 -> -0.2640986 | Y32: =+Y31/X31-1 -> -0.060332191 | Z32: =+Z31/Y31-1 -> -0.11774919 | ... AE32: =+AE31/AD31-1 -> 0.58858515
A33: Shares | B33: 188782 | C33: 210768 | D33: 226935 | E33: 231076 | F33: 231702 | G33: 403212 | H33: 511036 | I33: 523485 | R33: 187207 | S33: 195612 | T33: 337044 | U33: =+T33*1.1 -> 370748.4 | V33: =+U33*1.1 -> 407823.24 | W33: =+V33*1.1 -> 448605.56 | X33: =+W33*1.1 -> 493466.12 | Y33: =+X33*0.99 -> 488531.46 | Z33: =+Y33*0.99 -> 483646.14 | AA33: =+Z33*0.99 -> 478809.68 | AB33: =+AA33*0.99 -> 474021.59 | AC33: =+AB33*0.99 -> 469281.37 | AD33: =+AC33*0.99 -> 464588.56 | AE33: =+AD33*0.99 -> 459942.67
F34: =+F33/B33-1 -> 0.22735218 | G34: =+G33/C33-1 -> 0.91306081 | H34: =+H33/D33-1 -> 1.2519047 | I34: =+I33/E33-1 -> 1.2654235 | S34: =+S33/R33-1 -> 0.044896825 | T34: =+T33/S33-1 -> 0.72302313 | U34: =+U33/T33-1 -> 0.1 | V34: =+V33/U33-1 -> 0.1 | W34: =+W33/V33-1 -> 0.1 | X34: =+X33/W33-1 -> 0.1 | Y34: =+Y33/X33-1 -> -0.01 | Z34: =+Z33/Y33-1 -> -0.01 | ... AE34: =+AE33/AD33-1 -> -0.01
A36: Gross Margin | B36: =+B7/B3 -> 0.7767582 | C36: =+C7/C3 -> 0.90584427 | D36: =+D7/D3 -> 0.92411441 | E36: =+E7/E3 -> 0.91475861 | F36: =+F7/F3 -> 0.88828313 | G36: =+G7/G3 -> 0.69404719 | H36: =+H7/H3 -> 0.82124328 | I36: =+I7/I3 -> 0.79406728 | S36: =+S7/S3 -> 0.88316059 | T36: =+T7/T3 -> 0.82427628 | U36: =+U7/U3 -> 0.83 | V36: =+V7/V3 -> 0.835 | W36: =+W7/W3 -> 0.84 | X36: =+X7/X3 -> 0.845 | Y36: =+Y7/Y3 -> 0.85 | Z36: =+Z7/Z3 -> 0.855 | ... AE36: =+AE7/AE3 -> 0.88 | AI36: Terminal | AJ36: 0.01
A37: OP Margin | B37: =+B17/B3 -> -5.0468233 | C37: =+C17/C3 -> -0.23830164 | D37: =+D17/D3 -> 0.23816636 | E37: =+E17/E3 -> 0.17418569 | F37: =+F17/F3 -> 0.008315975 | G37: =+G17/G3 -> -4.1462143 | H37: =+H17/H3 -> -0.6435729 | I37: =+I17/I3 -> -0.41206338 | S37: =+S17/S3 -> -1.1714554 | T37: =+T17/T3 -> -1.2222691 | U37: =+U17/U3 -> -0.95901351 | V37: =+V17/V3 -> -0.72953998 | W37: =+W17/W3 -> -0.5507022 | X37: =+X17/X3 -> -0.36526881 | Y37: =+Y17/Y3 -> -0.28424438 | Z37: =+Z17/Z3 -> -0.20852068 | ... AE37: =+AE17/AE3 -> 0.25821283 | AI37: ROIC | AJ37: 0.02
A38: NI Margin | B38: =+B29/B3 -> -4.671915 | C38: =+C29/C3 -> -0.078524358 | D38: =+D29/D3 -> 0.15243495 | E38: =+E29/E3 -> 0.037734609 | F38: =+F29/F3 -> 0.00338888 | G38: =+G29/G3 -> -4.0011781 | H38: =+H29/H3 -> -0.74580283 | I38: =+I29/I3 -> -0.42706762 | S38: =+S29/S3 -> -0.97744893 | T38: =+T29/T3 -> -1.1843883 | U38: =+U29/U3 -> -1.0028211 | V38: =+V29/V3 -> -0.76528413 | W38: =+W29/W3 -> -0.57820957 | X38: =+X29/X3 -> -0.34670797 | Y38: =+Y29/Y3 -> -0.26877701 | Z38: =+Z29/Z3 -> -0.19563121 | ... AE38: =+AE29/AE3 -> 0.20580219 | AI38: Discount | AJ38: =+Main!E13 -> 0.12525
A39: Rule of 40 | E39: =+E37+E4 -> 0.17418569 | F39: =+F37+F4 -> 0.41713549 | G39: =+G37+G4 -> -3.7659566 | H39: =+H37+H4 -> -0.24332859 | I39: =+I37+I4 -> 0.049113053 | S39: =+S37+S4 -> -0.68789517 | T39: =+T37+T4 -> -0.81269296 | U39: =+U37+U4 -> -0.55901351 | V39: =+V37+V4 -> -0.32953998 | W39: =+W37+W4 -> -0.2007022 | X39: =+X37+X4 -> -0.015268811 | Y39: =+Y37+Y4 -> -0.084244381 | Z39: =+Z37+Z4 -> -0.0085206817 | ... AE39: =+AE37+AE4 -> 0.41821283 | AI39: NPV | AJ39: =+NPV(AJ38,U29:CW29) -> 1617314.1
A40: Tax Rate | B40: =+B23/B21 -> 0.063670336 | C40: =+C23/C21 -> 0.46992456 | D40: =+D23/D21 -> -0.077205194 | E40: =+E23/E21 -> 0.04553091 | F40: =+F23/F21 -> 0.27723153 | G40: =+G23/G21 -> 0.0094449085 | H40: =+H23/H21 -> -0.10924678 | I40: =+I23/I21 -> -0.00478398 | R40: =+R23/R21 -> 0.21997444 | S40: =+S23/S21 -> 0.076854405 | T40: =+T23/T21 -> -0.020251427 | U40: =+U23/U21 -> -0.1 | V40: =+V23/V21 -> -0.1 | W40: =+W23/W21 -> -0.1 | X40: =+X23/X21 -> 0 | Y40: =+Y23/Y21 -> 0 | ... AE40: =+AE23/AE21 -> 0.22 | AI40: Share | AJ40: =+AJ39/(Main!F2+Main!F3)-1 -> 3059.9118
AI41: Diff | AJ41: =+AJ40/Main!F1-1 -> 127.02978
...
