Workbook

Sheet Main
A1: Alphabeth Inc. | D1: Share A | E1: 344
D2: Share B | E2: 0 | I2: -> | J2: Increasing growth of Google cloud
D3: Share C | E3: 340 | I3: -> | J3: +74% CapEx in AI (?)
D4: Shares A | E4: 5868 | F4: Q226 | I4: -> | J4: Waymo more than 500.000 drives a week
D5: Shares B | E5: 835 | F5: Q226 | I5: -> | J5: 350 M paid users between Google One and YT Premium
D6: Shares C | E6: 5527 | F6: Q226
D7: MC | E7: =+E4*E1+E6*E3 -> 3897772
D8: Cash | E8: 242474 | F8: Q226
D9: Debt | E9: 98165 | F9: Q226
D10: Preferred | E10: 18023 | F10: Q226
D11: Ev | E11: =+E7-E8+E9+E10 -> 3771486
D13: IPO | E13: 2004
A15: HQ | B15: 1600 Amphitheatre Parkway, Mountain View, CA 94043, US
A16: CEO | B16: Sundar Pichai
A18: P/FCF | B18: =+E7/SUM(Model!P139:S139) -> 73.165994 | D18: WACC | E18: =+(E7/(E7+E9+E10))*B24+(E10/(E10+E9+E7))*B25*(1-Model!AH59) -> 0.10946049
A19: P/E | B19: =+E7/SUM(Model!P41:S41) -> 15.961065
A20: EV/EBITDA | B20: =+E11/SUM(Model!P71:S71) -> 17.708502
A21: EV/FCF | B21: =+E11/SUM(Model!O139:R139) -> 58.537087
A22: Inc Margin | B22: =+((Model!S33+Model!R33+Model!Q33+Model!P33)-(Model!O33+Model!N33+Model!M33+Model!L33))/((Model!S19+Model!R19+Model!Q19+Model!P19)-(Model!O19+Model!N19+Model!M19+Model!L19)) -> 0.35261257
A23: BETA | B23: 1.25
A24: CAPM | B24: =+0.05+B23*(0.1-0.05) -> 0.1125
A25: Cost of Debt | B25: =+0.05+(B26/100) -> 0.058052174 | C25: =+Bond!D50/100000 -> 0.036967174
A26: Cr. Spread | B26: =+'[1]Credit Spread US'!J6 -> 0.80521739
A27: Rating | B27: AA+ | C27: AA1
B28: S&P | C28: Moody’s
A30: Google Search and Other
B31: Google Search Advertising
B32: Revenues from properties like Gmail, Maps and Google Play
A34: YT Ads
B35: Advertising on Youtube
B36: -> | C36: Long form video
B37: -> | C37: Short form video
B38: -> | C38: Connected-TV / living room viewers
B39: -> | C39: Music
B40: -> | C40: Live Streams
A42: Google Network
B43: Google’s revenue on third party websites
B44: -> | C44: AdSense
B45: -> | C45: AdMob
B46: -> | C46: Google Ad Manager
...

Sheet Model
A1: Main | B1: 03/22 | C1: 06/22 | D1: 09/22 | E1: 12/22 | F1: 03/23 | G1: 06/23 | H1: 09/23 | I1: 12/23 | J1: 03/24 | K1: 06/24 | L1: 09/24 | M1: 12/24 | N1: 03/25 | O1: 06/25 | P1: 09/25 | Q1: 12/25 | R1: 03/26 | S1: 06/26 | T1: 09/26 | U1: 12/26 | AC1: 12/20 | AD1: 12/21 | AE1: 12/22 | AF1: 12/23 | AG1: 12/24 | AH1: 12/25 | AI1: 12/26 | AJ1: 12/27 | AK1: 12/28 | AL1: 12/29 | AM1: 12/30
A2: in Millions | B2: Q122 | C2: Q222 | D2: Q322 | E2: Q422 | F2: Q123 | G2: Q223 | H2: Q323 | I2: Q423 | J2: Q124 | K2: Q224 | L2: Q324 | M2: Q424 | N2: Q125 | O2: Q225 | P2: Q325 | Q2: Q425 | R2: Q126 | S2: Q226 | T2: Q326 | U2: Q426 | AC2: 2020 | AD2: =+AC2+1 -> 2021 | AE2: =+AD2+1 -> 2022 | AF2: =+AE2+1 -> 2023 | AG2: =+AF2+1 -> 2024 | AH2: =+AG2+1 -> 2025 | AI2: =+AH2+1 -> 2026 | AJ2: =+AI2+1 -> 2027 | AK2: =+AJ2+1 -> 2028 | ... AM2: =+AL2+1 -> 2030
A3: Google Search & Other | B3: 39618 | C3: 40689 | D3: 39539 | E3: 42604 | F3: 40359 | G3: 42628 | H3: 44026 | I3: 48020 | J3: 46156 | K3: 48509 | L3: 49385 | M3: 54034 | N3: 50702 | O3: 54190 | P3: 56567 | Q3: 63073 | R3: 60399 | S3: 63271 | T3: =+P3*1.13 -> 63920.71 | U3: =+Q3*1.13 -> 71272.49 | AC3: 104062 | AD3: 148951 | AE3: =SUM(B3:E3) -> 162450 | AF3: =SUM(F3:I3) -> 175033 | AG3: =SUM(J3:M3) -> 198084 | AH3: =SUM(N3:Q3) -> 224532
F4: =F3/B3-1 -> 0.01870362 | G4: =G3/C3-1 -> 0.047654157 | H4: =H3/D3-1 -> 0.11348289 | I4: =I3/E3-1 -> 0.12712421 | J4: =J3/F3-1 -> 0.14363587 | K4: =K3/G3-1 -> 0.13796096 | L4: =L3/H3-1 -> 0.12172353 | M4: =M3/I3-1 -> 0.12523948 | ... U4: =U3/Q3-1 -> 0.13 | AD4: =+AD3/AC3-1 -> 0.43136784 | AE4: =+AE3/AD3-1 -> 0.090627119 | AF4: =+AF3/AE3-1 -> 0.077457679 | AG4: =+AG3/AF3-1 -> 0.13169517 | AH4: =+AH3/AG3-1 -> 0.13351911
A5: YT Ads | B5: 6869 | C5: 7340 | D5: 7071 | E5: 7963 | F5: 6693 | G5: 7665 | H5: 7952 | I5: 9200 | J5: 8090 | K5: 8663 | L5: 8921 | M5: 10473 | N5: 8927 | O5: 9796 | P5: 10261 | Q5: 11383 | R5: 9883 | S5: 11055 | T5: =+P5*1.1 -> 11287.1 | U5: =+Q5*1.1 -> 12521.3 | AC5: 19772 | AD5: 28845 | AE5: =SUM(B5:E5) -> 29243 | AF5: =SUM(F5:I5) -> 31510 | AG5: =SUM(J5:M5) -> 36147 | AH5: =SUM(N5:Q5) -> 40367
F6: =F5/B5-1 -> -0.025622361 | G6: =G5/C5-1 -> 0.044277929 | H6: =H5/D5-1 -> 0.12459341 | I6: =I5/E5-1 -> 0.15534346 | J6: =J5/F5-1 -> 0.20872553 | K6: =K5/G5-1 -> 0.13020222 | L6: =L5/H5-1 -> 0.12185614 | M6: =M5/I5-1 -> 0.13836957 | ... U6: =U5/Q5-1 -> 0.1 | AD6: =+AD5/AC5-1 -> 0.45888125 | AE6: =+AE5/AD5-1 -> 0.013797885 | AF6: =+AF5/AE5-1 -> 0.077522826 | AG6: =+AG5/AF5-1 -> 0.14715963 | AH6: =+AH5/AG5-1 -> 0.11674551
A7: Google Network | B7: 8174 | C7: 8259 | D7: 7872 | E7: 8475 | F7: 7496 | G7: 7850 | H7: 7669 | I7: 8297 | J7: 7413 | K7: 7444 | L7: 7548 | M7: 7954 | N7: 7256 | O7: 7354 | P7: 7354 | Q7: 7828 | R7: 6971 | S7: 7303 | T7: =+S7*0.99 -> 7229.97 | U7: =+T7*0.99 -> 7157.6703 | AC7: 23090 | AD7: 31701 | AE7: =SUM(B7:E7) -> 32780 | AF7: =SUM(F7:I7) -> 31312 | AG7: =SUM(J7:M7) -> 30359 | AH7: =SUM(N7:Q7) -> 29792
F8: =F7/B7-1 -> -0.082945926 | G8: =G7/C7-1 -> -0.049521734 | H8: =H7/D7-1 -> -0.025787602 | I8: =I7/E7-1 -> -0.02100295 | J8: =J7/F7-1 -> -0.011072572 | K8: =K7/G7-1 -> -0.051719745 | L8: =L7/H7-1 -> -0.015777807 | M8: =M7/I7-1 -> -0.041340243 | ... U8: =U7/Q7-1 -> -0.085632307 | AD8: =+AD7/AC7-1 -> 0.37293201 | AE8: =+AE7/AD7-1 -> 0.034036781 | AF8: =+AF7/AE7-1 -> -0.044783405 | AG8: =+AG7/AF7-1 -> -0.030435616 | AH8: =+AH7/AG7-1 -> -0.018676504
A9: Google Subscriptions | B9: 6811 | C9: 6553 | D9: 6895 | E9: 8796 | F9: 7413 | G9: 8142 | H9: 8339 | I9: 10794 | J9: 8739 | K9: 9312 | L9: 10656 | M9: 11633 | N9: 10379 | O9: 11203 | P9: 12870 | Q9: 13578 | R9: 12384 | S9: 12911 | T9: =+P9*1.15 -> 14800.5 | U9: =+Q9*1.15 -> 15614.7 | AC9: 21711 | AD9: 28032 | AE9: =SUM(B9:E9) -> 29055 | AF9: =SUM(F9:I9) -> 34688 | AG9: =SUM(J9:M9) -> 40340 | AH9: =SUM(N9:Q9) -> 48030
F10: =F9/B9-1 -> 0.088386434 | G10: =G9/C9-1 -> 0.24248436 | H10: =H9/D9-1 -> 0.20942712 | I10: =I9/E9-1 -> 0.2271487 | J10: =J9/F9-1 -> 0.17887495 | K10: =K9/G9-1 -> 0.14369934 | L10: =L9/H9-1 -> 0.27785106 | M10: =M9/I9-1 -> 0.077728368 | ... U10: =U9/Q9-1 -> 0.15 | AD10: =+AD9/AC9-1 -> 0.29114274 | AE10: =+AE9/AD9-1 -> 0.036494007 | AF10: =+AF9/AE9-1 -> 0.19387369 | AG10: =+AG9/AF9-1 -> 0.16293819 | AH10: =+AH9/AG9-1 -> 0.19062965
A11: Total Google Services | B11: =+B9+B7+B5+B3 -> 61472 | C11: =+C9+C7+C5+C3 -> 62841 | D11: =+D9+D7+D5+D3 -> 61377 | E11: =+E9+E7+E5+E3 -> 67838 | F11: =+F9+F7+F5+F3 -> 61961 | G11: =+G9+G7+G5+G3 -> 66285 | H11: =+H9+H7+H5+H3 -> 67986 | I11: =+I9+I7+I5+I3 -> 76311 | ... U11: =+U9+U7+U5+U3 -> 106566.16 | AC11: =+AC9+AC7+AC5+AC3 -> 168635 | AD11: =+AD9+AD7+AD5+AD3 -> 237529 | AE11: =+AE9+AE7+AE5+AE3 -> 253528 | AF11: =+AF9+AF7+AF5+AF3 -> 272543 | AG11: =+AG9+AG7+AG5+AG3 -> 304930 | AH11: =+AH9+AH7+AH5+AH3 -> 342721
F12: =F11/B11-1 -> 0.0079548412 | G12: =G11/C11-1 -> 0.054804984 | H12: =H11/D11-1 -> 0.10767877 | I12: =I11/E11-1 -> 0.1249005 | J12: =J11/F11-1 -> 0.1361663 | K12: =K11/G11-1 -> 0.11530512 | L12: =L11/H11-1 -> 0.12537875 | M12: =M11/I11-1 -> 0.10199054 | ... U12: =U11/Q11-1 -> 0.11166218 | AD12: =+AD11/AC11-1 -> 0.40853915 | AE12: =+AE11/AD11-1 -> 0.067355986 | AF12: =+AF11/AE11-1 -> 0.075001578 | AG12: =+AG11/AF11-1 -> 0.11883262 | AH12: =+AH11/AG11-1 -> 0.12393336
A13: Google Cloud | B13: 5821 | C13: 6276 | D13: 6868 | E13: 7315 | F13: 7454 | G13: 8031 | H13: 8411 | I13: 9192 | J13: 9574 | K13: 10347 | L13: 11353 | M13: 11955 | N13: 12260 | O13: 13624 | P13: 15157 | Q13: 17664 | R13: 20028 | S13: 24768 | T13: =+P13*1.35 -> 20461.95 | U13: =+Q13*1.35 -> 23846.4 | AC13: 13059 | AD13: 19206 | AE13: =SUM(B13:E13) -> 26280 | AF13: =SUM(F13:I13) -> 33088 | AG13: =SUM(J13:M13) -> 43229 | AH13: =SUM(N13:Q13) -> 58705
F14: =F13/B13-1 -> 0.28053599 | G14: =G13/C13-1 -> 0.27963671 | H14: =H13/D13-1 -> 0.22466511 | I14: =I13/E13-1 -> 0.25659604 | J14: =J13/F13-1 -> 0.28441105 | K14: =K13/G13-1 -> 0.28838252 | L14: =L13/H13-1 -> 0.34978005 | M14: =M13/I13-1 -> 0.30058747 | ... U14: =U13/Q13-1 -> 0.35 | AD14: =+AD13/AC13-1 -> 0.47070986 | AE14: =+AE13/AD13-1 -> 0.3683224 | AF14: =+AF13/AE13-1 -> 0.25905632 | AG14: =+AG13/AF13-1 -> 0.30648574 | AH14: =+AH13/AG13-1 -> 0.35800042
A15: Other Bets | B15: 440 | C15: 193 | D15: 209 | E15: 226 | F15: 288 | G15: 285 | H15: 297 | I15: 657 | J15: 495 | K15: 365 | L15: 388 | M15: 400 | N15: 450 | O15: 373 | P15: 344 | Q15: 370 | R15: 411 | S15: 382 | T15: =+P15*0.93 -> 319.92 | U15: =+Q15*0.93 -> 344.1 | AC15: 657 | AD15: 753 | AE15: =SUM(B15:E15) -> 1068 | AF15: =SUM(F15:I15) -> 1527 | AG15: =SUM(J15:M15) -> 1648 | AH15: =SUM(N15:Q15) -> 1537
F16: =F15/B15-1 -> -0.34545455 | G16: =G15/C15-1 -> 0.47668394 | H16: =H15/D15-1 -> 0.42105263 | I16: =I15/E15-1 -> 1.9070796 | J16: =J15/F15-1 -> 0.71875 | K16: =K15/G15-1 -> 0.28070175 | L16: =L15/H15-1 -> 0.30639731 | M16: =M15/I15-1 -> -0.39117199 | ... U16: =U15/Q15-1 -> -0.07 | AD16: =+AD15/AC15-1 -> 0.14611872 | AE16: =+AE15/AD15-1 -> 0.41832669 | AF16: =+AF15/AE15-1 -> 0.42977528 | AG16: =+AG15/AF15-1 -> 0.079240341 | AH16: =+AH15/AG15-1 -> -0.067354369
A17: Hedging gains | B17: 278 | C17: 375 | D17: 638 | E17: 669 | F17: 84 | G17: 3 | H17: -1 | I17: 150 | J17: 72 | K17: 102 | L17: 17 | M17: 20 | N17: 260 | O17: -112 | P17: -207 | Q17: -68 | R17: -180 | S17: 106 | T17: -100 | U17: -100 | AC17: 176 | AD17: 149 | AE17: =SUM(B17:E17) -> 1960 | AF17: =SUM(F17:I17) -> 236 | AG17: =SUM(J17:M17) -> 211 | AH17: =SUM(N17:Q17) -> -127
F18: =F17/B17-1 -> -0.69784173 | G18: =G17/C17-1 -> -0.992 | H18: =H17/D17-1 -> -1.0015674 | I18: =I17/E17-1 -> -0.77578475 | J18: =J17/F17-1 -> -0.14285714 | K18: =K17/G17-1 -> 33 | L18: =L17/H17-1 -> -18 | M18: =M17/I17-1 -> -0.86666667 | ... U18: =U17/Q17-1 -> 0.47058824 | AD18: =+AD17/AC17-1 -> -0.15340909 | AE18: =+AE17/AD17-1 -> 12.154362 | AF18: =+AF17/AE17-1 -> -0.87959184 | AG18: =+AG17/AF17-1 -> -0.1059322 | AH18: =+AH17/AG17-1 -> -1.6018957
A19: Revenues | B19: =+B17+B15+B13+B11 -> 68011 | C19: =+C17+C15+C13+C11 -> 69685 | D19: =+D17+D15+D13+D11 -> 69092 | E19: =+E17+E15+E13+E11 -> 76048 | F19: =+F17+F15+F13+F11 -> 69787 | G19: =+G17+G15+G13+G11 -> 74604 | H19: =+H17+H15+H13+H11 -> 76693 | I19: =+I17+I15+I13+I11 -> 86310 | ... S19: =+S17+S15+S13+S11 -> 119796 | T19: =+P19*1.17 -> 119744.82 | U19: =+Q19*1.16 -> 132040.48 | AC19: =+AC17+AC15+AC13+AC11 -> 182527 | AD19: =+AD17+AD15+AD13+AD11 -> 257637 | AE19: =+AE17+AE15+AE13+AE11 -> 282836 | AF19: =+AF17+AF15+AF13+AF11 -> 307394 | AG19: =+AG17+AG15+AG13+AG11 -> 350018 | AH19: =+AH17+AH15+AH13+AH11 -> 402836 | AI19: =+AH19*1.2 -> 483403.2 | AJ19: =+AI19*1.18 -> 570415.78 | AK19: =+AJ19*1.16 -> 661682.3 | AL19: =+AK19*1.15 -> 760934.65 | AM19: =+AL19*1.14 -> 867465.5
AD20: =+AD19/AC19-1 -> 0.41150076 | AE20: =+AE19/AD19-1 -> 0.097808156 | AF20: =+AF19/AE19-1 -> 0.086827702 | AG20: =+AG19/AF19-1 -> 0.13866243 | AH20: =+AH19/AG19-1 -> 0.15090081 | AI20: =+AI19/AH19-1 -> 0.2 | AJ20: =+AJ19/AI19-1 -> 0.18 | AK20: =+AK19/AJ19-1 -> 0.16 | ... AM20: =+AM19/AL19-1 -> 0.14
A21: COGS | B21: 29599 | C21: 30104 | D21: 31158 | E21: 35342 | F21: 30612 | G21: 31916 | H21: 33229 | I21: 37575 | J21: 33712 | K21: 35507 | L21: 36474 | M21: 40613 | N21: 36361 | O21: 39039 | P21: 41369 | Q21: 45766 | R21: 41271 | S21: 45943 | T21: =+T19-T23 -> 46700.48 | U21: =+U19-U23 -> 51495.787 | AC21: 84732 | AD21: 110939 | AE21: =SUM(B21:E21) -> 126203 | AF21: =SUM(F21:I21) -> 133332 | AG21: =SUM(J21:M21) -> 146306 | AH21: =SUM(N21:Q21) -> 162535 | AI21: =+AI19-AI23 -> 188527.25 | AJ21: =+AJ19-AJ23 -> 219610.07 | AK21: =+AK19-AK23 -> 251439.27 | AL21: =+AL19-AL23 -> 285350.49 | AM21: =+AM19-AM23 -> 320962.23
B22: =+B21/B$19 -> 0.43520901 | C22: =+C21/C$19 -> 0.43200115 | D22: =+D21/D$19 -> 0.45096393 | E22: =+E21/E$19 -> 0.4647328 | F22: =+F21/F$19 -> 0.43864903 | G22: =+G21/G$19 -> 0.42780548 | H22: =+H21/H$19 -> 0.43327292 | I22: =+I21/I$19 -> 0.43534932 | ... U22: =+U21/U$19 -> 0.39 | AC22: =+AC21/AC$19 -> 0.46421625 | AD22: =+AD21/AD$19 -> 0.43060197 | AE22: =+AE21/AE$19 -> 0.44620557 | AF22: =+AF21/AF$19 -> 0.43374952 | AG22: =+AG21/AG$19 -> 0.41799565 | AH22: =+AH21/AH$19 -> 0.40347685 | AI22: =+AI21/AI$19 -> 0.39 | AJ22: =+AJ21/AJ$19 -> 0.385 | ... AM22: =+AM21/AM$19 -> 0.37
A23: Gross Margin | B23: =+B19-B21 -> 38412 | C23: =+C19-C21 -> 39581 | D23: =+D19-D21 -> 37934 | E23: =+E19-E21 -> 40706 | F23: =+F19-F21 -> 39175 | G23: =+G19-G21 -> 42688 | H23: =+H19-H21 -> 43464 | I23: =+I19-I21 -> 48735 | ... S23: =+S19-S21 -> 73853 | T23: =+T19*0.61 -> 73044.34 | U23: =+U19*0.61 -> 80544.693 | AC23: =+AC19-AC21 -> 97795 | AD23: =+AD19-AD21 -> 146698 | AE23: =+AE19-AE21 -> 156633 | AF23: =+AF19-AF21 -> 174062 | AG23: =+AG19-AG21 -> 203712 | AH23: =+AH19-AH21 -> 240301 | AI23: =+AI19*0.61 -> 294875.95 | AJ23: =+AJ19*0.615 -> 350805.7 | AK23: =+AK19*0.62 -> 410243.03 | AL23: =+AL19*0.625 -> 475584.15 | AM23: =+AM19*0.63 -> 546503.26
B24: =+B23/B$19 -> 0.56479099 | C24: =+C23/C$19 -> 0.56799885 | D24: =+D23/D$19 -> 0.54903607 | E24: =+E23/E$19 -> 0.5352672 | F24: =+F23/F$19 -> 0.56135097 | G24: =+G23/G$19 -> 0.57219452 | H24: =+H23/H$19 -> 0.56672708 | I24: =+I23/I$19 -> 0.56465068 | ... U24: =+U23/U$19 -> 0.61 | AC24: =+AC23/AC$19 -> 0.53578375 | AD24: =+AD23/AD$19 -> 0.56939803 | AE24: =+AE23/AE$19 -> 0.55379443 | AF24: =+AF23/AF$19 -> 0.56625048 | AG24: =+AG23/AG$19 -> 0.58200435 | AH24: =+AH23/AH$19 -> 0.59652315 | AI24: =+AI23/AI$19 -> 0.61 | AJ24: =+AJ23/AJ$19 -> 0.615 | ... AM24: =+AM23/AM$19 -> 0.63
A25: R&D | B25: 9119 | C25: 9841 | D25: 10273 | E25: 10267 | F25: 11468 | G25: 10588 | H25: 11258 | I25: 12113 | J25: 11903 | K25: 11860 | L25: 12447 | M25: 13116 | N25: 13556 | O25: 13808 | P25: 15151 | Q25: 18572 | R25: 17032 | S25: 18219 | T25: =+S25*1.1 -> 20040.9 | U25: =+T25*1.1 -> 22044.99 | AC25: 27573 | AD25: 31562 | AE25: =SUM(B25:E25) -> 39500 | AF25: =SUM(F25:I25) -> 45427 | AG25: =SUM(J25:M25) -> 49326 | AH25: =SUM(N25:Q25) -> 61087 | AI25: =+AH25*1.12 -> 68417.44 | AJ25: =+AI25*1.12 -> 76627.533 | AK25: =+AJ25*1.12 -> 85822.837 | AL25: =+AK25*1.12 -> 96121.577 | AM25: =+AL25*1.12 -> 107656.17
B26: =+B25/B$19 -> 0.13408125 | C26: =+C25/C$19 -> 0.14122121 | D26: =+D25/D$19 -> 0.14868581 | E26: =+E25/E$19 -> 0.13500684 | F26: =+F25/F$19 -> 0.1643286 | G26: =+G25/G$19 -> 0.14192269 | H26: =+H25/H$19 -> 0.14679306 | I26: =+I25/I$19 -> 0.14034295 | ... U26: =+U25/U$19 -> 0.1669563 | AC26: =+AC25/AC$19 -> 0.15106258 | AD26: =+AD25/AD$19 -> 0.1225057 | AE26: =+AE25/AE$19 -> 0.1396569 | AF26: =+AF25/AF$19 -> 0.14778102 | AG26: =+AG25/AG$19 -> 0.14092418 | AH26: =+AH25/AH$19 -> 0.15164236 | AI26: =+AI25/AI$19 -> 0.14153287 | AJ26: =+AJ25/AJ$19 -> 0.13433628 | ... AM26: =+AM25/AM$19 -> 0.12410426
A27: S&M | B27: 5825 | C27: 6630 | D27: 6929 | E27: 7183 | F27: 6533 | G27: 6781 | H27: 6884 | I27: 7719 | J27: 6426 | K27: 6792 | L27: 7227 | M27: 7363 | N27: 6172 | O27: 7101 | P27: 7205 | Q27: 8215 | R27: 7606 | S27: 8403 | T27: =+S27*1.1 -> 9243.3 | U27: =+T27*1.1 -> 10167.63 | AC27: 17946 | AD27: 22912 | AE27: =SUM(B27:E27) -> 26567 | AF27: =SUM(F27:I27) -> 27917 | AG27: =SUM(J27:M27) -> 27808 | AH27: =SUM(N27:Q27) -> 28693 | AI27: =+AH27*1.12 -> 32136.16 | AJ27: =+AI27*1.12 -> 35992.499 | AK27: =+AJ27*1.12 -> 40311.599 | AL27: =+AK27*1.12 -> 45148.991 | AM27: =+AL27*1.12 -> 50566.87
B28: =+B27/B$19 -> 0.08564791 | C28: =+C27/C$19 -> 0.095142427 | D28: =+D27/D$19 -> 0.10028657 | E28: =+E27/E$19 -> 0.094453503 | F28: =+F27/F$19 -> 0.093613424 | G28: =+G27/G$19 -> 0.09089325 | H28: =+H27/H$19 -> 0.089760474 | I28: =+I27/I$19 -> 0.089433438 | ... U28: =+U27/U$19 -> 0.077003885 | AC28: =+AC27/AC$19 -> 0.098319701 | AD28: =+AD27/AD$19 -> 0.088931326 | AE28: =+AE27/AE$19 -> 0.093930758 | AF28: =+AF27/AF$19 -> 0.090818298 | AG28: =+AG27/AG$19 -> 0.079447343 | AH28: =+AH27/AH$19 -> 0.071227497 | AI28: =+AI27/AI$19 -> 0.066478997 | AJ28: =+AJ27/AJ$19 -> 0.063098709 | ... AM28: =+AM27/AM$19 -> 0.058292659
A29: G&A | B29: 3374 | C29: 3657 | D29: 3597 | E29: 5096 | F29: 3759 | G29: 3481 | H29: 3979 | I29: 5206 | J29: 3026 | K29: 3158 | L29: 3599 | M29: 4405 | N29: 3539 | O29: 5209 | P29: 7393 | Q29: 5341 | R29: 4291 | S29: 6461 | T29: =+S29*1.1 -> 7107.1 | U29: =+T29*1.1 -> 7817.81 | AC29: 11052 | AD29: 13510 | AE29: =SUM(B29:E29) -> 15724 | AF29: =SUM(F29:I29) -> 16425 | AG29: =SUM(J29:M29) -> 14188 | AH29: =SUM(N29:Q29) -> 21482 | AI29: =+AH29*1.12 -> 24059.84 | AJ29: =+AI29*1.12 -> 26947.021 | AK29: =+AJ29*1.12 -> 30180.663 | AL29: =+AK29*1.12 -> 33802.343 | AM29: =+AL29*1.12 -> 37858.624
B30: =+B29/B$19 -> 0.049609622 | C30: =+C29/C$19 -> 0.052479013 | D30: =+D29/D$19 -> 0.05206102 | E30: =+E29/E$19 -> 0.067010309 | F30: =+F29/F$19 -> 0.0538639 | G30: =+G29/G$19 -> 0.046659697 | H30: =+H29/H$19 -> 0.05188218 | I30: =+I29/I$19 -> 0.06031746 | ... U30: =+U29/U$19 -> 0.059207676 | AC30: =+AC29/AC$19 -> 0.060549946 | AD30: =+AD29/AD$19 -> 0.05243812 | AE30: =+AE29/AE$19 -> 0.055594055 | AF30: =+AF29/AF$19 -> 0.053433053 | AG30: =+AG29/AG$19 -> 0.040535058 | AH30: =+AH29/AH$19 -> 0.053326912 | AI30: =+AI29/AI$19 -> 0.049771785 | AJ30: =+AJ29/AJ$19 -> 0.047241016 | ... AM30: =+AM29/AM$19 -> 0.043642801
A31: Op Exp | B31: =+B29+B27+B25 -> 18318 | C31: =+C29+C27+C25 -> 20128 | D31: =+D29+D27+D25 -> 20799 | E31: =+E29+E27+E25 -> 22546 | F31: =+F29+F27+F25 -> 21760 | G31: =+G29+G27+G25 -> 20850 | H31: =+H29+H27+H25 -> 22121 | I31: =+I29+I27+I25 -> 25038 | ... U31: =+U29+U27+U25 -> 40030.43 | AC31: =+AC29+AC27+AC25 -> 56571 | AD31: =+AD29+AD27+AD25 -> 67984 | AE31: =+AE29+AE27+AE25 -> 81791 | AF31: =+AF29+AF27+AF25 -> 89769 | AG31: =+AG29+AG27+AG25 -> 91322 | AH31: =+AH29+AH27+AH25 -> 111262 | AI31: =+AI29+AI27+AI25 -> 124613.44 | AJ31: =+AJ29+AJ27+AJ25 -> 139567.05 | ... AM31: =+AM29+AM27+AM25 -> 196081.66
B32: =+B31/B$19 -> 0.26933878 | C32: =+C31/C$19 -> 0.28884265 | D32: =+D31/D$19 -> 0.3010334 | E32: =+E31/E$19 -> 0.29647065 | F32: =+F31/F$19 -> 0.31180592 | G32: =+G31/G$19 -> 0.27947563 | H32: =+H31/H$19 -> 0.28843571 | I32: =+I31/I$19 -> 0.29009385 | ... U32: =+U31/U$19 -> 0.30316786 | AC32: =+AC31/AC$19 -> 0.30993223 | AD32: =+AD31/AD$19 -> 0.26387514 | AE32: =+AE31/AE$19 -> 0.28918172 | AF32: =+AF31/AF$19 -> 0.29203238 | AG32: =+AG31/AG$19 -> 0.26090658 | AH32: =+AH31/AH$19 -> 0.27619676 | AI32: =+AI31/AI$19 -> 0.25778365 | AJ32: =+AJ31/AJ$19 -> 0.244676 | ... AM32: =+AM31/AM$19 -> 0.22603972
A33: EBIT | B33: =+B23-B31 -> 20094 | C33: =+C23-C31 -> 19453 | D33: =+D23-D31 -> 17135 | E33: =+E23-E31 -> 18160 | F33: =+F23-F31 -> 17415 | G33: =+G23-G31 -> 21838 | H33: =+H23-H31 -> 21343 | I33: =+I23-I31 -> 23697 | ... U33: =+U23-U31 -> 40514.263 | AC33: =+AC23-AC31 -> 41224 | AD33: =+AD23-AD31 -> 78714 | AE33: =+AE23-AE31 -> 74842 | AF33: =+AF23-AF31 -> 84293 | AG33: =+AG23-AG31 -> 112390 | AH33: =+AH23-AH31 -> 129039 | AI33: =+AI23-AI31 -> 170262.51 | AJ33: =+AJ23-AJ31 -> 211238.65 | ... AM33: =+AM23-AM31 -> 350421.6
B34: =+B33/B$19 -> 0.29545221 | C34: =+C33/C$19 -> 0.2791562 | D34: =+D33/D$19 -> 0.24800266 | E34: =+E33/E$19 -> 0.23879655 | F34: =+F33/F$19 -> 0.24954504 | G34: =+G33/G$19 -> 0.29271889 | H34: =+H33/H$19 -> 0.27829137 | I34: =+I33/I$19 -> 0.27455683 | ... U34: =+U33/U$19 -> 0.30683214 | AC34: =+AC33/AC$19 -> 0.22585152 | AD34: =+AD33/AD$19 -> 0.30552289 | AE34: =+AE33/AE$19 -> 0.26461271 | AF34: =+AF33/AF$19 -> 0.2742181 | AG34: =+AG33/AG$19 -> 0.32109777 | AH34: =+AH33/AH$19 -> 0.32032639 | AI34: =+AI33/AI$19 -> 0.35221635 | AJ34: =+AJ33/AJ$19 -> 0.370324 | ... AM34: =+AM33/AM$19 -> 0.40396028
A35: Other Income | B35: -1160 | C35: -439 | D35: -902 | E35: -1013 | F35: 790 | G35: 65 | H35: -146 | I35: 715 | J35: 2843 | K35: 126 | L35: 3185 | M35: 1271 | N35: 11183 | O35: 2662 | P35: 12759 | Q35: 3183 | R35: 37716 | S35: 97983 | T35: 3000 | U35: 3000 | AC35: 6858 | AD35: 12020 | AE35: =SUM(B35:E35) -> -3514 | AF35: =SUM(F35:I35) -> 1424 | AG35: =SUM(J35:M35) -> 7425 | AH35: =SUM(N35:Q35) -> 29787 | AI35: =+AH86*$AQ$59 -> 1605.92 | AJ35: =+AI86*$AQ$59 -> 4527.6833 | AK35: =+AJ86*$AQ$59 -> 8195.711 | AL35: =+AK86*$AQ$59 -> 12651.813 | AM35: =+AL86*$AQ$59 -> 17975.585
B36: =+B35/B$19 -> -0.017056064 | C36: =+C35/C$19 -> -0.0062997776 | D36: =+D35/D$19 -> -0.013055057 | E36: =+E35/E$19 -> -0.013320534 | F36: =+F35/F$19 -> 0.01132016 | G36: =+G35/G$19 -> 0.00087126696 | H36: =+H35/H$19 -> -0.0019036939 | I36: =+I35/I$19 -> 0.0082840922 | ... U36: =+U35/U$19 -> 0.022720305 | AC36: =+AC35/AC$19 -> 0.037572524 | AD36: =+AD35/AD$19 -> 0.046654789 | AE36: =+AE35/AE$19 -> -0.012424161 | AF36: =+AF35/AF$19 -> 0.0046324912 | AG36: =+AG35/AG$19 -> 0.021213195 | AH36: =+AH35/AH$19 -> 0.073943242 | AI36: =+AI35/AI$19 -> 0.0033221129 | AJ36: =+AJ35/AJ$19 -> 0.0079375142 | ... AM36: =+AM35/AM$19 -> 0.020721959
A37: EBT | B37: =+B33+B35 -> 18934 | C37: =+C33+C35 -> 19014 | D37: =+D33+D35 -> 16233 | E37: =+E33+E35 -> 17147 | F37: =+F33+F35 -> 18205 | G37: =+G33+G35 -> 21903 | H37: =+H33+H35 -> 21197 | I37: =+I33+I35 -> 24412 | ... U37: =+U33+U35 -> 43514.263 | AC37: =+AC33+AC35 -> 48082 | AD37: =+AD33+AD35 -> 90734 | AE37: =+AE33+AE35 -> 71328 | AF37: =+AF33+AF35 -> 85717 | AG37: =+AG33+AG35 -> 119815 | AH37: =+AH33+AH35 -> 158826 | AI37: =+AI33+AI35 -> 171868.43 | AJ37: =+AJ33+AJ35 -> 215766.33 | ... AM37: =+AM33+AM35 -> 368397.19
B38: =+B37/B$19 -> 0.27839614 | C38: =+C37/C$19 -> 0.27285643 | D38: =+D37/D$19 -> 0.23494761 | E38: =+E37/E$19 -> 0.22547602 | F38: =+F37/F$19 -> 0.2608652 | G38: =+G37/G$19 -> 0.29359016 | H38: =+H37/H$19 -> 0.27638768 | I38: =+I37/I$19 -> 0.28284092 | ... U38: =+U37/U$19 -> 0.32955244 | AC38: =+AC37/AC$19 -> 0.26342404 | AD38: =+AD37/AD$19 -> 0.35217768 | AE38: =+AE37/AE$19 -> 0.25218855 | AF38: =+AF37/AF$19 -> 0.2788506 | AG38: =+AG37/AG$19 -> 0.34231097 | AH38: =+AH37/AH$19 -> 0.39426963 | AI38: =+AI37/AI$19 -> 0.35553847 | AJ38: =+AJ37/AJ$19 -> 0.37826151 | ... AM38: =+AM37/AM$19 -> 0.42468224
A39: Taxes | B39: 2498 | C39: 3012 | D39: 2323 | E39: 3523 | F39: 3154 | G39: 3535 | H39: 1508 | I39: 3725 | J39: 4653 | K39: 3932 | L39: 5405 | M39: 5707 | N39: 7249 | O39: 5737 | P39: 9008 | Q39: 4662 | R39: 14834 | S39: 26560 | T39: =+T37*P59 -> 8120.458 | U39: =+U37*Q59 -> 5186.0698 | AC39: 7813 | AD39: 14701 | AE39: =SUM(B39:E39) -> 11356 | AF39: =SUM(F39:I39) -> 11922 | AG39: =SUM(J39:M39) -> 19697 | AH39: =SUM(N39:Q39) -> 26656 | AI39: =+AI37*0.15 -> 25780.265 | AJ39: =+AJ37*0.15 -> 32364.95 | AK39: =+AK37*0.15 -> 39318.546 | AL39: =+AL37*0.15 -> 46974.458 | AM39: =+AM37*0.15 -> 55259.578
B40: =+B39/B$19 -> 0.036729353 | C40: =+C39/C$19 -> 0.043223075 | D40: =+D39/D$19 -> 0.033621838 | E40: =+E39/E$19 -> 0.046326005 | F40: =+F39/F$19 -> 0.045194664 | G40: =+G39/G$19 -> 0.047383518 | H40: =+H39/H$19 -> 0.019662811 | I40: =+I39/I$19 -> 0.043158383 | ... U40: =+U39/U$19 -> 0.039276363 | AC40: =+AC39/AC$19 -> 0.042804626 | AD40: =+AD39/AD$19 -> 0.057060904 | AE40: =+AE39/AE$19 -> 0.040150476 | AF40: =+AF39/AF$19 -> 0.038784101 | AG40: =+AG39/AG$19 -> 0.056274249 | AH40: =+AH39/AH$19 -> 0.066170849 | AI40: =+AI39/AI$19 -> 0.05333077 | AJ40: =+AJ39/AJ$19 -> 0.056739227 | ... AM40: =+AM39/AM$19 -> 0.063702335
...

Sheet Bond
A1: Main
B3: isin | C3: bondType | D3: coupon | E3: couponType | F3: maturityDate | G3: callable | H3: currency | I3: seniorityLevel
B4: US02079KAC18 | C4: — | D4: 1998 | E4: Fixed Listing | F4: 15/08/2026 | G4: Y | H4: USD | I4: Senior
B5: US02079KAJ60 | C5: — | D5: 800 | E5: Fixed Listing | F5: 15/08/2027 | G5: Y | H5: USD | I5: Senior
B6: XS3226478918 | C6: — | D6: 2375 | E6: Fixed Listing | F6: 06/11/2028 | G6: Y | H6: EUR | I6: Senior
B7: US02079KAU16 | C7: — | D7: 4181 | E7: Floating Rate | F7: 15/11/2028 | G7: Y | H7: USD | I7: Senior
B8: US02079KAV98 | C8: — | D8: 3875 | E8: Fixed Listing | F8: 15/11/2028 | G8: Y | H8: USD | I8: Senior
B9: XS3285554096 | C9: — | D9: 4125 | E9: Fixed Listing | F9: 13/02/2029 | G9: Y | H9: GBP | I9: Senior
B10: US02079KBJ51 | C10: — | D10: 3700 | E10: Fixed Listing | F10: 15/02/2029 | G10: Y | H10: USD | I10: Senior
B11: CH1504033700 | C11: — | D11: 427 | E11: Fixed Listing | F11: 01/03/2029 | G11: Y | H11: CHF | I11: Senior
B12: XS3064418687 | C12: — | D12: 2500 | E12: Fixed Listing | F12: 06/05/2029 | G12: Y | H12: EUR | I12: Senior
B13: US02079KAK34 | C13: — | D13: 4000 | E13: Fixed Listing | F13: 15/05/2030 | G13: Y | H13: USD | I13: Senior
B14: US02079KAD90 | C14: Sustainable | D14: 1100 | E14: Fixed Listing | F14: 15/08/2030 | G14: Y | H14: USD | I14: Senior
B15: US02079KAW71 | C15: — | D15: 4100 | E15: Fixed Listing | F15: 15/11/2030 | G15: Y | H15: USD | I15: Senior
... B49: XS3285675040 | C49: — | D49: 6125 | E49: Fixed Listing | F49: 13/02/2126 | G49: Y | H49: GBP | I49: Senior
D50: =+AVERAGE(D4:D49) -> 3696.7174

Sheet Board
A1: Main
