Workbook

Sheet Main
A1: META | E1: Share A | F1: 2205.1285 | G1: Q226 | L1: -> | M1: 2026 Focus on AI, Reels, Youth Platform (?), Platform Support, Infrastucture Capacity (AI)
E2: Share B | F2: 342.37772 | G2: Q226
E3: Price | F3: 644 | L3: -> | M3: Dependant on the ADV market, a decrease in spending whould mean a decrease in the core business of META
E4: MC | F4: =+F3*(F2+F1) -> 1640594 | L4: -> | M4: Testing a shopping feature with their chatbot Llama. Increase In monetization
E5: Cash | F5: 90260 | G5: Q226 | M5: possible monetization of where to buy the product?
E6: Debt | F6: 83664 | G6: Q226 | L6: -> | M6: Server and Network depreciation from 3 to 5 years minimum
E7: EV | F7: =F4-F5+F6 -> 1633998 | L7: -> | M7: Dismissed the METAverse project
M8: -> | N8: Mark Zuckerberg (and the board) is willing to transform the whole business to pursue a risky project that may pay off
L9: -> | M9: California alligations agains META and GOOGL that the companies have to pay for the mental problems of those that use their platforms
M10: I wouldn’t consider this a real therat since it is not illegal to maximise the engagement of the platform’s users
M11: META and GOOGL will appeal to the sentence
A12: P/FCF | B12: =+F4/SUM(Model!P148:S148) -> 43.318989 | D12: WACC | E12: =+(F4/(F4+F6))*B17+(F6/(F4+F6))*B18*(1-0.11) -> 0.10915439 | H12: mu | I12: 0.0008 | L12: -> | M12: Mark Zuckerberg is locked in
A13: P/E | B13: =+F3/SUM(Model!P54:S54) -> 19.640087 | H13: sigma | I13: 0.0248 | M13: -> | N13: Mark has the majority of the voting power
A14: EV/EBITDA | B14: =+F7/SUM(Model!P90:S90) -> 12.403109 | D14: PEG | E14: =+B13/11.37 -> 1.7273603 | L14: -> | M14: META experimenting a subscription model on Instagram in order to have certain “premium” feature
A15: EV/FCF | B15: =+F7/SUM(Model!P148:S148) -> 43.144825 | L15: -> | M15: META to expand their partnership with broadcom from the production of meta’s MTIA
A16: Inc. Margin | B16: =+((Model!S44+Model!R44+Model!Q44+Model!P44)-(Model!O44+Model!N44+Model!M44+Model!L44))/((Model!S30+Model!R30+Model!Q30+Model!P30)-(Model!O30+Model!N30+Model!M30+Model!L30)) -> 0.16617115 | D16: FPE | E16: =+F3/Model!AO54 -> 19.150959 | M16: MTIA (Meta Training and Inference Accellerator) is e purpose-built silicon-chip in order to make training and inference (usage of ML models) of ML cheaper, faster and energy efficient.
A17: CAPM | B17: =+0.0495+1.24*(0.1-0.0495) -> 0.11212 | M17: commitment that exceeds 1GW (30B$ ca. Per GW) → Hock Tan (Broadcom CEO) to become META’s advisor in META’s BoD
A18: Cost of Debt | B18: =+0.0495 + (B19/100) -> 0.057304348 | L18: -> | M18: META to monetise MetaAI by introducing a subscription model in order to access enhanced capabilities of the AI
A19: Cr. Spread | B19: =+'[1]Credit Spread US'!J6 -> 0.78043478 | L19: -> | M19: META shifting from AI buyer to AI provider with news disclosing their intentions to become a neocloud
A20: Rating | B20: AA- | C20: Aa3 | M20: BofA disclosed memo shows that META’s CapEx spends 22B$ per GW instead of the 40B$ consensus and 30B$ my guess
B21: S&P | C21: Moody’s | L21: -> | M21: Committing from 9-25 years to purchase clean and renewable energy
A22: EV/Sales | B22: =+F7/SUM(Model!P30:S30) -> 7.1589025 | L22: -> | M22: META agreed to settle the 1.4T (200B) fine with up to 17B fine paying it in 9 years
A23: EV/DAU | B23: =+F7/Model!S16 -> 453.88834 | M23: This is an outstanding win because accounting for an 8% cost of capital it is closer to a 9B fine
M24: Secondly they passed the ball to TikTok and YouTube saying that if they do not agree META will pay only up to 70% of the fine
M25: META positions itself as proactive to child care (also given everything that they are doing for children) and now TikTok and YT will fight against this ruling
A26: Seasonality | B26: Demand historically strong during fourth quarter due to holidays demand | M26: On top of that META bought for 9B$ the legislative safety for at least 9 years for their algoroithm
A28: Family of Apps (FoA)
B29: Facebook | E29: IPO | F29: 41030
B30: Facebook Dating (?)
B31: Facebook Marketplace
B32: Instagram
B33: Messanger
B34: Whatsapp
B35: Meta AI
B36: Threads | C36: -> | D36: Fastest organic growth among all kind of ages
B37: Aveola (?) | C37: -> | D37: “Live video chat”
B38: Meta Pay
B39: -> | C39: Advertisement
B40: -> | C40: paid messaging from Whatsapp, Verified on Instagram (and further Instagram paid feature), fees from developers, …
A43: Reality Labs Products
...

Sheet Model
A1: Main | B1: 03/22 | C1: 06/22 | D1: 09/22 | E1: 12/22 | F1: 03/23 | G1: 06/23 | H1: 09/23 | I1: 12/23 | J1: 03/24 | K1: 06/24 | L1: 09/24 | M1: 12/24 | N1: 03/25 | O1: 06/25 | P1: 09/25 | Q1: 12/25 | R1: 03/26 | S1: 06/26 | T1: 09/26 | U1: 12/26 | Z1: 12/10 | AA1: 12/11 | AB1: 12/12 | AC1: 12/13 | AD1: 12/14 | AE1: 12/15 | AF1: 12/16 | AG1: 12/17 | AH1: 12/18 | AI1: 12/20 | AJ1: 12/21 | AK1: 12/22 | AL1: 12/23 | AM1: 12/24 | AN1: 12/25 | AO1: 12/26 | AP1: 12/27 | AQ1: 12/28 | AR1: 12/29 | AS1: 12/30 | AT1: 12/31
A2: in Millions | B2: Q122 | C2: Q222 | D2: Q322 | E2: Q422 | F2: Q123 | G2: Q223 | H2: Q323 | I2: Q423 | J2: Q124 | K2: Q224 | L2: Q324 | M2: Q424 | N2: Q125 | O2: Q225 | P2: Q325 | Q2: Q425 | R2: Q126 | S2: Q226 | T2: Q326 | U2: Q426 | Z2: =+AA2-1 -> 2011 | AA2: =+AB2-1 -> 2012 | AB2: =+AC2-1 -> 2013 | AC2: =+AD2-1 -> 2014 | AD2: =+AE2-1 -> 2015 | AE2: =+AF2-1 -> 2016 | AF2: =+AG2-1 -> 2017 | AG2: =+AH2-1 -> 2018 | AH2: =+AI2-1 -> 2019 | AI2: 2020 | AJ2: =+AI2+1 -> 2021 | AK2: =+AJ2+1 -> 2022 | AL2: =+AK2+1 -> 2023 | AM2: =+AL2+1 -> 2024 | AN2: =+AM2+1 -> 2025 | AO2: =+AN2+1 -> 2026 | AP2: =+AO2+1 -> 2027 | AQ2: =+AP2+1 -> 2028 | ... AT2: =+AS2+1 -> 2031 | AV2: CAGR ‘26 – ‘36
A3: SNAP DAU | B3: 332 | C3: 347 | D3: 363 | E3: 375 | F3: 383 | G3: 397 | H3: 406 | I3: 414 | J3: 422 | K3: 432 | L3: 443 | M3: 453 | N3: 460 | O3: 469 | P3: 477 | Q3: 474 | R3: 483 | S3: 493 | Z3: NA | AA3: NA | AB3: NA | AC3: 71 | AD3: 107 | AE3: 158 | AF3: 187 | AG3: 186 | AH3: 218 | AI3: 265 | AJ3: 319 | AK3: 374 | AL3: 414 | AM3: 453 | AN3: 474
A4: Y/Y % | F4: =+F3/B3-1 -> 0.15361446 | G4: =+G3/C3-1 -> 0.14409222 | H4: =+H3/D3-1 -> 0.1184573 | I4: =+I3/E3-1 -> 0.104 | J4: =+J3/F3-1 -> 0.10182768 | K4: =+K3/G3-1 -> 0.088161209 | L4: =+L3/H3-1 -> 0.091133005 | M4: =+M3/I3-1 -> 0.094202899 | ... S4: =+S3/O3-1 -> 0.051172708 | AD4: =+AD3/AC3-1 -> 0.50704225 | AE4: =+AE3/AD3-1 -> 0.47663551 | AF4: =+AF3/AE3-1 -> 0.1835443 | AG4: =+AG3/AF3-1 -> -0.0053475936 | AH4: =+AH3/AG3-1 -> 0.17204301 | AI4: =+AI3/AH3-1 -> 0.21559633 | AJ4: =+AJ3/AI3-1 -> 0.20377358 | AK4: =+AK3/AJ3-1 -> 0.17241379 | ... AN4: =+AN3/AM3-1 -> 0.046357616
A5: SNAP ARPU | B5: 3.2 | C5: 3.2 | D5: 3.11 | E5: 3.47 | F5: 2.58 | G5: 2.69 | H5: 2.93 | I5: 3.29 | J5: 2.83 | K5: 2.86 | L5: 3.1 | M5: 3.44 | N5: 2.96 | O5: 2.87 | P5: 3.16 | Q5: 3.62 | R5: 3.17 | S5: 3.25 | Z5: NA | AA5: NA | AB5: NA | AC5: NA | AD5: NA | AE5: =+0.32+0.5+0.84+1.05 -> 2.71 | AF5: =+0.9+1.05+1.17+1.53 -> 4.65 | AG5: =+1.21+1.4+1.6+2.09 -> 6.3 | AH5: =+1.68+1.91+2.12+2.58 -> 8.29 | AI5: =+2.02+1.91+2.73+3.44 -> 10.1 | AJ5: 13.65 | AK5: 12.98 | AL5: 11.49 | AM5: 12.23 | AN5: 12.61
A6: Y/Y % | F6: =+F5/B5-1 -> -0.19375 | G6: =+G5/C5-1 -> -0.159375 | H6: =+H5/D5-1 -> -0.057877814 | I6: =+I5/E5-1 -> -0.051873199 | J6: =+J5/F5-1 -> 0.096899225 | K6: =+K5/G5-1 -> 0.063197026 | L6: =+L5/H5-1 -> 0.058020478 | M6: =+M5/I5-1 -> 0.045592705 | ... S6: =+S5/O5-1 -> 0.13240418 | AF6: =+AF5/AE5-1 -> 0.71586716 | AG6: =+AG5/AF5-1 -> 0.35483871 | AH6: =+AH5/AG5-1 -> 0.31587302 | AI6: =+AI5/AH5-1 -> 0.21833534 | AJ6: =+AJ5/AI5-1 -> 0.35148515 | AK6: =+AK5/AJ5-1 -> -0.049084249 | AL6: =+AL5/AK5-1 -> -0.11479199 | AM6: =+AM5/AL5-1 -> 0.064403829 | AN6: =+AN5/AM5-1 -> 0.031071137
A7: RDDT DAU | B7: NA | C7: NA | D7: NA | E7: NA | F7: 60.3 | G7: 60.4 | H7: 66 | I7: 73.1 | J7: 82.7 | K7: 91.2 | L7: 97.2 | M7: 101.7 | N7: 108.1 | O7: 110.4 | P7: 116 | Q7: 121.4 | R7: 127 | S7: 130 | Z7: NA | AA7: NA | AB7: NA | AC7: NA | AD7: NA | AE7: NA | AF7: NA | AG7: NA | AH7: NA | AI7: NA | AJ7: NA | AK7: NA | AL7: 73.1 | AM7: 101.7 | AN7: 121
A8: Y/Y % | J8: =+J7/F7-1 -> 0.37147595 | K8: =+K7/G7-1 -> 0.50993377 | L8: =+L7/H7-1 -> 0.47272727 | M8: =+M7/I7-1 -> 0.39124487 | N8: =+N7/J7-1 -> 0.30713422 | O8: =+O7/K7-1 -> 0.21052632 | P8: =+P7/L7-1 -> 0.19341564 | Q8: =+Q7/M7-1 -> 0.19370698 | ... S8: =+S7/O7-1 -> 0.17753623 | AM8: =+AM7/AL7-1 -> 0.39124487 | AN8: =+AN7/AM7-1 -> 0.18977384
A9: RDDT ARPU | B9: NA | C9: NA | D9: NA | E9: NA | F9: 2.72 | G9: 3.03 | H9: 3.14 | I9: 3.42 | J9: 2.94 | K9: 3.08 | L9: 3.58 | M9: 4.21 | N9: 3.63 | O9: 4.53 | P9: 5.04 | Q9: 5.98 | R9: 5.23 | S9: 6.18 | Z9: NA | AA9: NA | AB9: NA | AC9: NA | AD9: NA | AE9: NA | AF9: NA | AG9: NA | AH9: NA | AI9: NA | AJ9: NA | AK9: NA | AL9: 3.42 | AM9: 4.21 | AN9: 5.98
A10: Y/Y % | J10: =+J9/F9-1 -> 0.080882353 | K10: =+K9/G9-1 -> 0.01650165 | L10: =+L9/H9-1 -> 0.14012739 | M10: =+M9/I9-1 -> 0.23099415 | N10: =+N9/J9-1 -> 0.23469388 | O10: =+O9/K9-1 -> 0.47077922 | P10: =+P9/L9-1 -> 0.40782123 | Q10: =+Q9/M9-1 -> 0.42042755 | ... S10: =+S9/O9-1 -> 0.36423841 | AM10: =+AM9/AL9-1 -> 0.23099415 | AN10: =+AN9/AM9-1 -> 0.42042755
A11: PINS MAU | B11: 433 | C11: 433 | D11: 445 | E11: 450 | F11: 463 | G11: 465 | H11: 482 | I11: 498 | J11: 518 | K11: 522 | L11: 537 | M11: 553 | N11: 570 | O11: 578 | P11: 600 | Q11: 619 | R11: 631 | S11: 640 | Z11: NA | AA11: NA | AB11: NA | AC11: NA | AD11: NA | AE11: NA | AF11: NA | AG11: 265 | AH11: 335 | AI11: 459 | AJ11: 431 | AK11: 450 | AL11: 498 | AM11: 553 | AN11: 619
A12: Y/Y % | F12: =+F11/B11-1 -> 0.069284065 | G12: =+G11/C11-1 -> 0.073903002 | H12: =+H11/D11-1 -> 0.083146067 | I12: =+I11/E11-1 -> 0.10666667 | J12: =+J11/F11-1 -> 0.1187905 | K12: =+K11/G11-1 -> 0.12258065 | L12: =+L11/H11-1 -> 0.11410788 | M12: =+M11/I11-1 -> 0.11044177 | ... S12: =+S11/O11-1 -> 0.10726644 | AH12: =+AH11/AG11-1 -> 0.26415094 | AI12: =+AI11/AH11-1 -> 0.37014925 | AJ12: =+AJ11/AI11-1 -> -0.061002179 | AK12: =+AK11/AJ11-1 -> 0.044083527 | AL12: =+AL11/AK11-1 -> 0.10666667 | AM12: =+AM11/AL11-1 -> 0.11044177 | AN12: =+AN11/AM11-1 -> 0.11934901
A13: PINS ARPU | B13: 1.33 | C13: 1.54 | D13: 1.56 | E13: 1.96 | F13: 1.32 | G13: 1.53 | H13: 1.61 | I13: 2 | J13: 1.46 | K13: 1.64 | L13: 1.7 | M13: 2.12 | N13: 1.52 | O13: 1.74 | P13: 1.78 | Q13: 2.16 | R13: 1.61 | S13: 1.86 | Z13: NA | AA13: NA | AB13: NA | AC13: NA | AD13: NA | AE13: NA | AF13: NA | AG13: 1.06 | AH13: 1.22 | AI13: 1.57 | AJ13: 1.93 | AK13: 1.96 | AL13: 2 | AM13: 2.12 | AN13: 2.16
A14: Y/Y % | F14: =+F13/B13-1 -> -0.007518797 | G14: =+G13/C13-1 -> -0.0064935065 | H14: =+H13/D13-1 -> 0.032051282 | I14: =+I13/E13-1 -> 0.020408163 | J14: =+J13/F13-1 -> 0.10606061 | K14: =+K13/G13-1 -> 0.071895425 | L14: =+L13/H13-1 -> 0.055900621 | M14: =+M13/I13-1 -> 0.06 | ... S14: =+S13/O13-1 -> 0.068965517 | AH14: =+AH13/AG13-1 -> 0.1509434 | AI14: =+AI13/AH13-1 -> 0.28688525 | AJ14: =+AJ13/AI13-1 -> 0.22929936 | AK14: =+AK13/AJ13-1 -> 0.015544041 | AL14: =+AL13/AK13-1 -> 0.020408163 | AM14: =+AM13/AL13-1 -> 0.06 | AN14: =+AN13/AM13-1 -> 0.018867925
A16: DAU | B16: 2870 | C16: 2880 | D16: 2930 | E16: 2963 | F16: 3020 | G16: 3070 | H16: 3140 | I16: 3190 | J16: 3240 | K16: 3270 | L16: 3290 | M16: 3350 | N16: 3430 | O16: 3480 | P16: 3540 | Q16: 3580 | R16: 3560 | S16: 3600 | T16: =+S16*1.01 -> 3636 | U16: =+T16*1.01 -> 3672.36 | Z16: 483 | AA16: 618 | AB16: 757 | AC16: 890 | AD16: 1018 | AE16: 1227 | AF16: 1401 | AG16: 1523 | AH16: 1657 | AI16: 2540 | AJ16: 2820 | AK16: 2963 | AL16: 3190 | AM16: 3350 | AN16: 3580 | AO16: =+AN16*1.03 -> 3687.4 | AP16: =+AO16*1.04 -> 3834.896 | AQ16: =+AP16*1.04 -> 3988.2918 | AR16: =+AQ16*1.04 -> 4147.8235
A17: Y/Y % | B17: 0 | C17: 0 | D17: 0 | E17: 0 | F17: =+F16/B16-1 -> 0.052264808 | G17: =+G16/C16-1 -> 0.065972222 | H17: =+H16/D16-1 -> 0.071672355 | I17: =+I16/E16-1 -> 0.076611542 | J17: =+J16/F16-1 -> 0.072847682 | K17: =+K16/G16-1 -> 0.06514658 | L17: =+L16/H16-1 -> 0.047770701 | M17: =+M16/I16-1 -> 0.05015674 | ... U17: =+U16/Q16-1 -> 0.025798883 | AA17: =AA16/Z16-1 -> 0.27950311 | AB17: =AB16/AA16-1 -> 0.22491909 | AC17: =AC16/AB16-1 -> 0.17569353 | AD17: =AD16/AC16-1 -> 0.14382022 | AE17: =AE16/AD16-1 -> 0.20530452 | AF17: =AF16/AE16-1 -> 0.14180929 | AG17: =AG16/AF16-1 -> 0.087080657 | AH17: =AH16/AG16-1 -> 0.087984242 | ... AR17: =AR16/AQ16-1 -> 0.04
A18: q/q % | C18: =+C16/B16-1 -> 0.0034843206 | D18: =+D16/C16-1 -> 0.017361111 | E18: =+E16/D16-1 -> 0.011262799 | F18: =+F16/E16-1 -> 0.01923726 | G18: =+G16/F16-1 -> 0.016556291 | H18: =+H16/G16-1 -> 0.022801303 | I18: =+I16/H16-1 -> 0.015923567 | J18: =+J16/I16-1 -> 0.015673981 | ... U18: =+U16/T16-1 -> 0.01
A19: ARPU | B19: 9.57 | C19: 9.87 | D19: 9.44 | E19: 10.68 | F19: 9.47 | G19: 10.42 | H19: 10.93 | I19: 12.33 | J19: 11.2 | K19: 11.89 | L19: 12.29 | M19: 14.25 | N19: 12.36 | O19: 13.65 | P19: 14.46 | Q19: 16.56 | R19: 15.66 | S19: 16.86 | T19: =+P19*1.2 -> 17.352 | U19: =+Q19*1.2 -> 19.872 | Z19: =+AA19*0.94 -> 5.0008 | AA19: 5.32 | AB19: 6.81 | AC19: 9.45 | AD19: 11.96 | AE19: 15.98 | AF19: 20.21 | AG19: 24.96 | AH19: 29.25 | AI19: 27.51 | AJ19: 33.68 | AK19: 31.79 | AL19: 34.72 | AM19: 49.63 | AN19: 57.03 | AO19: =+AN19*1.2 -> 68.436 | AP19: =+AO19*1.1 -> 75.2796 | AQ19: =+AP19*1.1 -> 82.80756 | AR19: =+AQ19*1.1 -> 91.088316
A20: Y/Y % | B20: 0 | C20: 0 | D20: 0 | E20: 0 | F20: =+F19/B19-1 -> -0.010449321 | G20: =+G19/C19-1 -> 0.055724417 | H20: =+H19/D19-1 -> 0.15783898 | I20: =+I19/E19-1 -> 0.15449438 | J20: =+J19/F19-1 -> 0.18268215 | K20: =+K19/G19-1 -> 0.14107486 | L20: =+L19/H19-1 -> 0.12442818 | M20: =+M19/I19-1 -> 0.15571776 | ... U20: =+U19/Q19-1 -> 0.2 | AA20: =+AA19/Z19 -> 1.0638298 | AB20: =+AB19/AA19-1 -> 0.28007519 | AC20: =+AC19/AB19-1 -> 0.3876652 | AD20: =+AD19/AC19-1 -> 0.26560847 | AE20: =+AE19/AD19-1 -> 0.3361204 | AF20: =+AF19/AE19-1 -> 0.26470588 | AG20: =+AG19/AF19-1 -> 0.23503216 | AH20: =+AH19/AG19-1 -> 0.171875 | AI20: =+AI19/AH19-1 -> -0.059487179 | ... AR20: =+AR19/AQ19-1 -> 0.1
A21: DAU * ARPU | B21: =+B19*B16 -> 27465.9 | C21: =+C19*C16 -> 28425.6 | D21: =+D19*D16 -> 27659.2 | E21: =+E19*E16 -> 31644.84 | F21: =+F19*F16 -> 28599.4 | G21: =+G19*G16 -> 31989.4 | H21: =+H19*H16 -> 34320.2 | I21: =+I19*I16 -> 39332.7 | ... U21: =+U19*U16 -> 72977.138 | Z21: =+Z19*Z16 -> 2415.3864 | AA21: =+AA19*AA16 -> 3287.76 | AB21: =+AB19*AB16 -> 5155.17 | AC21: =+AC19*AC16 -> 8410.5 | AD21: =+AD19*AD16 -> 12175.28 | AE21: =+AE19*AE16 -> 19607.46 | AF21: =+AF19*AF16 -> 28314.21 | AG21: =+AG19*AG16 -> 38014.08 | ... AR21: =+AR19*AR16 -> 377818.26
B22: =+B21/B30 -> 0.98415866 | C22: =+C21/C30 -> 0.98624662 | D22: =+D21/D30 -> 0.99802266 | E22: =+E21/E30 -> 0.98382838 | F22: =+F21/F30 -> 0.9984081 | G22: =+G21/G30 -> 0.99969999 | H22: =+H21/H30 -> 1.0051016 | I22: =+I21/I30 -> 0.98059635 | ... U22: =+U21/U30 -> 0.95941618 | Z22: =+Z21/Z30 -> 0.65087211 | AA22: =+AA21/AA30 -> 0.64605227 | AB22: =+AB21/AB30 -> 0.65487424 | AC22: =+AC21/AC30 -> 0.67467512 | AD22: =+AD21/AD30 -> 0.67912093 | AE22: =+AE21/AE30 -> 0.70943845 | AF22: =+AF21/AF30 -> 0.69648513 | AG22: =+AG21/AG30 -> 0.68079229 | ... AR22: =+AR21/AR30 -> 0.93361205
A24: Advertising | B24: 26998 | C24: 28152 | D24: 27237 | E24: 31254 | F24: 28101 | G24: 31498 | H24: 33643 | I24: 38706 | J24: 35635 | K24: 38329 | L24: 39885 | M24: 46783 | N24: 41392 | O24: 46563 | P24: 50082 | Q24: 58137 | R24: 55024 | S24: 59363 | Z24: 3711 | AA24: 5089 | AB24: 6986 | AC24: 11492 | AD24: 17079 | AE24: 26885 | AF24: 39942 | AG24: 55013 | AH24: 69655 | AI24: 84169 | AJ24: 114934 | AK24: 113642 | AL24: 131948 | AM24: 160633 | AN24: 196175 | AO24: =+AO30-AO26 -> 253360.48 | AP24: =+AP30-AP26 -> 303838.78 | AQ24: =+AQ30-AQ26 -> 349414.59 | AR24: =+AR30-AR26 -> 398332.64 | AS24: =+AS30-AS26 -> 450115.88 | AT24: =+AT30-AT26 -> 504058.01
F25: =+F24/B24-1 -> 0.040854878 | G25: =+G24/C24-1 -> 0.11885479 | H25: =+H24/D24-1 -> 0.23519477 | I25: =+I24/E24-1 -> 0.23843348 | J25: =+J24/F24-1 -> 0.26810434 | K25: =+K24/G24-1 -> 0.21687091 | L25: =+L24/H24-1 -> 0.18553637 | M25: =+M24/I24-1 -> 0.20867566 | ... S25: =+S24/O24-1 -> 0.27489638 | AA25: =+AA24/Z24-1 -> 0.37132848 | AB25: =+AB24/AA24-1 -> 0.37276479 | AC25: =+AC24/AB24-1 -> 0.64500429 | AD25: =+AD24/AC24-1 -> 0.48616429 | AE25: =+AE24/AD24-1 -> 0.5741554 | AF25: =+AF24/AE24-1 -> 0.48566115 | AG25: =+AG24/AF24-1 -> 0.37732212 | AH25: =+AH24/AG24-1 -> 0.26615527 | ... AN25: =+AN24/AM24-1 -> 0.22126213 | AO25: =+AO24/AO$30 -> 0.98493215 | AP25: =+AP24/AP$30 -> 0.98430433 | AQ25: =+AQ24/AQ$30 -> 0.98430433 | AR25: =+AR24/AR$30 -> 0.98430433 | AS25: =+AS24/AS$30 -> 0.98430433 | AT25: =+AT24/AT$30 -> 0.98416419
A26: Other | B26: 215 | C26: 218 | D26: 192 | E26: 184 | F26: 205 | G26: 225 | H26: 293 | I26: 334 | J26: 380 | K26: 389 | L26: 434 | M26: 519 | N26: 510 | O26: 583 | P26: 690 | Q26: 801 | R26: 885 | S26: 1007 | Z26: 0 | AA26: 0 | AB26: 886 | AC26: 974 | AD26: 849 | AE26: 753 | AF26: 711 | AG26: 825 | AH26: 1042 | AI26: 657 | AJ26: 721 | AK26: 808 | AL26: 1058 | AM26: 1722 | AN26: 2584 | AO26: =+AN26*1.5 -> 3876 | AP26: =+AO26*1.25 -> 4845 | AQ26: =+AP26*1.15 -> 5571.75 | AR26: =+AQ26*1.14 -> 6351.795 | AS26: =+AR26*1.13 -> 7177.5283 | AT26: =+AS26*1.13 -> 8110.607
F27: =+F26/B26-1 -> -0.046511628 | G27: =+G26/C26-1 -> 0.032110092 | H27: =+H26/D26-1 -> 0.52604167 | I27: =+I26/E26-1 -> 0.81521739 | J27: =+J26/F26-1 -> 0.85365854 | K27: =+K26/G26-1 -> 0.72888889 | L27: =+L26/H26-1 -> 0.48122867 | M27: =+M26/I26-1 -> 0.55389222 | ... S27: =+S26/O26-1 -> 0.72727273 | AC27: =+AC26/AB26-1 -> 0.099322799 | AD27: =+AD26/AC26-1 -> -0.12833676 | AE27: =+AE26/AD26-1 -> -0.1130742 | AF27: =+AF26/AE26-1 -> -0.055776892 | AG27: =+AG26/AF26-1 -> 0.16033755 | AH27: =+AH26/AG26-1 -> 0.2630303 | AI27: =+AI26/AH26-1 -> -0.36948177 | AJ27: =+AJ26/AI26-1 -> 0.097412481 | ... AN27: =+AN26/AM26-1 -> 0.50058072 | AO27: =+AO26/AO$30 -> 0.015067847 | AP27: =+AP26/AP$30 -> 0.015695674 | AQ27: =+AQ26/AQ$30 -> 0.015695674 | AR27: =+AR26/AR$30 -> 0.015695674 | AS27: =+AS26/AS$30 -> 0.015695674 | AT27: =+AT26/AT$30 -> 0.015835814
A28: Reality Labs | B28: 695 | C28: 452 | D28: 285 | E28: 727 | F28: 339 | G28: 276 | H28: 210 | I28: 1071 | J28: 440 | K28: 353 | L28: 270 | M28: 1083 | N28: 412 | O28: 370 | P28: 470 | Q28: 955 | R28: 402 | S28: 431 | AI28: 1139 | AJ28: 2274 | AK28: 2159 | AL28: 1896 | AM28: 2146 | AN28: 2207
F29: =+F28/B28-1 -> -0.51223022 | G29: =+G28/C28-1 -> -0.38938053 | H29: =+H28/D28-1 -> -0.26315789 | I29: =+I28/E28-1 -> 0.47317744 | J29: =+J28/F28-1 -> 0.2979351 | K29: =+K28/G28-1 -> 0.27898551 | L29: =+L28/H28-1 -> 0.28571429 | M29: =+M28/I28-1 -> 0.011204482 | ... S29: =+S28/O28-1 -> 0.16486486 | AJ29: =+AJ28/AI28-1 -> 0.99648815 | AK29: =+AK28/AJ28-1 -> -0.05057168 | AL29: =+AL28/AK28-1 -> -0.12181566 | AM29: =+AM28/AL28-1 -> 0.13185654 | AN29: =+AN28/AM28-1 -> 0.028424977
A30: Revenues | B30: =+B24+B26+B28 -> 27908 | C30: =+C24+C26+C28 -> 28822 | D30: =+D24+D26+D28 -> 27714 | E30: =+E24+E26+E28 -> 32165 | F30: =+F24+F26+F28 -> 28645 | G30: =+G24+G26+G28 -> 31999 | H30: =+H24+H26+H28 -> 34146 | I30: =+I24+I26+I28 -> 40111 | ... Q30: =+Q24+Q26+Q28 -> 59893 | R30: 56311 | S30: 60801 | T30: =+P30*1.24 -> 63540.08 | U30: =+Q30*1.27 -> 76064.11 | Z30: =+Z24+Z26+Z28 -> 3711 | AA30: =+AA24+AA26+AA28 -> 5089 | AB30: =+AB24+AB26+AB28 -> 7872 | AC30: =+AC24+AC26+AC28 -> 12466 | AD30: =+AD24+AD26+AD28 -> 17928 | AE30: =+AE24+AE26+AE28 -> 27638 | AF30: =+AF24+AF26+AF28 -> 40653 | AG30: =+AG24+AG26+AG28 -> 55838 | ... AN30: =+AN24+AN26+AN28 -> 200966 | AO30: =+AN30*1.28 -> 257236.48 | AP30: =+AO30*1.2 -> 308683.78 | AQ30: =+AP30*1.15 -> 354986.34 | AR30: =+AQ30*1.14 -> 404684.43 | AS30: =+AR30*1.13 -> 457293.41 | AT30: =+AS30*1.12 -> 512168.62
F31: =+F30/B30-1 -> 0.026408198 | G31: =+G30/C30-1 -> 0.1102283 | H31: =+H30/D30-1 -> 0.23208487 | I31: =+I30/E30-1 -> 0.24703871 | J31: =+J30/F30-1 -> 0.27264793 | K31: =+K30/G30-1 -> 0.22100691 | L31: =+L30/H30-1 -> 0.18868974 | M31: =+M30/I30-1 -> 0.20627758 | ... U31: =+U30/Q30-1 -> 0.27 | AA31: =+AA30/Z30-1 -> 0.37132848 | AB31: =+AB30/AA30-1 -> 0.54686579 | AC31: =+AC30/AB30-1 -> 0.5835874 | AD31: =+AD30/AC30-1 -> 0.43815177 | AE31: =+AE30/AD30-1 -> 0.54161089 | AF31: =+AF30/AE30-1 -> 0.47090962 | AG31: =+AG30/AF30-1 -> 0.37352717 | AH31: =+AH30/AG30-1 -> 0.2661091 | ... AT31: =+AT30/AS30-1 -> 0.12 | AV31: =+(AT30/AO30)^(1/(AT2-AO2))-1 -> 0.14766749
A32: COGS | B32: 6005 | C32: 5192 | D32: 5716 | E32: 8336 | F32: 6108 | G32: 5945 | H32: 6210 | I32: 7695 | J32: 6640 | K32: 7308 | L32: 7375 | M32: 8839 | N32: 7572 | O32: 8491 | P32: 9206 | Q32: 10905 | R32: 10218 | S32: 11330 | T32: =+T30-T34 -> 11500.754 | U32: =+U30-U34 -> 13767.604 | Z32: 860 | AA32: 1364 | AB32: 1875 | AC32: 2153 | AD32: 2867 | AE32: 3789 | AF32: 5454 | AG32: 9355 | AH32: 12770 | AI32: 16692 | AJ32: 22649 | AK32: 25249 | AL32: 25959 | AM32: 30161 | AN32: 36175 | AO32: =+AO30-AO34 -> 46302.566 | AP32: =+AP30-AP34 -> 55563.08 | AQ32: =+AQ30-AQ34 -> 60347.678 | AR32: =+AR30-AR34 -> 68796.353 | AS32: =+AS30-AS34 -> 73166.945 | AT32: =+AT30-AT34 -> 81946.978
B33: =+B32/B$30 -> 0.21517128 | C33: =+C32/C$30 -> 0.18014017 | D33: =+D32/D$30 -> 0.20624955 | E33: =+E32/E$30 -> 0.25916369 | F33: =+F32/F$30 -> 0.21323093 | G33: =+G32/G$30 -> 0.18578706 | H33: =+H32/H$30 -> 0.1818661 | I33: =+I32/I$30 -> 0.19184264 | ... U33: =+U32/U$30 -> 0.181 | Z33: =+Z32/Z$30 -> 0.23174347 | AA33: =+AA32/AA$30 -> 0.26802908 | AB33: =+AB32/AB$30 -> 0.23818598 | AC33: =+AC32/AC$30 -> 0.17270977 | AD33: =+AD32/AD$30 -> 0.15991745 | AE33: =+AE32/AE$30 -> 0.13709386 | AF33: =+AF32/AF$30 -> 0.13415984 | AG33: =+AG32/AG$30 -> 0.16753824 | ... AT33: =+AT32/AT$30 -> 0.16
A34: Gross Profit | B34: =B30-B32 -> 21903 | C34: =C30-C32 -> 23630 | D34: =D30-D32 -> 21998 | E34: =E30-E32 -> 23829 | F34: =F30-F32 -> 22537 | G34: =G30-G32 -> 26054 | H34: =H30-H32 -> 27936 | I34: =I30-I32 -> 32416 | ... S34: =S30-S32 -> 49471 | T34: =+T30*0.819 -> 52039.326 | U34: =+U30*0.819 -> 62296.506 | Z34: =Z30-Z32 -> 2851 | AA34: =AA30-AA32 -> 3725 | AB34: =AB30-AB32 -> 5997 | AC34: =AC30-AC32 -> 10313 | AD34: =AD30-AD32 -> 15061 | AE34: =AE30-AE32 -> 23849 | AF34: =AF30-AF32 -> 35199 | AG34: =AG30-AG32 -> 46483 | ... AN34: =AN30-AN32 -> 164791 | AO34: =+AO30*0.82 -> 210933.91 | AP34: =+AP30*0.82 -> 253120.7 | AQ34: =+AQ30*0.83 -> 294638.66 | AR34: =+AR30*0.83 -> 335888.08 | AS34: =+AS30*0.84 -> 384126.46 | AT34: =+AT30*0.84 -> 430221.64
B35: =+B34/B$30 -> 0.78482872 | C35: =+C34/C$30 -> 0.81985983 | D35: =+D34/D$30 -> 0.79375045 | E35: =+E34/E$30 -> 0.74083631 | F35: =+F34/F$30 -> 0.78676907 | G35: =+G34/G$30 -> 0.81421294 | H35: =+H34/H$30 -> 0.8181339 | I35: =+I34/I$30 -> 0.80815736 | ... U35: =+U34/U$30 -> 0.819 | Z35: =+Z34/Z$30 -> 0.76825653 | AA35: =+AA34/AA$30 -> 0.73197092 | AB35: =+AB34/AB$30 -> 0.76181402 | AC35: =+AC34/AC$30 -> 0.82729023 | AD35: =+AD34/AD$30 -> 0.84008255 | AE35: =+AE34/AE$30 -> 0.86290614 | AF35: =+AF34/AF$30 -> 0.86584016 | AG35: =+AG34/AG$30 -> 0.83246176 | ... AT35: =+AT34/AT$30 -> 0.84
A36: R&D | B36: 7707 | C36: 8690 | D36: 9170 | E36: 9771 | F36: 9381 | G36: 9344 | H36: 9241 | I36: 10517 | J36: 9978 | K36: 10537 | L36: 11177 | M36: 12180 | N36: 12150 | O36: 12942 | P36: 15144 | Q36: 17136 | R36: 17699 | S36: 21656 | T36: =+P36*1.35 -> 20444.4 | U36: =+Q36*1.35 -> 23133.6 | Z36: 388 | AA36: 1399 | AB36: 1415 | AC36: 2666 | AD36: 4816 | AE36: 5919 | AF36: 7754 | AG36: 10273 | AH36: 13600 | AI36: 18447 | AJ36: 24655 | AK36: 35338 | AL36: 38483 | AM36: 43873 | AN36: 57372 | AO36: =+AO30*0.27 -> 69453.85 | AP36: =+AP30*0.27 -> 83344.62 | AQ36: =+AQ30*0.27 -> 95846.312 | AR36: =+AR30*0.27 -> 109264.8 | AS36: =+AS30*0.27 -> 123469.22 | AT36: =+AT30*0.25 -> 128042.15
B37: =+B36/B$30 -> 0.27615737 | C37: =+C36/C$30 -> 0.30150579 | D37: =+D36/D$30 -> 0.3308797 | E37: =+E36/E$30 -> 0.3037774 | F37: =+F36/F$30 -> 0.32749171 | G37: =+G36/G$30 -> 0.29200913 | H37: =+H36/H$30 -> 0.27063199 | I37: =+I36/I$30 -> 0.2621974 | ... U37: =+U36/U$30 -> 0.30413292 | Z37: =+Z36/Z$30 -> 0.10455403 | AA37: =+AA36/AA$30 -> 0.27490666 | AB37: =+AB36/AB$30 -> 0.17975102 | AC37: =+AC36/AC$30 -> 0.2138617 | AD37: =+AD36/AD$30 -> 0.26863008 | AE37: =+AE36/AE$30 -> 0.21416166 | AF37: =+AF36/AF$30 -> 0.19073623 | AG37: =+AG36/AG$30 -> 0.18397865 | ... AT37: =+AT36/AT$30 -> 0.25
A38: S&M | B38: 3312 | C38: 3595 | D38: 3780 | E38: 4574 | F38: 3044 | G38: 3154 | H38: 2877 | I38: 3226 | J38: 2564 | K38: 2721 | L38: 2822 | M38: 3240 | N38: 2757 | O38: 2979 | P38: 2845 | Q38: 3410 | R38: 2908 | S38: 3431 | T38: =+T30*0.055 -> 3494.7044 | U38: =+U30*0.055 -> 4183.5261 | Z38: 393 | AA38: 896 | AB38: 997 | AC38: 1680 | AD38: 2725 | AE38: 3772 | AF38: 4725 | AG38: 7846 | AH38: 9876 | AI38: 11591 | AJ38: 14043 | AK38: 15262 | AL38: 12301 | AM38: 11347 | AN38: 11991 | AO38: =+AO30*0.07 -> 18006.554 | AP38: =+AP30*0.07 -> 21607.864 | AQ38: =+AQ30*0.07 -> 24849.044 | AR38: =+AR30*0.07 -> 28327.91 | AS38: =+AS30*0.07 -> 32010.538 | AT38: =+AT30*0.05 -> 25608.431
B39: =+B38/B$30 -> 0.11867565 | C39: =+C38/C$30 -> 0.12473111 | D39: =+D38/D$30 -> 0.13639316 | E39: =+E38/E$30 -> 0.14220426 | F39: =+F38/F$30 -> 0.10626636 | G39: =+G38/G$30 -> 0.09856558 | H39: =+H38/H$30 -> 0.084255843 | I39: =+I38/I$30 -> 0.080426816 | ... U39: =+U38/U$30 -> 0.055 | Z39: =+Z38/Z$30 -> 0.10590137 | AA39: =+AA38/AA$30 -> 0.17606602 | AB39: =+AB38/AB$30 -> 0.12665142 | AC39: =+AC38/AC$30 -> 0.13476657 | AD39: =+AD38/AD$30 -> 0.15199688 | AE39: =+AE38/AE$30 -> 0.13647876 | AF39: =+AF38/AF$30 -> 0.11622758 | AG39: =+AG38/AG$30 -> 0.14051363 | ... AT39: =+AT38/AT$30 -> 0.05
A40: G&A | B40: 2360 | C40: 2987 | D40: 3384 | E40: 3085 | F40: 2885 | G40: 4164 | H40: 2070 | I40: 2289 | J40: 3455 | K40: 3658 | L40: 1865 | M40: 761 | N40: 2280 | O40: 2663 | P40: 3512 | Q40: 3697 | R40: 2614 | S40: 5609 | T40: =+T30*0.06 -> 3812.4048 | U40: =+U30*0.06 -> 4563.8466 | Z40: 314 | AA40: 892 | AB40: 781 | AC40: 973 | AD40: 1295 | AE40: 1731 | AF40: 2517 | AG40: 3451 | AH40: 10465 | AI40: 6564 | AJ40: 9829 | AK40: 11816 | AL40: 11408 | AM40: 9740 | AN40: 12152 | AO40: =+AO30*0.06 -> 15434.189 | AP40: =+AP30*0.06 -> 18521.027 | AQ40: =+AQ30*0.06 -> 21299.181 | AR40: =+AR30*0.06 -> 24281.066 | AS40: =+AS30*0.06 -> 27437.604 | AT40: =+AT30*0.06 -> 30730.117
B41: =+B40/B$30 -> 0.084563566 | C41: =+C40/C$30 -> 0.10363611 | D41: =+D40/D$30 -> 0.12210435 | E41: =+E40/E$30 -> 0.095911705 | F41: =+F40/F$30 -> 0.10071566 | G41: =+G40/G$30 -> 0.13012907 | H41: =+H40/H$30 -> 0.060622035 | I41: =+I40/I$30 -> 0.05706664 | ... U41: =+U40/U$30 -> 0.06 | Z41: =+Z40/Z$30 -> 0.084613312 | AA41: =+AA40/AA$30 -> 0.17528002 | AB41: =+AB40/AB$30 -> 0.099212398 | AC41: =+AC40/AC$30 -> 0.078052302 | AD41: =+AD40/AD$30 -> 0.072233378 | AE41: =+AE40/AE$30 -> 0.06263116 | AF41: =+AF40/AF$30 -> 0.06191425 | AG41: =+AG40/AG$30 -> 0.06180379 | ... AT41: =+AT40/AT$30 -> 0.06
A42: Op Ex | B42: =+B40+B38+B36 -> 13379 | C42: =+C40+C38+C36 -> 15272 | D42: =+D40+D38+D36 -> 16334 | E42: =+E40+E38+E36 -> 17430 | F42: =+F40+F38+F36 -> 15310 | G42: =+G40+G38+G36 -> 16662 | H42: =+H40+H38+H36 -> 14188 | I42: =+I40+I38+I36 -> 16032 | ... U42: =+U40+U38+U36 -> 31880.973 | Z42: =+Z40+Z38+Z36 -> 1095 | AA42: =+AA40+AA38+AA36 -> 3187 | AB42: =+AB40+AB38+AB36 -> 3193 | AC42: =+AC40+AC38+AC36 -> 5319 | AD42: =+AD40+AD38+AD36 -> 8836 | AE42: =+AE40+AE38+AE36 -> 11422 | AF42: =+AF40+AF38+AF36 -> 14996 | AG42: =+AG40+AG38+AG36 -> 21570 | ... AT42: =+AT40+AT38+AT36 -> 184380.7
...

Sheet Bond
A1: Main
B3: isin | C3: coupon | D3: couponType | E3: maturityDate | F3: callable | G3: currency | H3: Next Call Date
B4: US30303M8B15 | C4: 3.5 | D4: Fixed Listing | E4: 15/08/2027 | F4: Y | G4: USD
B5: US30303M8G02 | C5: 3.5 | D5: Fixed Listing | E5: 15/08/2027 | F5: Y | G5: USD
B6: USU59197AB66 | C6: 3.5 | D6: Fixed Listing | E6: 15/08/2027 | F6: Y | G6: USD
B7: US30303M8L96 | C7: 4.6 | D7: Fixed Listing | E7: 15/05/2028 | F7: Y | G7: USD
B8: US30303M8S40 | C8: 4.3 | D8: Fixed Listing | E8: 15/08/2029 | F8: Y | G8: USD
B9: US30303M8M79 | C9: 4.8 | D9: Fixed Listing | E9: 15/05/2030 | F9: Y | G9: USD
B10: US30303MAB81 | C10: 4.2 | D10: Fixed Listing | E10: 15/11/2030 | F10: Y | G10: USD
B11: US30303M8T23 | C11: 4.55 | D11: Fixed Listing | E11: 15/08/2031 | F11: Y | G11: USD
B12: US30303M8D70 | C12: 3.85 | D12: Fixed Listing | E12: 15/08/2032 | F12: Y | G12: USD
B13: US30303M8H84 | C13: 3.85 | D13: Fixed Listing | E13: 15/08/2032 | F13: Y | G13: USD
B14: USU59197AD23 | C14: 3.85 | D14: Fixed Listing | E14: 15/08/2032 | F14: Y | G14: USD
B15: US30303MAC64 | C15: 4.6 | D15: Fixed Listing | E15: 15/11/2032 | F15: Y | G15: USD
... B30: US30303M8W51 | C30: 5.55 | D30: Fixed Listing | E30: 15/08/2064 | F30: Y | G30: USD
B31: US30303M8Y18 | C31: 5.75 | D31: Fixed Listing | E31: 15/11/2065 | F31: Y | G31: USD | H31: 60402
C32: =+AVERAGE(C4:C31) -> 4.6482143

Sheet Board
A1: Main
A2: Mark Zuckerberg | B2: META CEO | G2: auditors | H2: EY
A5: Robert M. Kimmitt | B5: MD Lehman Brothers, General Counsel and Deputy Secretary of Department of Treasury, Law Background
B6: -> | C6: Privacy and Product compliance
A8: Peggy Alford | B8: eBay Director of Accounting Policy, Cfo rent.com (eBay), Executive roles Paypal
A11: Marc L. Andreesen
A14: John Arnold | B14: Enron VP, Centaurus Enercy and Centaurus Capital CEO
B15: -> | C15: Risk Oversight
A17: Patrick Collison | B17: CEO Stripe
A20: John Elkann | B20: Exor CEO, Chairman Ferrari and Stellantins | E20: -> | F20: Powerful italian family
A23: Andrew W. Houston | B23: Dropbox CEO
A26: Nancy Killefer | B26: McKinsey and Department of Treasury
A29: Dina Powell McCormick | B29: US Department of State, Excecutive Office of the President, Goldman Sachs
A32: Charles Songhurst | B32: Microsoft General Manager
A35: Hock E. Tan | B35: Broadcom CEO, Commodore VP of Finance
A38: Tracey T. Travis | B38: ?
A41: Dana White | B41: UFC CEO
A44: Tony Xu | B44: DoorDash CEO
