Workbook

Sheet Main
A1: Microsoft Corporation | D1: Price | E1: 484
D2: Share | E2: 7425.5455 | F2: Q426
D3: MC | E3: =+E2*E1 -> 3593964
D4: Cash | E4: 113191 | F4: Q426
D5: Debt | E5: =+31067+9227 -> 40294 | F5: Q426
D6: EV | E6: =+E3-E4+E5 -> 3521067
D8: Foundation | E8: 1975
A11: CAPM | B11: =+0.04+1.11*(0.1-0.04) -> 0.1066 | D11: WACC | E11: =+(E3/(E3+E5))*B11+(E5/(E5+E3))*B12*(1-0.17) -> 0.10594584
A12: Cost of Debt | B12: =+0.0495 + (B18/100) -> 0.057347826
A13: P/FCF | B13: =+E3/SUM(Model!R122:U122) -> 53.651664
A14: P/E | B14: =+E1/SUM(Model!R41:U41) -> 22.894938
A15: EV/EBITDA | B15: =+E6/SUM(Model!R65:U65) -> 16.816474
A16: EV/FCF | B16: =+E6/SUM(Model!R122:U122) -> 52.563438
A17: Inc. Margin | B17: =+((Model!U31+Model!T31+Model!S31+Model!R31)-(Model!Q31+Model!P31+Model!O31+Model!N31))/((Model!U13+Model!T13+Model!S13+Model!R13)-(Model!Q13+Model!P13+Model!O13+Model!N13)) -> 0.53295421
A18: Cr. Spread | B18: =+'[1]Credit Spread US'!J6 -> 0.78478261
A19: Rating | B19: AAA | C19: Aaa
B20: S&P | C20: Moody’s
A23: Productivity and Business Process
B24: -> | C24: Microsoft 365 Commercial Products
C25: AI-powered business and productivity solutions
B26: -> | C26: Microsoft 365 Consumer Products
B27: -> | C27: Linkedin
C28: Premium subscriptions and monetized solutions
B29: -> | C29: Dynamics Products (Dynamics 365)
C30: Enterprise resource planning, customer relationship management and supply chain management
A32: Intelligent Cloud
B33: -> | C33: public and private server products, cloud and AI based services. GitHub cloud services, Windows Server, Visual Studio
C34: Azure
B35: -> | C35: Enterprice and partner services (Enterprise support services, Industry solutions, Microsoft Partner Network)
A37: More Personal Computing
B38: product and services
B39: -> | C39: Windows devices (including licences)
C40: Windows Licences, Surface (PC), PC accessories
B41: -> | C41: Gaming (Xbox hardware and software)
B42: -> | C42: Search and news advertising (Bing, Copilot, Microsoft News)

Sheet Model
A1: Main | F1: 09/22 | J1: 09/23 | K1: 12/23 | L1: 03/24 | M1: 06/24 | N1: 09/24 | O1: 12/24 | P1: 03/25 | Q1: 06/25 | R1: 09/25 | S1: 12/25 | T1: 03/26 | U1: 06/26
A2: in Millions | B2: Q122 | C2: Q222 | D2: Q322 | E2: Q422 | F2: Q123 | G2: Q223 | H2: Q323 | I2: Q423 | J2: Q124 | K2: Q224 | L2: Q324 | M2: Q424 | N2: Q125 | O2: Q225 | P2: Q325 | Q2: Q425 | R2: Q126 | S2: Q226 | T2: Q326 | U2: Q426 | V2: Q127 | W2: Q227 | AB2: =+AC2-1 -> 2010 | AC2: =+AD2-1 -> 2011 | AD2: =+AE2-1 -> 2012 | AE2: =+AF2-1 -> 2013 | AF2: =+AG2-1 -> 2014 | AG2: =+AH2-1 -> 2015 | AH2: =+AI2-1 -> 2016 | AI2: =+AJ2-1 -> 2017 | ... AK2: =+AL2-1 -> 2019 | AL2: 2020 | AM2: =+AL2+1 -> 2021 | AN2: =+AM2+1 -> 2022 | AO2: =+AN2+1 -> 2023 | AP2: =+AO2+1 -> 2024 | AQ2: =+AP2+1 -> 2025 | AR2: =+AQ2+1 -> 2026 | AS2: =+AR2+1 -> 2027 | AT2: =+AS2+1 -> 2028 | ... BB2: =+BA2+1 -> 2036
A3: Productivity | K3: 25854 | L3: 27113 | N3: 28317 | O3: 29437 | P3: 29944 | Q3: =+AQ3-P3-O3-N3 -> 33112 | R3: 33020 | S3: 34116 | T3: 35013 | U3: =+AR3-T3-S3-R3 -> 37847 | AG3: 26430 | AH3: 26467 | AI3: 30444 | AJ3: 35865 | AK3: 41160 | AL3: 46398 | AM3: 53915 | AN3: 63364 | AO3: 69274 | AP3: 106820 | AQ3: 120810 | AR3: 139996
O4: =+O3/K3-1 -> 0.13858591 | P4: =+P3/L3-1 -> 0.10441486 | Q4: =+Q3/M3-1 -> #DIV/0! | R4: =+R3/N3-1 -> 0.16608398 | S4: =+S3/O3-1 -> 0.15894962 | T4: =+T3/P3-1 -> 0.16928266 | U4: =+U3/Q3-1 -> 0.14299952 | AH4: =+AH3/AG3-1 -> 0.0013999243 | AI4: =+AI3/AH3-1 -> 0.15026259 | AJ4: =+AJ3/AI3-1 -> 0.17806464 | AK4: =+AK3/AJ3-1 -> 0.14763697 | AL4: =+AL3/AK3-1 -> 0.12725948 | AM4: =+AM3/AL3-1 -> 0.16201129 | AN4: =+AN3/AM3-1 -> 0.17525735 | AO4: =+AO3/AN3-1 -> 0.093270627 | ... AR4: =+AR3/AQ3-1 -> 0.15881136
A5: Intelligent Cloud | K5: 21525 | L5: 22141 | N5: 24092 | O5: 25544 | P5: 26751 | Q5: =+AQ5-P5-O5-N5 -> 29878 | R5: 30897 | S5: 32907 | T5: 34681 | U5: =+AR5-T5-S5-R5 -> 39306 | AG5: 23715 | AH5: 25042 | AI5: 27440 | AJ5: 32219 | AK5: 38985 | AL5: 48366 | AM5: 60080 | AN5: 74965 | AO5: 87907 | AP5: 87464 | AQ5: 106265 | AR5: 137791
O6: =+O5/K5-1 -> 0.18671312 | P6: =+P5/L5-1 -> 0.20821101 | Q6: =+Q5/M5-1 -> #DIV/0! | R6: =+R5/N5-1 -> 0.28245891 | S6: =+S5/O5-1 -> 0.28824773 | T6: =+T5/P5-1 -> 0.29643752 | U6: =+U5/Q5-1 -> 0.3155499 | AH6: =+AH5/AG5-1 -> 0.055956146 | AI6: =+AI5/AH5-1 -> 0.095759125 | AJ6: =+AJ5/AI5-1 -> 0.17416181 | AK6: =+AK5/AJ5-1 -> 0.21000031 | AL6: =+AL5/AK5-1 -> 0.24063101 | AM6: =+AM5/AL5-1 -> 0.24219493 | AN6: =+AN5/AM5-1 -> 0.247753 | AO6: =+AO5/AN5-1 -> 0.17264057 | ... AR6: =+AR5/AQ5-1 -> 0.29667341
A7: More PC | K7: 14641 | L7: 12604 | N7: 13176 | O7: 14651 | P7: 13371 | Q7: =+AQ7-P7-O7-N7 -> 13451 | R7: 13756 | S7: 14250 | T7: 13192 | U7: =+AR7-T7-S7-R7 -> 12854 | AG7: 43435 | AH7: =+40434-6643 -> 33791 | AI7: =+38773-6707 -> 32066 | AJ7: 42276 | AK7: 45698 | AL7: 48251 | AM7: 54093 | AN7: 59941 | AO7: 54734 | AP7: 50838 | AQ7: 54649 | AR7: 54052
O8: =+O7/K7-1 -> 0.00068301346 | P8: =+P7/L7-1 -> 0.060853697 | Q8: =+Q7/M7-1 -> #DIV/0! | R8: =+R7/N7-1 -> 0.044019429 | S8: =+S7/O7-1 -> -0.027370145 | T8: =+T7/P7-1 -> -0.013387181 | U8: =+U7/Q7-1 -> -0.044383317 | AH8: =+AH7/AG7-1 -> -0.22203292 | AI8: =+AI7/AH7-1 -> -0.051049096 | AJ8: =+AJ7/AI7-1 -> 0.31840579 | AK8: =+AK7/AJ7-1 -> 0.080944271 | AL8: =+AL7/AK7-1 -> 0.055866778 | AM8: =+AM7/AL7-1 -> 0.12107521 | AN8: =+AN7/AM7-1 -> 0.10811011 | AO8: =+AO7/AN7-1 -> -0.086868754 | ... AR8: =+AR7/AQ7-1 -> -0.010924262
A9: Product | D9: 17366 | E9: 17956 | F9: 15741 | H9: 15588 | I9: 16853 | J9: 15535 | K9: 18941 | L9: 17080 | M9: 13217 | N9: 15272 | O9: 16219 | P9: 15319 | Q9: 17136 | R9: 15922 | S9: 16451 | T9: 15089 | U9: 17234 | AF9: 72948 | AG9: 75956 | AH9: 61502 | AI9: 57190 | AJ9: 64497 | AK9: 66069 | AL9: 68041 | AM9: 71074 | AN9: 72732 | AO9: 64699 | AP9: 64773 | AQ9: 63946 | AR9: 64696
F10: =+F9/B9-1 -> #DIV/0! | G10: =+G9/C9-1 -> #DIV/0! | H10: =+H9/D9-1 -> -0.10238397 | I10: =+I9/E9-1 -> -0.061427935 | J10: =+J9/F9-1 -> -0.013086843 | K10: =+K9/G9-1 -> #DIV/0! | L10: =+L9/H9-1 -> 0.095714652 | M10: =+M9/I9-1 -> -0.21574794 | ... U10: =+U9/Q9-1 -> 0.0057189542 | AG10: =+AG9/AF9-1 -> 0.041234852 | AH10: =+AH9/AG9-1 -> -0.19029438 | AI10: =+AI9/AH9-1 -> -0.070111541 | AJ10: =+AJ9/AI9-1 -> 0.12776709 | AK10: =+AK9/AJ9-1 -> 0.024373227 | AL10: =+AL9/AK9-1 -> 0.029847584 | AM10: =+AM9/AL9-1 -> 0.044576064 | AN10: =+AN9/AM9-1 -> 0.023327799 | ... AR10: =+AR9/AQ9-1 -> 0.011728646
A11: Service and other | D11: 31994 | E11: 33909 | F11: 34381 | H11: 37269 | I11: 39336 | J11: 40982 | K11: 43079 | L11: 44778 | M11: 51510 | N11: 50313 | O11: 53413 | P11: 54747 | Q11: 59305 | R11: 61751 | S11: 64822 | T11: 67797 | U11: 72773 | AF11: 13885 | AG11: 17624 | AH11: 23818 | AI11: 32760 | AJ11: 45863 | AK11: 59774 | AL11: 74974 | AM11: 97014 | AN11: 125538 | AO11: 147216 | AP11: 180349 | AQ11: 217778 | AR11: 267143
F12: =+F11/B11-1 -> #DIV/0! | G12: =+G11/C11-1 -> #DIV/0! | H12: =+H11/D11-1 -> 0.16487466 | I12: =+I11/E11-1 -> 0.16004601 | J12: =+J11/F11-1 -> 0.19199558 | K12: =+K11/G11-1 -> #DIV/0! | L12: =+L11/H11-1 -> 0.20148112 | M12: =+M11/I11-1 -> 0.30948749 | ... U12: =+U11/Q11-1 -> 0.22709721 | AG12: =+AG11/AF11-1 -> 0.2692834 | AH12: =+AH11/AG11-1 -> 0.35145256 | AI12: =+AI11/AH11-1 -> 0.37543035 | AJ12: =+AJ11/AI11-1 -> 0.39996947 | AK12: =+AK11/AJ11-1 -> 0.3033164 | AL12: =+AL11/AK11-1 -> 0.25429116 | AM12: =+AM11/AL11-1 -> 0.29396858 | AN12: =+AN11/AM11-1 -> 0.29401942 | ... AR12: =+AR11/AQ11-1 -> 0.22667579
A13: Revenue | B13: =+B11+B9 -> 0 | C13: =+C11+C9 -> 0 | D13: =+D11+D9 -> 49360 | E13: =+E11+E9 -> 51865 | F13: =+F11+F9 -> 50122 | G13: =+G11+G9 -> 0 | H13: =+H11+H9 -> 52857 | I13: =+I11+I9 -> 56189 | ... W13: =+W11+W9 -> 0 | AB13: 62484 | AC13: 69943 | AD13: 73723 | AE13: 77849 | AF13: =+AF11+AF9 -> 86833 | AG13: =+AG11+AG9 -> 93580 | AH13: =+AH11+AH9 -> 85320 | AI13: =+AI11+AI9 -> 89950 | AJ13: =+AJ11+AJ9 -> 110360 | AK13: =+AK11+AK9 -> 125843 | AL13: =+AL11+AL9 -> 143015 | AM13: =+AM11+AM9 -> 168088 | ... AR13: =+AR11+AR9 -> 331839 | AS13: =+AR13*1.17 -> 388251.63 | AT13: =+AS13*1.16 -> 450371.89 | AU13: =+AT13*1.15 -> 517927.67 | AV13: =+AU13*1.14 -> 590437.55 | AW13: =+AV13*1.13 -> 667194.43 | AX13: =+AW13*1.12 -> 747257.76 | AY13: =+AX13*1.11 -> 829456.12 | AZ13: =+AY13*1.11 -> 920696.29 | BA13: =+AZ13*1.11 -> 1021972.9 | BB13: =+BA13*1.11 -> 1134389.9
F14: =+F13/B13-1 -> #DIV/0! | G14: =+G13/C13-1 -> #DIV/0! | H14: =+H13/D13-1 -> 0.07084684 | I14: =+I13/E13-1 -> 0.083370288 | J14: =+J13/F13-1 -> 0.12758868 | K14: =+K13/G13-1 -> #DIV/0! | L14: =+L13/H13-1 -> 0.17028965 | M14: =+M13/I13-1 -> 0.15195145 | ... U14: =+U13/Q13-1 -> 0.17747021 | AC14: =+AC13/AB13-1 -> 0.11937456 | AD14: =+AD13/AC13-1 -> 0.054044007 | AE14: =+AE13/AD13-1 -> 0.055966252 | AF14: =+AF13/AE13-1 -> 0.1154029 | AG14: =+AG13/AF13-1 -> 0.077700874 | AH14: =+AH13/AG13-1 -> -0.088266724 | AI14: =+AI13/AH13-1 -> 0.054266292 | AJ14: =+AJ13/AI13-1 -> 0.22690384 | ... BB14: =+BB13/BA13-1 -> 0.11
A15: Product | D15: 4584 | E15: 4357 | F15: 4302 | H15: 3941 | I15: 3871 | J15: 3531 | K15: 5964 | L15: 4339 | M15: 1438 | N15: 3294 | O15: 3856 | P15: 3037 | Q15: 3314 | R15: 2922 | S15: 3505 | T15: 2733 | U15: 2938 | AF15: 16681 | AG15: 21410 | AH15: 17880 | AI15: 15175 | AJ15: 15420 | AK15: 16273 | AL15: 16017 | AM15: 18219 | AN15: 19064 | AO15: 17804 | AP15: 15272 | AQ15: 13501 | AR15: 12098
D16: =+D15/D$13 -> 0.09286872 | E16: =+E15/E$13 -> 0.084006555 | F16: =+F15/F$13 -> 0.085830573 | G16: =+G15/G$13 -> #DIV/0! | H16: =+H15/H$13 -> 0.074559661 | I16: =+I15/I$13 -> 0.068892488 | J16: =+J15/J$13 -> 0.062476777 | K16: =+K15/K$13 -> 0.096162528 | ... W16: =+W15/W$13 -> #DIV/0! | AG16: =+AG15/AF15-1 -> 0.28349619 | AH16: =+AH15/AG15-1 -> -0.16487623 | AI16: =+AI15/AH15-1 -> -0.15128635 | AJ16: =+AJ15/AI15-1 -> 0.016144975 | AK16: =+AK15/AJ15-1 -> 0.055317769 | AL16: =+AL15/AK15-1 -> -0.01573158 | AM16: =+AM15/AL15-1 -> 0.13747893 | AN16: =+AN15/AM15-1 -> 0.046380153 | ... AR16: =+AR15/AQ15-1 -> -0.10391823
A17: Service and Other | D17: 11031 | E17: 12072 | F17: 11150 | H17: 12187 | I17: 12924 | J17: 12771 | K17: 13659 | L17: 14166 | M17: 18246 | N17: 16805 | O17: 17943 | P17: 18882 | Q17: 20700 | R17: 21121 | S17: 22473 | T17: 24095 | U17: 26587 | AF17: 10397 | AG17: 11628 | AH17: 14900 | AI17: 19086 | AJ17: 22933 | AK17: 26637 | AL17: 30061 | AM17: 34013 | AN17: 43586 | AO17: 48059 | AP17: 58842 | AQ17: 74330 | AR17: 94276
D18: =+D17/D$13 -> 0.22348055 | E18: =+E17/E$13 -> 0.23275812 | F18: =+F17/F$13 -> 0.2224572 | G18: =+G17/G$13 -> #DIV/0! | H18: =+H17/H$13 -> 0.23056549 | I18: =+I17/I$13 -> 0.23000943 | J18: =+J17/J$13 -> 0.22596741 | K18: =+K17/K$13 -> 0.22023541 | ... W18: =+W17/W$13 -> #DIV/0! | AG18: =+AG17/AF17-1 -> 0.11839954 | AH18: =+AH17/AG17-1 -> 0.28138975 | AI18: =+AI17/AH17-1 -> 0.2809396 | AJ18: =+AJ17/AI17-1 -> 0.20156135 | AK18: =+AK17/AJ17-1 -> 0.16151398 | AL18: =+AL17/AK17-1 -> 0.128543 | AM18: =+AM17/AL17-1 -> 0.13146602 | AN18: =+AN17/AM17-1 -> 0.28145121 | ... AR18: =+AR17/AQ17-1 -> 0.26834387
A19: COGS | B19: =+B17+B15 -> 0 | C19: =+C17+C15 -> 0 | D19: =+D17+D15 -> 15615 | E19: =+E17+E15 -> 16429 | F19: =+F17+F15 -> 15452 | G19: =+G17+G15 -> 0 | H19: =+H17+H15 -> 16128 | I19: =+I17+I15 -> 16795 | ... W19: =+W17+W15 -> 0 | AB19: 12395 | AC19: 15577 | AD19: 17530 | AE19: 20249 | AF19: =+AF17+AF15 -> 27078 | AG19: =+AG17+AG15 -> 33038 | AH19: =+AH17+AH15 -> 32780 | AI19: =+AI17+AI15 -> 34261 | AJ19: =+AJ17+AJ15 -> 38353 | AK19: =+AK17+AK15 -> 42910 | AL19: =+AL17+AL15 -> 46078 | AM19: =+AM17+AM15 -> 52232 | ... AR19: =+AR17+AR15 -> 106374 | AS19: =+AS13-AS21 -> 122299.26 | AT19: =+AT13-AT21 -> 137363.43 | AU19: =+AU13-AU21 -> 152788.66 | AV19: =+AV13-AV21 -> 171226.89 | AW19: =+AW13-AW21 -> 190150.41 | AX19: =+AX13-AX21 -> 209232.17 | AY19: =+AY13-AY21 -> 228100.43 | AZ19: =+AZ13-AZ21 -> 248588 | ... BB19: =+BB13-BB21 -> 294941.37
D20: =+D19/D$13 -> 0.31634927 | E20: =+E19/E$13 -> 0.31676468 | F20: =+F19/F$13 -> 0.30828778 | G20: =+G19/G$13 -> #DIV/0! | H20: =+H19/H$13 -> 0.30512515 | I20: =+I19/I$13 -> 0.29890192 | J20: =+J19/J$13 -> 0.28844418 | K20: =+K19/K$13 -> 0.31639794 | ... W20: =+W19/W$13 -> #DIV/0! | AB20: =+AB19/AB$13 -> 0.19837078 | AC20: =+AC19/AC$13 -> 0.22270992 | AD20: =+AD19/AD$13 -> 0.23778197 | AE20: =+AE19/AE$13 -> 0.2601061 | AF20: =+AF19/AF$13 -> 0.31183997 | AG20: =+AG19/AG$13 -> 0.35304552 | AH20: =+AH19/AH$13 -> 0.38420066 | AI20: =+AI19/AI$13 -> 0.38088938 | ... BB20: =+BB19/BB$13 -> 0.26
A21: Gross Margin | B21: =+B13-B19 -> 0 | C21: =+C13-C19 -> 0 | D21: =+D13-D19 -> 33745 | E21: =+E13-E19 -> 35436 | F21: =+F13-F19 -> 34670 | G21: =+G13-G19 -> 0 | H21: =+H13-H19 -> 36729 | I21: =+I13-I19 -> 39394 | ... W21: =+W13-W19 -> 0 | AB21: =+AB13-AB19 -> 50089 | AC21: =+AC13-AC19 -> 54366 | AD21: =+AD13-AD19 -> 56193 | AE21: =+AE13-AE19 -> 57600 | AF21: =+AF13-AF19 -> 59755 | AG21: =+AG13-AG19 -> 60542 | AH21: =+AH13-AH19 -> 52540 | AI21: =+AI13-AI19 -> 55689 | ... AR21: =+AR13-AR19 -> 225465 | AS21: =+AS13*0.685 -> 265952.37 | AT21: =+AT13*0.695 -> 313008.46 | AU21: =+AU13*0.705 -> 365139.01 | AV21: =+AV13*0.71 -> 419210.66 | AW21: =+AW13*0.715 -> 477044.02 | AX21: =+AX13*0.72 -> 538025.59 | AY21: =+AY13*0.725 -> 601355.68 | AZ21: =+AZ13*0.73 -> 672108.29 | BA21: =+BA13*0.735 -> 751150.07 | BB21: =+BB13*0.74 -> 839448.52
D22: =+D21/D$13 -> 0.68365073 | E22: =+E21/E$13 -> 0.68323532 | F22: =+F21/F$13 -> 0.69171222 | G22: =+G21/G$13 -> #DIV/0! | H22: =+H21/H$13 -> 0.69487485 | I22: =+I21/I$13 -> 0.70109808 | J22: =+J21/J$13 -> 0.71155582 | K22: =+K21/K$13 -> 0.68360206 | ... W22: =+W21/W$13 -> #DIV/0! | AB22: =+AB21/AB$13 -> 0.80162922 | AC22: =+AC21/AC$13 -> 0.77729008 | AD22: =+AD21/AD$13 -> 0.76221803 | AE22: =+AE21/AE$13 -> 0.7398939 | AF22: =+AF21/AF$13 -> 0.68816003 | AG22: =+AG21/AG$13 -> 0.64695448 | AH22: =+AH21/AH$13 -> 0.61579934 | AI22: =+AI21/AI$13 -> 0.61911062 | ... BB22: =+BB21/BB$13 -> 0.74
A23: R&D | D23: 6306 | E23: 6849 | F23: 6628 | H23: 6984 | I23: 6739 | J23: 6659 | K23: 7142 | L23: 7653 | M23: 8056 | N23: 7544 | O23: 7917 | P23: 8198 | Q23: 8829 | R23: 8146 | S23: 8504 | T23: 8915 | U23: 9997 | AB23: 8714 | AC23: 9043 | AD23: 9811 | AE23: 10411 | AF23: 11381 | AG23: 12046 | AH23: 11988 | AI23: 13037 | AJ23: 14726 | AK23: 16876 | AL23: 19269 | AM23: 20716 | AN23: 24512 | AO23: 27195 | AP23: 29510 | AQ23: 32488 | AR23: 35562 | AS23: =+AS13*0.105 -> 40766.421 | AT23: =+AT13*0.105 -> 47289.049 | AU23: =+AU13*0.105 -> 54382.406 | AV23: =+AV13*0.1 -> 59043.755 | AW23: =+AW13*0.1 -> 66719.443 | AX23: =+AX13*0.1 -> 74725.776 | AY23: =+AY13*0.095 -> 78798.331 | AZ23: =+AZ13*0.095 -> 87466.147 | BA23: =+BA13*0.095 -> 97087.424 | BB23: =+BB13*0.095 -> 107767.04
D24: =+D23/D$13 -> 0.12775527 | E24: =+E23/E$13 -> 0.13205437 | F24: =+F23/F$13 -> 0.13223734 | G24: =+G23/G$13 -> #DIV/0! | H24: =+H23/H$13 -> 0.13213009 | I24: =+I23/I$13 -> 0.11993451 | J24: =+J23/J$13 -> 0.11782296 | K24: =+K23/K$13 -> 0.1151564 | ... W24: =+W23/W$13 -> #DIV/0! | AB24: =+AB23/AB$13 -> 0.1394597 | AC24: =+AC23/AC$13 -> 0.12929099 | AD24: =+AD23/AD$13 -> 0.13307923 | AE24: =+AE23/AE$13 -> 0.13373325 | AF24: =+AF23/AF$13 -> 0.13106768 | AG24: =+AG23/AG$13 -> 0.12872409 | AH24: =+AH23/AH$13 -> 0.14050633 | AI24: =+AI23/AI$13 -> 0.14493608 | ... BB24: =+BB23/BB$13 -> 0.095
A25: S&M | D25: 5595 | E25: 6304 | F25: 5126 | H25: 5750 | I25: 6204 | J25: 5187 | K25: 6246 | L25: 6207 | M25: 6816 | N25: 5717 | O25: 6440 | P25: 6212 | Q25: 7285 | R25: 5717 | S25: 6584 | T25: 6814 | U25: 7595 | AB25: 13214 | AC25: 13940 | AD25: 13857 | AE25: 15276 | AF25: 15811 | AG25: 15713 | AH25: 14697 | AI25: 15539 | AJ25: 17469 | AK25: 18213 | AL25: 19598 | AM25: 20117 | AN25: 21825 | AO25: 22759 | AP25: 24456 | AQ25: 25654 | AR25: 26710 | AS25: =+AS13*0.09 -> 34942.647 | AT25: =+AT13*0.09 -> 40533.47 | AU25: =+AU13*0.09 -> 46613.491 | AV25: =+AV13*0.09 -> 53139.379 | AW25: =+AW13*0.09 -> 60047.499 | AX25: =+AX13*0.09 -> 67253.199 | AY25: =+AY13*0.09 -> 74651.05 | AZ25: =+AZ13*0.09 -> 82862.666 | ... BB25: =+BB13*0.09 -> 102095.09
D26: =+D25/D$13 -> 0.11335089 | E26: =+E25/E$13 -> 0.12154632 | F26: =+F25/F$13 -> 0.10227046 | G26: =+G25/G$13 -> #DIV/0! | H26: =+H25/H$13 -> 0.10878408 | I26: =+I25/I$13 -> 0.11041307 | J26: =+J25/J$13 -> 0.091777695 | K26: =+K25/K$13 -> 0.10070945 | ... W26: =+W25/W$13 -> #DIV/0! | AB26: =+AB25/AB$13 -> 0.21147814 | AC26: =+AC25/AC$13 -> 0.19930515 | AD26: =+AD25/AD$13 -> 0.18796034 | AE26: =+AE25/AE$13 -> 0.19622603 | AF26: =+AF25/AF$13 -> 0.18208515 | AG26: =+AG25/AG$13 -> 0.16790981 | AH26: =+AH25/AH$13 -> 0.17225738 | AI26: =+AI25/AI$13 -> 0.17275153 | ... BB26: =+BB25/BB$13 -> 0.09
A27: G&A | D27: 1480 | E27: 1749 | F27: 1398 | H27: 1643 | I27: 2197 | J27: 1474 | K27: 1977 | L27: 1912 | M27: 2246 | N27: 1673 | O27: 1823 | P27: 1737 | Q27: 1990 | R27: 1806 | S27: 1932 | T27: 1931 | U27: 2287 | AB27: 4063 | AC27: 4222 | AD27: =+4569+6193 -> 10762 | AE27: 5149 | AF27: =+4677+127 -> 4804 | AG27: =+4611+10011 -> 14622 | AH27: =+4563+1110 -> 5673 | AI27: =+4481+306 -> 4787 | AJ27: 4754 | AK27: 4885 | AL27: 5111 | AM27: 5107 | AN27: 5900 | AO27: 7575 | AP27: 7609 | AQ27: 7223 | AR27: 7956 | AS27: =+AS13*0.024 -> 9318.0391 | AT27: =+AT13*0.024 -> 10808.925 | AU27: =+AU13*0.024 -> 12430.264 | AV27: =+AV13*0.024 -> 14170.501 | AW27: =+AW13*0.024 -> 16012.666 | AX27: =+AX13*0.024 -> 17934.186 | AY27: =+AY13*0.024 -> 19906.947 | AZ27: =+AZ13*0.024 -> 22096.711 | ... BB27: =+BB13*0.024 -> 27225.358
D28: =+D27/D$13 -> 0.029983793 | E28: =+E27/E$13 -> 0.033722163 | F28: =+F27/F$13 -> 0.027891944 | G28: =+G27/G$13 -> #DIV/0! | H28: =+H27/H$13 -> 0.031083868 | I28: =+I27/I$13 -> 0.03910018 | J28: =+J27/J$13 -> 0.026080648 | K28: =+K27/K$13 -> 0.031876814 | ... W28: =+W27/W$13 -> #DIV/0! | AB28: =+AB27/AB$13 -> 0.065024646 | AC28: =+AC27/AC$13 -> 0.060363439 | AD28: =+AD27/AD$13 -> 0.14597887 | AE28: =+AE27/AE$13 -> 0.066140862 | AF28: =+AF27/AF$13 -> 0.055324589 | AG28: =+AG27/AG$13 -> 0.15625134 | AH28: =+AH27/AH$13 -> 0.066490858 | AI28: =+AI27/AI$13 -> 0.053218455 | ... BB28: =+BB27/BB$13 -> 0.024
A29: OP Exp. | B29: =+B27+B25+B23 -> 0 | C29: =+C27+C25+C23 -> 0 | D29: =+D27+D25+D23 -> 13381 | E29: =+E27+E25+E23 -> 14902 | F29: =+F27+F25+F23 -> 13152 | G29: =+G27+G25+G23 -> 0 | H29: =+H27+H25+H23 -> 14377 | I29: =+I27+I25+I23 -> 15140 | ... W29: =+W27+W25+W23 -> 0 | AB29: =+AB27+AB25+AB23 -> 25991 | AC29: =+AC27+AC25+AC23 -> 27205 | AD29: =+AD27+AD25+AD23 -> 34430 | AE29: =+AE27+AE25+AE23 -> 30836 | AF29: =+AF27+AF25+AF23 -> 31996 | AG29: =+AG27+AG25+AG23 -> 42381 | AH29: =+AH27+AH25+AH23 -> 32358 | AI29: =+AI27+AI25+AI23 -> 33363 | ... BB29: =+BB27+BB25+BB23 -> 237087.49
D30: =+D29/D$13 -> 0.27108995 | E30: =+E29/E$13 -> 0.28732286 | F30: =+F29/F$13 -> 0.26239974 | G30: =+G29/G$13 -> #DIV/0! | H30: =+H29/H$13 -> 0.27199803 | I30: =+I29/I$13 -> 0.26944776 | J30: =+J29/J$13 -> 0.2356813 | K30: =+K29/K$13 -> 0.24774266 | ... W30: =+W29/W$13 -> #DIV/0! | AB30: =+AB29/AB$13 -> 0.41596249 | AC30: =+AC29/AC$13 -> 0.38895958 | AD30: =+AD29/AD$13 -> 0.46701843 | AE30: =+AE29/AE$13 -> 0.39610014 | AF30: =+AF29/AF$13 -> 0.36847742 | AG30: =+AG29/AG$13 -> 0.45288523 | AH30: =+AH29/AH$13 -> 0.37925457 | AI30: =+AI29/AI$13 -> 0.37090606 | ... BB30: =+BB29/BB$13 -> 0.209
A31: EBIT | B31: =+B21-B29 -> 0 | C31: =+C21-C29 -> 0 | D31: =+D21-D29 -> 20364 | E31: =+E21-E29 -> 20534 | F31: =+F21-F29 -> 21518 | G31: =+G21-G29 -> 0 | H31: =+H21-H29 -> 22352 | I31: =+I21-I29 -> 24254 | ... W31: =+W21-W29 -> 0 | AB31: =+AB21-AB29 -> 24098 | AC31: =+AC21-AC29 -> 27161 | AD31: =+AD21-AD29 -> 21763 | AE31: =+AE21-AE29 -> 26764 | AF31: =+AF21-AF29 -> 27759 | AG31: =+AG21-AG29 -> 18161 | AH31: =+AH21-AH29 -> 20182 | AI31: =+AI21-AI29 -> 22326 | ... BB31: =+BB21-BB29 -> 602361.04
D32: =+D31/D$13 -> 0.41256078 | E32: =+E31/E$13 -> 0.39591247 | F32: =+F31/F$13 -> 0.42931248 | G32: =+G31/G$13 -> #DIV/0! | H32: =+H31/H$13 -> 0.42287682 | I32: =+I31/I$13 -> 0.43165032 | J32: =+J31/J$13 -> 0.47587452 | K32: =+K31/K$13 -> 0.4358594 | ... W32: =+W31/W$13 -> #DIV/0! | AB32: =+AB31/AB$13 -> 0.38566673 | AC32: =+AC31/AC$13 -> 0.3883305 | AD32: =+AD31/AD$13 -> 0.2951996 | AE32: =+AE31/AE$13 -> 0.34379375 | AF32: =+AF31/AF$13 -> 0.31968261 | AG32: =+AG31/AG$13 -> 0.19406925 | AH32: =+AH31/AH$13 -> 0.23654477 | AI32: =+AI31/AI$13 -> 0.24820456 | ... BB32: =+BB31/BB$13 -> 0.531
A33: Other Income | D33: -174 | E33: -47 | F33: 54 | H33: 321 | I33: 473 | J33: 389 | K33: -506 | L33: -854 | M33: -675 | N33: -283 | O33: -2288 | P33: -623 | Q33: -1707 | R33: -3660 | S33: 9971 | T33: 942 | U33: 3444 | AB33: 915 | AC33: 910 | AD33: 504 | AE33: 288 | AF33: 61 | AG33: 346 | AH33: -431 | AI33: 823 | AJ33: 1416 | AK33: 729 | AL33: 77 | AM33: 1186 | AN33: 333 | AO33: 788 | AP33: -1646 | AQ33: -4901 | AR33: 10697 | AS33: =+AR66*$BE$48 -> 1851.63 | AT33: =+AS66*$BE$48 -> 3313.8451 | AU33: =+AT66*$BE$48 -> 5055.372 | AV33: =+AU66*$BE$48 -> 7058.1642 | AW33: =+AV66*$BE$48 -> 9397.5026 | AX33: =+AW66*$BE$48 -> 12078.066 | AY33: =+AX66*$BE$48 -> 14809.399 | AZ33: =+AY66*$BE$48 -> 17909.06 | ... BB33: =+BA66*$BE$48 -> 25304.853
D34: =+D33/D$13 -> -0.0035251216 | E34: =+E33/E$13 -> -0.00090619879 | F34: =+F33/F$13 -> 0.0010773712 | G34: =+G33/G$13 -> #DIV/0! | H34: =+H33/H$13 -> 0.0060729894 | I34: =+I33/I$13 -> 0.0084180178 | J34: =+J33/J$13 -> 0.0068828848 | K34: =+K33/K$13 -> -0.0081586585 | ... W34: =+W33/W$13 -> #DIV/0! | AB34: =+AB33/AB$13 -> 0.014643749 | AC34: =+AC33/AC$13 -> 0.013010594 | AD34: =+AD33/AD$13 -> 0.0068364011 | AE34: =+AE33/AE$13 -> 0.0036994695 | AF34: =+AF33/AF$13 -> 0.0007024979 | AG34: =+AG33/AG$13 -> 0.0036973712 | AH34: =+AH33/AH$13 -> -0.0050515706 | AI34: =+AI33/AI$13 -> 0.0091495275 | ... BB34: =+BB33/BB$13 -> 0.022307015
A35: EBT | B35: =+B31+B33 -> 0 | C35: =+C31+C33 -> 0 | D35: =+D31+D33 -> 20190 | E35: =+E31+E33 -> 20487 | F35: =+F31+F33 -> 21572 | G35: =+G31+G33 -> 0 | H35: =+H31+H33 -> 22673 | I35: =+I31+I33 -> 24727 | ... W35: =+W31+W33 -> 0 | AB35: =+AB31+AB33 -> 25013 | AC35: =+AC31+AC33 -> 28071 | AD35: =+AD31+AD33 -> 22267 | AE35: =+AE31+AE33 -> 27052 | AF35: =+AF31+AF33 -> 27820 | AG35: =+AG31+AG33 -> 18507 | AH35: =+AH31+AH33 -> 19751 | AI35: =+AI31+AI33 -> 23149 | ... BB35: =+BB31+BB33 -> 627665.89
D36: =+D35/D$13 -> 0.40903566 | E36: =+E35/E$13 -> 0.39500627 | F36: =+F35/F$13 -> 0.43038985 | G36: =+G35/G$13 -> #DIV/0! | H36: =+H35/H$13 -> 0.42894981 | I36: =+I35/I$13 -> 0.44006834 | J36: =+J35/J$13 -> 0.4827574 | K36: =+K35/K$13 -> 0.42770074 | ... W36: =+W35/W$13 -> #DIV/0! | AB36: =+AB35/AB$13 -> 0.40031048 | AC36: =+AC35/AC$13 -> 0.40134109 | AD36: =+AD35/AD$13 -> 0.302036 | AE36: =+AE35/AE$13 -> 0.34749322 | AF36: =+AF35/AF$13 -> 0.32038511 | AG36: =+AG35/AG$13 -> 0.19776662 | AH36: =+AH35/AH$13 -> 0.2314932 | AI36: =+AI35/AI$13 -> 0.25735409 | ... BB36: =+BB35/BB$13 -> 0.55330702
A37: Taxes | D37: 3462 | E37: 3747 | F37: 4016 | H37: 4374 | I37: 4646 | J37: 4993 | K37: 4656 | L37: 4788 | M37: 5214 | N37: 5602 | O37: 5257 | P37: 5553 | Q37: 5383 | R37: 6554 | S37: 9788 | T37: 7562 | U37: 8281 | AB37: 6253 | AC37: 4921 | AD37: 5289 | AE37: 5189 | AF37: 5746 | AG37: 6314 | AH37: 2953 | AI37: 1945 | AJ37: 19903 | AK37: 4448 | AL37: 8755 | AM37: 9831 | AN37: 10978 | AO37: 16950 | AP37: 19651 | AQ37: 21795 | AR37: 32185 | AS37: =+AS35*0.2 -> 36555.378 | AT37: =+AT35*0.2 -> 43538.173 | AU37: =+AU35*0.22 -> 56489.009 | AV37: =+AV35*0.22 -> 65981.341 | AW37: =+AW35*0.22 -> 75605.621 | AX37: =+AX35*0.3 -> 117057.15 | AY37: =+AY35*0.3 -> 132842.63 | AZ37: =+AZ35*0.3 -> 149277.55 | BA37: =+BA35*0.3 -> 167684.98 | BB37: =+BB35*0.3 -> 188299.77
D38: =+D37/D$13 -> 0.070137763 | E38: =+E37/E$13 -> 0.072245252 | F38: =+F37/F$13 -> 0.080124496 | G38: =+G37/G$13 -> #DIV/0! | H38: =+H37/H$13 -> 0.082751575 | I38: =+I37/I$13 -> 0.082685223 | J38: =+J37/J$13 -> 0.0883451 | K38: =+K37/K$13 -> 0.075072557 | ... W38: =+W37/W$13 -> #DIV/0! | AB38: =+AB37/AB$13 -> 0.10007362 | AC38: =+AC37/AC$13 -> 0.070357291 | AD38: =+AD37/AD$13 -> 0.071741519 | AE38: =+AE37/AE$13 -> 0.066654678 | AF38: =+AF37/AF$13 -> 0.066172999 | AG38: =+AG37/AG$13 -> 0.067471682 | AH38: =+AH37/AH$13 -> 0.034610877 | AI38: =+AI37/AI$13 -> 0.021623124 | ... BB38: =+BB37/BB$13 -> 0.1659921
A39: Net Income | B39: =+B35-B37 -> 0 | C39: =+C35-C37 -> 0 | D39: =+D35-D37 -> 16728 | E39: =+E35-E37 -> 16740 | F39: =+F35-F37 -> 17556 | G39: =+G35-G37 -> 0 | H39: =+H35-H37 -> 18299 | I39: =+I35-I37 -> 20081 | ... W39: =+W35-W37 -> 0 | AB39: =+AB35-AB37 -> 18760 | AC39: =+AC35-AC37 -> 23150 | AD39: =+AD35-AD37 -> 16978 | AE39: =+AE35-AE37 -> 21863 | AF39: =+AF35-AF37 -> 22074 | AG39: =+AG35-AG37 -> 12193 | AH39: =+AH35-AH37 -> 16798 | AI39: =+AI35-AI37 -> 21204 | ... BB39: =+BB35-BB37 -> 439366.12 | BC39: =+BB39*(1+$BE$46) -> 448153.44 | BD39: =+BC39*(1+$BE$46) -> 457116.51 | BE39: =+BD39*(1+$BE$46) -> 466258.84 | BF39: =+BE39*(1+$BE$46) -> 475584.02 | BG39: =+BF39*(1+$BE$46) -> 485095.7 | BH39: =+BG39*(1+$BE$46) -> 494797.61 | BI39: =+BH39*(1+$BE$46) -> 504693.57 | BJ39: =+BI39*(1+$BE$46) -> 514787.44 | ... DX39: =+DW39*(1+$BE$46) -> 1902126
D40: =+D39/D$13 -> 0.33889789 | E40: =+E39/E$13 -> 0.32276101 | F40: =+F39/F$13 -> 0.35026535 | G40: =+G39/G$13 -> #DIV/0! | H40: =+H39/H$13 -> 0.34619823 | I40: =+I39/I$13 -> 0.35738312 | J40: =+J39/J$13 -> 0.3944123 | K40: =+K39/K$13 -> 0.35262818 | ... W40: =+W39/W$13 -> #DIV/0! | AB40: =+AB39/AB$13 -> 0.30023686 | AC40: =+AC39/AC$13 -> 0.3309838 | AD40: =+AD39/AD$13 -> 0.23029448 | AE40: =+AE39/AE$13 -> 0.28083855 | AF40: =+AF39/AF$13 -> 0.25421211 | AG40: =+AG39/AG$13 -> 0.13029493 | AH40: =+AH39/AH$13 -> 0.19688233 | AI40: =+AI39/AI$13 -> 0.23573096 | ... BB40: =+BB39/BB$13 -> 0.38731491
...

Sheet Bond
A1: Main
B3: isin | C3: bondType | D3: immediateIssuer | E3: coupon | F3: couponType | G3: maturityDate | H3: callable | I3: currency | J3: seniorityLevel | K3: liquidityScore
B4: US594918BR43 | C4: — | D4: Microsoft Corporation | E4: 2400 | F4: Fixed Listing | G4: 08/08/2026 | H4: Y | I4: USD | J4: Senior | K4: —
B5: US00507VAK52 | C5: — | D5: Activision Blizzard, Inc. | E5: 3400 | F5: Fixed Listing | G5: 15/09/2026 | H5: Y | I5: USD | J5: Senior | K5: —
B6: US594918CG78 | C6: — | D6: Microsoft Corporation | E6: 3400 | F6: Fixed Listing | G6: 15/09/2026 | H6: Y | I6: USD | J6: Senior | K6: —
B7: US594918CM47 | C7: — | D7: Microsoft Corporation | E7: 3400 | F7: Fixed Listing | G7: 15/09/2026 | H7: Y | I7: USD | J7: Senior | K7: —
B8: US594918CN20 | C8: — | D8: Microsoft Corporation | E8: 3400 | F8: Fixed Listing | G8: 15/09/2026 | H8: Y | I8: USD | J8: Senior | K8: —
B9: USU59340AH90 | C9: — | D9: Microsoft Corporation | E9: 3400 | F9: Fixed Listing | G9: 15/09/2026 | H9: Y | I9: USD | J9: Senior | K9: —
B10: US594918BY93 | C10: — | D10: Microsoft Corporation | E10: 3300 | F10: Fixed Listing | G10: 06/02/2027 | H10: Y | I10: USD | J10: Senior | K10: —
B11: US00507VAM19 | C11: — | D11: Activision Blizzard, Inc. | E11: 3400 | F11: Fixed Listing | G11: 15/06/2027 | H11: Y | I11: USD | J11: Senior | K11: — | M11: MSFT acquired Blizzard in 2013
B12: US594918CH51 | C12: — | D12: Microsoft Corporation | E12: 3400 | F12: Fixed Listing | G12: 15/06/2027 | H12: Y | I12: USD | J12: Senior | K12: —
B13: US594918CP77 | C13: — | D13: Microsoft Corporation | E13: 3400 | F13: Fixed Listing | G13: 15/06/2027 | H13: Y | I13: USD | J13: Senior | K13: —
B14: US594918CQ50 | C14: — | D14: Microsoft Corporation | E14: 3400 | F14: Fixed Listing | G14: 15/06/2027 | H14: Y | I14: USD | J14: Senior | K14: —
B15: USU59340AJ56 | C15: — | D15: Microsoft Corporation | E15: 3400 | F15: Fixed Listing | G15: 15/06/2027 | H15: Y | I15: USD | J15: Senior | K15: —
B16: XS1001749289 | C16: — | D16: Microsoft Corporation | E16: 3125 | F16: Fixed Listing | G16: 06/12/2028 | H16: Y | I16: EUR | J16: Senior | K16: —
B17: US00507VAP40 | C17: — | D17: Activision Blizzard, Inc. | E17: 1350 | F17: Fixed Listing | G17: 15/09/2030 | H17: Y | I17: USD | J17: Senior | K17: —
B18: US594918CJ18 | C18: — | D18: Microsoft Corporation | E18: 1350 | F18: Fixed Listing | G18: 15/09/2030 | H18: Y | I18: USD | J18: Senior | K18: —
B19: US594918CR34 | C19: — | D19: Microsoft Corporation | E19: 1350 | F19: Fixed Listing | G19: 15/09/2030 | H19: Y | I19: USD | J19: Senior | K19: —
B20: US594918CS17 | C20: — | D20: Microsoft Corporation | E20: 1350 | F20: Fixed Listing | G20: 15/09/2030 | H20: Y | I20: USD | J20: Senior | K20: —
B21: USU59340AK20 | C21: — | D21: Microsoft Corporation | E21: 1350 | F21: Fixed Listing | G21: 15/09/2030 | H21: Y | I21: USD | J21: Senior | K21: —
B22: XS0922885362 | C22: — | D22: Microsoft Corporation | E22: 2625 | F22: Fixed Listing | G22: 02/05/2033 | H22: Y | I22: EUR | J22: Senior | K22: —
B23: US594918BC73 | C23: — | D23: Microsoft Corporation | E23: 3500 | F23: Fixed Listing | G23: 12/02/2035 | H23: Y | I23: USD | J23: Senior | K23: —
... B54: US594918CF95 | C54: — | D54: Microsoft Corporation | E54: 3041 | F54: Fixed Listing | G54: 17/03/2062 | H54: Y | I54: USD | J54: Senior | K54: —
E55: =+AVERAGE(E4:E54) -> 3413.4706

Sheet Board
A1: Main
