Workbook

Sheet Main
A1: Netflix | F1: price | G1: 78
A2: The 4th quarter is the most sub grower | F2: shares | G2: 4163.9397 | H2: Q226
A3: Asian users watch ½ to 2/3 the amount of TV as US consumers | F3: MC | G3: =G2*G1 -> 324787.29 | O3: -> | P3: After the NFLX – WBD acquisition, the management proved to be long term viewer and willing to maximize the shareholder value
F4: cash | G4: 9128 | H4: Q226 | O4: -> | P4: Acquired InterPositive AI film making studio
F5: debt | G5: 14309 | H5: Q226 | O5: -> | P5: NFLX to increase subscription prices.
F6: EV | G6: =G3-G4+G5 -> 329968.29 | P6: 8.99$ (from 7.99$) for AD supported tier, 19.99$ (from 17.99), adding a user in ad free account is not 6.99$ (from 7.99)
G7: =G6/(SUM(Model!W40:Z40)) -> 24.667473 | P7: and adding from an ad free account is 9.99$ (from 8.99). Ad free passes at 26.99$ (from 24.99)
O8: -> | P8: 275 M&A cost (not just for WBD)
A9: BETA | B9: 1.49 | D9: WACC | E9: =+(G3/(G3+G5))*B10+(G5/(G3+G5))*B11*(1-Model!AN52) -> 0.12117122
A10: CAPM | B10: =+0.05 + B9*(0.1 - 0.05) -> 0.1245
A11: Cost of Debt | B11: =+0.045 + (B17/100) -> 0.052847826 | C11: 0.0472 | D11: EV/Subs | E11: =+G6/Model!AN11 -> 1015.2871
A12: P/E | B12: =+G1/Model!AN42 -> 30.856029
A13: P/FCF | B13: =+G3/SUM(Model!X135:AA135) -> 29.125108 | H13: P/B | I13: =G3/Model!Z113 -> 10.434464
A14: EV/EBITDA | B14: =+G6/SUM(Model!X58:AA58) -> 22.404283 | H14: D/E | I14: =Model!Z97/Model!Z113 -> 0.42926042
A15: EV/FCF | B15: =+G6/SUM(Model!X135:AA135) -> 29.589711
A16: Inc Margin | B16: =+((Model!AA30+Model!Z30+Model!Y30+Model!X30)-(Model!W30+Model!V30+Model!U30+Model!T30))/((Model!AA16+Model!Z16+Model!Y16+Model!X16)-(Model!W16+Model!V16+Model!U16+Model!T16)) -> 0.29969701
A17: Cr. Spread | B17: =+'[1]Credit Spread US'!J6 -> 0.78478261
A18: Rating | B18: A- | C18: A3
B19: S&P | C19: Moody’s
A22: IR | F22: CEO | G22: Ted Sarandos
A23: ir@netflix.com | F23: Founded | G23: 1997
F24: Streaming | G24: 2007
A26: UCAN | B26: 2020 | C26: =B26+1 -> 2021 | D26: =C26+1 -> 2022 | E26: =D26+1 -> 2023 | F26: =E26+1 -> 2024 | G26: =F26+1 -> 2025 | I26: Arm | J26: =(Model!AN16/(F28+F33+F38+F43))/12 -> 12.487273
A27: Streaming Revenues | D27: 14084 | E27: 14873 | F27: 17359
A28: Memberships | D28: 74 | E28: 80.1 | F28: 89.625
A29: ARM | B29: =(B27/B28)/12 -> #DIV/0! | C29: =(C27/C28)/12 -> #DIV/0! | D29: =(D27/D28)/12 -> 15.86036 | E29: =(E27/E28)/12 -> 15.473367 | F29: =(F27/F28)/12 -> 16.1404 | G29: =(G27/G28)/12 -> #DIV/0!
A31: EMEA
A32: Streaming Revenues | D32: 9745 | E32: 10556.4 | F32: 12387
A33: Memberships | D33: 76.7 | E33: 88.8 | F33: 101.1
A34: ARM | B34: =(B32/B33)/12 -> #DIV/0! | C34: =(C32/C33)/12 -> #DIV/0! | D34: =(D32/D33)/12 -> 10.587788 | E34: =(E32/E33)/12 -> 9.9065315 | F34: =(F32/F33)/12 -> 10.210188 | G34: =(G32/G33)/12 -> #DIV/0!
A36: LATAM
A37: Streaming Revenues | D37: 4069.9 | E37: 4446.4 | F37: 4839.8
A38: Memberships | D38: 41.6 | E38: 45.9 | F38: 53.3
A39: ARM | B39: =(B37/B38)/12 -> #DIV/0! | C39: =(C37/C38)/12 -> #DIV/0! | D39: =(D37/D38)/12 -> 8.1528446 | E39: =(E37/E38)/12 -> 8.0726216 | F39: =(F37/F38)/12 -> 7.5669168 | G39: =(G37/G38)/12 -> #DIV/0!
A41: APAC
A42: Streaming Revenues | D42: 3570.2 | E42: 3763.7 | F42: 4414.7
A43: Memberships | D43: 38 | E43: 45.3 | F43: 57.5
A44: ARM | B44: =(B42/B43)/12 -> #DIV/0! | C44: =(C42/C43)/12 -> #DIV/0! | D44: =(D42/D43)/12 -> 7.829386 | E44: =(E42/E43)/12 -> 6.9236571 | F44: =(F42/F43)/12 -> 6.3981159 | G44: =(G42/G43)/12 -> #DIV/0!

Sheet Model
A1: Main
A2: in Millions | B2: Q120 | C2: Q220 | D2: Q320 | E2: Q420 | F2: Q121 | G2: Q221 | H2: Q321 | I2: Q421 | J2: Q122 | K2: Q222 | L2: Q322 | M2: Q422 | N2: Q123 | O2: Q223 | P2: Q323 | Q2: Q423 | R2: Q124 | S2: Q224 | T2: Q324 | U2: Q424 | V2: Q125 | W2: Q225 | X2: Q325 | Y2: Q425 | Z2: Q126 | AA2: Q226 | AB2: Q326 | AC2: Q426 | AI2: 2020 | AJ2: 2021 | AK2: 2022 | AL2: =AK2+1 -> 2023 | AM2: =AL2+1 -> 2024 | AN2: =AM2+1 -> 2025 | AO2: =AN2+1 -> 2026 | AP2: =AO2+1 -> 2027 | AQ2: =AP2+1 -> 2028 | AR2: =AQ2+1 -> 2029 | AS2: =AR2+1 -> 2030
A3: Disney + Subs | AK3: 102.9 | AL3: 112.6 | AM3: 125.3 | AN3: 131.6
AL4: =+AL3/AK3-1 -> 0.094266278 | AM4: =+AM3/AL3-1 -> 0.11278863 | AN4: =+AN3/AM3-1 -> 0.05027933
A5: Disney+ ARPU | AK5: 6.22 | AL5: 6.39 | AM5: 7.04 | AN5: 7.81
AL6: =+AL5/AK5-1 -> 0.02733119 | AM6: =+AM5/AL5-1 -> 0.10172144 | AN6: =+AN5/AM5-1 -> 0.109375
A7: Hulu Subs | AK7: 47.2 | AL7: 48.5 | AM7: 52 | AN7: 64.1
AL8: =+AL7/AK7-1 -> 0.027542373 | AM8: =+AM7/AL7-1 -> 0.072164948 | AN8: =+AN7/AM7-1 -> 0.23269231
A11: Subscriptions | B11: 182.8 | C11: 192.9 | D11: 195.1 | E11: 203.6 | F11: 107.6 | G11: 109.1 | H11: 213.56 | I11: 221.84 | J11: 221.64 | K11: 220.6 | L11: 223.09 | M11: 230.7 | N11: 232.5 | O11: 238.3 | P11: 247.15 | Q11: 260.2 | R11: 269.6 | S11: 277.6 | T11: 282.7 | U11: 301 | V11: - | W11: - | X11: - | Y11: 325 | Z11: 0 | AA11: =Z11*1.05 -> 0 | AB11: =AA11*1.05 -> 0 | AC11: =AB11*1.05 -> 0 | AI11: =E11 -> 203.6 | AJ11: =I11 -> 221.84 | AK11: =M11 -> 230.7 | AL11: =Q11 -> 260.2 | AM11: =U11 -> 301 | AN11: 325 | AO11: =AN11*1.07 -> 347.75 | AP11: =AO11*1.07 -> 372.0925 | AQ11: =AP11*1.07 -> 398.13898 | AR11: =AQ11*1.07 -> 426.0087 | AS11: =AR11*1.07 -> 455.82931
F12: =+F11/B11-1 -> -0.41137856 | G12: =+G11/C11-1 -> -0.43442198 | H12: =+H11/D11-1 -> 0.094618145 | I12: =+I11/E11-1 -> 0.089587426 | J12: =+J11/F11-1 -> 1.0598513 | K12: =+K11/G11-1 -> 1.0219982 | L12: =+L11/H11-1 -> 0.044624462 | M12: =+M11/I11-1 -> 0.039938695 | ... U12: =+U11/Q11-1 -> 0.15680246 | V12: N.M. | W12: N.M. | X12: N.M. | Y12: =+Y11/U11-1 -> 0.079734219 | Z12: N.M. | AJ12: =+AJ11/AI11-1 -> 0.089587426 | AK12: =+AK11/AJ11-1 -> 0.039938695 | AL12: =+AL11/AK11-1 -> 0.12787169 | AM12: =+AM11/AL11-1 -> 0.15680246 | AN12: =+AN11/AM11-1 -> 0.079734219 | AO12: =+AO11/AN11-1 -> 0.07 | AP12: =+AP11/AO11-1 -> 0.07 | AQ12: =+AQ11/AP11-1 -> 0.07 | ... AS12: =+AS11/AR11-1 -> 0.07
A13: ARM | B13: =+B16/B11 -> 31.551422 | C13: =+C16/C11 -> 31.872473 | D13: =+D16/D11 -> 32.986161 | E13: =+E16/E11 -> 32.634578 | F13: =+F16/F11 -> 66.572491 | G13: =+G16/G11 -> 67.294015 | H13: =+H16/H11 -> 35.041206 | I13: =+I16/I11 -> 34.751623 | ... U13: =+U16/U11 -> 34.043189 | V13: 0 | W13: 0 | X13: 0 | Y13: =+Y16/Y11 -> 37.079077 | AI13: =+AI16/AI11 -> 122.77041 | AJ13: =+AJ16/AJ11 -> 133.87056 | AK13: =+AK16/AK11 -> 137.04183 | AL13: =+AL16/AL11 -> 129.60529 | AM13: =+AM16/AM11 -> 129.57142 | AN13: =+AN16/AN11 -> 139.02369 | AO13: =+AO16/AO11 -> 147.72891 | AP13: =+AP16/AP11 -> 156.97923 | ... AS13: =+AS16/AS11 -> 183.25919
F14: =+F13/B13-1 -> 1.109968 | G14: =+G13/C13-1 -> 1.1113522 | H14: =+H13/D13-1 -> 0.062300226 | I14: =+I13/E13-1 -> 0.06487123 | J14: =+J13/F13-1 -> -0.46678195 | K14: =+K13/G13-1 -> -0.46312105 | L14: =+L13/H13-1 -> 0.013771598 | M14: =+M13/I13-1 -> -0.020605622 | ... U14: =+U13/Q13-1 -> 0.0029481288 | V14: N.M. | W14: N.M. | X14: N.M. | Y14: =+Y13/U13-1 -> 0.08917753 | Z14: N.M. | AJ14: =+AJ13/AI13-1 -> 0.090413826 | AK14: =+AK13/AJ13-1 -> 0.023689107 | AL14: =+AL13/AK13-1 -> -0.054264725 | AM14: =+AM13/AL13-1 -> -0.00026138439 | AN14: =+AN13/AM13-1 -> 0.072950326 | AO14: =+AO13/AN13-1 -> 0.062616822 | AP14: =+AP13/AO13-1 -> 0.062616822 | AQ14: =+AQ13/AP13-1 -> 0.056074766 | ... AS14: =+AS13/AR13-1 -> 0.046728972
A16: Revenues | B16: 5767.6 | C16: 6148.2 | D16: 6435.6 | E16: 6644.4 | F16: 7163.2 | G16: 7341.777 | H16: 7483.4 | I16: 7709.3 | J16: 7867.7 | K16: 7970 | L16: 7925 | M16: 7852 | N16: 8161.5 | O16: 8187 | P16: 8542 | Q16: 8832 | R16: 9370 | S16: 9559 | T16: 9824 | U16: 10247 | V16: 10543 | W16: 11079 | X16: 11510 | Y16: 12050.7 | Z16: 12249.757 | AA16: 12559.938 | AB16: =X16*1.155 -> 13294.05 | AC16: =Y16*1.155 -> 13918.558 | AI16: 24996.056 | AJ16: 29697.844 | AK16: 31615.55 | AL16: 33723.297 | AM16: 39000.996 | AN16: =SUM(V16:Y16) -> 45182.7 | AO16: =AN16*1.137 -> 51372.73 | AP16: =AO16*1.137 -> 58410.794 | AQ16: =AP16*1.13 -> 66004.197 | AR16: =AQ16*1.13 -> 74584.743 | AS16: =AR16*1.12 -> 83534.912
F17: =+F16/B16-1 -> 0.2419724 | G17: =+G16/C16-1 -> 0.19413438 | H17: =+H16/D16-1 -> 0.1628131 | I17: =+I16/E16-1 -> 0.1602703 | J17: =+J16/F16-1 -> 0.098349899 | K17: =+K16/G16-1 -> 0.085568249 | L17: =+L16/H16-1 -> 0.05901061 | M17: =+M16/I16-1 -> 0.018510111 | ... AC17: =+AC16/Y16-1 -> 0.155 | AJ17: =+AJ16/AI16-1 -> 0.18810119 | AK17: =+AK16/AJ16-1 -> 0.064573913 | AL17: =+AL16/AK16-1 -> 0.066668048 | AM17: =+AM16/AL16-1 -> 0.15650009 | AN17: =+AN16/AM16-1 -> 0.15850118 | AO17: =+AO16/AN16-1 -> 0.137 | AP17: =+AP16/AO16-1 -> 0.137 | AQ17: =+AQ16/AP16-1 -> 0.13 | ... AS17: =+AS16/AR16-1 -> 0.12
A18: COGS | B18: 3599.7 | C18: 3643.7 | D18: 3867.7 | E18: 4165.1 | F18: 3868.5 | G18: 4018 | H18: 4206.5 | I18: 5239.5 | J18: 4284.7 | K18: 4690.7 | L18: 4788 | M18: 5404 | N18: 4803 | O18: 4673 | P18: 4930 | Q18: 5307 | R18: 4977 | S18: 5174 | T18: 5119 | U18: 5767 | V18: 5263 | W18: 5325 | X18: 6164 | Y18: 6522.621 | Z18: 5888.238 | AA18: 6036.965 | AB18: =AB16-AB20 -> 6514.0845 | AC18: =AC16-AC20 -> 6820.0937 | AI18: 15276.319 | AJ18: 17332.683 | AK18: 19168.285 | AL18: 19715.368 | AM18: 21038.464 | AN18: 23275.329 | AO18: =AO16-AO20 -> 25686.365 | AP18: =AP16-AP20 -> 28329.235 | AQ18: =AQ16-AQ20 -> 31682.015 | AR18: =AR16-AR20 -> 35427.753 | AS18: =AS16-AS20 -> 39261.409
B19: =+B18/B$16 -> 0.62412442 | C19: =+C18/C$16 -> 0.592645 | D19: =+D18/D$16 -> 0.60098515 | E19: =+E18/E$16 -> 0.62685871 | F19: =+F18/F$16 -> 0.54005193 | G19: =+G18/G$16 -> 0.54727895 | H19: =+H18/H$16 -> 0.56211081 | I19: =+I18/I$16 -> 0.67963369 | ... AC19: =+AC18/AC$16 -> 0.49 | AI19: =+AI18/AI$16 -> 0.61114917 | AJ19: =+AJ18/AJ$16 -> 0.58363439 | AK19: =+AK18/AK$16 -> 0.60629295 | AL19: =+AL18/AL$16 -> 0.5846216 | AM19: =+AM18/AM$16 -> 0.53943402 | AN19: =+AN18/AN$16 -> 0.51513807 | AO19: =+AO18/AO$16 -> 0.5 | AP19: =+AP18/AP$16 -> 0.485 | ... AS19: =+AS18/AS$16 -> 0.47
A20: Gross Profit | B20: =B16-B18 -> 2167.9 | C20: =C16-C18 -> 2504.5 | D20: =D16-D18 -> 2567.9 | E20: =E16-E18 -> 2479.3 | F20: =F16-F18 -> 3294.7 | G20: =G16-G18 -> 3323.777 | H20: =H16-H18 -> 3276.9 | I20: =I16-I18 -> 2469.8 | ... AA20: =AA16-AA18 -> 6522.973 | AB20: =AB16*0.51 -> 6779.9655 | AC20: =AC16*0.51 -> 7098.4648 | AI20: =AI16-AI18 -> 9719.737 | AJ20: =AJ16-AJ18 -> 12365.161 | AK20: =AK16-AK18 -> 12447.265 | AL20: =AL16-AL18 -> 14007.929 | AM20: =AM16-AM18 -> 17962.532 | AN20: =AN16-AN18 -> 21907.371 | AO20: =AO16*0.5 -> 25686.365 | AP20: =AP16*0.515 -> 30081.559 | AQ20: =AQ16*0.52 -> 34322.182 | AR20: =AR16*0.525 -> 39156.99 | AS20: =AS16*0.53 -> 44273.503
B21: =+B20/B$16 -> 0.37587558 | C21: =+C20/C$16 -> 0.407355 | D21: =+D20/D$16 -> 0.39901485 | E21: =+E20/E$16 -> 0.37314129 | F21: =+F20/F$16 -> 0.45994807 | G21: =+G20/G$16 -> 0.45272105 | H21: =+H20/H$16 -> 0.43788919 | I21: =+I20/I$16 -> 0.32036631 | ... AC21: =+AC20/AC$16 -> 0.51 | AI21: =+AI20/AI$16 -> 0.38885083 | AJ21: =+AJ20/AJ$16 -> 0.41636561 | AK21: =+AK20/AK$16 -> 0.39370705 | AL21: =+AL20/AL$16 -> 0.4153784 | AM21: =+AM20/AM$16 -> 0.46056598 | AN21: =+AN20/AN$16 -> 0.48486193 | AO21: =+AO20/AO$16 -> 0.5 | AP21: =+AP20/AP$16 -> 0.515 | ... AS21: =+AS20/AS$16 -> 0.53
A22: T&D | B22: 453.8 | C22: 435 | D22: 453.8 | E22: 486.9 | F22: 525.2 | G22: 537.3 | H22: 563.8 | I22: 647 | J22: 657.5 | K22: 716.8 | L22: 662.7 | M22: 673.9 | N22: 687.2 | O22: 657 | P22: 657 | Q22: 673 | R22: 702 | S22: 711 | T22: 735 | U22: 776 | V22: 822 | W22: 824 | X22: 853 | Y22: 890.3 | Z22: 959.696 | AA22: 1007.675 | AB22: =X22*1.13 -> 963.89 | AC22: =Y22*1.13 -> 1006.039 | AI22: 1829.6 | AJ22: 2273.885 | AK22: 2711.041 | AL22: 2675.758 | AM22: 2925.295 | AN22: 3391.39 | AO22: =+AO16*0.073 -> 3750.2093 | AP22: =+AP16*0.073 -> 4263.988 | AQ22: =+AQ16*0.073 -> 4818.3064 | AR22: =+AR16*0.073 -> 5444.6862 | AS22: =+AS16*0.07 -> 5847.4438
B23: =+B22/B$16 -> 0.078680907 | C23: =+C22/C$16 -> 0.070752415 | D23: =+D22/D$16 -> 0.070514016 | E23: =+E22/E$16 -> 0.073279754 | F23: =+F22/F$16 -> 0.073319187 | G23: =+G22/G$16 -> 0.073183917 | H23: =+H22/H$16 -> 0.075340086 | I23: =+I22/I$16 -> 0.083924611 | ... AC23: =+AC22/AC$16 -> 0.072280402 | AI23: =+AI22/AI$16 -> 0.073195547 | AJ23: =+AJ22/AJ$16 -> 0.076567343 | AK23: =+AK22/AK$16 -> 0.08575024 | AL23: =+AL22/AL$16 -> 0.079344496 | AM23: =+AM22/AM$16 -> 0.075005649 | AN23: =+AN22/AN$16 -> 0.075059481 | AO23: =+AO22/AO$16 -> 0.073 | AP23: =+AP22/AP$16 -> 0.073 | ... AS23: =+AS22/AS$16 -> 0.07
A24: S&M | B24: 503.8 | C24: 434.3 | D24: 527.5 | E24: 762.5 | F24: 512.5 | G24: 603.9 | H24: 635.9 | I24: 792 | J24: 555.9 | K24: 574.9 | L24: 567.9 | M24: 831.6 | N24: 555.3 | O24: 627 | P24: 558 | Q24: 916 | R24: 654 | S24: 688 | T24: 642 | U24: 976 | V24: 644 | W24: 713 | X24: 786 | Y24: 1113.376 | Z24: 842.217 | AA24: 823.838 | AB24: =X24*1.13 -> 888.18 | AC24: =Y24*1.13 -> 1258.1149 | AI24: 2228.362 | AJ24: 2545.146 | AK24: 2530.502 | AL24: 2657.883 | AM24: 2917.554 | AN24: 3301.306 | AO24: =+AO16*0.07 -> 3596.0911 | AP24: =+AP16*0.07 -> 4088.7556 | AQ24: =+AQ16*0.067 -> 4422.2812 | AR24: =+AR16*0.067 -> 4997.1778 | AS24: =+AS16*0.065 -> 5429.7693
B25: =+B24/B$16 -> 0.087350024 | C25: =+C24/C$16 -> 0.070638561 | D25: =+D24/D$16 -> 0.081965939 | E25: =+E24/E$16 -> 0.11475829 | F25: =+F24/F$16 -> 0.071546236 | G25: =+G24/G$16 -> 0.082255291 | H25: =+H24/H$16 -> 0.084974744 | I25: =+I24/I$16 -> 0.10273306 | ... AC25: =+AC24/AC$16 -> 0.090391177 | AI25: =+AI24/AI$16 -> 0.089148544 | AJ25: =+AJ24/AJ$16 -> 0.085701373 | AK25: =+AK24/AK$16 -> 0.080039791 | AL25: =+AL24/AL$16 -> 0.078814447 | AM25: =+AM24/AM$16 -> 0.074807166 | AN25: =+AN24/AN$16 -> 0.073065709 | AO25: =+AO24/AO$16 -> 0.07 | AP25: =+AP24/AP$16 -> 0.07 | ... AS25: =+AS24/AS$16 -> 0.065
A26: G&A | B26: 252 | C26: 277.2 | D26: 271.6 | E26: 275.5 | F26: 297.1 | G26: 334.8 | H26: 321.7 | I26: 397.7 | J26: 397.9 | K26: 409.2 | L26: 373 | M26: 392.4 | N26: 400.9 | O26: 401 | P26: 478 | Q26: 429 | R26: 404 | S26: 426 | T26: 417 | U26: 453 | V26: 421 | W26: 441 | X26: 457 | Y26: 567.802 | Z26: 602.609 | AA26: 498.85 | AB26: =X26*1.13 -> 516.41 | AC26: =Y26*1.13 -> 641.61626 | AI26: 1076.486 | AJ26: 1351.621 | AK26: 1572.891 | AL26: 1720.285 | AM26: 1702.039 | AN26: 1888.408 | AO26: =+AO16*0.042 -> 2157.6547 | AP26: =+AP16*0.042 -> 2453.2533 | AQ26: =+AQ16*0.04 -> 2640.1679 | AR26: =+AR16*0.04 -> 2983.3897 | AS26: =+AS16*0.04 -> 3341.3965
B27: =+B26/B$16 -> 0.04369235 | C27: =+C26/C$16 -> 0.045086367 | D27: =+D26/D$16 -> 0.042202747 | E27: =+E26/E$16 -> 0.041463488 | F27: =+F26/F$16 -> 0.041475877 | G27: =+G26/G$16 -> 0.045602039 | H27: =+H26/H$16 -> 0.042988481 | I27: =+I26/I$16 -> 0.051587044 | ... AC27: =+AC26/AC$16 -> 0.046097896 | AI27: =+AI26/AI$16 -> 0.043066234 | AJ27: =+AJ26/AJ$16 -> 0.045512428 | AK27: =+AK26/AK$16 -> 0.04975055 | AL27: =+AL26/AL$16 -> 0.051011768 | AM27: =+AM26/AM$16 -> 0.043640911 | AN27: =+AN26/AN$16 -> 0.041794935 | AO27: =+AO26/AO$16 -> 0.042 | AP27: =+AP26/AP$16 -> 0.042 | ... AS27: =+AS26/AS$16 -> 0.04
A28: OpEx | B28: =SUM(B22:B26) -> 1209.766 | C28: =SUM(C22:C26) -> 1146.6414 | D28: =SUM(D22:D26) -> 1253.0525 | E28: =SUM(E22:E26) -> 1525.088 | F28: =SUM(F22:F26) -> 1334.9449 | G28: =SUM(G22:G26) -> 1476.1554 | H28: =SUM(H22:H26) -> 1521.5603 | I28: =SUM(I22:I26) -> 1836.8867 | ... AC28: =SUM(AC22:AC26) -> 2905.9328 | AI28: =SUM(AI22:AI26) -> 5134.6103 | AJ28: =SUM(AJ22:AJ26) -> 6170.8143 | AK28: =SUM(AK22:AK26) -> 6814.5998 | AL28: =SUM(AL22:AL26) -> 7054.0842 | AM28: =SUM(AM22:AM26) -> 7545.0378 | AN28: =SUM(AN22:AN26) -> 8581.2521 | AO28: =SUM(AO22:AO26) -> 9504.098 | AP28: =SUM(AP22:AP26) -> 10806.14 | ... AS28: =SUM(AS22:AS26) -> 14618.745
B29: =+B28/B$16 -> 0.20975207 | C29: =+C28/C$16 -> 0.18650034 | D29: =+D28/D$16 -> 0.1947064 | E29: =+E28/E$16 -> 0.22952984 | F29: =+F28/F$16 -> 0.18636152 | G29: =+G28/G$16 -> 0.20106242 | H29: =+H28/H$16 -> 0.20332473 | I29: =+I28/I$16 -> 0.23826893 | ... AC29: =+AC28/AC$16 -> 0.20878116 | AI29: =+AI28/AI$16 -> 0.20541682 | AJ29: =+AJ28/AJ$16 -> 0.20778661 | AK29: =+AK28/AK$16 -> 0.21554582 | AL29: =+AL28/AL$16 -> 0.2091754 | AM29: =+AM28/AM$16 -> 0.19345757 | AN29: =+AN28/AN$16 -> 0.1899234 | AO29: =+AO28/AO$16 -> 0.18500278 | AP29: =+AP28/AP$16 -> 0.18500245 | ... AS29: =+AS28/AS$16 -> 0.17500162
A30: EBIT | B30: =B20-B28 -> 958.13397 | C30: =C20-C28 -> 1357.8586 | D30: =D20-D28 -> 1314.8475 | E30: =E20-E28 -> 954.21196 | F30: =F20-F28 -> 1959.7551 | G30: =G20-G28 -> 1847.6216 | H30: =H20-H28 -> 1755.3397 | I30: =I20-I28 -> 632.91334 | ... AC30: =AC20-AC28 -> 4192.532 | AI30: =AI20-AI28 -> 4585.1267 | AJ30: =AJ20-AJ28 -> 6194.3467 | AK30: =AK20-AK28 -> 5632.6652 | AL30: =AL20-AL28 -> 6953.8448 | AM30: =AM20-AM28 -> 10417.494 | AN30: =AN20-AN28 -> 13326.119 | AO30: =AO20-AO28 -> 16182.267 | AP30: =AP20-AP28 -> 19275.419 | ... AS30: =AS20-AS28 -> 29654.759
B31: =+B30/B$16 -> 0.16612351 | C31: =+C30/C$16 -> 0.22085466 | D31: =+D30/D$16 -> 0.20430846 | E31: =+E30/E$16 -> 0.14361146 | F31: =+F30/F$16 -> 0.27358654 | G31: =+G30/G$16 -> 0.25165863 | H31: =+H30/H$16 -> 0.23456446 | I31: =+I30/I$16 -> 0.082097381 | ... AC31: =+AC30/AC$16 -> 0.30121884 | AI31: =+AI30/AI$16 -> 0.183434 | AJ31: =+AJ30/AJ$16 -> 0.208579 | AK31: =+AK30/AK$16 -> 0.17816123 | AL31: =+AL30/AL$16 -> 0.20620299 | AM31: =+AM30/AM$16 -> 0.26710841 | AN31: =+AN30/AN$16 -> 0.29493852 | AO31: =+AO30/AO$16 -> 0.31499722 | AP31: =+AP30/AP$16 -> 0.32999755 | ... AS31: =+AS30/AS$16 -> 0.35499838
A32: Interest Exp | B32: -184 | C32: -189.1 | D32: -197 | E32: -197.1 | F32: -194.4 | G32: -191.3 | H32: -190 | I32: -189.4 | J32: -187.5 | K32: -175.4 | L32: -187.5 | M32: -170.6 | N32: -174.2 | O32: -174.8 | P32: -175.5 | Q32: -175.2 | R32: -173.3 | S32: -167.9 | T32: -184.8 | U32: -192.6 | V32: -184.1 | W32: -182.6 | X32: -175 | Y32: -234.395 | Z32: -262.077 | AA32: -175.685 | AB32: -175 | AC32: -234.3 | AI32: -767.499 | AJ32: -765.62 | AK32: -706.212 | AL32: -699.826 | AM32: -718.733 | AN32: -776.51 | AO32: =SUM(Z32:AC32) -> -847.062 | AP32: =AO32*1.02 -> -864.00324 | AQ32: =AP32*1.02 -> -881.2833 | AR32: =AQ32*1.02 -> -898.90897 | AS32: =AR32*1.02 -> -916.88715
B33: =+B32/B$16 -> -0.031902351 | C33: =+C32/C$16 -> -0.03075697 | D33: =+D32/D$16 -> -0.030610976 | E33: =+E32/E$16 -> -0.029664078 | F33: =+F32/F$16 -> -0.027138709 | G33: =+G32/G$16 -> -0.026056362 | H33: =+H32/H$16 -> -0.025389529 | I33: =+I32/I$16 -> -0.02456773 | ... AC33: =+AC32/AC$16 -> -0.01683364 | AI33: =+AI32/AI$16 -> -0.030704804 | AJ33: =+AJ32/AJ$16 -> -0.025780323 | AK33: =+AK32/AK$16 -> -0.022337489 | AL33: =+AL32/AL$16 -> -0.020752004 | AM33: =+AM32/AM$16 -> -0.018428581 | AN33: =+AN32/AN$16 -> -0.017186003 | AO33: =+AO32/AO$16 -> -0.016488553 | AP33: =+AP32/AP$16 -> -0.014791842 | ... AS33: =+AS32/AS$16 -> -0.010976095
A34: Other Income | B34: 21.6 | C34: -133.1 | D34: -256.3 | E34: -250.6 | F34: 269 | G34: -62.5 | H34: 96.1 | I34: 108.5 | J34: 195.6 | K34: 220.2 | L34: 195 | M34: -339.9 | N34: -71 | O34: 26.9 | P34: 168.2 | Q34: -172.7 | R34: 155.3 | S34: 79 | T34: -21.6 | U34: 54.1 | V34: 50 | W34: 39.6 | X34: 36.4 | Y34: 45.473 | Z34: 2852.166 | AA34: 51.661 | AB34: =AA34 -> 51.661 | AC34: =AB34 -> 51.661 | AI34: -618.441 | AJ34: 411.214 | AK34: 337.31 | AL34: -48.772 | AM34: 266.776 | AN34: 172.459 | AO34: =+AO16*0.003 -> 154.11819 | AP34: =+AP16*0.003 -> 175.23238 | AQ34: =+AQ16*0.003 -> 198.01259 | AR34: =+AR16*0.003 -> 223.75423 | AS34: =+AS16*0.003 -> 250.60474
B35: =+B34/B$16 -> 0.0037450586 | C35: =+C34/C$16 -> -0.021648613 | D35: =+D34/D$16 -> -0.039825347 | E35: =+E34/E$16 -> -0.037715971 | F35: =+F34/F$16 -> 0.037553049 | G35: =+G34/G$16 -> -0.0085129254 | H35: =+H34/H$16 -> 0.012841756 | I35: =+I34/I$16 -> 0.014073911 | ... AC35: =+AC34/AC$16 -> 0.0037116631 | AI35: =+AI34/AI$16 -> -0.024741543 | AJ35: =+AJ34/AJ$16 -> 0.013846594 | AK35: =+AK34/AK$16 -> 0.010669117 | AL35: =+AL34/AL$16 -> -0.0014462406 | AM35: =+AM34/AM$16 -> 0.0068402356 | AN35: =+AN34/AN$16 -> 0.0038169255 | AO35: =+AO34/AO$16 -> 0.003 | AP35: =+AP34/AP$16 -> 0.003 | ... AS35: =+AS34/AS$16 -> 0.003
A36: EBT | B36: =B30+B32+B34 -> 795.73397 | C36: =C30+C32+C34 -> 1035.6586 | D36: =D30+D32+D34 -> 861.54752 | E36: =E30+E32+E34 -> 506.51196 | F36: =F30+F32+F34 -> 2034.3551 | G36: =G30+G32+G34 -> 1593.8216 | H36: =H30+H32+H34 -> 1661.4397 | I36: =I30+I32+I34 -> 552.01334 | ... AC36: =AC30+AC32+AC34 -> 4009.893 | AI36: =AI30+AI32+AI34 -> 3199.1867 | AJ36: =AJ30+AJ32+AJ34 -> 5839.9407 | AK36: =AK30+AK32+AK34 -> 5263.7632 | AL36: =AL30+AL32+AL34 -> 6205.2468 | AM36: =AM30+AM32+AM34 -> 9965.5372 | AN36: =AN30+AN32+AN34 -> 12722.068 | AO36: =AO30+AO32+AO34 -> 15489.323 | AP36: =AP30+AP32+AP34 -> 18586.648 | ... AS36: =AS30+AS32+AS34 -> 28988.476
B37: =+B36/B$16 -> 0.13796622 | C37: =+C36/C$16 -> 0.16844908 | D37: =+D36/D$16 -> 0.13387214 | E37: =+E36/E$16 -> 0.076231407 | F37: =+F36/F$16 -> 0.28400088 | G37: =+G36/G$16 -> 0.21708935 | H37: =+H36/H$16 -> 0.22201669 | I37: =+I36/I$16 -> 0.071603562 | ... AC37: =+AC36/AC$16 -> 0.28809686 | AI37: =+AI36/AI$16 -> 0.12798766 | AJ37: =+AJ36/AJ$16 -> 0.19664528 | AK37: =+AK36/AK$16 -> 0.16649286 | AL37: =+AL36/AL$16 -> 0.18400475 | AM37: =+AM36/AM$16 -> 0.25552007 | AN37: =+AN36/AN$16 -> 0.28156945 | AO37: =+AO36/AO$16 -> 0.30150866 | AP37: =+AP36/AP$16 -> 0.31820571 | ... AS37: =+AS36/AS$16 -> 0.34702229
A38: Taxes | B38: 86.8 | C38: 315.4 | D38: 71.4 | E38: -35.7 | F38: 327.7 | G38: 240.7 | H38: 211.8 | I38: -56.5 | J38: 382.2 | K38: 182.1 | L38: 223.6 | M38: -15.9 | N38: 163.7 | O38: 191.7 | P38: 191.7 | Q38: 210.3 | R38: 282 | S38: 323 | T38: 339 | U38: 265.6 | V38: 366 | W38: 506 | X38: 562.4 | Y38: 349.22 | Z38: 1264.295 | AA38: 667.172 | AB38: =AB36*X52 -> 775.11269 | AC38: =AC36*Y52 -> 505.99039 | AI38: 437.954 | AJ38: 723.875 | AK38: 772.005 | AL38: 797.415 | AM38: 1254.026 | AN38: 1741.351 | AO38: =AO36*0.15 -> 2323.3985 | AP38: =AP36*0.15 -> 2787.9972 | AQ38: =AQ36*0.15 -> 3263.7024 | AR38: =AR36*0.15 -> 3758.4662 | AS38: =AS36*0.15 -> 4348.2714
B39: =+B38/B$16 -> 0.015049587 | C39: =+C38/C$16 -> 0.051299567 | D39: =+D38/D$16 -> 0.011094537 | E39: =+E38/E$16 -> -0.0053729456 | F39: =+F38/F$16 -> 0.045747711 | G39: =+G38/G$16 -> 0.032784978 | H39: =+H38/H$16 -> 0.028302643 | I39: =+I38/I$16 -> -0.0073288107 | ... AC39: =+AC38/AC$16 -> 0.036353649 | AI39: =+AI38/AI$16 -> 0.017520924 | AJ39: =+AJ38/AJ$16 -> 0.024374665 | AK39: =+AK38/AK$16 -> 0.024418522 | AL39: =+AL38/AL$16 -> 0.02364582 | AM39: =+AM38/AM$16 -> 0.032153692 | AN39: =+AN38/AN$16 -> 0.038540216 | AO39: =+AO38/AO$16 -> 0.045226299 | AP39: =+AP38/AP$16 -> 0.047730856 | ... AS39: =+AS38/AS$16 -> 0.052053343
A40: Net Inc | B40: =B36-B38 -> 708.93397 | C40: =C36-C38 -> 720.25861 | D40: =D36-D38 -> 790.14752 | E40: =E36-E38 -> 542.21196 | F40: =F36-F38 -> 1706.6551 | G40: =G36-G38 -> 1353.1216 | H40: =H36-H38 -> 1449.6397 | I40: =I36-I38 -> 608.51334 | ... AC40: =AC36-AC38 -> 3503.9026 | AI40: =AI36-AI38 -> 2761.2327 | AJ40: =AJ36-AJ38 -> 5116.0657 | AK40: =AK36-AK38 -> 4491.7582 | AL40: =AL36-AL38 -> 5407.8318 | AM40: =AM36-AM38 -> 8711.5112 | AN40: =AN36-AN38 -> 10980.717 | AO40: =AO36-AO38 -> 13165.925 | AP40: =AP36-AP38 -> 15798.651 | ... AS40: =AS36-AS38 -> 24640.205 | AT40: =AS40*(1+$AX$49) -> 25133.009 | AU40: =AT40*(1+$AX$49) -> 25635.669 | AV40: =AU40*(1+$AX$49) -> 26148.383 | AW40: =AV40*(1+$AX$49) -> 26671.35 | AX40: =AW40*(1+$AX$49) -> 27204.777 | AY40: =AX40*(1+$AX$49) -> 27748.873 | AZ40: =AY40*(1+$AX$49) -> 28303.85 | BA40: =AZ40*(1+$AX$49) -> 28869.927 | ... DH40: =DG40*(1+$AX$49) -> 92865.804
B41: =+B40/B$16 -> 0.12291663 | C41: =+C40/C$16 -> 0.11714951 | D41: =+D40/D$16 -> 0.1227776 | E41: =+E40/E$16 -> 0.081604353 | F41: =+F40/F$16 -> 0.23825317 | G41: =+G40/G$16 -> 0.18430437 | H41: =+H40/H$16 -> 0.19371405 | I41: =+I40/I$16 -> 0.078932373 | ... AC41: =+AC40/AC$16 -> 0.25174321 | AI41: =+AI40/AI$16 -> 0.11046673 | AJ41: =+AJ40/AJ$16 -> 0.17227061 | AK41: =+AK40/AK$16 -> 0.14207433 | AL41: =+AL40/AL$16 -> 0.16035893 | AM41: =+AM40/AM$16 -> 0.22336638 | AN41: =+AN40/AN$16 -> 0.24302923 | AO41: =+AO40/AO$16 -> 0.25628236 | AP41: =+AP40/AP$16 -> 0.27047485 | ... AS41: =+AS40/AS$16 -> 0.29496895
A42: EPS | B42: =B40/B44 -> 1.5670512 | C42: =C40/C44 -> 1.5868222 | D42: =D40/D44 -> 1.736588 | E42: =E40/E44 -> 1.1916746 | F42: =F40/F44 -> 3.7459507 | G42: =G40/G44 -> 2.9732401 | H42: =H40/H44 -> 3.1867217 | I42: =I40/I44 -> 1.3353376 | ... AC42: =AC40/AC44 -> 0.83895667 | AI42: =AI40/AI44 -> 6.0792251 | AJ42: =AJ40/AJ44 -> 11.234915 | AK42: =AK40/AK44 -> 9.9531525 | AL42: =AL40/AL44 -> 12.030825 | AM42: =AM40/AM44 -> 1.9832207 | AN42: =AN40/AN44 -> 2.5278691 | AO42: =AO40/AO44 -> 3.0615408 | AP42: =AP40/AP44 -> 3.7108508 | ... AS42: =AS40/AS44 -> 5.9647497
F43: =+F42/B42-1 -> 1.3904456 | G43: =+G42/C42-1 -> 0.8737071 | H43: =+H42/D42-1 -> 0.83504766 | I43: =+I42/E42-1 -> 0.12055552 | J43: =+J42/F42-1 -> -0.058410194 | K43: =+K42/G42-1 -> 0.076728682 | L43: =+L42/H42-1 -> -0.082116812 | M43: =+M42/I42-1 -> -0.90828402 | ... AC43: =+AC42/Y42-1 -> 0.49769289 | AJ43: =+AJ42/AI42-1 -> 0.84808342 | AK43: =+AK42/AJ42-1 -> -0.11408742 | AL43: =+AL42/AK42-1 -> 0.20874518 | AM43: =+AM42/AL42-1 -> -0.83515505 | AN43: =+AN42/AM42-1 -> 0.2746282 | AO43: =+AO42/AN42-1 -> 0.21111526 | AP43: =+AP42/AO42-1 -> 0.21208602 | AQ43: =+AQ42/AP42-1 -> 0.18245065 | ... AS43: =+AS42/AR42-1 -> 0.16861324
...

Sheet Bonds
A1: Main
B3: yield
A4: US64110LAN64 | B4: 4375 | C4: Fixed Listing | D4: 15/11/2026 | E4: 1 | F4: USD | G4: Senior
A5: XS1821883102 | B5: 3625 | C5: Fixed Listing | D5: 15/05/2027 | E5: 1 | F5: EUR | G5: Senior
A6: US64110LAS51 | B6: 4875 | C6: Fixed Listing | D6: 15/04/2028 | E6: 1 | F6: USD | G6: Senior
A7: US64110LAT35 | B7: 5875 | C7: Fixed Listing | D7: 15/11/2028 | E7: 1 | F7: USD | G7: Senior
A8: US64110LAX47 | B8: 6375 | C8: Fixed Listing | D8: 15/05/2029 | E8: 1 | F8: USD | G8: Senior
A9: XS2076099865 | B9: 4625 | C9: Fixed Listing | D9: 15/05/2029 | E9: 1 | F9: EUR | G9: Senior
A10: US64110LAU08 | B10: 5375 | C10: Fixed Listing | D10: 15/11/2029 | E10: 1 | F10: USD | G10: Senior
A11: USU74079AN15 | B11: 5375 | C11: Fixed Listing | D11: 15/11/2029 | E11: 1 | F11: USD | G11: Senior
A12: XS1989380172 | B12: 3875 | C12: Fixed Listing | D12: 15/11/2029 | E12: 1 | F12: EUR | G12: Senior
A13: XS1989380503 | B13: 3875 | C13: Fixed Listing | D13: 15/11/2029 | E13: 1 | F13: EUR | G13: Senior
A14: US64110LAV80 | B14: 4875 | C14: Fixed Listing | D14: 15/06/2030 | E14: 1 | F14: USD | G14: Senior
A15: USU74079AQ46 | B15: 4875 | C15: Fixed Listing | D15: 15/06/2030 | E15: 1 | F15: USD | G15: Senior
... A19: US64110LBA35 | B19: 5400 | C19: Fixed Listing | D19: 15/08/2054 | E19: 1 | F19: USD | G19: Senior
A22: average yield | B22: =AVERAGE(B4:B19) -> 4721.875
