Workbook

Sheet Main
A1: Nvidia Corp | E1: Price | F1: 219
E2: Share | F2: 24100 | G2: Q227 | I2: -> | J2: Increasing strategic partenrship with UBER in order to inprove Drive and Alpamayo in real world scenarios
E3: MC | F3: =+F1*F2 -> 5277900 | J3: Exploiting UBER’s network effect in order to engage more users and deploy L4 AV in 28 cities by 2028
E4: Cash | F4: 99369 | G4: Q227 | J4: -> | K4: Nvidia’s Level 4 AV are developed altogether with Mercedes Benz, Stellantis and Lucid
E5: Debt | F5: =+1000+32366 -> 33366 | G5: Q227
E6: EV | F6: =+F3-F4+F5 -> 5211897
A10: P/FCF | B10: =+F3/SUM(Model!L131:O131) -> 41.556286 | D10: BETA | E10: 2.21 | G10: WACC | H10: =+(F3/(F3+F5))*E11+(F5/(F3+F5))*E12*(1-Model!N64) -> 0.15870008
A11: EV/EBITDA | B11: =+F6/SUM(Model!L73:O73) -> 25.82026 | D11: CAPM | E11: =+'[1]Zero-rate curve US'!J3+E10*(0.1-'[1]Zero-rate curve US'!J3) -> 0.15939289
A12: EV/FCF | B12: =+F6/SUM(Model!L131:O131) -> 41.036602 | D12: Cost of Debt | E12: =+'[1]Zero-rate curve US'!J3+(E13/100) -> 0.058862796
A13: Inc. Margin | B13: =+((Model!O31+Model!N31+Model!M31+Model!L31)-(Model!K31+Model!J31+Model!I31+Model!H31))/((Model!O19+Model!N19+Model!M19+Model!L19)-(Model!K19+Model!J19+Model!I19+Model!H19)) -> 0.72775945 | D13: Cr. Spread | E13: =+'[1]Credit Spread US'!J6 -> 0.79478261
A14: P/E | B14: =+F1/SUM(Model!L45:O45) -> 27.683985 | D14: Rating | E14: AA | F14: Aa2
E15: S&P | F15: Moody’s

Sheet Model
A1: Main | B1: 45042 | C1: 45133 | D1: 45224 | E1: 45348 | F1: 45408 | G1: 45499 | H1: 45589 | I1: 45683 | J1: 45773 | K1: 45864 | L1: 45955 | M1: 46079 | N1: 46138 | O1: 46229 | P1: 46320 | Q1: 46444
A2: in Millions | B2: Q124 | C2: Q224 | D2: Q324 | E2: Q424 | F2: Q125 | G2: Q225 | H2: Q325 | I2: Q425 | J2: Q126 | K2: Q226 | L2: Q326 | M2: Q426 | N2: Q127 | O2: Q227 | P2: Q327 | Q2: Q427 | V2: =+W2-1 -> 2011 | W2: =+X2-1 -> 2012 | X2: =+Y2-1 -> 2013 | Y2: =+Z2-1 -> 2014 | Z2: =+AA2-1 -> 2015 | AA2: =+AB2-1 -> 2016 | AB2: =+AC2-1 -> 2017 | AC2: =+AD2-1 -> 2018 | AD2: =+AE2-1 -> 2019 | AE2: 2020 | AF2: =+AE2+1 -> 2021 | AG2: =+AF2+1 -> 2022 | AH2: =+AG2+1 -> 2023 | AI2: =+AH2+1 -> 2024 | AJ2: =+AI2+1 -> 2025 | AK2: =+AJ2+1 -> 2026 | AL2: =+AK2+1 -> 2027 | AM2: =+AL2+1 -> 2028 | ... AP2: =+AO2+1 -> 2031
A3: Data Center | B3: =SUM(B5:B6) -> 4284 | C3: =SUM(C5:C6) -> 10323 | D3: =SUM(D5:D6) -> 14514 | E3: =SUM(E5:E6) -> 18404 | F3: =SUM(F5:F6) -> 22563 | G3: =SUM(G5:G6) -> 26272 | H3: =SUM(H5:H6) -> 30771 | I3: =SUM(I5:I6) -> 35580 | ... O3: =SUM(O5:O6) -> 89023 | Y3: 199 | Z3: 317 | AA3: 339 | AB3: 830 | AC3: 1932 | AD3: 2932 | AE3: 2983 | AF3: 6696 | AG3: 10613 | AH3: 15005 | AI3: =SUM(AI5:AI6) -> 47525 | AJ3: =SUM(AJ5:AJ6) -> 115186 | AK3: 193737
F4: =+F3/B3-1 -> 4.2668067 | G4: =+G3/C3-1 -> 1.5449966 | H4: =+H3/D3-1 -> 1.1200909 | I4: =+I3/E3-1 -> 0.93327537 | J4: =+J3/F3-1 -> 0.95284315 | K4: =+K3/G3-1 -> 0.56425091 | L4: =+L3/H3-1 -> 0.6643918 | M4: =+M3/I3-1 -> 0.75137718 | ... O4: =+O3/K3-1 -> 1.1662206
A5: Compute | B5: 3357 | C5: 8612 | D5: 11908 | E5: 15073 | F5: 19392 | G5: 22604 | H5: 27644 | I5: 32556 | J5: 39112 | K5: 33844 | L5: 43028 | M5: 51334 | N5: 60400 | O5: 48710 | AI5: =SUM(B5:E5) -> 38950 | AJ5: =SUM(F5:I5) -> 102196 | AK5: 162361
A6: Networking | B6: 927 | C6: 1711 | D6: 2606 | E6: 3331 | F6: 3171 | G6: 3668 | H6: 3127 | I6: 3024 | J6: 4950 | K6: 7252 | L6: 8187 | M6: 10980 | N6: 14800 | O6: 40313 | AI6: =SUM(B6:E6) -> 8575 | AJ6: =SUM(F6:I6) -> 12990 | AK6: =SUM(J6:M6) -> 31369
A7: % | F7: =+F6/B6-1 -> 2.420712 | G7: =+G6/C6-1 -> 1.1437756 | H7: =+H6/D6-1 -> 0.19992325 | I7: =+I6/E6-1 -> -0.092164515 | J7: =+J6/F6-1 -> 0.56102176 | K7: =+K6/G6-1 -> 0.97709924 | L7: =+L6/H6-1 -> 1.6181644 | M7: =+M6/I6-1 -> 2.6309524 | ... O7: =+O6/K6-1 -> 4.5588803 | Y7: =Y3/Y$19 -> 0.048184019 | Z7: =Z3/Z$19 -> 0.067706109 | AA7: =AA3/AA$19 -> 0.067664671 | AB7: =AB3/AB$19 -> 0.12011577 | AC7: =AC3/AC$19 -> 0.1988882 | AD7: =AD3/AD$19 -> 0.25025606 | AE7: =AE3/AE$19 -> 0.27321854 | AF7: =AF3/AF$19 -> 0.40155922 | ... AK7: =AK3/AK$19 -> 0.89718808
A8: Gaming | B8: 2240 | C8: 2486 | D8: 2856 | E8: 2865 | F8: 2647 | G8: 2880 | H8: 3279 | I8: 2544 | J8: 3763 | K8: 4287 | L8: 4265 | M8: 3727 | Y8: 1511 | Z8: 2058 | AA8: 2818 | AB8: 4060 | AC8: 5513 | AD8: 6246 | AE8: 5518 | AF8: 7759 | AG8: 12462 | AH8: 9067 | AI8: =SUM(B8:E8) -> 10447 | AJ8: =SUM(F8:I8) -> 11350 | AK8: =SUM(J8:M8) -> 16042
A9: % | F9: =+F8/B8-1 -> 0.18169643 | G9: =+G8/C8-1 -> 0.15848753 | H9: =+H8/D8-1 -> 0.14810924 | I9: =+I8/E8-1 -> -0.11204188 | J9: =+J8/F8-1 -> 0.42160937 | K9: =+K8/G8-1 -> 0.48854167 | L9: =+L8/H8-1 -> 0.30070143 | M9: =+M8/I8-1 -> 0.46501572 | Y9: =Y8/Y$19 -> 0.36585956 | Z9: =Z8/Z$19 -> 0.43955575 | AA9: =AA8/AA$19 -> 0.56247505 | AB9: =AB8/AB$19 -> 0.58755427 | AC9: =AC8/AC$19 -> 0.5675314 | AD9: =AD8/AD$19 -> 0.5331171 | AE9: =AE8/AE$19 -> 0.50540392 | AF9: =AF8/AF$19 -> 0.46530735 | ... AK9: =AK8/AK$19 -> 0.074289842
A10: Professional Vis | B10: 295 | C10: 379 | D10: 416 | E10: 463 | F10: 427 | G10: 454 | H10: 489 | I10: 511 | J10: 509 | K10: 601 | L10: 760 | M10: 1321 | Y10: 789 | Z10: 795 | AA10: 750 | AB10: 835 | AC10: 934 | AD10: 1130 | AE10: 1212 | AF10: 1053 | AG10: 2111 | AH10: 1544 | AI10: =SUM(B10:E10) -> 1553 | AJ10: 1878 | AK10: =SUM(J10:M10) -> 3191
A11: % | F11: =+F10/B10-1 -> 0.44745763 | G11: =+G10/C10-1 -> 0.19788918 | H11: =+H10/D10-1 -> 0.17548077 | I11: =+I10/E10-1 -> 0.10367171 | J11: =+J10/F10-1 -> 0.19203747 | K11: =+K10/G10-1 -> 0.32378855 | L11: =+L10/H10-1 -> 0.55419223 | M11: =+M10/I10-1 -> 1.5851272 | Y11: =Y10/Y$19 -> 0.19104116 | Z11: =Z10/Z$19 -> 0.16979923 | AA11: =AA10/AA$19 -> 0.1497006 | AB11: =AB10/AB$19 -> 0.12083936 | AC11: =AC10/AC$19 -> 0.096149887 | AD11: =AD10/AD$19 -> 0.0964493 | AE11: =AE10/AE$19 -> 0.11100934 | AF11: =AF10/AF$19 -> 0.063148426 | ... AK11: =AK10/AK$19 -> 0.01477739
A12: Auto | B12: 296 | C12: 253 | D12: 261 | E12: 281 | F12: 329 | G12: 346 | H12: 449 | I12: 570 | J12: 567 | K12: 586 | L12: 592 | M12: 604 | Y12: 99 | Z12: 183 | AA12: 320 | AB12: 487 | AC12: 558 | AD12: 641 | AE12: 700 | AF12: 536 | AG12: 566 | AH12: 903 | AI12: =SUM(B12:E12) -> 1091 | AJ12: =SUM(F12:I12) -> 1694 | AK12: =SUM(J12:M12) -> 2349
A13: % | F13: =+F12/B12-1 -> 0.11148649 | G13: =+G12/C12-1 -> 0.36758893 | H13: =+H12/D12-1 -> 0.72030651 | I13: =+I12/E12-1 -> 1.0284698 | J13: =+J12/F12-1 -> 0.72340426 | K13: =+K12/G12-1 -> 0.69364162 | L13: =+L12/H12-1 -> 0.31848552 | M13: =+M12/I12-1 -> 0.059649123 | Y13: =Y12/Y$19 -> 0.023970944 | Z13: =Z12/Z$19 -> 0.039085861 | AA13: =AA12/AA$19 -> 0.063872255 | AB13: =AB12/AB$19 -> 0.070477569 | AC13: =AC12/AC$19 -> 0.057442866 | AD13: =AD12/AD$19 -> 0.054711506 | AE13: =AE12/AE$19 -> 0.064114307 | AF13: =AF12/AF$19 -> 0.032143928 | ... AK13: =AK12/AK$19 -> 0.010878122
A14: OEM & Other | B14: 77 | C14: 66 | D14: 73 | E14: 90 | F14: 78 | G14: 88 | H14: 97 | I14: 126 | J14: 111 | K14: 173 | L14: 174 | M14: 161 | Y14: 1532 | Z14: 1329 | AA14: 783 | AB14: 698 | AC14: 777 | AD14: 767 | AE14: 505 | AF14: 631 | AG14: 1162 | AH14: 455 | AI14: =SUM(B14:E14) -> 306 | AJ14: =SUM(F14:I14) -> 389 | AK14: =SUM(J14:M14) -> 619
A15: % | F15: =+F14/B14-1 -> 0.012987013 | G15: =+G14/C14-1 -> 0.33333333 | H15: =+H14/D14-1 -> 0.32876712 | I15: =+I14/E14-1 -> 0.4 | J15: =+J14/F14-1 -> 0.42307692 | K15: =+K14/G14-1 -> 0.96590909 | L15: =+L14/H14-1 -> 0.79381443 | M15: =+M14/I14-1 -> 0.27777778 | Y15: =Y14/Y$19 -> 0.37094431 | Z15: =Z14/Z$19 -> 0.28385305 | AA15: =AA14/AA$19 -> 0.15628743 | AB15: =AB14/AB$19 -> 0.10101302 | AC15: =AC14/AC$19 -> 0.079987647 | AD15: =AD14/AD$19 -> 0.065466029 | AE15: =AE14/AE$19 -> 0.046253893 | AF15: =AF14/AF$19 -> 0.037841079 | ... AK15: =AK14/AK$19 -> 0.0028665636
A16: Edge Computing | K16: =+K14+K12+K10+K8 -> 5647 | L16: =+L14+L12+L10+L8 -> 5791 | M16: =+M14+M12+M10+M8 -> 5813 | N16: 6369 | O16: 7198
O17: =+O16/K16-1 -> 0.27465911
A19: Revenue | B19: =+B14+B12+B10+B8+B3 -> 7192 | C19: =+C14+C12+C10+C8+C3 -> 13507 | D19: =+D14+D12+D10+D8+D3 -> 18120 | E19: =+E14+E12+E10+E8+E3 -> 22103 | F19: =+F14+F12+F10+F8+F3 -> 26044 | G19: =+G14+G12+G10+G8+G3 -> 30040 | H19: =+H14+H12+H10+H8+H3 -> 35085 | I19: =+I14+I12+I10+I8+I3 -> 39331 | ... M19: =+M14+M12+M10+M8+M3 -> 68127 | N19: 81615 | O19: =+O16+O3 -> 96221 | P19: =+L19*1.9 -> 108311.4 | Q19: =+M19*1.9 -> 129441.3 | V19: 3543.309 | W19: 3997.93 | X19: 4280.159 | Y19: =+Y14+Y12+Y10+Y8+Y3 -> 4130 | Z19: =+Z14+Z12+Z10+Z8+Z3 -> 4682 | AA19: =+AA14+AA12+AA10+AA8+AA3 -> 5010 | AB19: =+AB14+AB12+AB10+AB8+AB3 -> 6910 | AC19: =+AC14+AC12+AC10+AC8+AC3 -> 9714 | AD19: =+AD14+AD12+AD10+AD8+AD3 -> 11716 | AE19: =+AE14+AE12+AE10+AE8+AE3 -> 10918 | AF19: =+AF14+AF12+AF10+AF8+AF3 -> 16675 | ... AJ19: =+AJ14+AJ12+AJ10+AJ8+AJ3 -> 130497 | AK19: 215938 | AL19: =+AK19*1.9 -> 410282.2 | AM19: =+AL19*1.8 -> 738507.96 | AN19: =+AM19*1.4 -> 1033911.1 | AO19: =+AN19*1.2 -> 1240693.4 | AP19: =+AO19*1.2 -> 1488832
F20: =+F19/B19-1 -> 2.6212458 | G20: =+G19/C19-1 -> 1.224032 | H20: =+H19/D19-1 -> 0.93625828 | I20: =+I19/E19-1 -> 0.7794417 | J20: =+J19/F19-1 -> 0.88189218 | K20: =+K19/G19-1 -> 0.5560253 | L20: =+L19/H19-1 -> 0.62479692 | M20: =+M19/I19-1 -> 0.73214513 | ... Q20: =+Q19/M19-1 -> 0.9
A21: COGS | B21: 2544 | C21: 4045 | D21: 4720 | E21: 5312 | F21: 5638 | G21: 7466 | H21: 8926 | I21: 10608 | J21: 17394 | K21: 12890 | L21: 15157 | M21: 17034 | N21: 20458 | O21: 24079 | P21: =+P19*0.25 -> 27077.85 | Q21: =+Q19*0.25 -> 32360.325 | V21: 2134.219 | W21: 1941.413 | X21: 2053.816 | Y21: 1862 | Z21: 2083 | AA21: 2199 | AB21: 2847 | AC21: 3892 | AD21: 4545 | AE21: 4150 | AF21: 6279 | AG21: 9439 | AH21: 11618 | AI21: =SUM(B21:E21) -> 16621 | AJ21: =SUM(F21:I21) -> 32638 | AK21: =SUM(J21:M21) -> 62475 | AL21: =+AL19-AL23 -> 114879.02 | AM21: =+AM19-AM23 -> 203089.69 | AN21: =+AN19-AN23 -> 279156.01 | AO21: =+AO19-AO23 -> 328783.74 | AP21: =+AP19-AP23 -> 387096.33
B22: =+B21/B$19 -> 0.35372636 | C22: =+C21/C$19 -> 0.29947435 | D22: =+D21/D$19 -> 0.26048565 | E22: =+E21/E$19 -> 0.24032937 | F22: =+F21/F$19 -> 0.2164798 | G22: =+G21/G$19 -> 0.24853529 | H22: =+H21/H$19 -> 0.25441072 | I22: =+I21/I$19 -> 0.26971092 | ... Q22: =+Q21/Q$19 -> 0.25 | V22: =+V21/V$19 -> 0.6023237 | W22: =+W21/W$19 -> 0.48560455 | X22: =+X21/X$19 -> 0.47984573 | Y22: =+Y21/Y$19 -> 0.45084746 | Z22: =+Z21/Z$19 -> 0.44489534 | AA22: =+AA21/AA$19 -> 0.43892216 | AB22: =+AB21/AB$19 -> 0.41201158 | AC22: =+AC21/AC$19 -> 0.40065884 | ... AP22: =+AP21/AP$19 -> 0.26
A23: Gross Profit | B23: =B19-B21 -> 4648 | C23: =C19-C21 -> 9462 | D23: =D19-D21 -> 13400 | E23: =E19-E21 -> 16791 | F23: =F19-F21 -> 20406 | G23: =G19-G21 -> 22574 | H23: =H19-H21 -> 26159 | I23: =I19-I21 -> 28723 | ... Q23: =Q19-Q21 -> 97080.975 | V23: =V19-V21 -> 1409.09 | W23: =W19-W21 -> 2056.517 | X23: =X19-X21 -> 2226.343 | Y23: =Y19-Y21 -> 2268 | Z23: =Z19-Z21 -> 2599 | AA23: =AA19-AA21 -> 2811 | AB23: =AB19-AB21 -> 4063 | AC23: =AC19-AC21 -> 5822 | ... AK23: =AK19-AK21 -> 153463 | AL23: =+AL19*0.72 -> 295403.18 | AM23: =+AM19*0.725 -> 535418.27 | AN23: =+AN19*0.73 -> 754755.14 | AO23: =+AO19*0.735 -> 911909.63 | AP23: =+AP19*0.74 -> 1101735.7
B24: =+B23/B$19 -> 0.64627364 | C24: =+C23/C$19 -> 0.70052565 | D24: =+D23/D$19 -> 0.73951435 | E24: =+E23/E$19 -> 0.75967063 | F24: =+F23/F$19 -> 0.7835202 | G24: =+G23/G$19 -> 0.75146471 | H24: =+H23/H$19 -> 0.74558928 | I24: =+I23/I$19 -> 0.73028908 | ... Q24: =+Q23/Q$19 -> 0.75 | V24: =+V23/V$19 -> 0.3976763 | W24: =+W23/W$19 -> 0.51439545 | X24: =+X23/X$19 -> 0.52015427 | Y24: =+Y23/Y$19 -> 0.54915254 | Z24: =+Z23/Z$19 -> 0.55510466 | AA24: =+AA23/AA$19 -> 0.56107784 | AB24: =+AB23/AB$19 -> 0.58798842 | AC24: =+AC23/AC$19 -> 0.59934116 | ... AP24: =+AP23/AP$19 -> 0.74
A25: R&D | B25: 1875 | C25: 2040 | D25: 2294 | E25: 2465 | F25: 2720 | G25: 3090 | H25: 3390 | I25: 3714 | J25: 3989 | K25: 4291 | L25: 4705 | M25: 5512 | N25: 6321 | O25: 7054 | P25: =+P19*0.07 -> 7581.798 | Q25: =+Q19*0.07 -> 9060.891 | V25: 848.83 | W25: 1002.605 | X25: 1147.282 | Y25: 1336 | Z25: 1360 | AA25: 1331 | AB25: 1463 | AC25: 1797 | AD25: 2376 | AE25: 2829 | AF25: 3924 | AG25: 5268 | AH25: 7339 | AI25: =SUM(B25:E25) -> 8674 | AJ25: =SUM(F25:I25) -> 12914 | AK25: =SUM(J25:M25) -> 18497 | AL25: =+AL19*0.1 -> 41028.22 | AM25: =+AM19*0.1 -> 73850.796 | AN25: =+AN19*0.1 -> 103391.11 | AO25: =+AO19*0.1 -> 124069.34 | AP25: =+AP19*0.1 -> 148883.2
B26: =+B25/B$19 -> 0.26070634 | C26: =+C25/C$19 -> 0.1510328 | D26: =+D25/D$19 -> 0.12660044 | E26: =+E25/E$19 -> 0.11152332 | F26: =+F25/F$19 -> 0.10443864 | G26: =+G25/G$19 -> 0.10286285 | H26: =+H25/H$19 -> 0.096622488 | I26: =+I25/I$19 -> 0.094429331 | ... Q26: =+Q25/Q$19 -> 0.07 | V26: =+V25/V$19 -> 0.23955856 | W26: =+W25/W$19 -> 0.25078103 | X26: =+X25/X$19 -> 0.26804658 | Y26: =+Y25/Y$19 -> 0.32348668 | Z26: =+Z25/Z$19 -> 0.29047416 | AA26: =+AA25/AA$19 -> 0.26566866 | AB26: =+AB25/AB$19 -> 0.21172214 | AC26: =+AC25/AC$19 -> 0.18499074 | ... AP26: =+AP25/AP$19 -> 0.1
A27: SG&A | B27: 633 | C27: 622 | D27: 689 | E27: 711 | F27: 777 | G27: 842 | H27: 897 | I27: 975 | J27: 1041 | K27: 1122 | L27: 1134 | M27: 1282 | N27: 1300 | O27: 1354 | P27: =+P19*0.015 -> 1624.671 | Q27: =+Q19*0.015 -> 1941.6195 | V27: =+361.513-57 -> 304.513 | W27: 405.613 | X27: 430.822 | Y27: 436 | Z27: 480 | AA27: =+602+131 -> 733 | AB27: =+663+3 -> 666 | AC27: 815 | AD27: 991 | AE27: 1093 | AF27: 1940 | AG27: 2166 | AH27: =+2440+1353 -> 3793 | AI27: =SUM(B27:E27) -> 2655 | AJ27: =SUM(F27:I27) -> 3491 | AK27: =SUM(J27:M27) -> 4579 | AL27: =+AL19*0.02 -> 8205.644 | AM27: =+AM19*0.02 -> 14770.159 | AN27: =+AN19*0.02 -> 20678.223 | AO27: =+AO19*0.02 -> 24813.867 | AP27: =+AP19*0.02 -> 29776.641
B28: =+B27/B$19 -> 0.088014461 | C28: =+C27/C$19 -> 0.046050196 | D28: =+D27/D$19 -> 0.038024283 | E28: =+E27/E$19 -> 0.032167579 | F28: =+F27/F$19 -> 0.029834127 | G28: =+G27/G$19 -> 0.028029294 | H28: =+H27/H$19 -> 0.025566481 | I28: =+I27/I$19 -> 0.024789606 | ... Q28: =+Q27/Q$19 -> 0.015 | V28: =+V27/V$19 -> 0.085940289 | W28: =+W27/W$19 -> 0.10145575 | X28: =+X27/X$19 -> 0.10065561 | Y28: =+Y27/Y$19 -> 0.10556901 | Z28: =+Z27/Z$19 -> 0.10252029 | AA28: =+AA27/AA$19 -> 0.14630739 | AB28: =+AB27/AB$19 -> 0.096382055 | AC28: =+AC27/AC$19 -> 0.083899526 | ... AP28: =+AP27/AP$19 -> 0.02
A29: Op Exp | B29: =+B27+B25 -> 2508 | C29: =+C27+C25 -> 2662 | D29: =+D27+D25 -> 2983 | E29: =+E27+E25 -> 3176 | F29: =+F27+F25 -> 3497 | G29: =+G27+G25 -> 3932 | H29: =+H27+H25 -> 4287 | I29: =+I27+I25 -> 4689 | ... Q29: =+Q27+Q25 -> 11002.511 | V29: =+V27+V25 -> 1153.343 | W29: =+W27+W25 -> 1408.218 | X29: =+X27+X25 -> 1578.104 | Y29: =+Y27+Y25 -> 1772 | Z29: =+Z27+Z25 -> 1840 | AA29: =+AA27+AA25 -> 2064 | AB29: =+AB27+AB25 -> 2129 | AC29: =+AC27+AC25 -> 2612 | ... AP29: =+AP27+AP25 -> 178659.85
B30: =+B29/B$19 -> 0.3487208 | C30: =+C29/C$19 -> 0.19708299 | D30: =+D29/D$19 -> 0.16462472 | E30: =+E29/E$19 -> 0.1436909 | F30: =+F29/F$19 -> 0.13427277 | G30: =+G29/G$19 -> 0.13089214 | H30: =+H29/H$19 -> 0.12218897 | I30: =+I29/I$19 -> 0.11921894 | ... Q30: =+Q29/Q$19 -> 0.085 | V30: =+V29/V$19 -> 0.32549885 | W30: =+W29/W$19 -> 0.35223678 | X30: =+X29/X$19 -> 0.36870219 | Y30: =+Y29/Y$19 -> 0.42905569 | Z30: =+Z29/Z$19 -> 0.39299445 | AA30: =+AA29/AA$19 -> 0.41197605 | AB30: =+AB29/AB$19 -> 0.3081042 | AC30: =+AC29/AC$19 -> 0.26889026 | ... AP30: =+AP29/AP$19 -> 0.12
A31: Op Inc | B31: =B23-B29 -> 2140 | C31: =C23-C29 -> 6800 | D31: =D23-D29 -> 10417 | E31: =E23-E29 -> 13615 | F31: =F23-F29 -> 16909 | G31: =G23-G29 -> 18642 | H31: =H23-H29 -> 21872 | I31: =I23-I29 -> 24034 | ... Q31: =Q23-Q29 -> 86078.465 | V31: =V23-V29 -> 255.747 | W31: =W23-W29 -> 648.299 | X31: =X23-X29 -> 648.239 | Y31: =Y23-Y29 -> 496 | Z31: =Z23-Z29 -> 759 | AA31: =AA23-AA29 -> 747 | AB31: =AB23-AB29 -> 1934 | AC31: =AC23-AC29 -> 3210 | ... AP31: =AP23-AP29 -> 923075.87
B32: =+B31/B$19 -> 0.29755284 | C32: =+C31/C$19 -> 0.50344266 | D32: =+D31/D$19 -> 0.57488962 | E32: =+E31/E$19 -> 0.61597973 | F32: =+F31/F$19 -> 0.64924743 | G32: =+G31/G$19 -> 0.62057257 | H32: =+H31/H$19 -> 0.62340031 | I32: =+I31/I$19 -> 0.61107015 | ... Q32: =+Q31/Q$19 -> 0.665 | V32: =+V31/V$19 -> 0.072177448 | W32: =+W31/W$19 -> 0.16215867 | X32: =+X31/X$19 -> 0.15145208 | Y32: =+Y31/Y$19 -> 0.12009685 | Z32: =+Z31/Z$19 -> 0.16211021 | AA32: =+AA31/AA$19 -> 0.1491018 | AB32: =+AB31/AB$19 -> 0.27988423 | AC32: =+AC31/AC$19 -> 0.3304509 | ... AP32: =+AP31/AP$19 -> 0.62
A33: Int Income | B33: 150 | C33: 187 | D33: 234 | E33: 294 | F33: 359 | G33: 444 | H33: 472 | I33: 511 | J33: 515 | K33: 592 | L33: 624 | M33: 568 | N33: 540 | V33: 19.057 | W33: 19.149 | X33: 19.908 | Y33: 17 | Z33: 28 | AA33: 39 | AB33: 54 | AC33: 69 | AD33: 136 | AE33: 178 | AF33: 57 | AG33: 29 | AH33: 267 | AI33: =SUM(B33:E33) -> 865 | AJ33: =SUM(F33:I33) -> 1786 | AK33: =SUM(J33:M33) -> 2299 | AL33: =+AL19*0.01 -> 4102.822 | AM33: =+AM19*0.01 -> 7385.0796 | AN33: =+AN19*0.01 -> 10339.111 | AO33: =+AO19*0.01 -> 12406.934 | AP33: =+AP19*0.01 -> 14888.32
B34: =+B33/B$19 -> 0.020856507 | C34: =+C33/C$19 -> 0.013844673 | D34: =+D33/D$19 -> 0.012913907 | E34: =+E33/E$19 -> 0.013301362 | F34: =+F33/F$19 -> 0.013784365 | G34: =+G33/G$19 -> 0.014780293 | H34: =+H33/H$19 -> 0.013453043 | I34: =+I33/I$19 -> 0.012992296 | ... N34: =+N33/N$19 -> 0.0066164308 | V34: =+V33/V$19 -> 0.005378306 | W34: =+W33/W$19 -> 0.0047897287 | X34: =+X33/X$19 -> 0.0046512291 | Y34: =+Y33/Y$19 -> 0.0041162228 | Z34: =+Z33/Z$19 -> 0.0059803503 | AA34: =+AA33/AA$19 -> 0.0077844311 | AB34: =+AB33/AB$19 -> 0.0078147612 | AC34: =+AC33/AC$19 -> 0.0071031501 | ... AP34: =+AP33/AP$19 -> 0.01
A35: Int Exp | B35: -66 | C35: -65 | D35: -63 | E35: -63 | F35: -64 | G35: -61 | H35: -61 | I35: -61 | J35: -63 | K35: -62 | L35: -61 | M35: -74 | N35: -102 | V35: -3.127 | W35: -3.089 | X35: -3.294 | Y35: -10 | Z35: -46 | AA35: -47 | AB35: -58 | AC35: -61 | AD35: -58 | AE35: -52 | AF35: -184 | AG35: -236 | AH35: -262 | AI35: =SUM(B35:E35) -> -257 | AJ35: =SUM(F35:I35) -> -247 | AK35: =SUM(J35:M35) -> -260 | AL35: -300 | AM35: -300 | AN35: -300 | AO35: -300 | AP35: -300
B36: =+B35/B$19 -> -0.0091768632 | C36: =+C35/C$19 -> -0.0048123195 | D36: =+D35/D$19 -> -0.0034768212 | E36: =+E35/E$19 -> -0.0028502918 | F36: =+F35/F$19 -> -0.0024573798 | G36: =+G35/G$19 -> -0.0020306258 | H36: =+H35/H$19 -> -0.0017386347 | I36: =+I35/I$19 -> -0.0015509395 | ... N36: =+N35/N$19 -> -0.0012497703 | V36: =+V35/V$19 -> -0.00088250841 | W36: =+W35/W$19 -> -0.00077264985 | X36: =+X35/X$19 -> -0.00076959758 | Y36: =+Y35/Y$19 -> -0.0024213075 | Z36: =+Z35/Z$19 -> -0.0098248612 | AA36: =+AA35/AA$19 -> -0.0093812375 | AB36: =+AB35/AB$19 -> -0.0083936324 | AC36: =+AC35/AC$19 -> -0.0062795965 | ... AP36: =+AP35/AP$19 -> -0.00020150023
A37: Other Income | B37: -15 | C37: 59 | D37: -66 | E37: 260 | F37: 75 | G37: 189 | H37: 36 | I37: 733 | J37: -180 | K37: 2236 | L37: 1363 | M37: 5604 | N37: 15929 | O37: 7773 | P37: =+P19*0.08 -> 8664.912 | Q37: =+Q19*0.08 -> 10355.304 | V37: -0.508 | W37: -0.963 | X37: -2.814 | Y37: 7 | Z37: 14 | AA37: 4 | AB37: -25 | AC37: -22 | AD37: 14 | AE37: -2 | AF37: 4 | AG37: 107 | AH37: -48 | AI37: =SUM(B37:E37) -> 238 | AJ37: =SUM(F37:I37) -> 1033 | AK37: =SUM(J37:M37) -> 9023 | AL37: 30000 | AM37: =+AM19*0.01 -> 7385.0796 | AN37: =+AN19*0.01 -> 10339.111 | AO37: =+AO19*0.01 -> 12406.934 | AP37: =+AP19*0.01 -> 14888.32
B38: =+B37/B$19 -> -0.0020856507 | C38: =+C37/C$19 -> 0.0043681054 | D38: =+D37/D$19 -> -0.0036423841 | E38: =+E37/E$19 -> 0.011763109 | F38: =+F37/F$19 -> 0.002879742 | G38: =+G37/G$19 -> 0.0062916112 | H38: =+H37/H$19 -> 0.0010260795 | I38: =+I37/I$19 -> 0.018636699 | ... Q38: =+Q37/Q$19 -> 0.08 | V38: =+V37/V$19 -> -0.00014336881 | W38: =+W37/W$19 -> -0.00024087465 | X38: =+X37/X$19 -> -0.00065745221 | Y38: =+Y37/Y$19 -> 0.0016949153 | Z38: =+Z37/Z$19 -> 0.0029901751 | AA38: =+AA37/AA$19 -> 0.00079840319 | AB38: =+AB37/AB$19 -> -0.003617945 | AC38: =+AC37/AC$19 -> -0.0022647725 | ... AP38: =+AP37/AP$19 -> 0.01
A39: Pretax | B39: =SUM(B31:B37) -> 2209.3092 | C39: =SUM(C31:C37) -> 6981.5125 | D39: =SUM(D31:D37) -> 10522.584 | E39: =SUM(E31:E37) -> 14106.626 | F39: =SUM(F31:F37) -> 17279.661 | G39: =SUM(G31:G37) -> 19214.633 | H39: =SUM(H31:H37) -> 22319.635 | I39: =SUM(I31:I37) -> 25217.623 | ... Q39: =SUM(Q31:Q37) -> 96434.433 | V39: =SUM(V31:V37)-V32-V34-V36 -> 271.169 | W39: =SUM(W31:W37)-W32-W34-W36 -> 663.396 | X39: =SUM(X31:X37)-X32-X34-X36 -> 662.039 | Y39: =SUM(Y31:Y37)-Y32-Y34-Y36 -> 510 | Z39: =SUM(Z31:Z37)-Z32-Z34-Z36 -> 755 | AA39: =SUM(AA31:AA37)-AA32-AA34-AA36 -> 743 | AB39: =SUM(AB31:AB37)-AB32-AB34-AB36 -> 1905 | AC39: =SUM(AC31:AC37)-AC32-AC34-AC36 -> 3196 | ... AP39: =SUM(AP31:AP37)-AP32-AP34-AP36 -> 952552.51
B40: =+B39/B$19 -> 0.30718983 | C40: =+C39/C$19 -> 0.51688106 | D40: =+D39/D$19 -> 0.58071657 | E40: =+E39/E$19 -> 0.63822225 | F40: =+F39/F$19 -> 0.66347952 | G40: =+G39/G$19 -> 0.63963493 | H40: =+H39/H$19 -> 0.6361589 | I40: =+I39/I$19 -> 0.64116403 | ... Q40: =+Q39/Q$19 -> 0.74500514 | V40: =+V39/V$19 -> 0.076529876 | W40: =+W39/W$19 -> 0.16593487 | X40: =+X39/X$19 -> 0.15467626 | Y40: =+Y39/Y$19 -> 0.12348668 | Z40: =+Z39/Z$19 -> 0.16125587 | AA40: =+AA39/AA$19 -> 0.14830339 | AB40: =+AB39/AB$19 -> 0.27568741 | AC40: =+AC39/AC$19 -> 0.32900968 | ... AP40: =+AP39/AP$19 -> 0.6397985
A41: Tax | B41: 166 | C41: 793 | D41: 1279 | E41: 1821 | F41: 2398 | G41: 2615 | H41: 3007 | I41: 3126 | J41: 3135 | K41: 4784 | L41: 6026 | M41: 7437 | N41: 11582 | O41: 11819 | V41: 18.023 | W41: 82.306 | X41: 99.503 | Y41: 70 | Z41: 124 | AA41: 129 | AB41: 239 | AC41: 149 | AD41: -245 | AE41: 174 | AF41: 77 | AG41: 189 | AH41: -187 | AI41: =SUM(B41:E41) -> 4059 | AJ41: =SUM(F41:I41) -> 11146 | AK41: =SUM(J41:M41) -> 21382 | AL41: =+AL39*0.13 -> 36396.378 | AM41: =+AM39*0.13 -> 59964.772 | AN41: =+AN39*0.13 -> 84638.323 | AO41: =+AO39*0.13 -> 102380.24 | AP41: =+AP39*0.13 -> 123831.83
...

Sheet Bond
A1: Main
B4: isin | C4: immediateIssuer | D4: coupon | E4: couponType | F4: maturityDate | G4: callable | H4: currency
B5: US67066GAE44 | C5: NVIDIA Corporation | D5: 3200 | E5: Fixed Listing | F5: 16/09/2026 | G5: Y | H5: USD
B6: US67066GAM69 | C6: NVIDIA Corporation | D6: 1550 | E6: Fixed Listing | F6: 15/06/2028 | G6: Y | H6: USD
B7: US67066GAF19 | C7: NVIDIA Corporation | D7: 2850 | E7: Fixed Listing | F7: 01/04/2030 | G7: Y | H7: USD
B8: US67066GAN43 | C8: NVIDIA Corporation | D8: 2000 | E8: Fixed Listing | F8: 15/06/2031 | G8: Y | H8: USD
B9: US67066GAG91 | C9: NVIDIA Corporation | D9: 3500 | E9: Fixed Listing | F9: 01/04/2040 | G9: Y | H9: USD
B10: US67066GAH74 | C10: NVIDIA Corporation | D10: 3500 | E10: Fixed Listing | F10: 01/04/2050 | G10: Y | H10: USD
B11: US67066GAJ31 | C11: NVIDIA Corporation | D11: 3700 | E11: Fixed Listing | F11: 01/04/2060 | G11: Y | H11: USD
D12: =AVERAGE(D5:D11) -> 2900

Sheet Board
A1: Main
