Workbook

Sheet Main
A1: Spotify Technologies S.A. | E1: Price | F1: 485
E2: Share | F2: 209.28045 | G2: Q425
E3: MC | F3: =F1*F2 -> 101501.02
B4: Beta | C4: 1.02 | E4: Cash | F4: =+5314+3491 -> 8805 | G4: Q126
E5: Debt | F5: 414 | G5: Q126
E6: EV | F6: =F3-F4+F5 -> 93110.018
F7: =F6/17186 -> 5.4177829
A9: CAPM | B9: =0.04+(C4*(0.1-0.04)) -> 0.1012 | D9: WACC | E9: =+(F3/(F3+F5))*B9+(F5/(F5+F3))*B10*(1-Model!R68) -> 0.1009541
A10: Cost of Debt | B10: =+0.045 + (B17/100) -> 0.052847826
A11: Incremental Margin TTM | B11: =((Model!S46+Model!R46+Model!Q46+Model!P46)-(Model!O46+Model!N46+Model!M46+Model!L46))/((Model!S28+Model!R28+Model!Q28+Model!P28)-(Model!O28+Model!N28+Model!M28+Model!L28)) -> 0.5378799
A12: Leverage | B12: =(F5-F4)/Model!S70 -> -12.267544
A13: EV/FCF (TTM) | B13: =+F6/SUM(Model!P144:S144) -> 28.552597
A14: EV/FCF (FFCF) | B14: =$F$6/(SUM(Model!Q144:T144)) -> 27.207649
A15: P/FCF | B15: =+F3/SUM(Model!Q144:T144) -> 29.659581
A16: EV/EBITDA | B16: =+F6/SUM(Model!P70:S70) -> 33.768888
A17: Cr. Spread | B17: =+'[1]Credit Spread US'!J6 -> 0.78478261
A18: Rating | B18: N.A. | C18: N.A.
B19: S&P | C19: Moody’s
A21: ir@spotify.com
A22: Founder and CEO | B22: Daniel Ek | C22: Holds 13 % | J22: Management
A23: Tencent holds 8 % | K23: -> | L23: Approached AI in 2021
B25: -> | C25: ChatGPT integration
C26: Use of AI for algorithm and playlist → increase engagement?
C27: -> | D27: Prompted end of year wrapped (boosted Q4 2025 subs and earnings)
A30: Sector | B30: “Audio Streaming”
A37: Plans | B37: Ad-Supported | C37: Music and Audiobook with Ad break
B38: Basic | C38: Ad Supported account with certain Premium features ???
B39: Audiobook Access | C39: Only with Audiobooks without ads, music with ads
B40: Premium | C40: Audiobook and Music without ad break | G40: -> | H40: Mainly sold to end users and businesses that sell the service in bundle with their own service
B41: Standard
B42: Family
B43: Duo
B44: Student
A46: Seasonality | B46: There is no clear seasonality for the Premium revenues
B47: There is seasonality in the Ad-Supported accounts since in the 4th quarter there is a higher demand for advertisement due to the holiday season.
B48: During the 1st quarter there is a lower demand for ADV
B49: In 4th quarter there is also the Spotify Wrapper (which has a big social appeal). On top of that, there are also Christmas Gifts
A54: Revenues | B54: 88% of revenues is dependant on Premium subscriptions
B55: -> | C55: which is a fixed income for the firm
B56: -> | C56: every month has 281 people paying on avg $4.53
...

Sheet Model
A1: Main
A2: in Millions | B2: Q122 | C2: Q222 | D2: Q322 | E2: Q422 | F2: Q123 | G2: Q223 | H2: Q323 | I2: Q423 | J2: Q124 | K2: Q224 | L2: Q324 | M2: Q424 | N2: Q125 | O2: Q225 | P2: Q325 | Q2: Q425 | R2: Q126 | S2: Q226 | T2: Q326 | U2: Q426 | AA2: 2019 | AB2: 2020 | AC2: =AB2+1 -> 2021 | AD2: =AC2+1 -> 2022 | AE2: =AD2+1 -> 2023 | AF2: =AE2+1 -> 2024 | AG2: =AF2+1 -> 2025 | AH2: =AG2+1 -> 2026 | AI2: =AH2+1 -> 2027 | AJ2: =AI2+1 -> 2028 | ... AQ2: =AP2+1 -> 2035
A3: Streamed Hours | AE3: =AF3*0.85 -> 161500 | AF3: 190000
AF4: =+AF3/AE3-1 -> 0.17647059
A6: MAU | B6: 422 | C6: 433 | D6: 456 | E6: 489 | F6: 515 | G6: 551 | H6: 574 | I6: 602 | J6: 615 | K6: 626 | L6: 640 | M6: 675 | N6: 678 | O6: 696 | P6: 713 | Q6: 751 | R6: 761 | S6: 777 | AA6: 271 | AB6: 345 | AC6: 406 | AD6: 489 | AE6: 602 | AF6: 675 | AG6: 751 | AH6: 759
F7: =+F6/B6-1 -> 0.22037915 | G7: =+G6/C6-1 -> 0.27251732 | H7: =+H6/D6-1 -> 0.25877193 | I7: =+I6/E6-1 -> 0.23108384 | J7: =+J6/F6-1 -> 0.19417476 | K7: =+K6/G6-1 -> 0.13611615 | L7: =+L6/H6-1 -> 0.11498258 | M7: =+M6/I6-1 -> 0.12126246 | ... S7: =+S6/O6-1 -> 0.11637931 | AB7: =+AB6/AA6-1 -> 0.27306273 | AC7: =+AC6/AB6-1 -> 0.17681159 | AD7: =+AD6/AC6-1 -> 0.2044335 | AE7: =+AE6/AD6-1 -> 0.23108384 | AF7: =+AF6/AE6-1 -> 0.12126246 | AG7: =+AG6/AF6-1 -> 0.11259259 | AH7: =+AH6/AG6-1 -> 0.010652463
A8: Premium Subs | B8: 182 | C8: 188 | D8: 195 | E8: 205 | F8: 210 | G8: 220 | H8: 226 | I8: 236 | J8: 239 | K8: 246 | L8: 252 | M8: 263 | N8: 268 | O8: 276 | P8: 281 | Q8: 290 | R8: 293 | S8: 300 | AA8: 124 | AB8: 155 | AC8: 180 | AD8: 205 | AE8: 236 | AF8: 263 | AG8: =Q8 -> 290 | AH8: =+AG8+3 -> 293
F9: =+F8/B8-1 -> 0.15384615 | G9: =+G8/C8-1 -> 0.17021277 | H9: =+H8/D8-1 -> 0.15897436 | I9: =+I8/E8-1 -> 0.15121951 | J9: =+J8/F8-1 -> 0.13809524 | K9: =+K8/G8-1 -> 0.11818182 | L9: =+L8/H8-1 -> 0.11504425 | M9: =+M8/I8-1 -> 0.11440678 | ... S9: =+S8/O8-1 -> 0.086956522 | AB9: =+AB8/AA8-1 -> 0.25 | AC9: =+AC8/AB8-1 -> 0.16129032 | AD9: =+AD8/AC8-1 -> 0.13888889 | AE9: =+AE8/AD8-1 -> 0.15121951 | AF9: =+AF8/AE8-1 -> 0.11440678 | AG9: =+AG8/AF8-1 -> 0.1026616 | AH9: =+AH8/AG8-1 -> 0.010344828
A10: Premium ARPU | B10: 4.38 | C10: 4.54 | D10: 4.63 | E10: 4.55 | F10: 4.32 | G10: 4.27 | H10: 4.34 | I10: 4.6 | J10: 4.55 | K10: 4.62 | L10: 4.71 | M10: 4.85 | N10: 4.73 | O10: 4.57 | P10: 4.53 | Q10: 4.7 | R10: 4.76 | S10: 4.89 | AA10: 4.72 | AB10: 4.31 | AC10: 4.29 | AD10: 4.52 | AE10: 4.39 | AF10: 4.69 | AG10: =Q10 -> 4.7 | AH10: =+AG10*1.06 -> 4.982
F11: =+F10/B10-1 -> -0.01369863 | G11: =+G10/C10-1 -> -0.059471366 | H11: =+H10/D10-1 -> -0.062634989 | I11: =+I10/E10-1 -> 0.010989011 | J11: =+J10/F10-1 -> 0.053240741 | K11: =+K10/G10-1 -> 0.081967213 | L11: =+L10/H10-1 -> 0.085253456 | M11: =+M10/I10-1 -> 0.054347826 | ... S11: =+S10/O10-1 -> 0.070021882 | AB11: =+AB10/AA10-1 -> -0.086864407 | AC11: =+AC10/AB10-1 -> -0.0046403712 | AD11: =+AD10/AC10-1 -> 0.053613054 | AE11: =+AE10/AD10-1 -> -0.028761062 | AF11: =+AF10/AE10-1 -> 0.06833713 | AG11: =+AG10/AF10-1 -> 0.0021321962 | AH11: =+AH10/AG10-1 -> 0.06
A12: Ad-Sup MAU | B12: 252 | C12: 256 | D12: 273 | E12: 295 | F12: 317 | G12: 343 | H12: 361 | I12: 379 | J12: 388 | K12: 393 | L12: 402 | M12: 425 | N12: 423 | O12: 433 | P12: 446 | Q12: 476 | R12: 483 | S12: 494 | AA12: 153 | AB12: 199 | AC12: 236 | AD12: 295 | AE12: 379 | AF12: 425 | AG12: =Q12 -> 476
F13: =+F12/B12-1 -> 0.25793651 | G13: =+G12/C12-1 -> 0.33984375 | H13: =+H12/D12-1 -> 0.32234432 | I13: =+I12/E12-1 -> 0.28474576 | J13: =+J12/F12-1 -> 0.22397476 | K13: =+K12/G12-1 -> 0.14577259 | L13: =+L12/H12-1 -> 0.11357341 | M13: =+M12/I12-1 -> 0.12137203 | ... S13: =+S12/O12-1 -> 0.1408776 | AB13: =+AB12/AA12-1 -> 0.30065359 | AC13: =+AC12/AB12-1 -> 0.18592965 | AD13: =+AD12/AC12-1 -> 0.25 | AE13: =+AE12/AD12-1 -> 0.28474576 | AF13: =+AF12/AE12-1 -> 0.12137203 | AG13: =+AG12/AF12-1 -> 0.12
A15: Premium % | B15: =B8/B6 -> 0.43127962 | C15: =C8/C6 -> 0.43418014 | D15: =D8/D6 -> 0.42763158 | E15: =E8/E6 -> 0.4192229 | F15: =F8/F6 -> 0.40776699 | G15: =G8/G6 -> 0.39927405 | H15: =H8/H6 -> 0.39372822 | I15: =I8/I6 -> 0.39202658 | ... S15: =S8/S6 -> 0.38610039 | AA15: =AA8/AA6 -> 0.45756458 | AB15: =AB8/AB6 -> 0.44927536 | AC15: =AC8/AC6 -> 0.44334975 | AD15: =AD8/AD6 -> 0.4192229 | AE15: =AE8/AE6 -> 0.39202658 | AF15: =AF8/AF6 -> 0.38962963 | AG15: =AG8/AG6 -> 0.3861518
F16: =+F15/B15-1 -> -0.054518297 | G16: =+G15/C15-1 -> -0.080395413 | H16: =+H15/D15-1 -> -0.079281694 | I16: =+I15/E15-1 -> -0.064873187 | J16: =+J15/F15-1 -> -0.046960898 | K16: =+K15/G15-1 -> -0.015785652 | L16: =+L15/H15-1 -> 5.5309735e-05 | M16: =+M15/I15-1 -> -0.0061142498 | ... S16: =+S15/O15-1 -> -0.026355548 | AB16: =+AB15/AA15-1 -> -0.018115942 | AC16: =+AC15/AB15-1 -> -0.013189258 | AD16: =+AD15/AC15-1 -> -0.05441945 | AE16: =+AE15/AD15-1 -> -0.064873187 | AF16: =+AF15/AE15-1 -> -0.0061142498 | AG16: =+AG15/AF15-1 -> -0.0089259947
A17: ARPU | B17: =B28/B6 -> 6.3056872 | C17: =C28/C6 -> 6.6143187 | D17: =D28/D6 -> 6.6578947 | E17: =E28/E6 -> 6.4744376 | F17: =F28/F6 -> 5.9070687 | G17: =G28/G6 -> 5.7660752 | H17: =H28/H6 -> 5.8486023 | I17: =I28/I6 -> 6.0982836 | ... S17: =S28/S6 -> 6.1480051 | AA17: =AA28/AA6 -> 24.95941 | AB17: =AB28/AB6 -> 22.841079 | AC17: =AC28/AC6 -> 23.813265 | AD17: =AD28/AD6 -> 23.982028 | AE17: =AE28/AE6 -> 22.005196 | AF17: =AF28/AF6 -> 23.219548 | AG17: =AG28/AG6 -> 22.884306
F18: =+F17/B17-1 -> -0.063215707 | G18: =+G17/C17-1 -> -0.12824352 | H18: =+H17/D17-1 -> -0.12155381 | I18: =+I17/E17-1 -> -0.058098332 | J18: =+J17/F17-1 -> 0.00092202118 | K18: =+K17/G17-1 -> 0.054756038 | L18: =+L17/H17-1 -> 0.065481137 | M18: =+M17/I17-1 -> 0.03056776 | ... S18: =+S17/O17-1 -> 0.02048394 | AB18: =+AB17/AA17-1 -> -0.084871009 | AC18: =+AC17/AB17-1 -> 0.042563049 | AD18: =+AD17/AC17-1 -> 0.0070869214 | AE18: =+AE17/AD17-1 -> -0.082429707 | AF18: =+AF17/AE17-1 -> 0.055184755 | AG18: =+AG17/AF17-1 -> -0.014437917
A19: CPU | B19: =B34/B6 -> 4.7156398 | C19: =C34/C6 -> 4.9884527 | D19: =D34/D6 -> 5.0131579 | E19: =E34/E6 -> 4.8364008 | F19: =F34/F6 -> 4.4194175 | G19: =G34/G6 -> 4.3756806 | H19: =H34/H6 -> 4.3066202 | I19: =I34/I6 -> 4.4700997 | ... S19: =S34/S6 -> 4.0939511 | AA19: =AA34/AA6 -> 18.605166 | AB19: =AB34/AB6 -> 17 | AC19: =AC34/AC6 -> 17.431034 | AD19: =AD34/AD6 -> 17.997955 | AE19: =AE34/AE6 -> 16.362126 | AF19: =AF34/AF6 -> 16.220741 | AG19: =AG34/AG6 -> 15.565912
F20: =+F19/B19-1 -> -0.062816998 | G20: =+G19/C19-1 -> -0.12283811 | H20: =+H19/D19-1 -> -0.14093665 | I20: =+I19/E19-1 -> -0.075738377 | J20: =+J19/F19-1 -> -0.031620158 | K20: =+K19/G19-1 -> -0.016127493 | L20: =+L19/H19-1 -> -0.0029884709 | M20: =+M19/I19-1 -> -0.047498245 | ... S20: =+S19/O19-1 -> -0.0082179041 | AB20: =+AB19/AA19-1 -> -0.086275288 | AC20: =+AC19/AB19-1 -> 0.02535497 | AD20: =+AD19/AC19-1 -> 0.032523631 | AE20: =+AE19/AD19-1 -> -0.090889702 | AF20: =+AF19/AE19-1 -> -0.0086410227 | AG20: =+AG19/AF19-1 -> -0.040369835
A21: PPU | B21: =B17-B19 -> 1.5900474 | C21: =C17-C19 -> 1.6258661 | D21: =D17-D19 -> 1.6447368 | E21: =E17-E19 -> 1.6380368 | F21: =F17-F19 -> 1.4876513 | G21: =G17-G19 -> 1.3903946 | H21: =H17-H19 -> 1.5419821 | I21: =I17-I19 -> 1.6281839 | ... S21: =S17-S19 -> 2.0540541 | AA21: =AA17-AA19 -> 6.3542435 | AB21: =AB17-AB19 -> 5.8410793 | AC21: =AC17-AC19 -> 6.3822308 | AD21: =AD17-AD19 -> 5.984073 | AE21: =AE17-AE19 -> 5.6430702 | AF21: =AF17-AF19 -> 6.9988071 | AG21: =AG17-AG19 -> 7.3183938
F22: =+F21/B21-1 -> -0.064398169 | G22: =+G21/C21-1 -> -0.14482832 | H22: =+H21/D21-1 -> -0.062474911 | I22: =+I21/E21-1 -> -0.0060150518 | J22: =+J21/F21-1 -> 0.097596208 | K22: =+K21/G21-1 -> 0.27783205 | L22: =+L21/H21-1 -> 0.25671073 | M22: =+M21/I21-1 -> 0.24489418 | ... S22: =+S21/O21-1 -> 0.082948263 | AB22: =+AB21/AA21-1 -> -0.080759295 | AC22: =+AC21/AB21-1 -> 0.092645804 | AD22: =+AD21/AC21-1 -> -0.062385363 | AE22: =+AE21/AD21-1 -> -0.056985063 | AF22: =+AF21/AE21-1 -> 0.24024809 | AG22: =+AG21/AF21-1 -> 0.045663026
A24: Premium | B24: 2379 | C24: 2504 | D24: 2651 | E24: =AD24-D24-C24-B24 -> 2717 | F24: 2713 | G24: 2773 | H24: 2910 | I24: 3170 | J24: 3247 | K24: 3351 | L24: 3516 | M24: 3705 | N24: 3783 | O24: 3753 | P24: 3835 | Q24: 4020 | R24: 4148 | AA24: 6086 | AB24: 7135 | AC24: 8460 | AD24: 10251 | AE24: 11566 | AF24: 13819 | AG24: =SUM(N24:Q24) -> 15391
F25: =+F24/B24-1 -> 0.14039512 | G25: =+G24/C24-1 -> 0.10742812 | H25: =+H24/D24-1 -> 0.097698982 | I25: =+I24/E24-1 -> 0.16672801 | J25: =+J24/F24-1 -> 0.19683008 | K25: =+K24/G24-1 -> 0.20843851 | L25: =+L24/H24-1 -> 0.20824742 | M25: =+M24/I24-1 -> 0.16876972 | ... S25: =+S24/O24-1 -> -1 | AB25: =+AB24/AA24-1 -> 0.1723628 | AC25: =+AC24/AB24-1 -> 0.18570427 | AD25: =+AD24/AC24-1 -> 0.21170213 | AE25: =+AE24/AD24-1 -> 0.12828017 | AF25: =+AF24/AE24-1 -> 0.19479509 | AG25: =+AG24/AF24-1 -> 0.11375642
A26: Ad-Sup | B26: 282 | C26: 360 | D26: 385 | E26: =AD26-D26-C26-B26 -> 449 | F26: 329 | G26: 404 | H26: 447 | I26: 501 | J26: 389 | K26: 456 | L26: 472 | M26: 537 | N26: 407 | O26: 440 | P26: 437 | Q26: 511 | R26: 385 | AA26: 678 | AB26: 745 | AC26: 1208 | AD26: 1476 | AE26: 1681 | AF26: 1854 | AG26: =SUM(N26:Q26) -> 1795
F27: =+F26/B26-1 -> 0.16666667 | G27: =+G26/C26-1 -> 0.12222222 | H27: =+H26/D26-1 -> 0.16103896 | I27: =+I26/E26-1 -> 0.11581292 | J27: =+J26/F26-1 -> 0.18237082 | K27: =+K26/G26-1 -> 0.12871287 | L27: =+L26/H26-1 -> 0.055928412 | M27: =+M26/I26-1 -> 0.071856287 | ... S27: =+S26/O26-1 -> -1 | AB27: =+AB26/AA26-1 -> 0.098820059 | AC27: =+AC26/AB26-1 -> 0.62147651 | AD27: =+AD26/AC26-1 -> 0.2218543 | AE27: =+AE26/AD26-1 -> 0.13888889 | AF27: =+AF26/AE26-1 -> 0.10291493 | AG27: =+AG26/AF26-1 -> -0.031823085
A28: Revenue | B28: =SUM(B24:B26) -> 2661 | C28: =SUM(C24:C26) -> 2864 | D28: =SUM(D24:D26) -> 3036 | E28: 3166 | F28: =SUM(F24:F26) -> 3042.1404 | G28: =SUM(G24:G26) -> 3177.1074 | H28: =SUM(H24:H26) -> 3357.0977 | I28: =SUM(I24:I26) -> 3671.1667 | J28: =SUM(J24:J26) -> 3636.1968 | K28: =SUM(K24:K26) -> 3807.2084 | L28: =SUM(L24:L26) -> 3988.2082 | M28: =SUM(M24:M26) -> 4242.1688 | ... R28: =SUM(R24:R26) -> 4533.0965 | S28: 4777 | T28: =+P28*1.145 -> 4891.5439 | U28: =+Q28*1.145 -> 5188.0923 | AA28: =SUM(AA24:AA26) -> 6764 | AB28: =SUM(AB24:AB26) -> 7880.1724 | AC28: =SUM(AC24:AC26) -> 9668.1857 | AD28: =SUM(AD24:AD26) -> 11727.212 | AE28: =SUM(AE24:AE26) -> 13247.128 | AF28: =SUM(AF24:AF26) -> 15673.195 | AG28: =SUM(AG24:AG26) -> 17186.114 | AH28: =AG28*1.15 -> 19764.031 | AI28: =AH28*1.15 -> 22728.635 | AJ28: =AI28*1.15 -> 26137.931 | AK28: =AJ28*1.15 -> 30058.62 | AL28: =AK28*1.15 -> 34567.413 | AM28: =AL28*1.15 -> 39752.525 | AN28: =AM28*1.15 -> 45715.404 | AO28: =AN28*1.15 -> 52572.715 | ... AQ28: =AP28*1.15 -> 69527.415
F29: =+F28/B28-1 -> 0.14323202 | G29: =+G28/C28-1 -> 0.10932522 | H29: =+H28/D28-1 -> 0.10576341 | I29: =+I28/E28-1 -> 0.15955993 | J29: =+J28/F28-1 -> 0.19527581 | K29: =+K28/G28-1 -> 0.19832537 | L29: =+L28/H28-1 -> 0.1879929 | M29: =+M28/I28-1 -> 0.15553694 | ... U29: =+U28/Q28-1 -> 0.145 | AB29: =+AB28/AA28-1 -> 0.16501661 | AC29: =+AC28/AB28-1 -> 0.22690028 | AD29: =+AD28/AC28-1 -> 0.21296922 | AE29: =+AE28/AD28-1 -> 0.12960596 | AF29: =+AF28/AE28-1 -> 0.18313905 | AG29: =+AG28/AF28-1 -> 0.096529073 | AH29: =+AH28/AG28-1 -> 0.15 | AI29: =+AI28/AH28-1 -> 0.15 | ... AQ29: =+AQ28/AP28-1 -> 0.15
A30: Premium COGS | B30: 1704 | C30: 1804 | D30: 1908 | E30: =AD30-D30-C30-B30 -> 1939 | F30: 1937 | G30: 1984 | H30: 2062 | I30: =AE30-H30-G30-F30 -> 2248 | J30: 2268 | K30: 2300 | L30: 2338 | M30: 2425 | N30: 2514 | O30: 2509 | P30: 2561 | Q30: 2623 | R30: 2703 | AA30: 4443 | AB30: 5126 | AC30: 5986 | AD30: 7355 | AE30: 8231 | AF30: 9324 | AG30: =SUM(N30:Q30) -> 10207
B31: =+B30/B$28 -> 0.64036077 | C31: =+C30/C$28 -> 0.62988827 | D31: =+D30/D$28 -> 0.6284585 | E31: =+E30/E$28 -> 0.61244473 | F31: =+F30/F$28 -> 0.63672275 | G31: =+G30/G$28 -> 0.6244674 | H31: =+H30/H$28 -> 0.61422103 | I31: =+I30/I$28 -> 0.61233939 | ... U31: =+U30/U$28 -> 0 | AB31: =+AB30/AA30-1 -> 0.15372496 | AC31: =+AC30/AB30-1 -> 0.16777214 | AD31: =+AD30/AC30-1 -> 0.2287003 | AE31: =+AE30/AD30-1 -> 0.11910265 | AF31: =+AF30/AE30-1 -> 0.13279067 | AG31: =+AG30/AF30-1 -> 0.094701845
A32: Ad-Sup COGS | B32: 286 | C32: 356 | D32: 378 | E32: =AD32-D32-C32-B32 -> 426 | F32: 339 | G32: 427 | H32: 410 | I32: =AE32-H32-G32-F32 -> 443 | J32: 364 | K32: 395 | L32: 410 | M32: 449 | N32: 350 | O32: 364 | P32: 360 | Q32: 409 | R32: 335 | AA32: 599 | AB32: 739 | AC32: 1091 | AD32: 1446 | AE32: 1619 | AF32: 1625 | AG32: =SUM(N32:Q32) -> 1483
B33: =+B32/B$28 -> 0.10747839 | C33: =+C32/C$28 -> 0.12430168 | D33: =+D32/D$28 -> 0.12450593 | E33: =+E32/E$28 -> 0.13455464 | F33: =+F32/F$28 -> 0.1114347 | G33: =+G32/G$28 -> 0.13439898 | H33: =+H32/H$28 -> 0.1221293 | I33: =+I32/I$28 -> 0.12067008 | ... U33: =+U32/U$28 -> 0 | AB33: =+AB32/AA32-1 -> 0.23372287 | AC33: =+AC32/AB32-1 -> 0.47631935 | AD33: =+AD32/AC32-1 -> 0.32538955 | AE33: =+AE32/AD32-1 -> 0.11964039 | AF33: =+AF32/AE32-1 -> 0.0037059914 | AG33: =+AG32/AF32-1 -> -0.087384615
A34: COGS | B34: =SUM(B30:B32)-B31 -> 1990 | C34: =SUM(C30:C32)-C31 -> 2160 | D34: =SUM(D30:D32)-D31 -> 2286 | E34: =SUM(E30:E32)-E31 -> 2365 | F34: =SUM(F30:F32)-F31 -> 2276 | G34: =SUM(G30:G32)-G31 -> 2411 | H34: =SUM(H30:H32)-H31 -> 2472 | I34: =SUM(I30:I32)-I31 -> 2691 | ... R34: =SUM(R30:R32)-R31 -> 3038 | S34: 3181 | T34: =+T28-T36 -> 3277.3344 | U34: =+U28-U36 -> 3476.0219 | AA34: =SUM(AA30:AA32)-AA31 -> 5042 | AB34: =SUM(AB30:AB32)-AB31 -> 5865 | AC34: =SUM(AC30:AC32)-AC31 -> 7077 | AD34: =SUM(AD30:AD32)-AD31 -> 8801 | AE34: =SUM(AE30:AE32)-AE31 -> 9850 | AF34: =SUM(AF30:AF32)-AF31 -> 10949 | AG34: =SUM(AG30:AG32)-AG31 -> 11690 | AH34: =AH28-AH36 -> 13439.541 | AI34: =AI28-AI36 -> 15341.829 | AJ34: =AJ28-AJ36 -> 17512.414 | AK34: =AK28-AK36 -> 19988.983 | AL34: =AL28-AL36 -> 22814.493 | AM34: =AM28-AM36 -> 26037.904 | AN34: =AN28-AN36 -> 29715.013 | AO34: =AO28-AO36 -> 33909.401 | ... AQ34: =AQ28-AQ36 -> 44149.909
B35: =+B34/B$28 -> 0.74783916 | C35: =+C34/C$28 -> 0.75418994 | D35: =+D34/D$28 -> 0.75296443 | E35: =+E34/E$28 -> 0.74699937 | F35: =+F34/F$28 -> 0.74815745 | G35: =+G34/G$28 -> 0.75886638 | H35: =+H34/H$28 -> 0.73635033 | I35: =+I34/I$28 -> 0.73300948 | ... U35: =+U34/U$28 -> 0.67 | AA35: =+AA34/AA$28 -> 0.74541691 | AB35: =+AB34/AB$28 -> 0.74427306 | AC35: =+AC34/AC$28 -> 0.73198842 | AD35: =+AD34/AD$28 -> 0.75047677 | AE35: =+AE34/AE$28 -> 0.74355738 | AF35: =+AF34/AF$28 -> 0.69858125 | AG35: =+AG34/AG$28 -> 0.68020032 | AH35: =+AH34/AH$28 -> 0.68 | ... AQ35: =+AQ34/AQ$28 -> 0.635
A36: Gross Profit | B36: =B28-B34 -> 671 | C36: =C28-C34 -> 704 | D36: =D28-D34 -> 750 | E36: =E28-E34 -> 801 | F36: =F28-F34 -> 766.1404 | G36: =G28-G34 -> 766.10743 | H36: =H28-H34 -> 885.0977 | I36: =I28-I34 -> 980.16673 | ... S36: =S28-S34 -> 1596 | T36: =+T28*0.33 -> 1614.2095 | U36: =+U28*0.33 -> 1712.0705 | AA36: =AA28-AA34 -> 1722 | AB36: =AB28-AB34 -> 2015.1724 | AC36: =AC28-AC34 -> 2591.1857 | AD36: =AD28-AD34 -> 2926.2117 | AE36: =AE28-AE34 -> 3397.1283 | AF36: =AF28-AF34 -> 4724.1948 | AG36: =AG28-AG34 -> 5496.1138 | AH36: =AH28*0.32 -> 6324.4899 | AI36: =AI28*0.325 -> 7386.8065 | AJ36: =AJ28*0.33 -> 8625.5172 | AK36: =AK28*0.335 -> 10069.638 | AL36: =AL28*0.34 -> 11752.921 | AM36: =AM28*0.345 -> 13714.621 | AN36: =AN28*0.35 -> 16000.391 | AO36: =AO28*0.355 -> 18663.314 | AP36: =AP28*0.36 -> 21765.104 | AQ36: =AQ28*0.365 -> 25377.507
B37: =+B36/B$28 -> 0.25216084 | C37: =+C36/C$28 -> 0.24581006 | D37: =+D36/D$28 -> 0.24703557 | E37: =+E36/E$28 -> 0.25300063 | F37: =+F36/F$28 -> 0.25184255 | G37: =+G36/G$28 -> 0.24113362 | H37: =+H36/H$28 -> 0.26364967 | I37: =+I36/I$28 -> 0.26699052 | ... U37: =+U36/U$28 -> 0.33 | AA37: =+AA36/AA$28 -> 0.25458309 | AB37: =+AB36/AB$28 -> 0.25572694 | AC37: =+AC36/AC$28 -> 0.26801158 | AD37: =+AD36/AD$28 -> 0.24952323 | AE37: =+AE36/AE$28 -> 0.25644262 | AF37: =+AF36/AF$28 -> 0.30141875 | AG37: =+AG36/AG$28 -> 0.31979968 | AH37: =+AH36/AH$28 -> 0.32 | ... AQ37: =+AQ36/AQ$28 -> 0.365
A38: R&D | B38: 250 | C38: 336 | D38: 386 | E38: 415 | F38: 435 | G38: 453 | H38: 369 | I38: 468 | J38: 389 | K38: 379 | L38: 342 | M38: 376 | N38: 379 | O38: 415 | P38: 309 | Q38: 290 | R38: 331 | S38: 403 | T38: =+P38*0.9 -> 278.1 | U38: =+Q38*0.9 -> 261 | AA38: 615 | AB38: 837 | AC38: 912 | AD38: 1387 | AE38: 1725 | AF38: 1486 | AG38: =SUM(N38:Q38) -> 1393 | AH38: =AG38*1.1 -> 1532.3 | AI38: =AH38*1.1 -> 1685.53 | AJ38: =AI38*1.1 -> 1854.083 | AK38: =AJ38*1.1 -> 2039.4913 | AL38: =AK38*1.1 -> 2243.4404 | AM38: =AL38*1.1 -> 2467.7845 | AN38: =AM38*1.1 -> 2714.5629 | AO38: =AN38*1.1 -> 2986.0192 | ... AQ38: =AP38*1.1 -> 3613.0832
B39: =+B38/B$28 -> 0.093949643 | C39: =+C38/C$28 -> 0.11731844 | D39: =+D38/D$28 -> 0.12714097 | E39: =+E38/E$28 -> 0.13108023 | F39: =+F38/F$28 -> 0.14299143 | G39: =+G38/G$28 -> 0.14258253 | H39: =+H38/H$28 -> 0.10991637 | I39: =+I38/I$28 -> 0.12747991 | ... U39: =+U38/U$28 -> 0.050307509 | AA39: =+AA38/AA$28 -> 0.090922531 | AB39: =+AB38/AB$28 -> 0.10621595 | AC39: =+AC38/AC$28 -> 0.094330004 | AD39: =+AD38/AD$28 -> 0.11827193 | AE39: =+AE38/AE$28 -> 0.1302169 | AF39: =+AF38/AF$28 -> 0.094811557 | AG39: =+AG38/AG$28 -> 0.08105381 | AH39: =+AH38/AH$28 -> 0.077529731 | ... AQ39: =+AQ38/AQ$28 -> 0.05196631
A40: S&M | B40: 296 | C40: 391 | D40: 432 | E40: 453 | F40: 347 | G40: 399 | H40: 355 | I40: 432 | J40: 324 | K40: 343 | L40: 332 | M40: 393 | N40: 314 | O40: 364 | P40: 349 | Q40: 399 | R40: 342 | S40: 390 | T40: =+P40*1.01 -> 352.49 | U40: =+Q40*1.01 -> 402.99 | AA40: 826 | AB40: 1029 | AC40: 1135 | AD40: 1572 | AE40: 1533 | AF40: 1392 | AG40: =SUM(N40:Q40) -> 1426 | AH40: =AG40*1.08 -> 1540.08 | AI40: =AH40*1.08 -> 1663.2864 | AJ40: =AI40*1.08 -> 1796.3493 | AK40: =AJ40*1.08 -> 1940.0573 | AL40: =AK40*1.08 -> 2095.2618 | AM40: =AL40*1.08 -> 2262.8828 | AN40: =AM40*1.08 -> 2443.9134 | AO40: =AN40*1.08 -> 2639.4265 | ... AQ40: =AP40*1.08 -> 3078.627
B41: =+B40/B$28 -> 0.11123638 | C41: =+C40/C$28 -> 0.13652235 | D41: =+D40/D$28 -> 0.14229249 | E41: =+E40/E$28 -> 0.14308275 | F41: =+F40/F$28 -> 0.11406443 | G41: =+G40/G$28 -> 0.12558593 | H41: =+H40/H$28 -> 0.1057461 | I41: =+I40/I$28 -> 0.11767376 | ... U41: =+U40/U$28 -> 0.07767595 | AA41: =+AA40/AA$28 -> 0.12211709 | AB41: =+AB40/AB$28 -> 0.1305809 | AC41: =+AC40/AC$28 -> 0.11739535 | AD41: =+AD40/AD$28 -> 0.13404721 | AE41: =+AE40/AE$28 -> 0.11572319 | AF41: =+AF40/AF$28 -> 0.088814056 | AG41: =+AG40/AG$28 -> 0.082973965 | AH41: =+AH40/AH$28 -> 0.077923376 | ... AQ41: =+AQ40/AQ$28 -> 0.044279325
A42: G&A | B42: 131 | C42: 171 | D42: 160 | E42: 164 | F42: 140 | G42: 161 | H42: 129 | I42: 155 | J42: 123 | K42: 124 | L42: 112 | M42: 122 | N42: 124 | O42: 135 | P42: 111 | Q42: 109 | R42: 107 | S42: 148 | T42: =+P42*0.9 -> 99.9 | U42: =+Q42*0.9 -> 98.1 | AA42: 354 | AB42: 442 | AC42: 450 | AD42: 626 | AE42: 585 | AF42: 481 | AG42: =SUM(N42:Q42) -> 479 | AH42: =AG42*1.05 -> 502.95 | AI42: =AH42*1.05 -> 528.0975 | AJ42: =AI42*1.05 -> 554.50238 | AK42: =AJ42*1.05 -> 582.22749 | AL42: =AK42*1.05 -> 611.33887 | AM42: =AL42*1.05 -> 641.90581 | AN42: =AM42*1.05 -> 674.0011 | AO42: =AN42*1.05 -> 707.70116 | ... AQ42: =AP42*1.05 -> 780.24053
B43: =+B42/B$28 -> 0.049229613 | C43: =+C42/C$28 -> 0.059706704 | D43: =+D42/D$28 -> 0.052700922 | E43: =+E42/E$28 -> 0.051800379 | F43: =+F42/F$28 -> 0.04602023 | G43: =+G42/G$28 -> 0.050675026 | H43: =+H42/H$28 -> 0.038426049 | I43: =+I42/I$28 -> 0.04222091 | ... U43: =+U42/U$28 -> 0.018908684 | AA43: =+AA42/AA$28 -> 0.052335896 | AB43: =+AB42/AB$28 -> 0.056090144 | AC43: =+AC42/AC$28 -> 0.04654441 | AD43: =+AD42/AD$28 -> 0.053380123 | AE43: =+AE42/AE$28 -> 0.044160514 | AF43: =+AF42/AF$28 -> 0.03068934 | AG43: =+AG42/AG$28 -> 0.027871339 | AH43: =+AH42/AH$28 -> 0.025447744 | ... AQ43: =+AQ42/AQ$28 -> 0.011222056
...
