Workbook

Sheet Main
A1: UBER | D1: Price | E1: 75 | L1: -> | M1: Waabi (ai company that builds AV)
D2: Share | E2: 2035.599 | F2: Q126 | L2: -> | M2: Wayve (british based ai company that builds AV)
D3: MC | E3: =E1*E2 -> 152669.93 | L3: -> | M3: Airport to increase pick-up fees (LAX)
D4: Cash | E4: 8911 | F4: Q126 | L4: -> | M4: Online Food Delivery marlket projected to expand by 9.7% CAGR up to 2032
D5: Debt | E5: 10514 | F5: Q126 | L5: -> | M5: Zoox strategic partnership (AMZN)
D6: EV | E6: =E3-E4+E5 -> 154272.93 | L6: -> | M6: Robotaxi collaboration with Wayve and Nissan in Tokyo powered by Nissan LEAF with Wayve AI
L7: -> | M7: Robotaxi collaboration with Motional (Hyunday Motor Group) in Las Vegas
A8: BETA | B8: 1.2 | D8: EV / Rev | E8: =+E6/(SUM(Model!O68:R68)) -> 24.640606 | M8: one of the first SAE Level 4 AV
L9: -> | M9: Increasing the strategic partnership with Nvidia in order to deploy their L4 (high automation) driverless vehicle in 28 cities by 2028
M10: Using UBER’s network effect to test and improve Nvidia’s DRIVE AGX and Ampamayo
L11: -> | M11: Partnership with Rivianto help them deploy 50,000 R2 robotaxies
A12: CAPM / Cost of Equity | B12: =0.045+B8*(0.1-0.0495) -> 0.1056 | D12: Cr. Spread | E12: =+'[1]Credit Spread US'!J6 -> 0.78043478 | M12: - currently still a L3 automation but this partnership sould help them develop at least an L4 automation
A13: Cost Debt | B13: =+0.0495+(E12/10) -> 0.12754348 | M13: - the full deployment should happen in 2031 with a total investment of 1.25$ B into the company given certain milestones
A14: Incremental Margin TTM | B14: =((Model!S68+Model!R68+Model!Q68+Model!P68)-(Model!O68+Model!N68+Model!M68+Model!L68))/((Model!S52+Model!R52+Model!Q52+Model!P52)-(Model!O52+Model!N52+Model!M52+Model!L52)) -> 0.27737452 | D14: WACC | E14: =+(E4/(E4+E5))*B12+(E5/(E4+E5)*B13*(1-0.22)) -> 0.1022896 | L14: -> | M14: Multi – year partnership with Ibotta to use Ibotta’s discounts over CPG (consumer Packed Goods) into Uber Eat.
A15: Leverage | B15: =(E5-E4)/Model!S111 -> 0.56864136 | M15: -> | N15: Ibotta will reach a bigger audience while UBER Eat ueasers (and UBER One) will have a better experience with the product (higher conversion rate?)
A16: EV/FCF (TTM) | B16: =+E6/SUM(Model!P175:S175) -> 15.304769 | L16: -> | M16: UBER to inctease not temporaly the prices for ridesharing services in order to bear oil price hikes
A17: EV/EBITDA | B17: =E6/(SUM(Model!O111:R111)) -> 16.51214 | M17: the change won’t be temporaly
A18: P/E | B18: =+E1/SUM(Model!P86:S86) -> 16.466975 | L18: -> | M18: UBER to parner with Pony.ai and Verne to deploy the first robotaxies in europe (Zagreb)
A19: P/FCF (TTM) | B19: =E3/SUM(Model!P175:S175) -> 15.145742 | M19: Following this strategic partnership, UBER will invest in Verne
A20: Rating | B20: BBB+ | C20: Baa1 | M20: Pony.ai will bring the Gen-7 autonomous vehicles, Verne will be the owner of the fleet while UBER will provide the networking (the demand)
B21: S&P | C21: Moody’s | M21: Still waiting for EU approval
L22: -> | M22: UBER to acquire Blacklane to improve it’s luxury and executive driving. UBER Elite
M23: Blacklane already operates in over 500 cities.
D24: Founded | E24: 2009 | F24: Delaware | M24: waiting for antitrust approval
D25: UBERCAB | E25: 2010 | L25: -> | M25: UBER to deploy fully driverless (Level 4) robotaxies in Dubai together with WeRide and Tawasul.
D26: UBER | E26: 2011 | M26: Tawasul will be the fleet operator. WeRide committed to deploy at least 1,200 Robotaxis in the ME (WeRide has been the first company to receive a national licence for self driving vehicles in the UAE).
D27: IPO | E27: May 9th 2019 | M27: UBER owns 5.82% of WeRide Class A shares
C28: Sector | D28: Technology Platform | L28: -> | M28: MOIA America will test its AV in LA through Uber in late 2026
C29: CEO | D29: Dara Khosrowshahi | M29: This partnership has been going on since 2025 and aims to deploy thousands of AV. MOIA (and theparent VolksWagen) are advancing AV testing in Hamburg, Oslo, Berlin, Munich.
C30: Founder | D30: Travis Kalanick | L30: -> | M30: UBER to add Cash App Pay (Block inc. XYZ) into the app to reach the over 59 million transaction done mainly from Millenials and Gen Zs
A31: investor@uber.com | L31: -> | M31: UBER to launch a robotaxi program in Munich together with NVDA Hyperion
L32: -> | M32: UBER together with AVOMO and WERIDE to launch the first robotaxi fleet in Madrid aiming to deploy hudreds of robotaxies in the region in the foreseeable future as certain milestones are met
M33: This partnerships have already been tested in the US (AVOMO) and in the ME (WERIDE) and show positive sign as of relationship and clear path
A34: Segments | M34: Still 11 cities do expand the partnership with WeRide before 2030. Next sure is Riyadh.
A35: Delivery (UberEats) | L35: -> | M35: UBER expands further the shops where consumers can buy through UBER Eats beyond the food segment.
A36: Mobility (Uber, Lime, carsharing, taxi, …) | M36: Consumers are using delivery apps not anymore just for food delivery, but they want a wider range of goods to choose from. UBER is targeting this niche
A37: Freight (on demand platform to automate logistics transactions) UBER freight | L37: -> | M37: UBER to expand their commercial robotaxies to Zurich with WeRide. Ryderra will manage day-to-day fleet operations
A38: Nissan, Kellog, CL, … | G38: -> | H38: Prashanth Mahendra-Rajan in US gov? | L38: -> | M38: UBER to deploy in mid-2027 Robotaxies in Houston with Nuro (Level 4 AV) and Lucid
G39: -> | H39: Reserve increased Uber’s reliability | M39: Nuro aims to deploy over 35,000 AVs globally
L40: -> | M40: UBER to acquire Delibvery Hero for 14.8B$ to be approved around Q2 27. It is expected to create synergies for at least 1.2B$
...

Sheet Model
A1: Main | B1: 03/22 | C1: 06/22 | D1: 09/22 | E1: 12/22 | F1: 03/23 | G1: 06/23 | H1: 09/23 | I1: 12/23 | J1: 03/24 | K1: 06/24 | L1: 09/24 | M1: 12/24 | N1: 03/25 | O1: 06/25 | P1: 09/25 | Q1: 12/25 | R1: 03/26 | S1: 06/26 | T1: 09/26 | U1: 12/26 | Y1: 12/19 | Z1: 12/20 | AA1: 12/21 | AB1: 12/22 | AC1: 12/23 | AD1: 12/24 | AE1: 12/25 | AF1: 12/26 | AG1: 12/27 | AH1: 12/28 | AI1: 12/29 | AJ1: 12/30 | AK1: 12/31 | AL1: 12/32 | AM1: 12/33 | AN1: 12/34 | AO1: 12/35
A2: in Millions | B2: Q122 | C2: Q222 | D2: Q322 | E2: Q422 | F2: Q123 | G2: Q223 | H2: Q323 | I2: Q423 | J2: Q124 | K2: Q224 | L2: Q324 | M2: Q424 | N2: Q125 | O2: Q225 | P2: Q325 | Q2: Q425 | R2: Q126 | S2: Q226 | T2: Q326 | U2: Q426 | Y2: 2019 | Z2: 2020 | AA2: =Z2+1 -> 2021 | AB2: =AA2+1 -> 2022 | AC2: =AB2+1 -> 2023 | AD2: =AC2+1 -> 2024 | AE2: =AD2+1 -> 2025 | AF2: =AE2+1 -> 2026 | AG2: =AF2+1 -> 2027 | AH2: =AG2+1 -> 2028 | ... AO2: =AN2+1 -> 2035
A3: GRAB Group MTUs | B3: 30.9 | C3: 32.6 | D3: 33.5 | E3: 33.6 | F3: 33.3 | G3: 34.9 | H3: 36 | I3: 37.7 | J3: 38.5 | K3: 40.9 | L3: 41.9 | M3: 43.9 | N3: 44.5 | O3: 46.2 | P3: 47.7 | Q3: 50.5 | R3: 51.6 | Z3: 27.7 | AA3: 28.1 | AB3: 32.7 | AC3: 35.5 | AD3: 41.3 | AE3: 50.5
A4: % | F4: =F3/B3-1 -> 0.077669903 | G4: =G3/C3-1 -> 0.070552147 | H4: =H3/D3-1 -> 0.074626866 | I4: =I3/E3-1 -> 0.12202381 | J4: =J3/F3-1 -> 0.15615616 | K4: =K3/G3-1 -> 0.17191977 | L4: =L3/H3-1 -> 0.16388889 | M4: =M3/I3-1 -> 0.16445623 | ... R4: =R3/N3-1 -> 0.15955056 | AA4: =+AA3/Z3-1 -> 0.014440433 | AB4: =+AB3/AA3-1 -> 0.16370107 | AC4: =+AC3/AB3-1 -> 0.085626911 | AD4: =+AD3/AC3-1 -> 0.16338028 | AE4: =+AE3/AD3-1 -> 0.22276029
A5: GRAB GMV | B5: - | C5: - | D5: - | E5: 0 | F5: 3600 | G5: 3939 | H5: 4063 | I5: =+AC5-F5-G5-H5 -> 4183 | J5: 4242 | K5: 4434 | L5: 4659 | M5: 5028 | N5: 4932 | O5: 5354 | P5: 5774 | Q5: 6077 | R5: 6131 | Y5: - | Z5: - | AA5: - | AB5: 15592 | AC5: 15785 | AD5: 18364 | AE5: 22138
A6: % | J6: =J5/F5-1 -> 0.17833333 | K6: =K5/G5-1 -> 0.12566641 | L6: =L5/H5-1 -> 0.14668964 | M6: =M5/I5-1 -> 0.20200813 | N6: =N5/J5-1 -> 0.16265912 | O6: =O5/K5-1 -> 0.2074876 | P6: =P5/L5-1 -> 0.23932174 | Q6: =Q5/M5-1 -> 0.20863166 | R6: =R5/N5-1 -> 0.24310624 | AC6: =+AC5/AB5-1 -> 0.012378143 | AD6: =+AD5/AC5-1 -> 0.16338296 | AE6: =+AE5/AD5-1 -> 0.20551078
A8: DASH Orders | B8: 404 | C8: 426 | D8: 439 | E8: 467 | F8: 512 | G8: 532 | H8: 543 | I8: 574 | J8: 620 | K8: 635 | L8: 643 | M8: 685 | N8: 732 | O8: 761 | P8: 776 | Q8: 903 | R8: 933 | Y8: 263 | Z8: 816 | AA8: 1390 | AB8: 1736 | AC8: 2161 | AD8: 2583 | AE8: 3172
A9: % | F9: =F8/B8-1 -> 0.26732673 | G9: =G8/C8-1 -> 0.24882629 | H9: =H8/D8-1 -> 0.23690205 | I9: =I8/E8-1 -> 0.22912206 | J9: =J8/F8-1 -> 0.2109375 | K9: =K8/G8-1 -> 0.19360902 | L9: =L8/H8-1 -> 0.18416206 | M9: =M8/I8-1 -> 0.19337979 | ... R9: =R8/N8-1 -> 0.27459016 | Z9: =+Z8/Y8-1 -> 2.1026616 | AA9: =+AA8/Z8-1 -> 0.70343137 | AB9: =+AB8/AA8-1 -> 0.24892086 | AC9: =+AC8/AB8-1 -> 0.24481567 | AD9: =+AD8/AC8-1 -> 0.19527996 | AE9: =+AE8/AD8-1 -> 0.22802942
A10: ZOOX Trips (‘000)
A11: Waymo Trips (‘000) | P11: 3500 | Q11: 5300 | R11: 6200 | AC11: 0.8 | AD11: 4 | AE11: 15
A12: Apollo Go (‘000) | F12: 660 | G12: 714 | H12: 821 | I12: 839 | J12: 826 | K12: 899 | L12: 988 | M12: 1100 | N12: 1400 | O12: 2200 | P12: 3100 | Q12: 3400 | R12: 3200 | AB12: 1.5 | AC12: 3.03 | AD12: 3.813 | AE12: 10.1
J13: =J12/F12-1 -> 0.25151515 | K13: =K12/G12-1 -> 0.25910364 | L13: =L12/H12-1 -> 0.20341048 | M13: =M12/I12-1 -> 0.31108462 | N13: =N12/J12-1 -> 0.69491525 | O13: =O12/K12-1 -> 1.4471635 | P13: =P12/L12-1 -> 2.1376518 | Q13: =Q12/M12-1 -> 2.0909091 | R13: =R12/N12-1 -> 1.2857143 | AC13: =AC12/AB12-1 -> 1.02 | AD13: =AD12/AC12-1 -> 0.25841584 | AE13: =AE12/AD12-1 -> 1.6488329
A14: Tesla Robotaxi
A15: Texla FSD (miles) | S15: 10000
A18: LYFT Trips | B18: 139.5 | C18: 152.1 | D18: 155.8 | E18: 151.1 | F18: 153 | G18: 177.9 | H18: 187.4 | I18: 190.8 | J18: 187.7 | K18: 205.3 | L18: 216.7 | M18: 218.5 | N18: 218.4 | O18: 234.8 | P18: 248.8 | Q18: 243.5 | R18: 236.9 | Y18: - | Z18: - | AA18: - | AB18: 598.5 | AC18: =SUM(F18:I18) -> 709.1 | AD18: =SUM(J18:M18) -> 828.2 | AE18: =SUM(N18:Q18) -> 945.5
A19: % | F19: =F18/B18-1 -> 0.096774194 | G19: =G18/C18-1 -> 0.16962525 | H19: =H18/D18-1 -> 0.20282413 | I19: =I18/E18-1 -> 0.26273991 | J19: =J18/F18-1 -> 0.22679739 | K19: =K18/G18-1 -> 0.15401911 | L19: =L18/H18-1 -> 0.15635005 | M19: =M18/I18-1 -> 0.1451782 | ... R19: =R18/N18-1 -> 0.08470696 | AC19: =AC18/AB18-1 -> 0.18479532 | AD19: =AD18/AC18-1 -> 0.16795939 | AE19: =AE18/AD18-1 -> 0.14163246
A20: LYFT Gross Book | B20: 2694 | C20: 3093 | D20: 3079 | E20: 3191 | F20: 3051 | G20: 3446 | H20: 3554 | I20: 3724 | J20: 3693 | K20: 4019 | L20: 4108 | M20: 4279 | N20: 4162 | O20: 4490 | P20: 4780 | Q20: 5074 | R20: 4946 | Y20: - | Z20: - | AA20: - | AB20: 12057 | AC20: =SUM(F20:I20) -> 13775 | AD20: =SUM(J20:M20) -> 16099 | AE20: =SUM(N20:Q20) -> 18506
A21: % | F21: =F20/B20-1 -> 0.1325167 | G21: =G20/C20-1 -> 0.11412868 | H21: =H20/D20-1 -> 0.15427087 | I21: =I20/E20-1 -> 0.16703228 | J21: =J20/F20-1 -> 0.21042281 | K21: =K20/G20-1 -> 0.16627974 | L21: =L20/H20-1 -> 0.1558807 | M21: =M20/I20-1 -> 0.1490333 | ... R21: =R20/N20-1 -> 0.18837098 | AC21: =AC20/AB20-1 -> 0.14248984 | AD21: =AD20/AC20-1 -> 0.16871143 | AE21: =AE20/AD20-1 -> 0.14951239
A24: MAD | B24: 4.4 | E24: 5.4 | F24: 5.7 | G24: 6 | H24: 6.5 | I24: 6.8 | J24: 7.1 | K24: 7.4 | L24: 7.8 | M24: 8.15 | N24: 8.5 | O24: 8.8 | P24: 9.4 | Q24: 9.7 | R24: 9.9 | Y24: - | Z24: 3.4 | AA24: 4.4 | AB24: 5.4 | AC24: 6.8 | AD24: 8.2 | AE24: 9.7 | AF24: =+AE24*1.17 -> 11.349
A25: % | F25: =F24/B24-1 -> 0.29545455 | G25: =G24/C24-1 -> #DIV/0! | H25: =H24/D24-1 -> #DIV/0! | I25: =I24/E24-1 -> 0.25925926 | J25: =J24/F24-1 -> 0.24561404 | K25: =K24/G24-1 -> 0.23333333 | L25: =L24/H24-1 -> 0.2 | M25: =M24/I24-1 -> 0.19852941 | ... S25: =S24/O24-1 -> -1 | AA25: =AA24/Z24-1 -> 0.29411765 | AB25: =AB24/AA24-1 -> 0.22727273 | AC25: =AC24/AB24-1 -> 0.25925926 | AD25: =AD24/AC24-1 -> 0.20588235 | AE25: =AE24/AD24-1 -> 0.18292683
A26: MAPC | B26: 115 | C26: 122 | D26: 124 | E26: 131 | F26: 130 | G26: 137 | H26: 142 | I26: 150 | J26: 149 | K26: 156 | L26: 161 | M26: 171 | N26: 170 | O26: 180 | P26: 189 | Q26: 202 | R26: 199 | S26: 208 | Y26: 111 | Z26: 93 | AA26: 118 | AB26: 131 | AC26: 150 | AD26: 171 | AE26: 202
A27: % | F27: =F26/B26-1 -> 0.13043478 | G27: =G26/C26-1 -> 0.12295082 | H27: =H26/D26-1 -> 0.14516129 | I27: =I26/E26-1 -> 0.14503817 | J27: =J26/F26-1 -> 0.14615385 | K27: =K26/G26-1 -> 0.13868613 | L27: =L26/H26-1 -> 0.13380282 | M27: =M26/I26-1 -> 0.14 | ... S27: =S26/O26-1 -> 0.15555556 | Z27: =Z26/Y26-1 -> -0.16216216 | AA27: =AA26/Z26-1 -> 0.2688172 | AB27: =AB26/AA26-1 -> 0.11016949 | AC27: =AC26/AB26-1 -> 0.14503817 | AD27: =AD26/AC26-1 -> 0.14 | AE27: =AE26/AD26-1 -> 0.18128655
A28: Trips | B28: 1713 | C28: 1872 | D28: 1953 | E28: 2104 | F28: 2124 | G28: 2282 | H28: 2441 | I28: 2601 | J28: 2572 | K28: 2765 | L28: 2868 | M28: 3068 | N28: 3036 | O28: 3268 | P28: 3512 | Q28: 3751 | R28: 3643 | S28: 3867 | Y28: =+1550+1677+1770+1907 -> 6904 | Z28: =+1661+737+1184+1443 -> 5025 | AA28: 6368 | AB28: 7642 | AC28: =SUM(F28:I28) -> 9448 | AD28: =SUM(J28:M28) -> 11273 | AE28: =SUM(N28:Q28) -> 13567
A29: % | F29: =F28/B28-1 -> 0.23992995 | G29: =G28/C28-1 -> 0.21901709 | H29: =H28/D28-1 -> 0.24987199 | I29: =I28/E28-1 -> 0.23621673 | J29: =J28/F28-1 -> 0.21092279 | K29: =K28/G28-1 -> 0.21165644 | L29: =L28/H28-1 -> 0.17492831 | M29: =M28/I28-1 -> 0.17954633 | ... S29: =S28/O28-1 -> 0.18329253 | Z29: =Z28/Y28-1 -> -0.27216107 | AA29: =AA28/Z28-1 -> 0.26726368 | AB29: =AB28/AA28-1 -> 0.20006281 | AC29: =AC28/AB28-1 -> 0.23632557 | AD29: =AD28/AC28-1 -> 0.19316257 | AE29: =AE28/AD28-1 -> 0.20349508
A31: Mobility GB | B31: 10723 | C31: 13364 | D31: 13684 | E31: 14894 | F31: 14981 | G31: 16728 | H31: 17903 | I31: 19285 | J31: 18670 | K31: 20554 | L31: 21002 | M31: 22798 | N31: 21182 | O31: 23762 | P31: 25111 | Q31: 27442 | R31: 26394 | S31: 28988
F32: =F31/B31-1 -> 0.39709037 | G32: =G31/C31-1 -> 0.25172104 | H32: =H31/D31-1 -> 0.30831628 | I32: =I31/E31-1 -> 0.2948167 | J32: =J31/F31-1 -> 0.24624524 | K32: =K31/G31-1 -> 0.22871832 | L32: =L31/H31-1 -> 0.17309948 | M32: =M31/I31-1 -> 0.1821623 | ... S32: =S31/O31-1 -> 0.21993098
A33: Delivery GB | B33: 13903 | C33: 13876 | D33: 13684 | E33: 14315 | F33: 15026 | G33: 15595 | H33: 16094 | I33: 17011 | J33: 17699 | K33: 18126 | L33: 18663 | M33: 20126 | N33: 20377 | O33: 21734 | P33: 23322 | Q33: 25431 | R33: 25992 | S33: 27463
F34: =F33/B33-1 -> 0.080773934 | G34: =G33/C33-1 -> 0.12388296 | H34: =H33/D33-1 -> 0.17611809 | I34: =I33/E33-1 -> 0.18833392 | J34: =J33/F33-1 -> 0.17789165 | K34: =K33/G33-1 -> 0.16229561 | L34: =L33/H33-1 -> 0.1596247 | M34: =M33/I33-1 -> 0.18311681 | ... S34: =S33/O33-1 -> 0.26359621
A35: Freight GB | B35: 1823 | C35: 1838 | D35: 1751 | E35: 1540 | F35: 1401 | G35: 1278 | H35: 1284 | I35: 1279 | J35: 1282 | K35: 1272 | L35: 1308 | M35: 1273 | N35: 1259 | O35: 1260 | P35: 1307 | Q35: 1267 | R35: 1334 | S35: 1571
F36: =F35/B35-1 -> -0.23148656 | G36: =G35/C35-1 -> -0.304679 | H36: =H35/D35-1 -> -0.26670474 | I36: =I35/E35-1 -> -0.16948052 | J36: =J35/F35-1 -> -0.084939329 | K36: =K35/G35-1 -> -0.0046948357 | L36: =L35/H35-1 -> 0.018691589 | M36: =M35/I35-1 -> -0.004691165 | ... S36: =S35/O35-1 -> 0.2468254
A37: Gross Booking | B37: =+B35+B33+B31 -> 26449 | C37: =+C35+C33+C31 -> 29078 | D37: =+D35+D33+D31 -> 29119 | E37: =+E35+E33+E31 -> 30749 | F37: =+F35+F33+F31 -> 31408 | G37: =+G35+G33+G31 -> 33601 | H37: =+H35+H33+H31 -> 35281 | I37: =+I35+I33+I31 -> 37575 | ... S37: =+S35+S33+S31 -> 58022 | T37: =+P37*1.18 -> 58693.2 | Y37: 65001 | Z37: 57897 | AA37: 90415 | AB37: 115395 | AC37: =SUM(F37:I37) -> 137865 | AD37: =SUM(J37:M37) -> 162773 | AE37: =SUM(N37:Q37) -> 193454 | AF37: =+AE37*1.2 -> 232144.8 | AG37: =+AF37*1.2 -> 278573.76 | AH37: =+AG37*1.2 -> 334288.51 | AI37: =+AH37*1.2 -> 401146.21 | AJ37: =+AI37*1.2 -> 481375.46 | AK37: =+AJ37*1.2 -> 577650.55 | AL37: =+AK37*1.2 -> 693180.66 | AM37: =+AL37*1.2 -> 831816.79 | ... AO37: =+AN37*1.2 -> 1197816.2
A38: % | F38: =F37/B37-1 -> 0.18749291 | G38: =G37/C37-1 -> 0.15554715 | H38: =H37/D37-1 -> 0.21161441 | I38: =I37/E37-1 -> 0.22199096 | J38: =J37/F37-1 -> 0.19877101 | K38: =K37/G37-1 -> 0.18901223 | L38: =L37/H37-1 -> 0.1613333 | M38: =M37/I37-1 -> 0.1762342 | ... T38: =T37/P37-1 -> 0.18 | Z38: =Z37/Y37-1 -> -0.10929063 | AA38: =AA37/Z37-1 -> 0.56165259 | AB38: =AB37/AA37-1 -> 0.27628159 | AC38: =AC37/AB37-1 -> 0.19472247 | AD38: =AD37/AC37-1 -> 0.1806695 | AE38: =AE37/AD37-1 -> 0.18848949 | AF38: =AF37/AE37-1 -> 0.2 | AG38: =AG37/AF37-1 -> 0.2 | ... AO38: =AO37/AN37-1 -> 0.2
A39: Uber One | H39: 15 | I39: 19 | L39: 25 | M39: 30 | Q39: 46 | R39: 50 | AC39: 19 | AD39: 30 | AE39: 46
A40: % | I40: =+I39/H39-1 -> 0.26666667 | M40: =+M39/L39-1 -> 0.2 | R40: =+R39/Q39-1 -> 0.086956522 | AD40: =AD39/AC39-1 -> 0.57894737 | AE40: =AE39/AD39-1 -> 0.53333333
A41: Take Rate | B41: =+B52/B37 -> 0.25914023 | C41: =+C52/C37 -> 0.27763257 | D41: =+D52/D37 -> 0.28651396 | E41: =+E52/E37 -> 0.27991154 | F41: =+F52/F37 -> 0.28094597 | G41: =+G52/G37 -> 0.27470952 | H41: =+H52/H37 -> 0.26338217 | I41: =+I52/I37 -> 0.26444186 | ... S41: =+S52/S37 -> 0.24457964 | Y41: =+Y52/Y37 -> 0.21764281 | Z41: =+Z52/Z37 -> 0.19240211 | AA41: =+AA52/AA37 -> 0.19308071 | AB41: =+AB52/AB37 -> 0.27627349 | AC41: =+AC52/AC37 -> 0.2704188 | AD41: =+AD52/AD37 -> 0.27018223 | AE41: =+AE52/AE37 -> 0.26888784 | AF41: =+AF52/AF37 -> 0.25096199 | ... AO41: =+AO52/AO37 -> 0.15247736
A42: % | F42: =F41/B41-1 -> 0.084146464 | G42: =G41/C41-1 -> -0.010528486 | H42: =H41/D41-1 -> -0.080735296 | I42: =I41/E41-1 -> -0.055266325 | J42: =J41/F41-1 -> -0.042216005 | K42: =K41/G41-1 -> -0.02504414 | L42: =L41/H41-1 -> 0.036777681 | M42: =M41/I41-1 -> 0.023265891 | ... S42: =S41/O41-1 -> -0.096105159 | Z42: =Z41/Y41-1 -> -0.11597302 | AA42: =AA41/Z41-1 -> 0.0035269882 | AB42: =AB41/AA41-1 -> 0.43087049 | AC42: =AC41/AB41-1 -> -0.02119165 | AD42: =AD41/AC41-1 -> -0.00087484337 | AE42: =AE41/AD41-1 -> -0.0047907832 | AF42: =AF41/AE41-1 -> -0.066666667 | AG42: =AG41/AF41-1 -> -0.041666667 | ... AO42: =AO41/AN41-1 -> -0.083333333
A44: Mobility | B44: 2518 | C44: 3553 | D44: 3822 | E44: 4136 | F44: 4330 | G44: 4894 | H44: 5071 | I44: 5537 | J44: 5633 | K44: 6134 | L44: 6409 | M44: 6911 | N44: 6496 | O44: 7288 | P44: 7682 | Q44: 8204 | R44: 6798 | S44: 7363 | Y44: 10745 | Z44: 6089 | AA44: 6953 | AB44: 14029 | AC44: 19832 | AD44: 25087 | AE44: =SUM(N44:Q44) -> 29670
A45: % | F45: =+F44/B44-1 -> 0.71961875 | G45: =+G44/C44-1 -> 0.37742753 | H45: =+H44/D44-1 -> 0.32679226 | I45: =+I44/E44-1 -> 0.33873308 | J45: =+J44/F44-1 -> 0.30092379 | K45: =+K44/G44-1 -> 0.25337148 | L45: =+L44/H44-1 -> 0.26385328 | M45: =+M44/I44-1 -> 0.24814882 | ... S45: =+S44/O44-1 -> 0.010290889 | Z45: =+Z44/Y44-1 -> -0.43331782 | AA45: =+AA44/Z44-1 -> 0.14189522 | AB45: =+AB44/AA44-1 -> 1.0176902 | AC45: =+AC44/AB44-1 -> 0.41364317 | AD45: =+AD44/AC44-1 -> 0.2649758 | AE45: =+AE44/AD44-1 -> 0.18268426
A46: Delivery | B46: 2512 | C46: 2688 | D46: 2770 | E46: 2931 | F46: 3093 | G46: 3057 | H46: 2935 | I46: 3119 | J46: 3214 | K46: 3293 | L46: 3470 | M46: 3773 | N46: 3777 | O46: 4102 | P46: 4477 | Q46: 4892 | R46: 5068 | S46: 5245 | Y46: 2510 | Z46: 3904 | AA46: 8362 | AB46: 10901 | AC46: 12204 | AD46: 13750 | AE46: =SUM(N46:Q46) -> 17248
A47: % | F47: =+F46/B46-1 -> 0.23128981 | G47: =+G46/C46-1 -> 0.13727679 | H47: =+H46/D46-1 -> 0.059566787 | I47: =+I46/E46-1 -> 0.064141931 | J47: =+J46/F46-1 -> 0.039120595 | K47: =+K46/G46-1 -> 0.077199869 | L47: =+L46/H46-1 -> 0.18228279 | M47: =+M46/I46-1 -> 0.20968259 | ... S47: =+S46/O46-1 -> 0.27864456 | Z47: =+Z46/Y46-1 -> 0.55537849 | AA47: =+AA46/Z46-1 -> 1.1419057 | AB47: =+AB46/AA46-1 -> 0.30363549 | AC47: =+AC46/AB46-1 -> 0.11953032 | AD47: =+AD46/AC46-1 -> 0.12667978 | AE47: =+AE46/AD46-1 -> 0.2544
...

Sheet Bond
A1: Main
B4: isin | C4: bondType | D4: immediateIssuer | E4: coupon | F4: couponType | G4: maturityDate | H4: callable | I4: currency | J4: seniorityLevel | K4: liquidityScore
B5: US90353TAR14 | C5: — | D5: Uber Technologies, Inc. | E5: 0 | F5: Non-Interest-Bearing | G5: 15/05/2028 | H5: N | I5: USD | J5: Senior | K5: — | M5: Zero-coupon bond backed by Aurora stocks priced at 8.50$ a share
B6: US90353TAM27 | C6: — | D6: Uber Technologies, Inc. | E6: 875 | F6: Fixed Listing | G6: 01/12/2028 | H6: N | I6: USD | J6: Senior | K6: — | M6: convertible bond with a conversion price of 72.54$. If the stock trades at 94.30$ for 20 trading days it can be redeemed.
B7: US90353TAK60 | C7: — | D7: Uber Technologies, Inc. | E7: 4500 | F7: Fixed Listing | G7: 15/08/2029 | H7: Y | I7: USD | J7: Senior | K7: —
B8: USU9029YAG53 | C8: — | D8: Uber Technologies, Inc. | E8: 4500 | F8: Fixed Listing | G8: 15/08/2029 | H8: Y | I8: USD | J8: Senior | K8: —
B9: US90353TAN00 | C9: — | D9: Uber Technologies, Inc. | E9: 4300 | F9: Fixed Listing | G9: 15/01/2030 | H9: Y | I9: USD | J9: Senior | K9: —
B10: US90353TAT79 | C10: — | D10: Uber Technologies, Inc. | E10: 4150 | F10: Fixed Listing | G10: 15/01/2031 | H10: Y | I10: USD | J10: Senior | K10: —
B11: US90353TAP57 | C11: — | D11: Uber Technologies, Inc. | E11: 4800 | F11: Fixed Listing | G11: 15/09/2034 | H11: Y | I11: USD | J11: Senior | K11: —
B12: US90353TAU43 | C12: — | D12: Uber Technologies, Inc. | E12: 4800 | F12: Fixed Listing | G12: 15/09/2035 | H12: Y | I12: USD | J12: Senior | K12: —
B13: US90353TAQ31 | C13: — | D13: Uber Technologies, Inc. | E13: 5350 | F13: Fixed Listing | G13: 15/09/2054 | H13: Y | I13: USD | J13: Senior | K13: —
E14: =+AVERAGE(E5:E13) -> 3697.2222

Sheet Board 
A1: Main | G1: auditor | H1: PwC
A2: 2026
A3: -> | B3: EPS instead of adj. EBITDA and adj. EBITDA less SBC
A4: -> | B4: EPS will account for 60% of compensation bonus, Gross Booking 30%
A5: -> | B5: shifting to a 3 years NON-GAAP bonus compensation instead of annual adj. EBITDA margin
B6: -> | C6: 90% of SBC will be based on financial performance, therefore they consider this the main long-term driver
A7: -> | B7: SBC liked to increase in safety in their departments (Delivery, Mobility, Freight) – 10% compensation
B10: Cybersecurity
B11: -> | C11: Nikesh Arora (Palo Alto Networks CEO) expertise in AI cybersecurity
B13: AV Transparency
B14: -> | C14: More transparency in the Autonomous, Mobility and Delivery safety guidelines (AM&D)
C15: AM&D safety program to govern partner deployment for future AV
B17: Electrification Strategy
B18: -> | C18: publishing the Electrification Update in order to focus more on EV and less on “Green Vehicles”
C19: 2040 net-zero goal
B22: The Board is aiming to partner with the highest amount of AV companies possible (and often investing in them) in order to have a competitive advantage as soon as someone reahces a level 5 automation.
A25: 6% of UBER is owned by the Public Investment Fund (Saudi’s investment fund)
