Workbook

Sheet Main
A1: Waste Management Inc. | E1: Price | F1: 225
E2: Share | F2: 399.71518 | G2: Q226
E3: MC | F3: =+F1*F2 -> 89935.916
E4: Cash | F4: 557 | G4: Q226
E5: Debt | F5: =+22281+1075 -> 23356 | G5: Q226
E6: EV | F6: =+F3-F4+F5 -> 112734.92
A9: CAPM | B9: =+0.0495+B10*(0.1-0.0495) -> 0.07172 | D9: WACC | E9: =+(F3/(F3+F5))*B9+(F5/(F3+F5))*B11*(1-Model!V70) -> 0.066275701
A10: BETA | B10: 0.44 | D10: PEG
A11: Cost of Debt | B11: =+0.0495+(B17/100) -> 0.057304348 | D11: FPE
D13: P/B | E13: =+F1/Model!K75 -> 9.1224181
A17: Cr Spread | B17: =+'[1]Credit Spread US'!J6 -> 0.78043478
A18: Cr Rating | B18: A- | C18: A3
B19: S&P | C19: Moody’s
A32: Solid Waste Business, managed locally
A34: WM Renewable Energy, operated through landfills gas-to-energy to produce RNG (Renewable Natural Gas)
A36: Following 2024 Sterilcycle they have been developing also Heathcare waste solutions.

Sheet Model
A1: Main
A2: in Million | B2: Q124 | C2: Q224 | D2: Q324 | E2: Q424 | F2: Q125 | G2: Q225 | H2: Q325 | I2: Q425 | J2: Q126 | K2: Q226 | L2: Q326 | M2: Q426 | Q2: 2020 | R2: =+Q2+1 -> 2021 | S2: =+R2+1 -> 2022 | T2: =+S2+1 -> 2023 | U2: =+T2+1 -> 2024 | V2: =+U2+1 -> 2025 | W2: =+V2+1 -> 2026 | X2: =+W2+1 -> 2027 | Y2: =+X2+1 -> 2028 | ... AG2: =+AF2+1 -> 2036
A4: Commercial | B4: 1316 | C4: 1330 | D4: 1359 | E4: 1366 | F4: 1380 | G4: 1398 | H4: 1419 | I4: 1433 | J4: 1429 | K4: 1485 | Q4: 4102 | R4: 4760 | S4: 4860 | T4: 5109 | U4: 5371 | V4: 5630
A5: Y/Y | F5: =+F4/B4-1 -> 0.048632219 | G5: =+G4/C4-1 -> 0.05112782 | H5: =+H4/D4-1 -> 0.04415011 | I5: =+I4/E4-1 -> 0.049048316 | J5: =+J4/F4-1 -> 0.035507246 | K5: =+K4/G4-1 -> 0.06223176 | R5: =+R4/Q4-1 -> 0.16040956 | T5: =+T4/S4-1 -> 0.051234568 | U5: =+U4/T4-1 -> 0.051282051 | V5: =+V4/U4-1 -> 0.048221933
A6: Industrial | B6: 747 | C6: 779 | D6: 797 | E6: 766 | F6: 741 | G6: 790 | H6: 808 | I6: 767 | J6: 758 | K6: 820 | Q6: 2716 | R6: 3210 | S6: 3025 | T6: 3083 | U6: 3089 | V6: 3106
A7: Y/Y | F7: =+F6/B6-1 -> -0.0080321285 | G7: =+G6/C6-1 -> 0.014120668 | H7: =+H6/D6-1 -> 0.013801757 | I7: =+I6/E6-1 -> 0.001305483 | J7: =+J6/F6-1 -> 0.02294197 | K7: =+K6/G6-1 -> 0.037974684 | R7: =+R6/Q6-1 -> 0.18188513 | T7: =+T6/S6-1 -> 0.019173554 | U7: =+U6/T6-1 -> 0.0019461563 | V7: =+V6/U6-1 -> 0.0055033992
A8: Residential | B8: 854 | C8: 863 | D8: 875 | E8: 874 | F8: 872 | G8: 872 | H8: 884 | I8: 882 | J8: 888 | K8: 911 | Q8: 2770 | R8: 3172 | S8: 3264 | T8: 3378 | U8: 3466 | V8: 3510
A9: Y/Y | F9: =+F8/B8-1 -> 0.021077283 | G9: =+G8/C8-1 -> 0.010428737 | H9: =+H8/D8-1 -> 0.010285714 | I9: =+I8/E8-1 -> 0.0091533181 | J9: =+J8/F8-1 -> 0.018348624 | K9: =+K8/G8-1 -> 0.044724771 | R9: =+R8/Q8-1 -> 0.14512635 | T9: =+T8/S8-1 -> 0.034926471 | U9: =+U8/T8-1 -> 0.026050918 | V9: =+V8/U8-1 -> 0.012694749
A10: Other Collection | B10: 698 | C10: 729 | D10: 765 | E10: 772 | F10: 753 | G10: 796 | H10: 819 | I10: 807 | J10: 794 | K10: 849 | Q10: 465 | R10: 533 | S10: 2466 | T10: 2786 | U10: 2964 | V10: 3175
A11: Y/Y | F11: =+F10/B10-1 -> 0.078796562 | G11: =+G10/C10-1 -> 0.091906722 | H11: =+H10/D10-1 -> 0.070588235 | I11: =+I10/E10-1 -> 0.045336788 | J11: =+J10/F10-1 -> 0.054448871 | K11: =+K10/G10-1 -> 0.066582915 | R11: =+R10/Q10-1 -> 0.14623656 | T11: =+T10/S10-1 -> 0.1297648 | U11: =+U10/T10-1 -> 0.063890883 | V11: =+V10/U10-1 -> 0.071187584
A12: Total Collection | B12: =+B10+B8+B6+B4 -> 3615 | C12: =+C10+C8+C6+C4 -> 3701 | D12: =+D10+D8+D6+D4 -> 3796 | E12: =+E10+E8+E6+E4 -> 3778 | F12: =+F10+F8+F6+F4 -> 3746 | G12: =+G10+G8+G6+G4 -> 3856 | H12: =+H10+H8+H6+H4 -> 3930 | I12: =+I10+I8+I6+I4 -> 3889 | ... K12: =+K10+K8+K6+K4 -> 4065 | Q12: =+Q10+Q8+Q6+Q4 -> 10053 | R12: =+R10+R8+R6+R4 -> 11675 | S12: =+S10+S8+S6+S4 -> 13615 | T12: =+T10+T8+T6+T4 -> 14356 | U12: =+U10+U8+U6+U4 -> 14890 | V12: =+V10+V8+V6+V4 -> 15421
A13: Y/Y | F13: =+F12/B12-1 -> 0.036237898 | G13: =+G12/C12-1 -> 0.041880573 | H13: =+H12/D12-1 -> 0.035300316 | I13: =+I12/E12-1 -> 0.029380625 | J13: =+J12/F12-1 -> 0.032835024 | K13: =+K12/G12-1 -> 0.054201245 | R13: =+R12/Q12-1 -> 0.16134487 | T13: =+T12/S12-1 -> 0.054425266 | U13: =+U12/T12-1 -> 0.037196991 | V13: =+V12/U12-1 -> 0.035661518
A14: Landfill | B14: 792 | C14: 873 | D14: 923 | E14: 857 | F14: 840 | G14: 1036 | H14: 995 | I14: 910 | J14: 864 | K14: 1004 | Q14: 3667 | R14: 4153 | S14: 3062 | T14: 3252 | U14: 3445 | V14: 3781
A15: Y/Y | F15: =+F14/B14-1 -> 0.060606061 | G15: =+G14/C14-1 -> 0.18671249 | H15: =+H14/D14-1 -> 0.078006501 | I15: =+I14/E14-1 -> 0.061843641 | J15: =+J14/F14-1 -> 0.028571429 | K15: =+K14/G14-1 -> -0.030888031 | R15: =+R14/Q14-1 -> 0.13253341 | T15: =+T14/S14-1 -> 0.062050947 | U15: =+U14/T14-1 -> 0.059348093 | V15: =+V14/U14-1 -> 0.097532656
A16: Transfer | B16: 309 | C16: 348 | D16: 365 | E16: 359 | F16: 336 | G16: 389 | H16: 396 | I16: 381 | J16: 348 | K16: 410 | Q16: 1855 | R16: 2072 | S16: 1166 | T16: 1257 | U16: 1381 | V16: 1502
A17: Y/Y | F17: =+F16/B16-1 -> 0.087378641 | G17: =+G16/C16-1 -> 0.11781609 | H17: =+H16/D16-1 -> 0.084931507 | I17: =+I16/E16-1 -> 0.061281337 | J17: =+J16/F16-1 -> 0.035714286 | K17: =+K16/G16-1 -> 0.053984576 | R17: =+R16/Q16-1 -> 0.11698113 | T17: =+T16/S16-1 -> 0.078044597 | U17: =+U16/T16-1 -> 0.098647574 | V17: =+V16/U16-1 -> 0.087617668
A18: Total Collection and Disposal | B18: =+B16+B14+B12 -> 4716 | C18: =+C16+C14+C12 -> 4922 | D18: =+D16+D14+D12 -> 5084 | E18: =+E16+E14+E12 -> 4994 | F18: =+F16+F14+F12 -> 4922 | G18: =+G16+G14+G12 -> 5281 | H18: =+H16+H14+H12 -> 5321 | I18: =+I16+I14+I12 -> 5180 | ... K18: =+K16+K14+K12 -> 5479 | Q18: =+Q16+Q14+Q12 -> 15575 | R18: =+R16+R14+R12 -> 17900 | S18: =+S16+S14+S12 -> 17843 | T18: =+T16+T14+T12 -> 18865 | U18: =+U16+U14+U12 -> 19716 | V18: =+V16+V14+V12 -> 20704
A19: Y/Y | F19: =+F18/B18-1 -> 0.043681086 | G19: =+G18/C18-1 -> 0.07293783 | H19: =+H18/D18-1 -> 0.046616837 | I19: =+I18/E18-1 -> 0.037244694 | J19: =+J18/F18-1 -> 0.032303941 | K19: =+K18/G18-1 -> 0.037492899 | R19: =+R18/Q18-1 -> 0.14927769 | T19: =+T18/S18-1 -> 0.057277364 | U19: =+U18/T18-1 -> 0.045109992 | V19: =+V18/U18-1 -> 0.050111584
A20: Recycling Processing | B20: 368 | C20: 405 | D20: 432 | E20: 398 | F20: 384 | G20: 381 | H20: 372 | I20: 355 | J20: 368 | K20: 403 | Q20: 1127 | R20: 1681 | S20: 1516 | T20: 1264 | U20: 1603 | V20: 1492
A21: Y/Y | F21: =+F20/B20-1 -> 0.043478261 | G21: =+G20/C20-1 -> -0.059259259 | H21: =+H20/D20-1 -> -0.13888889 | I21: =+I20/E20-1 -> -0.1080402 | J21: =+J20/F20-1 -> -0.041666667 | K21: =+K20/G20-1 -> 0.057742782 | R21: =+R20/Q20-1 -> 0.49157054 | T21: =+T20/S20-1 -> -0.16622691 | U21: =+U20/T20-1 -> 0.2681962 | V21: =+V20/U20-1 -> -0.069245165
A22: Renewable Energy | B22: 69 | C22: 69 | D22: 87 | E22: 93 | F22: 91 | G22: 115 | H22: 115 | I22: 157 | J22: 159 | K22: 157 | Q22: 1776 | R22: 2112 | S22: 312 | T22: 273 | U22: 318 | V22: 478
A23: Y/Y | F23: =+F22/B22-1 -> 0.31884058 | G23: =+G22/C22-1 -> 0.66666667 | H23: =+H22/D22-1 -> 0.32183908 | I23: =+I22/E22-1 -> 0.68817204 | J23: =+J22/F22-1 -> 0.74725275 | K23: =+K22/G22-1 -> 0.36521739 | R23: =+R22/Q22-1 -> 0.18918919 | T23: =+T22/S22-1 -> -0.125 | U23: =+U22/T22-1 -> 0.16483516 | V23: =+V22/U22-1 -> 0.50314465
A24: WM Business | B24: =+B22+B20+B18 -> 5153 | C24: =+C22+C20+C18 -> 5396 | D24: =+D22+D20+D18 -> 5603 | E24: =+E22+E20+E18 -> 5485 | F24: =+F22+F20+F18 -> 5397 | G24: =+G22+G20+G18 -> 5777 | H24: =+H22+H20+H18 -> 5808 | I24: =+I22+I20+I18 -> 5692 | ... K24: =+K22+K20+K18 -> 6039 | S24: =+S22+S20+S18 -> 19671 | T24: =+T22+T20+T18 -> 20402 | U24: =+U22+U20+U18 -> 21637 | V24: =+V22+V20+V18 -> 22674
A25: Y/Y | F25: =+F24/B24-1 -> 0.047351058 | G25: =+G24/C24-1 -> 0.070607858 | H25: =+H24/D24-1 -> 0.036587542 | I25: =+I24/E24-1 -> 0.037739289 | J25: =+J24/F24-1 -> 0.039095794 | K25: =+K24/G24-1 -> 0.045352259 | T25: =+T24/S24-1 -> 0.037161303 | U25: =+U24/T24-1 -> 0.060533281 | V25: =+V24/U24-1 -> 0.047927162
A26: WM Healthcare | B26: 0 | C26: 0 | D26: 0 | E26: 403 | F26: 619 | G26: 646 | H26: 628 | I26: 616 | J26: 614 | K26: 638 | S26: 0 | T26: 0 | U26: 403 | V26: 2508
A27: Y/Y | F27: =+F26/B26-1 -> #DIV/0! | G27: =+G26/C26-1 -> #DIV/0! | H27: =+H26/D26-1 -> #DIV/0! | I27: =+I26/E26-1 -> 0.52853598 | J27: =+J26/F26-1 -> -0.0080775444 | K27: =+K26/G26-1 -> -0.012383901 | T27: =+T26/S26-1 -> #DIV/0! | U27: =+U26/T26-1 -> #DIV/0! | V27: =+V26/U26-1 -> 5.2233251
A28: Corporate and Other | B28: 6 | C28: 6 | D28: 6 | E28: 5 | F28: 2 | G28: 7 | H28: 7 | I28: 6 | J28: 5 | K28: 7 | Q28: -3260 | R28: -3762 | S28: 27 | T28: 24 | U28: 23 | V28: 22
A29: Y/Y | F29: =+F28/B28-1 -> -0.66666667 | G29: =+G28/C28-1 -> 0.16666667 | H29: =+H28/D28-1 -> 0.16666667 | I29: =+I28/E28-1 -> 0.2 | J29: =+J28/F28-1 -> 1.5 | K29: =+K28/G28-1 -> 0 | R29: =+R28/Q28-1 -> 0.15398773 | T29: =+T28/S28-1 -> -0.11111111 | U29: =+U28/T28-1 -> -0.041666667 | V29: =+V28/U28-1 -> -0.043478261
A30: Revenues | B30: =+B28+B26+B24 -> 5159 | C30: =+C28+C26+C24 -> 5402 | D30: =+D28+D26+D24 -> 5609 | E30: =+E28+E26+E24 -> 5893 | F30: =+F28+F26+F24 -> 6018 | G30: =+G28+G26+G24 -> 6430 | H30: =+H28+H26+H24 -> 6443 | I30: =+I28+I26+I24 -> 6314 | ... K30: =+K28+K26+K24 -> 6684 | Q30: =+Q18+Q20+Q22+Q28 -> 15218 | R30: =+R18+R20+R22+R28 -> 17931 | S30: =+S28+S26+S24 -> 19698 | T30: =+T28+T26+T24 -> 20426 | U30: =+U28+U26+U24 -> 22063 | V30: =+V28+V26+V24 -> 25204 | W30: =+V30*1.05 -> 26464.2 | X30: =+W30*1.12 -> 29639.904 | Y30: =+X30*1.11 -> 32900.293 | Z30: =+Y30*1.1 -> 36190.323 | AA30: =+Z30*1.09 -> 39447.452 | AB30: =+AA30*1.08 -> 42603.248 | AC30: =+AB30*1.07 -> 45585.475 | AD30: =+AC30*1.07 -> 48776.459 | AE30: =+AD30*1.07 -> 52190.811 | AF30: =+AE30*1.07 -> 55844.167 | AG30: =+AF30*1.07 -> 59753.259
A31: Y/Y | F31: =+F30/B30-1 -> 0.16650514 | G31: =+G30/C30-1 -> 0.19029989 | H31: =+H30/D30-1 -> 0.14868961 | I31: =+I30/E30-1 -> 0.071440692 | J31: =+J30/F30-1 -> 0.034729146 | K31: =+K30/G30-1 -> 0.039502333 | R31: =+R30/Q30-1 -> 0.17827573 | S31: =+S30/R30-1 -> 0.09854442 | T31: =+T30/S30-1 -> 0.036958067 | U31: =+U30/T30-1 -> 0.080142955 | V31: =+V30/U30-1 -> 0.14236505 | W31: =+W30/V30-1 -> 0.05 | X31: =+X30/W30-1 -> 0.12 | Y31: =+Y30/X30-1 -> 0.11 | ... AG31: =+AG30/AF30-1 -> 0.07
A32: COGS | B32: 3140 | C32: 3291 | D32: 3399 | E32: 3553 | F32: 3612 | G32: 3803 | H32: 3833 | I32: 3693 | J32: 3694 | K32: 3955 | Q32: 9341 | R32: 11111 | S32: 12294 | T32: 12606 | U32: 13383 | V32: 15012 | W32: =+W30-W34 -> 15746.199 | X32: =+X30-X34 -> 17487.543 | Y32: =+Y30-Y34 -> 19246.672 | Z32: =+Z30-Z34 -> 20990.387 | AA32: =+AA30-AA34 -> 22682.285 | AB32: =+AB30-AB34 -> 24283.851 | AC32: =+AC30-AC34 -> 25755.794 | AD32: =+AD30-AD34 -> 27314.817 | ... AG32: =+AG30-AG34 -> 32565.526
B33: =+B32/B$30 -> 0.60864509 | C33: =+C32/C$30 -> 0.60921881 | D33: =+D32/D$30 -> 0.60599037 | E33: =+E32/E$30 -> 0.60291872 | F33: =+F32/F$30 -> 0.6001994 | G33: =+G32/G$30 -> 0.59144635 | H33: =+H32/H$30 -> 0.5949092 | I33: =+I32/I$30 -> 0.58489072 | ... K33: =+K32/K$30 -> 0.59171155 | Q33: =+Q32/Q$30 -> 0.61381259 | R33: =+R32/R$30 -> 0.61965311 | S33: =+S32/S$30 -> 0.62412428 | T33: =+T32/T$30 -> 0.61715461 | U33: =+U32/U$30 -> 0.60658115 | V33: =+V32/V$30 -> 0.59561974 | W33: =+W32/W$30 -> 0.595 | X33: =+X32/X$30 -> 0.59 | ... AG33: =+AG32/AG$30 -> 0.545
A34: Gross Profit | B34: =+B30-B32 -> 2019 | C34: =+C30-C32 -> 2111 | D34: =+D30-D32 -> 2210 | E34: =+E30-E32 -> 2340 | F34: =+F30-F32 -> 2406 | G34: =+G30-G32 -> 2627 | H34: =+H30-H32 -> 2610 | I34: =+I30-I32 -> 2621 | ... K34: =+K30-K32 -> 2729 | Q34: =+Q30-Q32 -> 5877 | R34: =+R30-R32 -> 6820 | S34: =+S30-S32 -> 7404 | T34: =+T30-T32 -> 7820 | U34: =+U30-U32 -> 8680 | V34: =+V30-V32 -> 10192 | W34: =+W30*0.405 -> 10718.001 | X34: =+X30*0.41 -> 12152.361 | Y34: =+Y30*0.415 -> 13653.622 | Z34: =+Z30*0.42 -> 15199.936 | AA34: =+AA30*0.425 -> 16765.167 | AB34: =+AB30*0.43 -> 18319.397 | AC34: =+AC30*0.435 -> 19829.682 | AD34: =+AD30*0.44 -> 21461.642 | AE34: =+AE30*0.445 -> 23224.911 | AF34: =+AF30*0.45 -> 25129.875 | AG34: =+AG30*0.455 -> 27187.733
B35: =+B34/B$30 -> 0.39135491 | C35: =+C34/C$30 -> 0.39078119 | D35: =+D34/D$30 -> 0.39400963 | E35: =+E34/E$30 -> 0.39708128 | F35: =+F34/F$30 -> 0.3998006 | G35: =+G34/G$30 -> 0.40855365 | H35: =+H34/H$30 -> 0.4050908 | I35: =+I34/I$30 -> 0.41510928 | ... K35: =+K34/K$30 -> 0.40828845 | Q35: =+Q34/Q$30 -> 0.38618741 | R35: =+R34/R$30 -> 0.38034689 | S35: =+S34/S$30 -> 0.37587572 | T35: =+T34/T$30 -> 0.38284539 | U35: =+U34/U$30 -> 0.39341885 | V35: =+V34/V$30 -> 0.40438026 | W35: =+W34/W$30 -> 0.405 | X35: =+X34/X$30 -> 0.41 | ... AG35: =+AG34/AG$30 -> 0.455
A36: SG&A | B36: 491 | C36: 501 | D36: 525 | E36: 747 | F36: 687 | G36: 696 | H36: 665 | I36: 674 | J36: 707 | K36: 683 | Q36: 1728 | R36: 1864 | S36: 1938 | T36: 1926 | U36: 2264 | V36: 2722 | W36: =+V36*1.15 -> 3130.3 | X36: =+W36*1.15 -> 3599.845 | Y36: =+X36*1.15 -> 4139.8218 | Z36: =+Y36*1.1 -> 4553.8039 | AA36: =+Z36*1.1 -> 5009.1843 | AB36: =+AA36*1.1 -> 5510.1027 | AC36: =+AB36*1.1 -> 6061.113 | AD36: =+AC36*1.1 -> 6667.2243 | AE36: =+AD36*1.05 -> 7000.5855 | AF36: =+AE36*1.05 -> 7350.6148 | AG36: =+AF36*1.05 -> 7718.1456
B37: =+B36/B$30 -> 0.095173483 | C37: =+C36/C$30 -> 0.092743428 | D37: =+D36/D$30 -> 0.093599572 | E37: =+E36/E$30 -> 0.12676056 | F37: =+F36/F$30 -> 0.11415753 | G37: =+G36/G$30 -> 0.10824261 | H37: =+H36/H$30 -> 0.10321279 | I37: =+I36/I$30 -> 0.10674691 | ... K37: =+K36/K$30 -> 0.10218432 | Q37: =+Q36/Q$30 -> 0.11354974 | R37: =+R36/R$30 -> 0.10395405 | S37: =+S36/S$30 -> 0.098385623 | T37: =+T36/T$30 -> 0.094291589 | U37: =+U36/U$30 -> 0.10261524 | V37: =+V36/V$30 -> 0.10799873 | W37: =+W36/W$30 -> 0.11828432 | X37: =+X36/X$30 -> 0.12145265 | ... AG37: =+AG36/AG$30 -> 0.12916694
A38: D&A | B38: 514 | C38: 543 | D38: 558 | E38: 652 | F38: 691 | G38: 744 | H38: 729 | I38: 770 | J38: 735 | K38: 777 | Q38: 1671 | R38: 1999 | S38: 2038 | T38: 2071 | U38: 2267 | V38: 2863 | W38: =+V38*1.15 -> 3292.45 | X38: =+W38*1.15 -> 3786.3175 | Y38: =+X38*1.15 -> 4354.2651 | Z38: =+Y38*1.1 -> 4789.6916 | AA38: =+Z38*1.1 -> 5268.6608 | AB38: =+AA38*1.1 -> 5795.5269 | AC38: =+AB38*1.1 -> 6375.0796 | AD38: =+AC38*1.1 -> 7012.5875 | AE38: =+AD38*1.05 -> 7363.2169 | AF38: =+AE38*1.05 -> 7731.3777 | AG38: =+AF38*1.05 -> 8117.9466
B39: =+B38/B$30 -> 0.099631712 | C39: =+C38/C$30 -> 0.10051833 | D39: =+D38/D$30 -> 0.099482974 | E39: =+E38/E$30 -> 0.11063974 | F39: =+F38/F$30 -> 0.1148222 | G39: =+G38/G$30 -> 0.11570762 | H39: =+H38/H$30 -> 0.11314605 | I39: =+I38/I$30 -> 0.12195122 | ... K39: =+K38/K$30 -> 0.11624776 | Q39: =+Q38/Q$30 -> 0.10980418 | R39: =+R38/R$30 -> 0.11148291 | S39: =+S38/S$30 -> 0.10346228 | T39: =+T38/T$30 -> 0.10139038 | U39: =+U38/U$30 -> 0.10275121 | V39: =+V38/V$30 -> 0.11359308 | W39: =+W38/W$30 -> 0.12441147 | X39: =+X38/X$30 -> 0.12774392 | ... AG39: =+AG38/AG$30 -> 0.13585781
A40: Restructuring | B40: 0 | C40: 0 | D40: 2 | E40: 2 | F40: 13 | G40: 12 | H40: 14 | I40: 12 | J40: 4 | K40: 6 | Q40: 9 | R40: 8 | S40: 1 | T40: 5 | U40: 4 | V40: 51 | W40: 20 | X40: 20 | Y40: 20 | Z40: 20 | AA40: 20 | AB40: 20 | AC40: 20 | AD40: 20 | AE40: 20 | AF40: 20 | AG40: 20
B41: =+B40/B$30 -> 0 | C41: =+C40/C$30 -> 0 | D41: =+D40/D$30 -> 0.0003565698 | E41: =+E40/E$30 -> 0.00033938571 | F41: =+F40/F$30 -> 0.0021601861 | G41: =+G40/G$30 -> 0.0018662519 | H41: =+H40/H$30 -> 0.0021729008 | I41: =+I40/I$30 -> 0.0019005385 | ... K41: =+K40/K$30 -> 0.00089766607 | Q41: =+Q40/Q$30 -> 0.00059140492 | R41: =+R40/R$30 -> 0.0004461547 | S41: =+S40/S$30 -> 5.0766575e-05 | T41: =+T40/T$30 -> 0.00024478606 | U41: =+U40/U$30 -> 0.00018129901 | V41: =+V40/V$30 -> 0.0020234883 | W41: =+W40/W$30 -> 0.00075573794 | X41: =+X40/X$30 -> 0.00067476602 | ... AG41: =+AG40/AG$30 -> 0.00033470978
...

Sheet Bond
A1: Main
B3: ISIN | C3: Bond Type | D3: Immediate Issuer | E3: Coupon (%) | F3: Maturity Date | G3: Callable | H3: Currency | I3: Seniority Level | J3: Yield To Worst
B4: US94106LBX64 | C4: - | D4: Waste Management, Inc. | E4: 4.95 | F4: 46571 | G4: Yes | H4: USD | I4: Senior | J4: 4.294
B5: US94106LBE83 | C5: - | D5: Waste Management, Inc. | E5: 3.15 | F5: 46706 | G5: Yes | H5: USD | I5: Senior | J5: 4.335
B6: US94106LBN82 | C6: - | D6: Waste Management, Inc. | E6: 1.15 | F6: 46827 | G6: Yes | H6: USD | I6: Senior | J6: 4.358
B7: US94106LCB36 | C7: - | D7: Waste Management, Inc. | E7: 4.5 | F7: 46827 | G7: Yes | H7: USD | I7: Senior | J7: 4.438
B8: US902917AH67 | C8: - | D8: Waste Management, Inc. | E8: 7 | F8: 46949 | G8: Yes | H8: USD | I8: Senior | J8: 4.544
B9: US858912AC34 | C9: - | D9: Stericycle, Inc. | E9: 3.875 | F9: 47133 | G9: Yes | H9: USD | I9: Senior | J9: 4.485
B10: US94106LBZ13 | C10: - | D10: Waste Management, Inc. | E10: 3.875 | F10: 47133 | G10: Yes | H10: USD | I10: Senior | J10: 4.485
B11: US94106LCA52 | C11: - | D11: Waste Management, Inc. | E11: 3.875 | F11: 47133 | G11: Yes | H11: USD | I11: Senior | J11: 4.485
B12: USU85881AC12 | C12: - | D12: Stericycle, Inc. | E12: 3.875 | F12: 47133 | G12: Yes | H12: USD | I12: Senior | J12: 4.485
B13: USU94106AK47 | C13: - | D13: Waste Management, Inc. | E13: 3.875 | F13: 47133 | G13: Yes | H13: USD | I13: Senior | J13: 4.485
B14: US94106LBV09 | C14: - | D14: Waste Management, Inc. | E14: 4.875 | F14: 47164 | G14: Yes | H14: USD | I14: Senior | J14: 4.533
B15: US94106LAG41 | C15: - | D15: Waste Management, Inc. | E15: 7.375 | F15: 47253 | G15: Yes | H15: USD | I15: Senior | J15: 5.06
... B34: US94106LCF40 | C34: - | D34: Waste Management, Inc. | E34: 5.35 | F34: 56537 | G34: Yes | H34: USD | I34: Senior | J34: 5.852
B35: US89351YAA70 | C35: - | D35: TransAmerican Waste Industries, I... | E35: 10 | F35: - | G35: -- | H35: USD | I35: - | J35: -
E37: =+AVERAGE(E4:E35) -> 4.5084063
